Workbook
Name Date_Range_Pb_2014: 'Lead (30-Day_Avg)'!#REF!
Name Lead_Table_2014: 'Lead (30-Day_Avg)'!#REF!
Name Month_Num_Arsenic: 'Arsenic (Daily)'!#REF!
Name Month_Num_Lead: 'Lead (30-Day_Avg)'!#REF!
Name Reporting_Limit_Table: #REF!
Name Station_1_As_2014: 'Arsenic (Daily)'!#REF!
Name Station_1_Pb_2014: 'Lead (30-Day_Avg)'!#REF!
Name Station_2_As_2014: 'Arsenic (Daily)'!#REF!
Name Station_2_Pb_2014: 'Lead (30-Day_Avg)'!#REF!
Name Station_4_As_2014: 'Arsenic (Daily)'!#REF!
Name Station_4_Pb_2014: 'Lead (30-Day_Avg)'!#REF!
Name Station_5_As_2014: 'Arsenic (Daily)'!#REF!
Name Station_5_Pb_2014: 'Lead (30-Day_Avg)'!#REF!
Name Date_Range_Pb_2014: 'Lead (30-Day_Avg)'!#REF!
Name Lead_Table_2014: 'Lead (30-Day_Avg)'!#REF!
Name Month_Num_Arsenic: 'Arsenic (Daily)'!#REF!
Name Month_Num_Lead: 'Lead (30-Day_Avg)'!#REF!
Name Reporting_Limit_Table: #REF!
Name Station_1_As_2014: 'Arsenic (Daily)'!#REF!
Name Station_1_Pb_2014: 'Lead (30-Day_Avg)'!#REF!
Name Station_2_As_2014: 'Arsenic (Daily)'!#REF!
Name Station_2_Pb_2014: 'Lead (30-Day_Avg)'!#REF!
Name Station_4_As_2014: 'Arsenic (Daily)'!#REF!
Name Station_4_Pb_2014: 'Lead (30-Day_Avg)'!#REF!
Name Station_5_As_2014: 'Arsenic (Daily)'!#REF!
Name Station_5_Pb_2014: 'Lead (30-Day_Avg)'!#REF!
Name Date_Range_Pb_2014: 'Lead (30-Day_Avg)'!#REF!
Name Lead_Table_2014: 'Lead (30-Day_Avg)'!#REF!
Name Month_Num_Arsenic: 'Arsenic (Daily)'!#REF!
Name Month_Num_Lead: 'Lead (30-Day_Avg)'!#REF!
Name Reporting_Limit_Table: #REF!
Name Station_1_As_2014: 'Arsenic (Daily)'!#REF!
Name Station_1_Pb_2014: 'Lead (30-Day_Avg)'!#REF!
Name Station_2_As_2014: 'Arsenic (Daily)'!#REF!
Name Station_2_Pb_2014: 'Lead (30-Day_Avg)'!#REF!
Name Station_4_As_2014: 'Arsenic (Daily)'!#REF!
Name Station_4_Pb_2014: 'Lead (30-Day_Avg)'!#REF!
Name Station_5_As_2014: 'Arsenic (Daily)'!#REF!
Name Station_5_Pb_2014: 'Lead (30-Day_Avg)'!#REF!
Name Date_Range_Pb_2014: 'Lead (30-Day_Avg)'!#REF!
Name Lead_Table_2014: 'Lead (30-Day_Avg)'!#REF!
Name Month_Num_Arsenic: 'Arsenic (Daily)'!#REF!
Name Month_Num_Lead: 'Lead (30-Day_Avg)'!#REF!
Name Reporting_Limit_Table: #REF!
Name Station_1_As_2014: 'Arsenic (Daily)'!#REF!
Name Station_1_Pb_2014: 'Lead (30-Day_Avg)'!#REF!
Name Station_2_As_2014: 'Arsenic (Daily)'!#REF!
Name Station_2_Pb_2014: 'Lead (30-Day_Avg)'!#REF!
Name Station_4_As_2014: 'Arsenic (Daily)'!#REF!
Name Station_4_Pb_2014: 'Lead (30-Day_Avg)'!#REF!
Name Station_5_As_2014: 'Arsenic (Daily)'!#REF!
Name Station_5_Pb_2014: 'Lead (30-Day_Avg)'!#REF!
Name Date_Range_Pb_2014: 'Lead (30-Day_Avg)'!#REF!
Name Lead_Table_2014: 'Lead (30-Day_Avg)'!#REF!
Name Month_Num_Arsenic: 'Arsenic (Daily)'!#REF!
Name Month_Num_Lead: 'Lead (30-Day_Avg)'!#REF!
Name Reporting_Limit_Table: #REF!
Name Station_1_As_2014: 'Arsenic (Daily)'!#REF!
Name Station_1_Pb_2014: 'Lead (30-Day_Avg)'!#REF!
Name Station_2_As_2014: 'Arsenic (Daily)'!#REF!

Sheet 2018 Summary
A1: Weekend / Weekday Ambient Monitor Results
C4: Lead (µg/m3) | F4: Arsenic (ng/m3)
A5: Parameter | B5: WeekEND | C5: WeekDAY | D5: % WD Diff | E5: WeekEND | F5: WeekDAY | G5: % WD Diff
A6: Maximum: | B6: ='Lead (30-Day_Avg)'!Z5 | C6: ='Lead (30-Day_Avg)'!AA5 | D6: =(C6-B6)/B6 | E6: ='Arsenic (Daily)'!V5 | F6: ='Arsenic (Daily)'!W5 | G6: =(F6-E6)/E6
A7: 90th percentile: | B7: ='Lead (30-Day_Avg)'!Z6 | C7: ='Lead (30-Day_Avg)'!AA6 | D7: =(C7-B7)/B7 | E7: ='Arsenic (Daily)'!V6 | F7: ='Arsenic (Daily)'!W6 | G7: =(F7-E7)/E7
A8: 75th percentile: | B8: ='Lead (30-Day_Avg)'!Z7 | C8: ='Lead (30-Day_Avg)'!AA7 | D8: =(C8-B8)/B8 | E8: ='Arsenic (Daily)'!V7 | F8: ='Arsenic (Daily)'!W7 | G8: =(F8-E8)/E8
A9: Average: | B9: ='Lead (30-Day_Avg)'!Z8 | C9: ='Lead (30-Day_Avg)'!AA8 | D9: =(C9-B9)/B9 | E9: ='Arsenic (Daily)'!V8 | F9: ='Arsenic (Daily)'!W8 | G9: =(F9-E9)/E9
A12: Excluding extraordinary events (looking at "normal" operations only).
A15: LEAD
C16: Averages | G16: Maximum
A17: Month | B17: Station 1 | C17: Station 2 | D17: Station 4 | E17: Station 5 | F17: Station 1 | G17: Station 2 | H17: Station 4 | I17: Station 5
A18: January | B18: ='Lead (30-Day_Avg)'!AA400 | C18: ='Lead (30-Day_Avg)'!AB400 | D18: ='Lead (30-Day_Avg)'!AC400 | E18: ='Lead (30-Day_Avg)'!AD400 | F18: ='Lead (30-Day_Avg)'!AA401 | G18: ='Lead (30-Day_Avg)'!AB401 | H18: ='Lead (30-Day_Avg)'!AC401 | I18: ='Lead (30-Day_Avg)'!AD401 | J18: =AVERAGE(B18:E18) | K18: =(J18-$B$33)/$B$33
A19: February | B19: ='Lead (30-Day_Avg)'!AA428 | C19: ='Lead (30-Day_Avg)'!AB428 | D19: ='Lead (30-Day_Avg)'!AC428 | E19: ='Lead (30-Day_Avg)'!AD428 | F19: ='Lead (30-Day_Avg)'!AA429 | G19: ='Lead (30-Day_Avg)'!AB429 | H19: ='Lead (30-Day_Avg)'!AC429 | I19: ='Lead (30-Day_Avg)'!AD429 | J19: =AVERAGE(B19:E19) | K19: =(J19-$B$33)/$B$33
A20: March | B20: ='Lead (30-Day_Avg)'!AA459 | C20: ='Lead (30-Day_Avg)'!AB459 | D20: ='Lead (30-Day_Avg)'!AC459 | E20: ='Lead (30-Day_Avg)'!AD459 | F20: ='Lead (30-Day_Avg)'!AA460 | G20: ='Lead (30-Day_Avg)'!AB460 | H20: ='Lead (30-Day_Avg)'!AC460 | I20: ='Lead (30-Day_Avg)'!AD460 | J20: =AVERAGE(B20:E20) | K20: =(J20-$B$33)/$B$33
A21: April | B21: ='Lead (30-Day_Avg)'!AA489 | C21: ='Lead (30-Day_Avg)'!AB489 | D21: ='Lead (30-Day_Avg)'!AC489 | E21: ='Lead (30-Day_Avg)'!AD489 | F21: ='Lead (30-Day_Avg)'!AA490 | G21: ='Lead (30-Day_Avg)'!AB490 | H21: ='Lead (30-Day_Avg)'!AC490 | I21: ='Lead (30-Day_Avg)'!AD490 | J21: =AVERAGE(B21:E21) | K21: =(J21-$B$33)/$B$33
A22: May | B22: ='Lead (30-Day_Avg)'!AA520 | C22: ='Lead (30-Day_Avg)'!AB520 | D22: ='Lead (30-Day_Avg)'!AC520 | E22: ='Lead (30-Day_Avg)'!AD520 | F22: ='Lead (30-Day_Avg)'!AA521 | G22: ='Lead (30-Day_Avg)'!AB521 | H22: ='Lead (30-Day_Avg)'!AC521 | I22: ='Lead (30-Day_Avg)'!AD521 | J22: =AVERAGE(B22:E22) | K22: =(J22-$B$33)/$B$33
A23: June | B23: ='Lead (30-Day_Avg)'!AA550 | C23: ='Lead (30-Day_Avg)'!AB550 | D23: ='Lead (30-Day_Avg)'!AC550 | E23: ='Lead (30-Day_Avg)'!AD550 | F23: ='Lead (30-Day_Avg)'!AA551 | G23: ='Lead (30-Day_Avg)'!AB551 | H23: ='Lead (30-Day_Avg)'!AC551 | I23: ='Lead (30-Day_Avg)'!AD551 | J23: =AVERAGE(B23:E23) | K23: =(J23-$B$33)/$B$33
A24: July | B24: ='Lead (30-Day_Avg)'!AA581 | C24: ='Lead (30-Day_Avg)'!AB581 | D24: ='Lead (30-Day_Avg)'!AC581 | E24: ='Lead (30-Day_Avg)'!AD581 | F24: ='Lead (30-Day_Avg)'!AA582 | G24: ='Lead (30-Day_Avg)'!AB582 | H24: ='Lead (30-Day_Avg)'!AC582 | I24: ='Lead (30-Day_Avg)'!AD582 | J24: =AVERAGE(B24:E24) | K24: =(J24-$B$33)/$B$33
A25: August | B25: ='Lead (30-Day_Avg)'!AA612 | C25: ='Lead (30-Day_Avg)'!AB612 | D25: ='Lead (30-Day_Avg)'!AC612 | E25: ='Lead (30-Day_Avg)'!AD612 | F25: ='Lead (30-Day_Avg)'!AA613 | G25: ='Lead (30-Day_Avg)'!AB613 | H25: ='Lead (30-Day_Avg)'!AC613 | I25: ='Lead (30-Day_Avg)'!AD613 | J25: =AVERAGE(B25:E25) | K25: =(J25-$B$33)/$B$33
A26: September | B26: ='Lead (30-Day_Avg)'!AA642 | C26: ='Lead (30-Day_Avg)'!AB642 | D26: ='Lead (30-Day_Avg)'!AC642 | E26: ='Lead (30-Day_Avg)'!AD642 | F26: ='Lead (30-Day_Avg)'!AA643 | G26: ='Lead (30-Day_Avg)'!AB643 | H26: ='Lead (30-Day_Avg)'!AC643 | I26: ='Lead (30-Day_Avg)'!AD643 | J26: =AVERAGE(B26:E26) | K26: =(J26-$B$33)/$B$33
A27: October | B27: ='Lead (30-Day_Avg)'!AA673 | C27: ='Lead (30-Day_Avg)'!AB673 | D27: ='Lead (30-Day_Avg)'!AC673 | E27: ='Lead (30-Day_Avg)'!AD673 | F27: ='Lead (30-Day_Avg)'!AA674 | G27: ='Lead (30-Day_Avg)'!AB674 | H27: ='Lead (30-Day_Avg)'!AC674 | I27: ='Lead (30-Day_Avg)'!AD674 | J27: =AVERAGE(B27:E27) | K27: =(J27-$B$33)/$B$33
A28: November | B28: ='Lead (30-Day_Avg)'!AA703 | C28: ='Lead (30-Day_Avg)'!AB703 | D28: ='Lead (30-Day_Avg)'!AC703 | E28: ='Lead (30-Day_Avg)'!AD703 | F28: ='Lead (30-Day_Avg)'!AA704 | G28: ='Lead (30-Day_Avg)'!AB704 | H28: ='Lead (30-Day_Avg)'!AC704 | I28: ='Lead (30-Day_Avg)'!AD704 | J28: =AVERAGE(B28:E28) | K28: =(J28-$B$33)/$B$33
A29: December | B29: ='Lead (30-Day_Avg)'!AA734 | C29: ='Lead (30-Day_Avg)'!AB734 | D29: ='Lead (30-Day_Avg)'!AC734 | E29: ='Lead (30-Day_Avg)'!AD734 | F29: ='Lead (30-Day_Avg)'!AA735 | G29: ='Lead (30-Day_Avg)'!AB735 | H29: ='Lead (30-Day_Avg)'!AC735 | I29: ='Lead (30-Day_Avg)'!AD735 | J29: =AVERAGE(B29:E29) | K29: =(J29-$B$33)/$B$33
B31: ='Lead (30-Day_Avg)'!AA741 | C31: ='Lead (30-Day_Avg)'!AB741 | D31: ='Lead (30-Day_Avg)'!AC741 | E31: ='Lead (30-Day_Avg)'!AD741 | F31: ='Lead (30-Day_Avg)'!AA742 | G31: ='Lead (30-Day_Avg)'!AB742 | H31: ='Lead (30-Day_Avg)'!AC742 | I31: ='Lead (30-Day_Avg)'!AD742
B33: ='Lead (30-Day_Avg)'!AA744
A36: ARSENIC
C37: Averages | G37: Maximum
A38: Month | B38: Station 1 | C38: Station 2 | D38: Station 4 | E38: Station 5 | F38: Station 1 | G38: Station 2 | H38: Station 4 | I38: Station 5
A39: January | B39: ='Arsenic (Daily)'!V35 | C39: ='Arsenic (Daily)'!W35 | D39: ='Arsenic (Daily)'!X35 | E39: ='Arsenic (Daily)'!Y35 | F39: ='Arsenic (Daily)'!V36 | G39: ='Arsenic (Daily)'!W36 | H39: ='Arsenic (Daily)'!X36 | I39: ='Arsenic (Daily)'!Y36 | J39: =AVERAGE(B39:E39) | K39: =(J39-$B$54)/$B$54
A40: February | B40: ='Arsenic (Daily)'!V63 | C40: ='Arsenic (Daily)'!W63 | D40: ='Arsenic (Daily)'!X63 | E40: ='Arsenic (Daily)'!Y63 | F40: ='Arsenic (Daily)'!V64 | G40: ='Arsenic (Daily)'!W64 | H40: ='Arsenic (Daily)'!X64 | I40: ='Arsenic (Daily)'!Y64 | J40: =AVERAGE(B40:E40) | K40: =(J40-$B$54)/$B$54
A41: March | B41: ='Arsenic (Daily)'!V94 | C41: ='Arsenic (Daily)'!W94 | D41: ='Arsenic (Daily)'!X94 | E41: ='Arsenic (Daily)'!Y94 | F41: ='Arsenic (Daily)'!V95 | G41: ='Arsenic (Daily)'!W95 | H41: ='Arsenic (Daily)'!X95 | I41: ='Arsenic (Daily)'!Y95 | J41: =AVERAGE(B41:E41) | K41: =(J41-$B$54)/$B$54
A42: April | B42: ='Arsenic (Daily)'!V125 | C42: ='Arsenic (Daily)'!W125 | D42: ='Arsenic (Daily)'!X125 | E42: ='Arsenic (Daily)'!Y125 | F42: ='Arsenic (Daily)'!V126 | G42: ='Arsenic (Daily)'!W126 | H42: ='Arsenic (Daily)'!X126 | I42: ='Arsenic (Daily)'!Y126 | J42: =AVERAGE(B42:E42) | K42: =(J42-$B$54)/$B$54
A43: May | B43: ='Arsenic (Daily)'!V155 | C43: ='Arsenic (Daily)'!W155 | D43: ='Arsenic (Daily)'!X155 | E43: ='Arsenic (Daily)'!Y155 | F43: ='Arsenic (Daily)'!V156 | G43: ='Arsenic (Daily)'!W156 | H43: ='Arsenic (Daily)'!X156 | I43: ='Arsenic (Daily)'!Y156 | J43: =AVERAGE(B43:E43) | K43: =(J43-$B$54)/$B$54
A44: June | B44: ='Arsenic (Daily)'!V186 | C44: ='Arsenic (Daily)'!W186 | D44: ='Arsenic (Daily)'!X186 | E44: ='Arsenic (Daily)'!Y186 | F44: ='Arsenic (Daily)'!V187 | G44: ='Arsenic (Daily)'!W187 | H44: ='Arsenic (Daily)'!X187 | I44: ='Arsenic (Daily)'!Y187 | J44: =AVERAGE(B44:E44) | K44: =(J44-$B$54)/$B$54
A45: July | B45: ='Arsenic (Daily)'!V216 | C45: ='Arsenic (Daily)'!W216 | D45: ='Arsenic (Daily)'!X216 | E45: ='Arsenic (Daily)'!Y216 | F45: ='Arsenic (Daily)'!V217 | G45: ='Arsenic (Daily)'!W217 | H45: ='Arsenic (Daily)'!X217 | I45: ='Arsenic (Daily)'!Y217 | J45: =AVERAGE(B45:E45) | K45: =(J45-$B$54)/$B$54
A46: August | B46: ='Arsenic (Daily)'!V247 | C46: ='Arsenic (Daily)'!W247 | D46: ='Arsenic (Daily)'!X247 | E46: ='Arsenic (Daily)'!Y247 | F46: ='Arsenic (Daily)'!V248 | G46: ='Arsenic (Daily)'!W248 | H46: ='Arsenic (Daily)'!X248 | I46: ='Arsenic (Daily)'!Y248 | J46: =AVERAGE(B46:E46) | K46: =(J46-$B$54)/$B$54
A47: September | B47: ='Arsenic (Daily)'!V278 | C47: ='Arsenic (Daily)'!W278 | D47: ='Arsenic (Daily)'!X278 | E47: ='Arsenic (Daily)'!Y278 | F47: ='Arsenic (Daily)'!V279 | G47: ='Arsenic (Daily)'!W279 | H47: ='Arsenic (Daily)'!X279 | I47: ='Arsenic (Daily)'!Y279 | J47: =AVERAGE(B47:E47) | K47: =(J47-$B$54)/$B$54
A48: October | B48: ='Arsenic (Daily)'!V308 | C48: ='Arsenic (Daily)'!W308 | D48: ='Arsenic (Daily)'!X308 | E48: ='Arsenic (Daily)'!Y308 | F48: ='Arsenic (Daily)'!V309 | G48: ='Arsenic (Daily)'!W309 | H48: ='Arsenic (Daily)'!X309 | I48: ='Arsenic (Daily)'!Y309 | J48: =AVERAGE(B48:E48) | K48: =(J48-$B$54)/$B$54
A49: November | B49: ='Arsenic (Daily)'!V339 | C49: ='Arsenic (Daily)'!W339 | D49: ='Arsenic (Daily)'!X339 | E49: ='Arsenic (Daily)'!Y339 | F49: ='Arsenic (Daily)'!V340 | G49: ='Arsenic (Daily)'!W340 | H49: ='Arsenic (Daily)'!X340 | I49: ='Arsenic (Daily)'!Y340 | J49: =AVERAGE(B49:E49) | K49: =(J49-$B$54)/$B$54
A50: December | B50: ='Arsenic (Daily)'!V369 | C50: ='Arsenic (Daily)'!W369 | D50: ='Arsenic (Daily)'!X369 | E50: ='Arsenic (Daily)'!Y369 | F50: ='Arsenic (Daily)'!V370 | G50: ='Arsenic (Daily)'!W370 | H50: ='Arsenic (Daily)'!X370 | I50: ='Arsenic (Daily)'!Y370 | J50: =AVERAGE(B50:E50) | K50: =(J50-$B$54)/$B$54
...

Sheet 2019 Summary
A1: Weekend / Weekday Ambient Monitor Results
C4: Lead (µg/m3) | F4: Arsenic (ng/m3)
A5: Parameter | B5: WeekEND | C5: WeekDAY | D5: % WD Diff | E5: WeekEND | F5: WeekDAY | G5: % WD Diff
A6: Maximum: | B6: ='Lead (30-Day_Avg)'!Z5 | C6: ='Lead (30-Day_Avg)'!AA5 | D6: =(C6-B6)/B6 | E6: ='Arsenic (Daily)'!V5 | F6: ='Arsenic (Daily)'!W5 | G6: =(F6-E6)/E6
A7: 90th percentile: | B7: ='Lead (30-Day_Avg)'!Z6 | C7: ='Lead (30-Day_Avg)'!AA6 | D7: =(C7-B7)/B7 | E7: ='Arsenic (Daily)'!V6 | F7: ='Arsenic (Daily)'!W6 | G7: =(F7-E7)/E7
A8: 75th percentile: | B8: ='Lead (30-Day_Avg)'!Z7 | C8: ='Lead (30-Day_Avg)'!AA7 | D8: =(C8-B8)/B8 | E8: ='Arsenic (Daily)'!V7 | F8: ='Arsenic (Daily)'!W7 | G8: =(F8-E8)/E8
A9: Average: | B9: ='Lead (30-Day_Avg)'!Z8 | C9: ='Lead (30-Day_Avg)'!AA8 | D9: =(C9-B9)/B9 | E9: ='Arsenic (Daily)'!V8 | F9: ='Arsenic (Daily)'!W8 | G9: =(F9-E9)/E9
A12: Excluding extraordinary events (looking at "normal" operations only).
A15: LEAD
C16: Averages | G16: Maximum
A17: Month | B17: Station 1 | C17: Station 2 | D17: Station 4 | E17: Station 5 | F17: Station 1 | G17: Station 2 | H17: Station 4 | I17: Station 5
A18: January | B18: ='Lead (30-Day_Avg)'!AA400 | C18: ='Lead (30-Day_Avg)'!AB400 | D18: ='Lead (30-Day_Avg)'!AC400 | E18: ='Lead (30-Day_Avg)'!AD400 | F18: ='Lead (30-Day_Avg)'!AA401 | G18: ='Lead (30-Day_Avg)'!AB401 | H18: ='Lead (30-Day_Avg)'!AC401 | I18: ='Lead (30-Day_Avg)'!AD401 | J18: =AVERAGE(B18:E18) | K18: =(J18-$B$33)/$B$33
A19: February | B19: ='Lead (30-Day_Avg)'!AA428 | C19: ='Lead (30-Day_Avg)'!AB428 | D19: ='Lead (30-Day_Avg)'!AC428 | E19: ='Lead (30-Day_Avg)'!AD428 | F19: ='Lead (30-Day_Avg)'!AA429 | G19: ='Lead (30-Day_Avg)'!AB429 | H19: ='Lead (30-Day_Avg)'!AC429 | I19: ='Lead (30-Day_Avg)'!AD429 | J19: =AVERAGE(B19:E19) | K19: =(J19-$B$33)/$B$33
A20: March | B20: ='Lead (30-Day_Avg)'!AA459 | C20: ='Lead (30-Day_Avg)'!AB459 | D20: ='Lead (30-Day_Avg)'!AC459 | E20: ='Lead (30-Day_Avg)'!AD459 | F20: ='Lead (30-Day_Avg)'!AA460 | G20: ='Lead (30-Day_Avg)'!AB460 | H20: ='Lead (30-Day_Avg)'!AC460 | I20: ='Lead (30-Day_Avg)'!AD460 | J20: =AVERAGE(B20:E20) | K20: =(J20-$B$33)/$B$33
A21: April | B21: ='Lead (30-Day_Avg)'!AA489 | C21: ='Lead (30-Day_Avg)'!AB489 | D21: ='Lead (30-Day_Avg)'!AC489 | E21: ='Lead (30-Day_Avg)'!AD489 | F21: ='Lead (30-Day_Avg)'!AA490 | G21: ='Lead (30-Day_Avg)'!AB490 | H21: ='Lead (30-Day_Avg)'!AC490 | I21: ='Lead (30-Day_Avg)'!AD490 | J21: =AVERAGE(B21:E21) | K21: =(J21-$B$33)/$B$33
A22: May | B22: ='Lead (30-Day_Avg)'!AA520 | C22: ='Lead (30-Day_Avg)'!AB520 | D22: ='Lead (30-Day_Avg)'!AC520 | E22: ='Lead (30-Day_Avg)'!AD520 | F22: ='Lead (30-Day_Avg)'!AA521 | G22: ='Lead (30-Day_Avg)'!AB521 | H22: ='Lead (30-Day_Avg)'!AC521 | I22: ='Lead (30-Day_Avg)'!AD521 | J22: =AVERAGE(B22:E22) | K22: =(J22-$B$33)/$B$33
A23: June | B23: ='Lead (30-Day_Avg)'!AA550 | C23: ='Lead (30-Day_Avg)'!AB550 | D23: ='Lead (30-Day_Avg)'!AC550 | E23: ='Lead (30-Day_Avg)'!AD550 | F23: ='Lead (30-Day_Avg)'!AA551 | G23: ='Lead (30-Day_Avg)'!AB551 | H23: ='Lead (30-Day_Avg)'!AC551 | I23: ='Lead (30-Day_Avg)'!AD551 | J23: =AVERAGE(B23:E23) | K23: =(J23-$B$33)/$B$33
A24: July | B24: ='Lead (30-Day_Avg)'!AA581 | C24: ='Lead (30-Day_Avg)'!AB581 | D24: ='Lead (30-Day_Avg)'!AC581 | E24: ='Lead (30-Day_Avg)'!AD581 | F24: ='Lead (30-Day_Avg)'!AA582 | G24: ='Lead (30-Day_Avg)'!AB582 | H24: ='Lead (30-Day_Avg)'!AC582 | I24: ='Lead (30-Day_Avg)'!AD582 | J24: =AVERAGE(B24:E24) | K24: =(J24-$B$33)/$B$33
A25: August | B25: ='Lead (30-Day_Avg)'!AA612 | C25: ='Lead (30-Day_Avg)'!AB612 | D25: ='Lead (30-Day_Avg)'!AC612 | E25: ='Lead (30-Day_Avg)'!AD612 | F25: ='Lead (30-Day_Avg)'!AA613 | G25: ='Lead (30-Day_Avg)'!AB613 | H25: ='Lead (30-Day_Avg)'!AC613 | I25: ='Lead (30-Day_Avg)'!AD613 | J25: =AVERAGE(B25:E25) | K25: =(J25-$B$33)/$B$33
A26: September | B26: ='Lead (30-Day_Avg)'!AA642 | C26: ='Lead (30-Day_Avg)'!AB642 | D26: ='Lead (30-Day_Avg)'!AC642 | E26: ='Lead (30-Day_Avg)'!AD642 | F26: ='Lead (30-Day_Avg)'!AA643 | G26: ='Lead (30-Day_Avg)'!AB643 | H26: ='Lead (30-Day_Avg)'!AC643 | I26: ='Lead (30-Day_Avg)'!AD643 | J26: =AVERAGE(B26:E26) | K26: =(J26-$B$33)/$B$33
A27: October | B27: ='Lead (30-Day_Avg)'!AA673 | C27: ='Lead (30-Day_Avg)'!AB673 | D27: ='Lead (30-Day_Avg)'!AC673 | E27: ='Lead (30-Day_Avg)'!AD673 | F27: ='Lead (30-Day_Avg)'!AA674 | G27: ='Lead (30-Day_Avg)'!AB674 | H27: ='Lead (30-Day_Avg)'!AC674 | I27: ='Lead (30-Day_Avg)'!AD674 | J27: =AVERAGE(B27:E27) | K27: =(J27-$B$33)/$B$33
A28: November | B28: ='Lead (30-Day_Avg)'!AA703 | C28: ='Lead (30-Day_Avg)'!AB703 | D28: ='Lead (30-Day_Avg)'!AC703 | E28: ='Lead (30-Day_Avg)'!AD703 | F28: ='Lead (30-Day_Avg)'!AA704 | G28: ='Lead (30-Day_Avg)'!AB704 | H28: ='Lead (30-Day_Avg)'!AC704 | I28: ='Lead (30-Day_Avg)'!AD704 | J28: =AVERAGE(B28:E28) | K28: =(J28-$B$33)/$B$33
A29: December | B29: ='Lead (30-Day_Avg)'!AA734 | C29: ='Lead (30-Day_Avg)'!AB734 | D29: ='Lead (30-Day_Avg)'!AC734 | E29: ='Lead (30-Day_Avg)'!AD734 | F29: ='Lead (30-Day_Avg)'!AA735 | G29: ='Lead (30-Day_Avg)'!AB735 | H29: ='Lead (30-Day_Avg)'!AC735 | I29: ='Lead (30-Day_Avg)'!AD735 | J29: =AVERAGE(B29:E29) | K29: =(J29-$B$33)/$B$33
B31: ='Lead (30-Day_Avg)'!AA741 | C31: ='Lead (30-Day_Avg)'!AB741 | D31: ='Lead (30-Day_Avg)'!AC741 | E31: ='Lead (30-Day_Avg)'!AD741 | F31: ='Lead (30-Day_Avg)'!AA742 | G31: ='Lead (30-Day_Avg)'!AB742 | H31: ='Lead (30-Day_Avg)'!AC742 | I31: ='Lead (30-Day_Avg)'!AD742
B33: ='Lead (30-Day_Avg)'!AA744
A36: ARSENIC
C37: Averages | G37: Maximum
A38: Month | B38: Station 1 | C38: Station 2 | D38: Station 4 | E38: Station 5 | F38: Station 1 | G38: Station 2 | H38: Station 4 | I38: Station 5
A39: January | B39: ='Arsenic (Daily)'!V400 | C39: ='Arsenic (Daily)'!W400 | D39: ='Arsenic (Daily)'!X400 | E39: ='Arsenic (Daily)'!Y400 | F39: ='Arsenic (Daily)'!V401 | G39: ='Arsenic (Daily)'!W401 | H39: ='Arsenic (Daily)'!X401 | I39: ='Arsenic (Daily)'!Y401 | J39: =AVERAGE(B39:E39) | K39: =(J39-$B$54)/$B$54
A40: February | B40: ='Arsenic (Daily)'!V428 | C40: ='Arsenic (Daily)'!W428 | D40: ='Arsenic (Daily)'!X428 | E40: ='Arsenic (Daily)'!Y428 | F40: ='Arsenic (Daily)'!V429 | G40: ='Arsenic (Daily)'!W429 | H40: ='Arsenic (Daily)'!X429 | I40: ='Arsenic (Daily)'!Y429 | J40: =AVERAGE(B40:E40) | K40: =(J40-$B$54)/$B$54
A41: March | B41: ='Arsenic (Daily)'!V459 | C41: ='Arsenic (Daily)'!W459 | D41: ='Arsenic (Daily)'!X459 | E41: ='Arsenic (Daily)'!Y459 | F41: ='Arsenic (Daily)'!V460 | G41: ='Arsenic (Daily)'!W460 | H41: ='Arsenic (Daily)'!X460 | I41: ='Arsenic (Daily)'!Y460 | J41: =AVERAGE(B41:E41) | K41: =(J41-$B$54)/$B$54
A42: April | B42: ='Arsenic (Daily)'!V490 | C42: ='Arsenic (Daily)'!W490 | D42: ='Arsenic (Daily)'!X490 | E42: ='Arsenic (Daily)'!Y490 | F42: ='Arsenic (Daily)'!V491 | G42: ='Arsenic (Daily)'!W491 | H42: ='Arsenic (Daily)'!X491 | I42: ='Arsenic (Daily)'!Y491 | J42: =AVERAGE(B42:E42) | K42: =(J42-$B$54)/$B$54
A43: May | B43: ='Arsenic (Daily)'!V520 | C43: ='Arsenic (Daily)'!W520 | D43: ='Arsenic (Daily)'!X520 | E43: ='Arsenic (Daily)'!Y520 | F43: ='Arsenic (Daily)'!V521 | G43: ='Arsenic (Daily)'!W521 | H43: ='Arsenic (Daily)'!X521 | I43: ='Arsenic (Daily)'!Y521 | J43: =AVERAGE(B43:E43) | K43: =(J43-$B$54)/$B$54
A44: June | B44: ='Arsenic (Daily)'!V551 | C44: ='Arsenic (Daily)'!W551 | D44: ='Arsenic (Daily)'!X551 | E44: ='Arsenic (Daily)'!Y551 | F44: ='Arsenic (Daily)'!V552 | G44: ='Arsenic (Daily)'!W552 | H44: ='Arsenic (Daily)'!X552 | I44: ='Arsenic (Daily)'!Y552 | J44: =AVERAGE(B44:E44) | K44: =(J44-$B$54)/$B$54
A45: July | B45: ='Arsenic (Daily)'!V581 | C45: ='Arsenic (Daily)'!W581 | D45: ='Arsenic (Daily)'!X581 | E45: ='Arsenic (Daily)'!Y581 | F45: ='Arsenic (Daily)'!V582 | G45: ='Arsenic (Daily)'!W582 | H45: ='Arsenic (Daily)'!X582 | I45: ='Arsenic (Daily)'!Y582 | J45: =AVERAGE(B45:E45) | K45: =(J45-$B$54)/$B$54
A46: August | B46: ='Arsenic (Daily)'!V612 | C46: ='Arsenic (Daily)'!W612 | D46: ='Arsenic (Daily)'!X612 | E46: ='Arsenic (Daily)'!Y612 | F46: ='Arsenic (Daily)'!V613 | G46: ='Arsenic (Daily)'!W613 | H46: ='Arsenic (Daily)'!X613 | I46: ='Arsenic (Daily)'!Y613 | J46: =AVERAGE(B46:E46) | K46: =(J46-$B$54)/$B$54
A47: September | B47: ='Arsenic (Daily)'!V643 | C47: ='Arsenic (Daily)'!W643 | D47: ='Arsenic (Daily)'!X643 | E47: ='Arsenic (Daily)'!Y643 | F47: ='Arsenic (Daily)'!V644 | G47: ='Arsenic (Daily)'!W644 | H47: ='Arsenic (Daily)'!X644 | I47: ='Arsenic (Daily)'!Y644 | J47: =AVERAGE(B47:E47) | K47: =(J47-$B$54)/$B$54
A48: October | B48: ='Arsenic (Daily)'!V673 | C48: ='Arsenic (Daily)'!W673 | D48: ='Arsenic (Daily)'!X673 | E48: ='Arsenic (Daily)'!Y673 | F48: ='Arsenic (Daily)'!V674 | G48: ='Arsenic (Daily)'!W674 | H48: ='Arsenic (Daily)'!X674 | I48: ='Arsenic (Daily)'!Y674 | J48: =AVERAGE(B48:E48) | K48: =(J48-$B$54)/$B$54
A49: November | B49: ='Arsenic (Daily)'!V704 | C49: ='Arsenic (Daily)'!W704 | D49: ='Arsenic (Daily)'!X704 | E49: ='Arsenic (Daily)'!Y704 | F49: ='Arsenic (Daily)'!V705 | G49: ='Arsenic (Daily)'!W705 | H49: ='Arsenic (Daily)'!X705 | I49: ='Arsenic (Daily)'!Y705 | J49: =AVERAGE(B49:E49) | K49: =(J49-$B$54)/$B$54
A50: December | B50: ='Arsenic (Daily)'!V734 | C50: ='Arsenic (Daily)'!W734 | D50: ='Arsenic (Daily)'!X734 | E50: ='Arsenic (Daily)'!Y734 | F50: ='Arsenic (Daily)'!V735 | G50: ='Arsenic (Daily)'!W735 | H50: ='Arsenic (Daily)'!X735 | I50: ='Arsenic (Daily)'!Y735 | J50: =AVERAGE(B50:E50) | K50: =(J50-$B$54)/$B$54
...

Sheet 2020 Summary
A1: Weekend / Weekday Ambient Monitor Results
C4: Lead (µg/m3) | F4: Arsenic (ng/m3)
A5: Parameter | B5: WeekEND | C5: WeekDAY | D5: % WD Diff | E5: WeekEND | F5: WeekDAY | G5: % WD Diff
A6: Maximum: | B6: ='Lead (30-Day_Avg)'!Z5 | C6: ='Lead (30-Day_Avg)'!AA5 | D6: =(C6-B6)/B6 | E6: ='Arsenic (Daily)'!V5 | F6: ='Arsenic (Daily)'!W5 | G6: =(F6-E6)/E6
A7: 90th percentile: | B7: ='Lead (30-Day_Avg)'!Z6 | C7: ='Lead (30-Day_Avg)'!AA6 | D7: =(C7-B7)/B7 | E7: ='Arsenic (Daily)'!V6 | F7: ='Arsenic (Daily)'!W6 | G7: =(F7-E7)/E7
A8: 75th percentile: | B8: ='Lead (30-Day_Avg)'!Z7 | C8: ='Lead (30-Day_Avg)'!AA7 | D8: =(C8-B8)/B8 | E8: ='Arsenic (Daily)'!V7 | F8: ='Arsenic (Daily)'!W7 | G8: =(F8-E8)/E8
A9: Average: | B9: ='Lead (30-Day_Avg)'!Z8 | C9: ='Lead (30-Day_Avg)'!AA8 | D9: =(C9-B9)/B9 | E9: ='Arsenic (Daily)'!V8 | F9: ='Arsenic (Daily)'!W8 | G9: =(F9-E9)/E9
A12: Excluding extraordinary events (looking at "normal" operations only).
A15: LEAD
C16: Averages | G16: Maximum
A17: Month | B17: Station 1 | C17: Station 2 | D17: Station 4 | E17: Station 5 | F17: Station 1 | G17: Station 2 | H17: Station 4 | I17: Station 5
A18: January | B18: ='Lead (30-Day_Avg)'!AA765 | C18: ='Lead (30-Day_Avg)'!AB765 | D18: ='Lead (30-Day_Avg)'!AC765 | E18: ='Lead (30-Day_Avg)'!AD765 | F18: ='Lead (30-Day_Avg)'!AA766 | G18: ='Lead (30-Day_Avg)'!AB766 | H18: ='Lead (30-Day_Avg)'!AC766 | I18: ='Lead (30-Day_Avg)'!AD766 | J18: =AVERAGE(B18:E18) | K18: =(J18-$B$33)/$B$33 | N18: 765 | O18: =1+N18
A19: February | B19: ='Lead (30-Day_Avg)'!AA795 | C19: ='Lead (30-Day_Avg)'!AB795 | D19: ='Lead (30-Day_Avg)'!AC795 | E19: ='Lead (30-Day_Avg)'!AD795 | F19: ='Lead (30-Day_Avg)'!AA796 | G19: ='Lead (30-Day_Avg)'!AB796 | H19: ='Lead (30-Day_Avg)'!AC796 | I19: ='Lead (30-Day_Avg)'!AD796 | J19: =AVERAGE(B19:E19) | K19: =(J19-$B$33)/$B$33 | M19: 29 | N19: =N18+M19+1 | O19: =1+N19
A20: March | B20: ='Lead (30-Day_Avg)'!AA825 | C20: ='Lead (30-Day_Avg)'!AB825 | D20: ='Lead (30-Day_Avg)'!AC825 | E20: ='Lead (30-Day_Avg)'!AD825 | F20: ='Lead (30-Day_Avg)'!AA826 | G20: ='Lead (30-Day_Avg)'!AB826 | H20: ='Lead (30-Day_Avg)'!AC826 | I20: ='Lead (30-Day_Avg)'!AD826 | J20: =AVERAGE(B20:E20) | K20: =(J20-$B$33)/$B$33 | M20: 31 | N20: =N19+M20-1 | O20: =1+N20
A21: April | B21: ='Lead (30-Day_Avg)'!AA855 | C21: ='Lead (30-Day_Avg)'!AB855 | D21: ='Lead (30-Day_Avg)'!AC855 | E21: ='Lead (30-Day_Avg)'!AD855 | F21: ='Lead (30-Day_Avg)'!AA856 | G21: ='Lead (30-Day_Avg)'!AB856 | H21: ='Lead (30-Day_Avg)'!AC856 | I21: ='Lead (30-Day_Avg)'!AD856 | J21: =AVERAGE(B21:E21) | K21: =(J21-$B$33)/$B$33 | M21: 30 | N21: 855 | O21: =1+N21
A22: May | B22: ='Lead (30-Day_Avg)'!AA886 | C22: ='Lead (30-Day_Avg)'!AB886 | D22: ='Lead (30-Day_Avg)'!AC886 | E22: ='Lead (30-Day_Avg)'!AD886 | F22: ='Lead (30-Day_Avg)'!AA887 | G22: ='Lead (30-Day_Avg)'!AB887 | H22: ='Lead (30-Day_Avg)'!AC887 | I22: ='Lead (30-Day_Avg)'!AD887 | J22: =AVERAGE(B22:E22) | K22: =(J22-$B$33)/$B$33 | M22: 31 | N22: 886 | O22: =1+N22
A23: June | B23: ='Lead (30-Day_Avg)'!AA916 | C23: ='Lead (30-Day_Avg)'!AB916 | D23: ='Lead (30-Day_Avg)'!AC916 | E23: ='Lead (30-Day_Avg)'!AD916 | F23: ='Lead (30-Day_Avg)'!AA917 | G23: ='Lead (30-Day_Avg)'!AB917 | H23: ='Lead (30-Day_Avg)'!AC917 | I23: ='Lead (30-Day_Avg)'!AD917 | J23: =AVERAGE(B23:E23) | K23: =(J23-$B$33)/$B$33 | M23: 30 | N23: 916 | O23: =1+N23
A24: July | B24: ='Lead (30-Day_Avg)'!AA947 | C24: ='Lead (30-Day_Avg)'!AB947 | D24: ='Lead (30-Day_Avg)'!AC947 | E24: ='Lead (30-Day_Avg)'!AD947 | F24: ='Lead (30-Day_Avg)'!AA948 | G24: ='Lead (30-Day_Avg)'!AB948 | H24: ='Lead (30-Day_Avg)'!AC948 | I24: ='Lead (30-Day_Avg)'!AD948 | J24: =AVERAGE(B24:E24) | K24: =(J24-$B$33)/$B$33 | M24: 31 | N24: 947 | O24: =1+N24
A25: August | B25: ='Lead (30-Day_Avg)'!AA978 | C25: ='Lead (30-Day_Avg)'!AB978 | D25: ='Lead (30-Day_Avg)'!AC978 | E25: ='Lead (30-Day_Avg)'!AD978 | F25: ='Lead (30-Day_Avg)'!AA979 | G25: ='Lead (30-Day_Avg)'!AB979 | H25: ='Lead (30-Day_Avg)'!AC979 | I25: ='Lead (30-Day_Avg)'!AD979 | J25: =AVERAGE(B25:E25) | K25: =(J25-$B$33)/$B$33 | M25: 31 | N25: 978 | O25: =1+N25
A26: September | B26: ='Lead (30-Day_Avg)'!AA1008 | C26: ='Lead (30-Day_Avg)'!AB1008 | D26: ='Lead (30-Day_Avg)'!AC1008 | E26: ='Lead (30-Day_Avg)'!AD1008 | F26: ='Lead (30-Day_Avg)'!AA1009 | G26: ='Lead (30-Day_Avg)'!AB1009 | H26: ='Lead (30-Day_Avg)'!AC1009 | I26: ='Lead (30-Day_Avg)'!AD1009 | J26: =AVERAGE(B26:E26) | K26: =(J26-$B$33)/$B$33 | M26: 30 | N26: 1008 | O26: =1+N26
A27: October | B27: ='Lead (30-Day_Avg)'!AA1039 | C27: ='Lead (30-Day_Avg)'!AB1039 | D27: ='Lead (30-Day_Avg)'!AC1039 | E27: ='Lead (30-Day_Avg)'!AD1039 | F27: ='Lead (30-Day_Avg)'!AA1040 | G27: ='Lead (30-Day_Avg)'!AB1040 | H27: ='Lead (30-Day_Avg)'!AC1040 | I27: ='Lead (30-Day_Avg)'!AD1040 | J27: =AVERAGE(B27:E27) | K27: =(J27-$B$33)/$B$33 | M27: 31 | N27: 1039 | O27: =1+N27
A28: November | B28: ='Lead (30-Day_Avg)'!AA1069 | C28: ='Lead (30-Day_Avg)'!AB1069 | D28: ='Lead (30-Day_Avg)'!AC1069 | E28: ='Lead (30-Day_Avg)'!AD1069 | F28: ='Lead (30-Day_Avg)'!AA1070 | G28: ='Lead (30-Day_Avg)'!AB1070 | H28: ='Lead (30-Day_Avg)'!AC1070 | I28: ='Lead (30-Day_Avg)'!AD1070 | J28: =AVERAGE(B28:E28) | K28: =(J28-$B$33)/$B$33 | M28: 30 | N28: 1069 | O28: =1+N28
A29: December | B29: ='Lead (30-Day_Avg)'!AA1100 | C29: ='Lead (30-Day_Avg)'!AB1100 | D29: ='Lead (30-Day_Avg)'!AC1100 | E29: ='Lead (30-Day_Avg)'!AD1100 | F29: ='Lead (30-Day_Avg)'!AA1101 | G29: ='Lead (30-Day_Avg)'!AB1101 | H29: ='Lead (30-Day_Avg)'!AC1101 | I29: ='Lead (30-Day_Avg)'!AD1101 | J29: =AVERAGE(B29:E29) | K29: =(J29-$B$33)/$B$33 | M29: 31 | N29: 1100 | O29: =1+N29
B31: ='Lead (30-Day_Avg)'!AA741 | C31: ='Lead (30-Day_Avg)'!AB741 | D31: ='Lead (30-Day_Avg)'!AC741 | E31: ='Lead (30-Day_Avg)'!AD741 | F31: ='Lead (30-Day_Avg)'!AA742 | G31: ='Lead (30-Day_Avg)'!AB742 | H31: ='Lead (30-Day_Avg)'!AC742 | I31: ='Lead (30-Day_Avg)'!AD742
B33: ='Lead (30-Day_Avg)'!AA1110
A36: ARSENIC | M36: ARSENIC
C37: Averages | G37: Maximum
A38: Month | B38: Station 1 | C38: Station 2 | D38: Station 4 | E38: Station 5 | F38: Station 1 | G38: Station 2 | H38: Station 4 | I38: Station 5 | M38: Month | N38: Average
A39: January | B39: ='Arsenic (Daily)'!V765 | C39: ='Arsenic (Daily)'!W765 | D39: ='Arsenic (Daily)'!X765 | E39: ='Arsenic (Daily)'!Y765 | F39: ='Arsenic (Daily)'!V766 | G39: ='Arsenic (Daily)'!W766 | H39: ='Arsenic (Daily)'!X766 | I39: ='Arsenic (Daily)'!Y766 | J39: =AVERAGE(B39:E39) | K39: =(J39-$B$54)/$B$54 | M39: January | N39: 1.0887102
A40: February | B40: ='Arsenic (Daily)'!V793 | C40: ='Arsenic (Daily)'!W793 | D40: ='Arsenic (Daily)'!X793 | E40: ='Arsenic (Daily)'!Y793 | F40: ='Arsenic (Daily)'!V794 | G40: ='Arsenic (Daily)'!W794 | H40: ='Arsenic (Daily)'!X794 | I40: ='Arsenic (Daily)'!Y794 | J40: =AVERAGE(B40:E40) | K40: =(J40-$B$54)/$B$54 | M40: February | N40: 1.0717926
A41: March | B41: ='Arsenic (Daily)'!V825 | C41: ='Arsenic (Daily)'!W825 | D41: ='Arsenic (Daily)'!X825 | E41: ='Arsenic (Daily)'!Y825 | F41: ='Arsenic (Daily)'!V826 | G41: ='Arsenic (Daily)'!W826 | H41: ='Arsenic (Daily)'!X826 | I41: ='Arsenic (Daily)'!Y826 | J41: =AVERAGE(B41:E41) | K41: =(J41-$B$54)/$B$54 | M41: March | N41: 0.58036048
A42: April | B42: ='Arsenic (Daily)'!V856 | C42: ='Arsenic (Daily)'!W856 | D42: ='Arsenic (Daily)'!X856 | E42: ='Arsenic (Daily)'!Y856 | F42: ='Arsenic (Daily)'!V857 | G42: ='Arsenic (Daily)'!W857 | H42: ='Arsenic (Daily)'!X857 | I42: ='Arsenic (Daily)'!Y857 | J42: =AVERAGE(B42:E42) | K42: =(J42-$B$54)/$B$54 | M42: April | N42: 0.63166833
A43: May | B43: ='Arsenic (Daily)'!V886 | C43: ='Arsenic (Daily)'!W886 | D43: ='Arsenic (Daily)'!X886 | E43: ='Arsenic (Daily)'!Y886 | F43: ='Arsenic (Daily)'!V887 | G43: ='Arsenic (Daily)'!W887 | H43: ='Arsenic (Daily)'!X887 | I43: ='Arsenic (Daily)'!Y887 | J43: =AVERAGE(B43:E43) | K43: =(J43-$B$54)/$B$54 | M43: May | N43: 0.7507543
A44: June | B44: ='Arsenic (Daily)'!V917 | C44: ='Arsenic (Daily)'!W917 | D44: ='Arsenic (Daily)'!X917 | E44: ='Arsenic (Daily)'!Y917 | F44: ='Arsenic (Daily)'!V918 | G44: ='Arsenic (Daily)'!W918 | H44: ='Arsenic (Daily)'!X918 | I44: ='Arsenic (Daily)'!Y918 | J44: =AVERAGE(B44:E44) | K44: =(J44-$B$54)/$B$54 | M44: June | N44: 0.6883
A45: July | B45: ='Arsenic (Daily)'!V947 | C45: ='Arsenic (Daily)'!W947 | D45: ='Arsenic (Daily)'!X947 | E45: ='Arsenic (Daily)'!Y947 | F45: ='Arsenic (Daily)'!V948 | G45: ='Arsenic (Daily)'!W948 | H45: ='Arsenic (Daily)'!X948 | I45: ='Arsenic (Daily)'!Y948 | J45: =AVERAGE(B45:E45) | K45: =(J45-$B$54)/$B$54 | M45: July | N45: 0.89686042
A46: August | B46: ='Arsenic (Daily)'!V978 | C46: ='Arsenic (Daily)'!W978 | D46: ='Arsenic (Daily)'!X978 | E46: ='Arsenic (Daily)'!Y978 | F46: ='Arsenic (Daily)'!V979 | G46: ='Arsenic (Daily)'!W979 | H46: ='Arsenic (Daily)'!X979 | I46: ='Arsenic (Daily)'!Y979 | J46: =AVERAGE(B46:E46) | K46: =(J46-$B$54)/$B$54 | M46: August | N46: 0.94646928
A47: September | B47: ='Arsenic (Daily)'!V1009 | C47: ='Arsenic (Daily)'!W1009 | D47: ='Arsenic (Daily)'!X1009 | E47: ='Arsenic (Daily)'!Y1009 | F47: ='Arsenic (Daily)'!V1010 | G47: ='Arsenic (Daily)'!W1010 | H47: ='Arsenic (Daily)'!X1010 | I47: ='Arsenic (Daily)'!Y1010 | J47: =AVERAGE(B47:E47) | K47: =(J47-$B$54)/$B$54 | M47: September | N47: 1.3210606
A48: October | B48: ='Arsenic (Daily)'!V1039 | C48: ='Arsenic (Daily)'!W1039 | D48: ='Arsenic (Daily)'!X1039 | E48: ='Arsenic (Daily)'!Y1039 | F48: ='Arsenic (Daily)'!V1040 | G48: ='Arsenic (Daily)'!W1040 | H48: ='Arsenic (Daily)'!X1040 | I48: ='Arsenic (Daily)'!Y1040 | J48: =AVERAGE(B48:E48) | K48: =(J48-$B$54)/$B$54 | M48: October | N48: 1.673792
A49: November | B49: ='Arsenic (Daily)'!V1070 | C49: ='Arsenic (Daily)'!W1070 | D49: ='Arsenic (Daily)'!X1070 | E49: ='Arsenic (Daily)'!Y1070 | F49: ='Arsenic (Daily)'!V1071 | G49: ='Arsenic (Daily)'!W1071 | H49: ='Arsenic (Daily)'!X1071 | I49: ='Arsenic (Daily)'!Y1071 | J49: =AVERAGE(B49:E49) | K49: =(J49-$B$54)/$B$54 | M49: November | N49: 1.2384024
A50: December | B50: ='Arsenic (Daily)'!V1100 | C50: ='Arsenic (Daily)'!W1100 | D50: ='Arsenic (Daily)'!X1100 | E50: ='Arsenic (Daily)'!Y1100 | F50: ='Arsenic (Daily)'!V1101 | G50: ='Arsenic (Daily)'!W1101 | H50: ='Arsenic (Daily)'!X1101 | I50: ='Arsenic (Daily)'!Y1101 | J50: =AVERAGE(B50:E50) | K50: =(J50-$B$54)/$B$54 | M50: December | N50: 1.6062174
...

Sheet 2021 Summary
A1: Monthly Ambient Monitor Statistics -- 2021
C4: Lead (µg/m3) | F4: Arsenic (ng/m3)
A5: Parameter | B5: WeekEND | C5: WeekDAY | D5: % WD Diff | E5: WeekEND | F5: WeekDAY | G5: % WD Diff
A6: Maximum: | B6: ='Lead (30-Day_Avg)'!Z5 | C6: ='Lead (30-Day_Avg)'!AA5 | D6: =(C6-B6)/B6 | E6: ='Arsenic (Daily)'!V5 | F6: ='Arsenic (Daily)'!W5 | G6: =(F6-E6)/E6
A7: 90th percentile: | B7: ='Lead (30-Day_Avg)'!Z6 | C7: ='Lead (30-Day_Avg)'!AA6 | D7: =(C7-B7)/B7 | E7: ='Arsenic (Daily)'!V6 | F7: ='Arsenic (Daily)'!W6 | G7: =(F7-E7)/E7
A8: 75th percentile: | B8: ='Lead (30-Day_Avg)'!Z7 | C8: ='Lead (30-Day_Avg)'!AA7 | D8: =(C8-B8)/B8 | E8: ='Arsenic (Daily)'!V7 | F8: ='Arsenic (Daily)'!W7 | G8: =(F8-E8)/E8
A9: Average: | B9: ='Lead (30-Day_Avg)'!Z8 | C9: ='Lead (30-Day_Avg)'!AA8 | D9: =(C9-B9)/B9 | E9: ='Arsenic (Daily)'!V8 | F9: ='Arsenic (Daily)'!W8 | G9: =(F9-E9)/E9
A12: Excluding extraordinary events (looking at "normal" operations only).
A15: LEAD
C16: Averages | G16: Maximum
A17: Month | B17: Station 1 | C17: Station 2 | D17: Station 4 | E17: Station 5 | F17: Station 1 | G17: Station 2 | H17: Station 4 | I17: Station 5
A18: January | B18: ='Lead (30-Day_Avg)'!AA1131 | C18: ='Lead (30-Day_Avg)'!AB1131 | D18: ='Lead (30-Day_Avg)'!AC1131 | E18: ='Lead (30-Day_Avg)'!AD1131 | F18: ='Lead (30-Day_Avg)'!AA1132 | G18: ='Lead (30-Day_Avg)'!AB1132 | H18: ='Lead (30-Day_Avg)'!AC766 | I18: ='Lead (30-Day_Avg)'!AD766 | J18: =AVERAGE(B18:E18) | K18: =(J18-$B$33)/$B$33 | N18: 765 | O18: =1+N18
A19: February | B19: ='Lead (30-Day_Avg)'!AA1160 | C19: ='Lead (30-Day_Avg)'!AB1160 | D19: ='Lead (30-Day_Avg)'!AC1160 | E19: ='Lead (30-Day_Avg)'!AD1160 | F19: ='Lead (30-Day_Avg)'!AA1161 | G19: ='Lead (30-Day_Avg)'!AB1161 | H19: ='Lead (30-Day_Avg)'!AC1161 | I19: ='Lead (30-Day_Avg)'!AD1161 | J19: =AVERAGE(B19:E19) | K19: =(J19-$B$33)/$B$33 | M19: 29 | N19: =N18+M19+1 | O19: =1+N19
A20: March | J20: =AVERAGE(B20:E20) | K20: =(J20-$B$33)/$B$33 | M20: 31 | N20: =N19+M20-1 | O20: =1+N20
A21: April | J21: =AVERAGE(B21:E21) | K21: =(J21-$B$33)/$B$33 | M21: 30 | N21: 855 | O21: =1+N21
A22: May | J22: =AVERAGE(B22:E22) | K22: =(J22-$B$33)/$B$33 | M22: 31 | N22: 886 | O22: =1+N22
A23: June | J23: =AVERAGE(B23:E23) | K23: =(J23-$B$33)/$B$33 | M23: 30 | N23: 916 | O23: =1+N23
A24: July | J24: =AVERAGE(B24:E24) | K24: =(J24-$B$33)/$B$33 | M24: 31 | N24: 947 | O24: =1+N24
A25: August | J25: =AVERAGE(B25:E25) | K25: =(J25-$B$33)/$B$33 | M25: 31 | N25: 978 | O25: =1+N25
A26: September | J26: =AVERAGE(B26:E26) | K26: =(J26-$B$33)/$B$33 | M26: 30 | N26: 1008 | O26: =1+N26
A27: October | J27: =AVERAGE(B27:E27) | K27: =(J27-$B$33)/$B$33 | M27: 31 | N27: 1039 | O27: =1+N27
A28: November | J28: =AVERAGE(B28:E28) | K28: =(J28-$B$33)/$B$33 | M28: 30 | N28: 1069 | O28: =1+N28
A29: December | J29: =AVERAGE(B29:E29) | K29: =(J29-$B$33)/$B$33 | M29: 31 | N29: 1100 | O29: =1+N29
B31: ='Lead (30-Day_Avg)'!AA741 | C31: ='Lead (30-Day_Avg)'!AB741 | D31: ='Lead (30-Day_Avg)'!AC741 | E31: ='Lead (30-Day_Avg)'!AD741 | F31: ='Lead (30-Day_Avg)'!AA742 | G31: ='Lead (30-Day_Avg)'!AB742 | H31: ='Lead (30-Day_Avg)'!AC742 | I31: ='Lead (30-Day_Avg)'!AD742
B33: ='Lead (30-Day_Avg)'!AA1110
A36: ARSENIC | M36: ARSENIC
C37: Averages | G37: Maximum
A38: Month | B38: Station 1 | C38: Station 2 | D38: Station 4 | E38: Station 5 | F38: Station 1 | G38: Station 2 | H38: Station 4 | I38: Station 5 | M38: Month | N38: Average
A39: January | B39: ='Arsenic (Daily)'!V1131 | C39: ='Arsenic (Daily)'!W1131 | D39: ='Arsenic (Daily)'!X1131 | E39: ='Arsenic (Daily)'!Y1131 | F39: ='Arsenic (Daily)'!V1132 | G39: ='Arsenic (Daily)'!W1132 | H39: ='Arsenic (Daily)'!X1132 | I39: ='Arsenic (Daily)'!Y1132 | J39: =AVERAGE(B39:E39) | K39: =(J39-$B$54)/$B$54 | M39: January
A40: February | B40: ='Arsenic (Daily)'!V1159 | C40: ='Arsenic (Daily)'!W1159 | D40: ='Arsenic (Daily)'!X1159 | E40: ='Arsenic (Daily)'!Y1159 | F40: ='Arsenic (Daily)'!V1160 | G40: ='Arsenic (Daily)'!W1160 | H40: ='Arsenic (Daily)'!X1160 | I40: ='Arsenic (Daily)'!Y1160 | J40: =AVERAGE(B40:E40) | K40: =(J40-$B$54)/$B$54 | M40: February
A41: March | J41: =AVERAGE(B41:E41) | K41: =(J41-$B$54)/$B$54 | M41: March
A42: April | J42: =AVERAGE(B42:E42) | K42: =(J42-$B$54)/$B$54 | M42: April
A43: May | J43: =AVERAGE(B43:E43) | K43: =(J43-$B$54)/$B$54 | M43: May
A44: June | J44: =AVERAGE(B44:E44) | K44: =(J44-$B$54)/$B$54 | M44: June
A45: July | J45: =AVERAGE(B45:E45) | K45: =(J45-$B$54)/$B$54 | M45: July
A46: August | J46: =AVERAGE(B46:E46) | K46: =(J46-$B$54)/$B$54 | M46: August
A47: September | J47: =AVERAGE(B47:E47) | K47: =(J47-$B$54)/$B$54 | M47: September
A48: October | J48: =AVERAGE(B48:E48) | K48: =(J48-$B$54)/$B$54 | M48: October
A49: November | J49: =AVERAGE(B49:E49) | K49: =(J49-$B$54)/$B$54 | M49: November
A50: December | J50: =AVERAGE(B50:E50) | K50: =(J50-$B$54)/$B$54 | M50: December
...

Sheet Average Summary
C3: Lead Averages | G3: Arsenic Averages
A4: Month | B4: Station 1 | C4: Station 2 | D4: Station 4 | E4: Station 5 | F4: Station 1 | G4: Station 2 | H4: Station 4 | I4: Station 5 | J4: All Stations | W4: 0 | X4: 0 | Y4: 0 | Z4: 0
A5: 43101 | F5: ='2018 Summary'!B39 | G5: ='2018 Summary'!C39 | H5: ='2018 Summary'!D39 | I5: ='2018 Summary'!E39 | J5: =AVERAGE(F5:I5) | O5: =IF(F5>=1.25,1,0) | P5: =IF(G5>=1.25,1,0) | Q5: =IF(H5>=1.25,1,0) | R5: =IF(I5>=1.25,1,0) | S5: =IF(F5>=1,1,0) | T5: =IF(G5>=1,1,0) | U5: =IF(H5>=1,1,0) | V5: =IF(I5>=1,1,0) | W5: =IF(S5=1,S5+W4,0) | X5: =IF(T5=1,T5+X4,0) | Y5: =IF(U5=1,U5+Y4,0) | Z5: =IF(V5=1,V5+Z4,0)
A6: 43132 | F6: ='2018 Summary'!B40 | G6: ='2018 Summary'!C40 | H6: ='2018 Summary'!D40 | I6: ='2018 Summary'!E40 | J6: =AVERAGE(F6:I6) | O6: =IF(F6>=1.25,1,0) | P6: =IF(G6>=1.25,1,0) | Q6: =IF(H6>=1.25,1,0) | R6: =IF(I6>=1.25,1,0) | S6: =IF(F6>=1,1,0) | T6: =IF(G6>=1,1,0) | U6: =IF(H6>=1,1,0) | V6: =IF(I6>=1,1,0) | W6: =IF(S6=1,S6+W5,0) | X6: =IF(T6=1,T6+X5,0) | Y6: =IF(U6=1,U6+Y5,0) | Z6: =IF(V6=1,V6+Z5,0)
A7: 43160 | F7: ='2018 Summary'!B41 | G7: ='2018 Summary'!C41 | H7: ='2018 Summary'!D41 | I7: ='2018 Summary'!E41 | J7: =AVERAGE(F7:I7) | O7: =IF(F7>=1.25,1,0) | P7: =IF(G7>=1.25,1,0) | Q7: =IF(H7>=1.25,1,0) | R7: =IF(I7>=1.25,1,0) | S7: =IF(F7>=1,1,0) | T7: =IF(G7>=1,1,0) | U7: =IF(H7>=1,1,0) | V7: =IF(I7>=1,1,0) | W7: =IF(S7=1,S7+W6,0) | X7: =IF(T7=1,T7+X6,0) | Y7: =IF(U7=1,U7+Y6,0) | Z7: =IF(V7=1,V7+Z6,0)
A8: 43191 | F8: ='2018 Summary'!B42 | G8: ='2018 Summary'!C42 | H8: ='2018 Summary'!D42 | I8: ='2018 Summary'!E42 | J8: =AVERAGE(F8:I8) | O8: =IF(F8>=1.25,1,0) | P8: =IF(G8>=1.25,1,0) | Q8: =IF(H8>=1.25,1,0) | R8: =IF(I8>=1.25,1,0) | S8: =IF(F8>=1,1,0) | T8: =IF(G8>=1,1,0) | U8: =IF(H8>=1,1,0) | V8: =IF(I8>=1,1,0) | W8: =IF(S8=1,S8+W7,0) | X8: =IF(T8=1,T8+X7,0) | Y8: =IF(U8=1,U8+Y7,0) | Z8: =IF(V8=1,V8+Z7,0)
A9: 43221 | F9: ='2018 Summary'!B43 | G9: ='2018 Summary'!C43 | H9: ='2018 Summary'!D43 | I9: ='2018 Summary'!E43 | J9: =AVERAGE(F9:I9) | O9: =IF(F9>=1.25,1,0) | P9: =IF(G9>=1.25,1,0) | Q9: =IF(H9>=1.25,1,0) | R9: =IF(I9>=1.25,1,0) | S9: =IF(F9>=1,1,0) | T9: =IF(G9>=1,1,0) | U9: =IF(H9>=1,1,0) | V9: =IF(I9>=1,1,0) | W9: =IF(S9=1,S9+W8,0) | X9: =IF(T9=1,T9+X8,0) | Y9: =IF(U9=1,U9+Y8,0) | Z9: =IF(V9=1,V9+Z8,0)
A10: 43252 | F10: ='2018 Summary'!B44 | G10: ='2018 Summary'!C44 | H10: ='2018 Summary'!D44 | I10: ='2018 Summary'!E44 | J10: =AVERAGE(F10:I10) | O10: =IF(F10>=1.25,1,0) | P10: =IF(G10>=1.25,1,0) | Q10: =IF(H10>=1.25,1,0) | R10: =IF(I10>=1.25,1,0) | S10: =IF(F10>=1,1,0) | T10: =IF(G10>=1,1,0) | U10: =IF(H10>=1,1,0) | V10: =IF(I10>=1,1,0) | W10: =IF(S10=1,S10+W9,0) | X10: =IF(T10=1,T10+X9,0) | Y10: =IF(U10=1,U10+Y9,0) | Z10: =IF(V10=1,V10+Z9,0)
A11: 43282 | F11: ='2018 Summary'!B45 | G11: ='2018 Summary'!C45 | H11: ='2018 Summary'!D45 | I11: ='2018 Summary'!E45 | J11: =AVERAGE(F11:I11) | O11: =IF(F11>=1.25,1,0) | P11: =IF(G11>=1.25,1,0) | Q11: =IF(H11>=1.25,1,0) | R11: =IF(I11>=1.25,1,0) | S11: =IF(F11>=1,1,0) | T11: =IF(G11>=1,1,0) | U11: =IF(H11>=1,1,0) | V11: =IF(I11>=1,1,0) | W11: =IF(S11=1,S11+W10,0) | X11: =IF(T11=1,T11+X10,0) | Y11: =IF(U11=1,U11+Y10,0) | Z11: =IF(V11=1,V11+Z10,0)
A12: 43313 | F12: ='2018 Summary'!B46 | G12: ='2018 Summary'!C46 | H12: ='2018 Summary'!D46 | I12: ='2018 Summary'!E46 | J12: =AVERAGE(F12:I12) | O12: =IF(F12>=1.25,1,0) | P12: =IF(G12>=1.25,1,0) | Q12: =IF(H12>=1.25,1,0) | R12: =IF(I12>=1.25,1,0) | S12: =IF(F12>=1,1,0) | T12: =IF(G12>=1,1,0) | U12: =IF(H12>=1,1,0) | V12: =IF(I12>=1,1,0) | W12: =IF(S12=1,S12+W11,0) | X12: =IF(T12=1,T12+X11,0) | Y12: =IF(U12=1,U12+Y11,0) | Z12: =IF(V12=1,V12+Z11,0)
A13: 43344 | F13: ='2018 Summary'!B47 | G13: ='2018 Summary'!C47 | H13: ='2018 Summary'!D47 | I13: ='2018 Summary'!E47 | J13: =AVERAGE(F13:I13) | O13: =IF(F13>=1.25,1,0) | P13: =IF(G13>=1.25,1,0) | Q13: =IF(H13>=1.25,1,0) | R13: =IF(I13>=1.25,1,0) | S13: =IF(F13>=1,1,0) | T13: =IF(G13>=1,1,0) | U13: =IF(H13>=1,1,0) | V13: =IF(I13>=1,1,0) | W13: =IF(S13=1,S13+W12,0) | X13: =IF(T13=1,T13+X12,0) | Y13: =IF(U13=1,U13+Y12,0) | Z13: =IF(V13=1,V13+Z12,0)
A14: 43374 | F14: ='2018 Summary'!B48 | G14: ='2018 Summary'!C48 | H14: ='2018 Summary'!D48 | I14: ='2018 Summary'!E48 | J14: =AVERAGE(F14:I14) | O14: =IF(F14>=1.25,1,0) | P14: =IF(G14>=1.25,1,0) | Q14: =IF(H14>=1.25,1,0) | R14: =IF(I14>=1.25,1,0) | S14: =IF(F14>=1,1,0) | T14: =IF(G14>=1,1,0) | U14: =IF(H14>=1,1,0) | V14: =IF(I14>=1,1,0) | W14: =IF(S14=1,S14+W13,0) | X14: =IF(T14=1,T14+X13,0) | Y14: =IF(U14=1,U14+Y13,0) | Z14: =IF(V14=1,V14+Z13,0)
A15: 43405 | F15: ='2018 Summary'!B49 | G15: ='2018 Summary'!C49 | H15: ='2018 Summary'!D49 | I15: ='2018 Summary'!E49 | J15: =AVERAGE(F15:I15) | O15: =IF(F15>=1.25,1,0) | P15: =IF(G15>=1.25,1,0) | Q15: =IF(H15>=1.25,1,0) | R15: =IF(I15>=1.25,1,0) | S15: =IF(F15>=1,1,0) | T15: =IF(G15>=1,1,0) | U15: =IF(H15>=1,1,0) | V15: =IF(I15>=1,1,0) | W15: =IF(S15=1,S15+W14,0) | X15: =IF(T15=1,T15+X14,0) | Y15: =IF(U15=1,U15+Y14,0) | Z15: =IF(V15=1,V15+Z14,0)
A16: 43435 | F16: ='2018 Summary'!B50 | G16: ='2018 Summary'!C50 | H16: ='2018 Summary'!D50 | I16: ='2018 Summary'!E50 | J16: =AVERAGE(F16:I16) | O16: =IF(F16>=1.25,1,0) | P16: =IF(G16>=1.25,1,0) | Q16: =IF(H16>=1.25,1,0) | R16: =IF(I16>=1.25,1,0) | S16: =IF(F16>=1,1,0) | T16: =IF(G16>=1,1,0) | U16: =IF(H16>=1,1,0) | V16: =IF(I16>=1,1,0) | W16: =IF(S16=1,S16+W15,0) | X16: =IF(T16=1,T16+X15,0) | Y16: =IF(U16=1,U16+Y15,0) | Z16: =IF(V16=1,V16+Z15,0)
A17: 43466 | F17: ='2019 Summary'!B39 | G17: ='2019 Summary'!C39 | H17: ='2019 Summary'!D39 | I17: ='2019 Summary'!E39 | J17: =AVERAGE(F17:I17) | O17: =IF(F17>=1.25,1,0) | P17: =IF(G17>=1.25,1,0) | Q17: =IF(H17>=1.25,1,0) | R17: =IF(I17>=1.25,1,0) | S17: =IF(F17>=1,1,0) | T17: =IF(G17>=1,1,0) | U17: =IF(H17>=1,1,0) | V17: =IF(I17>=1,1,0) | W17: =IF(S17=1,S17+W16,0) | X17: =IF(T17=1,T17+X16,0) | Y17: =IF(U17=1,U17+Y16,0) | Z17: =IF(V17=1,V17+Z16,0)
A18: 43497 | F18: ='2019 Summary'!B40 | G18: ='2019 Summary'!C40 | H18: ='2019 Summary'!D40 | I18: ='2019 Summary'!E40 | J18: =AVERAGE(F18:I18) | O18: =IF(F18>=1.25,1,0) | P18: =IF(G18>=1.25,1,0) | Q18: =IF(H18>=1.25,1,0) | R18: =IF(I18>=1.25,1,0) | S18: =IF(F18>=1,1,0) | T18: =IF(G18>=1,1,0) | U18: =IF(H18>=1,1,0) | V18: =IF(I18>=1,1,0) | W18: =IF(S18=1,S18+W17,0) | X18: =IF(T18=1,T18+X17,0) | Y18: =IF(U18=1,U18+Y17,0) | Z18: =IF(V18=1,V18+Z17,0)
A19: 43525 | F19: ='2019 Summary'!B41 | G19: ='2019 Summary'!C41 | H19: ='2019 Summary'!D41 | I19: ='2019 Summary'!E41 | J19: =AVERAGE(F19:I19) | O19: =IF(F19>=1.25,1,0) | P19: =IF(G19>=1.25,1,0) | Q19: =IF(H19>=1.25,1,0) | R19: =IF(I19>=1.25,1,0) | S19: =IF(F19>=1,1,0) | T19: =IF(G19>=1,1,0) | U19: =IF(H19>=1,1,0) | V19: =IF(I19>=1,1,0) | W19: =IF(S19=1,S19+W18,0) | X19: =IF(T19=1,T19+X18,0) | Y19: =IF(U19=1,U19+Y18,0) | Z19: =IF(V19=1,V19+Z18,0)
A20: 43556 | F20: ='2019 Summary'!B42 | G20: ='2019 Summary'!C42 | H20: ='2019 Summary'!D42 | I20: ='2019 Summary'!E42 | J20: =AVERAGE(F20:I20) | O20: =IF(F20>=1.25,1,0) | P20: =IF(G20>=1.25,1,0) | Q20: =IF(H20>=1.25,1,0) | R20: =IF(I20>=1.25,1,0) | S20: =IF(F20>=1,1,0) | T20: =IF(G20>=1,1,0) | U20: =IF(H20>=1,1,0) | V20: =IF(I20>=1,1,0) | W20: =IF(S20=1,S20+W19,0) | X20: =IF(T20=1,T20+X19,0) | Y20: =IF(U20=1,U20+Y19,0) | Z20: =IF(V20=1,V20+Z19,0) | AA20: <--Curtailment
A21: 43586 | F21: ='2019 Summary'!B43 | G21: ='2019 Summary'!C43 | H21: ='2019 Summary'!D43 | I21: ='2019 Summary'!E43 | J21: =AVERAGE(F21:I21) | O21: =IF(F21>=1.25,1,0) | P21: =IF(G21>=1.25,1,0) | Q21: =IF(H21>=1.25,1,0) | R21: =IF(I21>=1.25,1,0) | S21: =IF(F21>=1,1,0) | T21: =IF(G21>=1,1,0) | U21: =IF(H21>=1,1,0) | V21: =IF(I21>=1,1,0) | W21: =IF(S21=1,S21+W20,0) | X21: =IF(T21=1,T21+X20,0) | Y21: =IF(U21=1,U21+Y20,0) | Z21: =IF(V21=1,V21+Z20,0)
A22: 43617 | F22: ='2019 Summary'!B44 | G22: ='2019 Summary'!C44 | H22: ='2019 Summary'!D44 | I22: ='2019 Summary'!E44 | J22: =AVERAGE(F22:I22) | O22: =IF(F22>=1.25,1,0) | P22: =IF(G22>=1.25,1,0) | Q22: =IF(H22>=1.25,1,0) | R22: =IF(I22>=1.25,1,0) | S22: =IF(F22>=1,1,0) | T22: =IF(G22>=1,1,0) | U22: =IF(H22>=1,1,0) | V22: =IF(I22>=1,1,0) | W22: =IF(S22=1,S22+W21,0) | X22: =IF(T22=1,T22+X21,0) | Y22: =IF(U22=1,U22+Y21,0) | Z22: =IF(V22=1,V22+Z21,0)
A23: 43647 | F23: ='2019 Summary'!B45 | G23: ='2019 Summary'!C45 | H23: ='2019 Summary'!D45 | I23: ='2019 Summary'!E45 | J23: =AVERAGE(F23:I23) | O23: =IF(F23>=1.25,1,0) | P23: =IF(G23>=1.25,1,0) | Q23: =IF(H23>=1.25,1,0) | R23: =IF(I23>=1.25,1,0) | S23: =IF(F23>=1,1,0) | T23: =IF(G23>=1,1,0) | U23: =IF(H23>=1,1,0) | V23: =IF(I23>=1,1,0) | W23: =IF(S23=1,S23+W22,0) | X23: =IF(T23=1,T23+X22,0) | Y23: =IF(U23=1,U23+Y22,0) | Z23: =IF(V23=1,V23+Z22,0)
A24: 43678 | F24: ='2019 Summary'!B46 | G24: ='2019 Summary'!C46 | H24: ='2019 Summary'!D46 | I24: ='2019 Summary'!E46 | J24: =AVERAGE(F24:I24) | O24: =IF(F24>=1.25,1,0) | P24: =IF(G24>=1.25,1,0) | Q24: =IF(H24>=1.25,1,0) | R24: =IF(I24>=1.25,1,0) | S24: =IF(F24>=1,1,0) | T24: =IF(G24>=1,1,0) | U24: =IF(H24>=1,1,0) | V24: =IF(I24>=1,1,0) | W24: =IF(S24=1,S24+W23,0) | X24: =IF(T24=1,T24+X23,0) | Y24: =IF(U24=1,U24+Y23,0) | Z24: =IF(V24=1,V24+Z23,0)
A25: 43709 | F25: ='2019 Summary'!B47 | G25: ='2019 Summary'!C47 | H25: ='2019 Summary'!D47 | I25: ='2019 Summary'!E47 | J25: =AVERAGE(F25:I25) | O25: =IF(F25>=1.25,1,0) | P25: =IF(G25>=1.25,1,0) | Q25: =IF(H25>=1.25,1,0) | R25: =IF(I25>=1.25,1,0) | S25: =IF(F25>=1,1,0) | T25: =IF(G25>=1,1,0) | U25: =IF(H25>=1,1,0) | V25: =IF(I25>=1,1,0) | W25: =IF(S25=1,S25+W24,0) | X25: =IF(T25=1,T25+X24,0) | Y25: =IF(U25=1,U25+Y24,0) | Z25: =IF(V25=1,V25+Z24,0)
A26: 43739 | F26: ='2019 Summary'!B48 | G26: ='2019 Summary'!C48 | H26: ='2019 Summary'!D48 | I26: ='2019 Summary'!E48 | J26: =AVERAGE(F26:I26) | O26: =IF(F26>=1.25,1,0) | P26: =IF(G26>=1.25,1,0) | Q26: =IF(H26>=1.25,1,0) | R26: =IF(I26>=1.25,1,0) | S26: =IF(F26>=1,1,0) | T26: =IF(G26>=1,1,0) | U26: =IF(H26>=1,1,0) | V26: =IF(I26>=1,1,0) | W26: =IF(S26=1,S26+W25,0) | X26: =IF(T26=1,T26+X25,0) | Y26: =IF(U26=1,U26+Y25,0) | Z26: =IF(V26=1,V26+Z25,0)
A27: 43770 | F27: ='2019 Summary'!B49 | G27: ='2019 Summary'!C49 | H27: ='2019 Summary'!D49 | I27: ='2019 Summary'!E49 | J27: =AVERAGE(F27:I27) | O27: =IF(F27>=1.25,1,0) | P27: =IF(G27>=1.25,1,0) | Q27: =IF(H27>=1.25,1,0) | R27: =IF(I27>=1.25,1,0) | S27: =IF(F27>=1,1,0) | T27: =IF(G27>=1,1,0) | U27: =IF(H27>=1,1,0) | V27: =IF(I27>=1,1,0) | W27: =IF(S27=1,S27+W26,0) | X27: =IF(T27=1,T27+X26,0) | Y27: =IF(U27=1,U27+Y26,0) | Z27: =IF(V27=1,V27+Z26,0)
A28: 43800 | F28: ='2019 Summary'!B50 | G28: ='2019 Summary'!C50 | H28: ='2019 Summary'!D50 | I28: ='2019 Summary'!E50 | J28: =AVERAGE(F28:I28) | O28: =IF(F28>=1.25,1,0) | P28: =IF(G28>=1.25,1,0) | Q28: =IF(H28>=1.25,1,0) | R28: =IF(I28>=1.25,1,0) | S28: =IF(F28>=1,1,0) | T28: =IF(G28>=1,1,0) | U28: =IF(H28>=1,1,0) | V28: =IF(I28>=1,1,0) | W28: =IF(S28=1,S28+W27,0) | X28: =IF(T28=1,T28+X27,0) | Y28: =IF(U28=1,U28+Y27,0) | Z28: =IF(V28=1,V28+Z27,0)
A29: 43831 | F29: ='2020 Summary'!B39 | G29: ='2020 Summary'!C39 | H29: ='2020 Summary'!D39 | I29: ='2020 Summary'!E39 | J29: =AVERAGE(F29:I29) | O29: =IF(F29>=1.25,1,0) | P29: =IF(G29>=1.25,1,0) | Q29: =IF(H29>=1.25,1,0) | R29: =IF(I29>=1.25,1,0) | S29: =IF(F29>=1,1,0) | T29: =IF(G29>=1,1,0) | U29: =IF(H29>=1,1,0) | V29: =IF(I29>=1,1,0) | W29: =IF(S29=1,S29+W28,0) | X29: =IF(T29=1,T29+X28,0) | Y29: =IF(U29=1,U29+Y28,0) | Z29: =IF(V29=1,V29+Z28,0)
A30: 43862 | F30: ='2020 Summary'!B40 | G30: ='2020 Summary'!C40 | H30: ='2020 Summary'!D40 | I30: ='2020 Summary'!E40 | J30: =AVERAGE(F30:I30) | O30: =IF(F30>=1.25,1,0) | P30: =IF(G30>=1.25,1,0) | Q30: =IF(H30>=1.25,1,0) | R30: =IF(I30>=1.25,1,0) | S30: =IF(F30>=1,1,0) | T30: =IF(G30>=1,1,0) | U30: =IF(H30>=1,1,0) | V30: =IF(I30>=1,1,0) | W30: =IF(S30=1,S30+W29,0) | X30: =IF(T30=1,T30+X29,0) | Y30: =IF(U30=1,U30+Y29,0) | Z30: =IF(V30=1,V30+Z29,0)
A31: 43891 | F31: ='2020 Summary'!B41 | G31: ='2020 Summary'!C41 | H31: ='2020 Summary'!D41 | I31: ='2020 Summary'!E41 | J31: =AVERAGE(F31:I31) | O31: =IF(F31>=1.25,1,0) | P31: =IF(G31>=1.25,1,0) | Q31: =IF(H31>=1.25,1,0) | R31: =IF(I31>=1.25,1,0) | S31: =IF(F31>=1,1,0) | T31: =IF(G31>=1,1,0) | U31: =IF(H31>=1,1,0) | V31: =IF(I31>=1,1,0) | W31: =IF(S31=1,S31+W30,0) | X31: =IF(T31=1,T31+X30,0) | Y31: =IF(U31=1,U31+Y30,0) | Z31: =IF(V31=1,V31+Z30,0)
A32: 43922 | F32: ='2020 Summary'!B42 | G32: ='2020 Summary'!C42 | H32: ='2020 Summary'!D42 | I32: ='2020 Summary'!E42 | J32: =AVERAGE(F32:I32) | O32: =IF(F32>=1.25,1,0) | P32: =IF(G32>=1.25,1,0) | Q32: =IF(H32>=1.25,1,0) | R32: =IF(I32>=1.25,1,0) | S32: =IF(F32>=1,1,0) | T32: =IF(G32>=1,1,0) | U32: =IF(H32>=1,1,0) | V32: =IF(I32>=1,1,0) | W32: =IF(S32=1,S32+W31,0) | X32: =IF(T32=1,T32+X31,0) | Y32: =IF(U32=1,U32+Y31,0) | Z32: =IF(V32=1,V32+Z31,0)
A33: 43952 | F33: ='2020 Summary'!B43 | G33: ='2020 Summary'!C43 | H33: ='2020 Summary'!D43 | I33: ='2020 Summary'!E43 | J33: =AVERAGE(F33:I33) | O33: =IF(F33>=1.25,1,0) | P33: =IF(G33>=1.25,1,0) | Q33: =IF(H33>=1.25,1,0) | R33: =IF(I33>=1.25,1,0) | S33: =IF(F33>=1,1,0) | T33: =IF(G33>=1,1,0) | U33: =IF(H33>=1,1,0) | V33: =IF(I33>=1,1,0) | W33: =IF(S33=1,S33+W32,0) | X33: =IF(T33=1,T33+X32,0) | Y33: =IF(U33=1,U33+Y32,0) | Z33: =IF(V33=1,V33+Z32,0)
A34: 43983 | F34: ='2020 Summary'!B44 | G34: ='2020 Summary'!C44 | H34: ='2020 Summary'!D44 | I34: ='2020 Summary'!E44 | J34: =AVERAGE(F34:I34) | O34: =IF(F34>=1.25,1,0) | P34: =IF(G34>=1.25,1,0) | Q34: =IF(H34>=1.25,1,0) | R34: =IF(I34>=1.25,1,0) | S34: =IF(F34>=1,1,0) | T34: =IF(G34>=1,1,0) | U34: =IF(H34>=1,1,0) | V34: =IF(I34>=1,1,0) | W34: =IF(S34=1,S34+W33,0) | X34: =IF(T34=1,T34+X33,0) | Y34: =IF(U34=1,U34+Y33,0) | Z34: =IF(V34=1,V34+Z33,0)
A35: 44013 | F35: ='2020 Summary'!B45 | G35: ='2020 Summary'!C45 | H35: ='2020 Summary'!D45 | I35: ='2020 Summary'!E45 | J35: =AVERAGE(F35:I35) | O35: =IF(F35>=1.25,1,0) | P35: =IF(G35>=1.25,1,0) | Q35: =IF(H35>=1.25,1,0) | R35: =IF(I35>=1.25,1,0) | S35: =IF(F35>=1,1,0) | T35: =IF(G35>=1,1,0) | U35: =IF(H35>=1,1,0) | V35: =IF(I35>=1,1,0) | W35: =IF(S35=1,S35+W34,0) | X35: =IF(T35=1,T35+X34,0) | Y35: =IF(U35=1,U35+Y34,0) | Z35: =IF(V35=1,V35+Z34,0)
A36: 44044 | F36: ='2020 Summary'!B46 | G36: ='2020 Summary'!C46 | H36: ='2020 Summary'!D46 | I36: ='2020 Summary'!E46 | J36: =AVERAGE(F36:I36) | O36: =IF(F36>=1.25,1,0) | P36: =IF(G36>=1.25,1,0) | Q36: =IF(H36>=1.25,1,0) | R36: =IF(I36>=1.25,1,0) | S36: =IF(F36>=1,1,0) | T36: =IF(G36>=1,1,0) | U36: =IF(H36>=1,1,0) | V36: =IF(I36>=1,1,0) | W36: =IF(S36=1,S36+W35,0) | X36: =IF(T36=1,T36+X35,0) | Y36: =IF(U36=1,U36+Y35,0) | Z36: =IF(V36=1,V36+Z35,0)
A37: 44075 | F37: ='2020 Summary'!B47 | G37: ='2020 Summary'!C47 | H37: ='2020 Summary'!D47 | I37: ='2020 Summary'!E47 | J37: =AVERAGE(F37:I37) | K37: =RANK(F37,F$5:F$41) | L37: =RANK(G37,G$5:G$41) | M37: =RANK(H37,H$5:H$41) | N37: =RANK(I37,I$5:I$41) | O37: =IF(F37>=1.25,1,0) | P37: =IF(G37>=1.25,1,0) | Q37: =IF(H37>=1.25,1,0) | R37: =IF(I37>=1.25,1,0) | S37: =IF(F37>=1,1,0) | T37: =IF(G37>=1,1,0) | U37: =IF(H37>=1,1,0) | V37: =IF(I37>=1,1,0) | W37: =IF(S37=1,S37+W36,0) | X37: =IF(T37=1,T37+X36,0) | Y37: =IF(U37=1,U37+Y36,0) | Z37: =IF(V37=1,V37+Z36,0)
A38: 44105 | F38: ='2020 Summary'!B48 | G38: ='2020 Summary'!C48 | H38: ='2020 Summary'!D48 | I38: ='2020 Summary'!E48 | J38: =AVERAGE(F38:I38) | K38: =RANK(F38,F$5:F$41) | L38: =RANK(G38,G$5:G$41) | M38: =RANK(H38,H$5:H$41) | N38: =RANK(I38,I$5:I$41) | O38: =IF(F38>=1.25,1,0) | P38: =IF(G38>=1.25,1,0) | Q38: =IF(H38>=1.25,1,0) | R38: =IF(I38>=1.25,1,0) | S38: =IF(F38>=1,1,0) | T38: =IF(G38>=1,1,0) | U38: =IF(H38>=1,1,0) | V38: =IF(I38>=1,1,0) | W38: =IF(S38=1,S38+W37,0) | X38: =IF(T38=1,T38+X37,0) | Y38: =IF(U38=1,U38+Y37,0) | Z38: =IF(V38=1,V38+Z37,0)
A39: 44136 | F39: ='2020 Summary'!B49 | G39: ='2020 Summary'!C49 | H39: ='2020 Summary'!D49 | I39: ='2020 Summary'!E49 | J39: =AVERAGE(F39:I39) | K39: =RANK(F39,F$5:F$41) | L39: =RANK(G39,G$5:G$41) | M39: =RANK(H39,H$5:H$41) | N39: =RANK(I39,I$5:I$41) | O39: =IF(F39>=1.25,1,0) | P39: =IF(G39>=1.25,1,0) | Q39: =IF(H39>=1.25,1,0) | R39: =IF(I39>=1.25,1,0) | S39: =IF(F39>=1,1,0) | T39: =IF(G39>=1,1,0) | U39: =IF(H39>=1,1,0) | V39: =IF(I39>=1,1,0) | W39: =IF(S39=1,S39+W38,0) | X39: =IF(T39=1,T39+X38,0) | Y39: =IF(U39=1,U39+Y38,0) | Z39: =IF(V39=1,V39+Z38,0)
A40: 44166 | F40: ='2020 Summary'!B50 | G40: ='2020 Summary'!C50 | H40: ='2020 Summary'!D50 | I40: ='2020 Summary'!E50 | J40: =AVERAGE(F40:I40) | K40: =RANK(F40,F$5:F$41) | L40: =RANK(G40,G$5:G$41) | M40: =RANK(H40,H$5:H$41) | N40: =RANK(I40,I$5:I$41) | O40: =IF(F40>=1.25,1,0) | P40: =IF(G40>=1.25,1,0) | Q40: =IF(H40>=1.25,1,0) | R40: =IF(I40>=1.25,1,0) | S40: =IF(F40>=1,1,0) | T40: =IF(G40>=1,1,0) | U40: =IF(H40>=1,1,0) | V40: =IF(I40>=1,1,0) | W40: =IF(S40=1,S40+W39,0) | X40: =IF(T40=1,T40+X39,0) | Y40: =IF(U40=1,U40+Y39,0) | Z40: =IF(V40=1,V40+Z39,0)
A41: 44197 | F41: ='2021 Summary'!B39 | G41: ='2021 Summary'!C39 | H41: ='2021 Summary'!D39 | I41: ='2021 Summary'!E39 | J41: =AVERAGE(F41:I41) | K41: =RANK(F41,F$5:F$41) | L41: =RANK(G41,G$5:G$41) | M41: =RANK(H41,H$5:H$41) | N41: =RANK(I41,I$5:I$41) | O41: =IF(F41>=1.25,1,0) | P41: =IF(G41>=1.25,1,0) | Q41: =IF(H41>=1.25,1,0) | R41: =IF(I41>=1.25,1,0) | S41: =IF(F41>=1,1,0) | T41: =IF(G41>=1,1,0) | U41: =IF(H41>=1,1,0) | V41: =IF(I41>=1,1,0) | W41: =IF(S41=1,S41+W40,0) | X41: =IF(T41=1,T41+X40,0) | Y41: =IF(U41=1,U41+Y40,0) | Z41: =IF(V41=1,V41+Z40,0)
A42: 44228 | F42: ='2021 Summary'!B40 | G42: ='2021 Summary'!C40 | H42: ='2021 Summary'!D40 | I42: ='2021 Summary'!E40 | J42: =AVERAGE(F42:I42)
...

Sheet Maximum Summary
C3: Lead Averages | G3: Arsenic Averages
A4: Month | B4: Station 1 | C4: Station 2 | D4: Station 4 | E4: Station 5 | F4: Station 1 | G4: Station 2 | H4: Station 4 | I4: Station 5 | J4: All Stations | X4: 0 | Y4: 0 | Z4: 0 | AA4: 0
A5: 43101 | F5: ='2018 Summary'!F39 | G5: ='2018 Summary'!G39 | H5: ='2018 Summary'!H39 | I5: ='2018 Summary'!I39 | J5: =MAX(F5:I5) | K5: Curtailment | P5: =IF(F5>=1.25,1,0) | Q5: =IF(G5>=1.25,1,0) | R5: =IF(H5>=1.25,1,0) | S5: =IF(I5>=1.25,1,0) | T5: =IF(F5>=1,1,0) | U5: =IF(G5>=1,1,0) | V5: =IF(H5>=1,1,0) | W5: =IF(I5>=1,1,0) | X5: =IF(T5=1,T5+X4,0) | Y5: =IF(U5=1,U5+Y4,0) | Z5: =IF(V5=1,V5+Z4,0) | AA5: =IF(W5=1,W5+AA4,0)
A6: 43132 | F6: ='2018 Summary'!F40 | G6: ='2018 Summary'!G40 | H6: ='2018 Summary'!H40 | I6: ='2018 Summary'!I40 | J6: =MAX(F6:I6) | P6: =IF(F6>=1.25,1,0) | Q6: =IF(G6>=1.25,1,0) | R6: =IF(H6>=1.25,1,0) | S6: =IF(I6>=1.25,1,0) | T6: =IF(F6>=1,1,0) | U6: =IF(G6>=1,1,0) | V6: =IF(H6>=1,1,0) | W6: =IF(I6>=1,1,0) | X6: =IF(T6=1,T6+X5,0) | Y6: =IF(U6=1,U6+Y5,0) | Z6: =IF(V6=1,V6+Z5,0) | AA6: =IF(W6=1,W6+AA5,0)
A7: 43160 | F7: ='2018 Summary'!F41 | G7: ='2018 Summary'!G41 | H7: ='2018 Summary'!H41 | I7: ='2018 Summary'!I41 | J7: =MAX(F7:I7) | P7: =IF(F7>=1.25,1,0) | Q7: =IF(G7>=1.25,1,0) | R7: =IF(H7>=1.25,1,0) | S7: =IF(I7>=1.25,1,0) | T7: =IF(F7>=1,1,0) | U7: =IF(G7>=1,1,0) | V7: =IF(H7>=1,1,0) | W7: =IF(I7>=1,1,0) | X7: =IF(T7=1,T7+X6,0) | Y7: =IF(U7=1,U7+Y6,0) | Z7: =IF(V7=1,V7+Z6,0) | AA7: =IF(W7=1,W7+AA6,0)
A8: 43191 | F8: ='2018 Summary'!F42 | G8: ='2018 Summary'!G42 | H8: ='2018 Summary'!H42 | I8: ='2018 Summary'!I42 | J8: =MAX(F8:I8) | P8: =IF(F8>=1.25,1,0) | Q8: =IF(G8>=1.25,1,0) | R8: =IF(H8>=1.25,1,0) | S8: =IF(I8>=1.25,1,0) | T8: =IF(F8>=1,1,0) | U8: =IF(G8>=1,1,0) | V8: =IF(H8>=1,1,0) | W8: =IF(I8>=1,1,0) | X8: =IF(T8=1,T8+X7,0) | Y8: =IF(U8=1,U8+Y7,0) | Z8: =IF(V8=1,V8+Z7,0) | AA8: =IF(W8=1,W8+AA7,0)
A9: 43221 | F9: ='2018 Summary'!F43 | G9: ='2018 Summary'!G43 | H9: ='2018 Summary'!H43 | I9: ='2018 Summary'!I43 | J9: =MAX(F9:I9) | P9: =IF(F9>=1.25,1,0) | Q9: =IF(G9>=1.25,1,0) | R9: =IF(H9>=1.25,1,0) | S9: =IF(I9>=1.25,1,0) | T9: =IF(F9>=1,1,0) | U9: =IF(G9>=1,1,0) | V9: =IF(H9>=1,1,0) | W9: =IF(I9>=1,1,0) | X9: =IF(T9=1,T9+X8,0) | Y9: =IF(U9=1,U9+Y8,0) | Z9: =IF(V9=1,V9+Z8,0) | AA9: =IF(W9=1,W9+AA8,0)
A10: 43252 | F10: ='2018 Summary'!F44 | G10: ='2018 Summary'!G44 | H10: ='2018 Summary'!H44 | I10: ='2018 Summary'!I44 | J10: =MAX(F10:I10) | P10: =IF(F10>=1.25,1,0) | Q10: =IF(G10>=1.25,1,0) | R10: =IF(H10>=1.25,1,0) | S10: =IF(I10>=1.25,1,0) | T10: =IF(F10>=1,1,0) | U10: =IF(G10>=1,1,0) | V10: =IF(H10>=1,1,0) | W10: =IF(I10>=1,1,0) | X10: =IF(T10=1,T10+X9,0) | Y10: =IF(U10=1,U10+Y9,0) | Z10: =IF(V10=1,V10+Z9,0) | AA10: =IF(W10=1,W10+AA9,0)
A11: 43282 | F11: ='2018 Summary'!F45 | G11: ='2018 Summary'!G45 | H11: ='2018 Summary'!H45 | I11: ='2018 Summary'!I45 | J11: =MAX(F11:I11) | P11: =IF(F11>=1.25,1,0) | Q11: =IF(G11>=1.25,1,0) | R11: =IF(H11>=1.25,1,0) | S11: =IF(I11>=1.25,1,0) | T11: =IF(F11>=1,1,0) | U11: =IF(G11>=1,1,0) | V11: =IF(H11>=1,1,0) | W11: =IF(I11>=1,1,0) | X11: =IF(T11=1,T11+X10,0) | Y11: =IF(U11=1,U11+Y10,0) | Z11: =IF(V11=1,V11+Z10,0) | AA11: =IF(W11=1,W11+AA10,0)
A12: 43313 | F12: ='2018 Summary'!F46 | G12: ='2018 Summary'!G46 | H12: ='2018 Summary'!H46 | I12: ='2018 Summary'!I46 | J12: =MAX(F12:I12) | P12: =IF(F12>=1.25,1,0) | Q12: =IF(G12>=1.25,1,0) | R12: =IF(H12>=1.25,1,0) | S12: =IF(I12>=1.25,1,0) | T12: =IF(F12>=1,1,0) | U12: =IF(G12>=1,1,0) | V12: =IF(H12>=1,1,0) | W12: =IF(I12>=1,1,0) | X12: =IF(T12=1,T12+X11,0) | Y12: =IF(U12=1,U12+Y11,0) | Z12: =IF(V12=1,V12+Z11,0) | AA12: =IF(W12=1,W12+AA11,0)
A13: 43344 | F13: ='2018 Summary'!F47 | G13: ='2018 Summary'!G47 | H13: ='2018 Summary'!H47 | I13: ='2018 Summary'!I47 | J13: =MAX(F13:I13) | P13: =IF(F13>=1.25,1,0) | Q13: =IF(G13>=1.25,1,0) | R13: =IF(H13>=1.25,1,0) | S13: =IF(I13>=1.25,1,0) | T13: =IF(F13>=1,1,0) | U13: =IF(G13>=1,1,0) | V13: =IF(H13>=1,1,0) | W13: =IF(I13>=1,1,0) | X13: =IF(T13=1,T13+X12,0) | Y13: =IF(U13=1,U13+Y12,0) | Z13: =IF(V13=1,V13+Z12,0) | AA13: =IF(W13=1,W13+AA12,0)
A14: 43374 | F14: ='2018 Summary'!F48 | G14: ='2018 Summary'!G48 | H14: ='2018 Summary'!H48 | I14: ='2018 Summary'!I48 | J14: =MAX(F14:I14) | P14: =IF(F14>=1.25,1,0) | Q14: =IF(G14>=1.25,1,0) | R14: =IF(H14>=1.25,1,0) | S14: =IF(I14>=1.25,1,0) | T14: =IF(F14>=1,1,0) | U14: =IF(G14>=1,1,0) | V14: =IF(H14>=1,1,0) | W14: =IF(I14>=1,1,0) | X14: =IF(T14=1,T14+X13,0) | Y14: =IF(U14=1,U14+Y13,0) | Z14: =IF(V14=1,V14+Z13,0) | AA14: =IF(W14=1,W14+AA13,0)
A15: 43405 | F15: ='2018 Summary'!F49 | G15: ='2018 Summary'!G49 | H15: ='2018 Summary'!H49 | I15: ='2018 Summary'!I49 | J15: =MAX(F15:I15) | P15: =IF(F15>=1.25,1,0) | Q15: =IF(G15>=1.25,1,0) | R15: =IF(H15>=1.25,1,0) | S15: =IF(I15>=1.25,1,0) | T15: =IF(F15>=1,1,0) | U15: =IF(G15>=1,1,0) | V15: =IF(H15>=1,1,0) | W15: =IF(I15>=1,1,0) | X15: =IF(T15=1,T15+X14,0) | Y15: =IF(U15=1,U15+Y14,0) | Z15: =IF(V15=1,V15+Z14,0) | AA15: =IF(W15=1,W15+AA14,0)
A16: 43435 | F16: ='2018 Summary'!F50 | G16: ='2018 Summary'!G50 | H16: ='2018 Summary'!H50 | I16: ='2018 Summary'!I50 | J16: =MAX(F16:I16) | P16: =IF(F16>=1.25,1,0) | Q16: =IF(G16>=1.25,1,0) | R16: =IF(H16>=1.25,1,0) | S16: =IF(I16>=1.25,1,0) | T16: =IF(F16>=1,1,0) | U16: =IF(G16>=1,1,0) | V16: =IF(H16>=1,1,0) | W16: =IF(I16>=1,1,0) | X16: =IF(T16=1,T16+X15,0) | Y16: =IF(U16=1,U16+Y15,0) | Z16: =IF(V16=1,V16+Z15,0) | AA16: =IF(W16=1,W16+AA15,0)
