Workbook
Name Date_Range_Pb_2014: 'Lead (30-Day_Avg)'!#REF!
Name Date_Range_Pb_2014: 'Lead (30-Day_Avg)'!#REF!
Name Date_Range_Pb_2014: 'Lead (30-Day_Avg)'!#REF!
Name Date_Range_Pb_2014: 'Lead (30-Day_Avg)'!#REF!
Name Date_Range_Pb_2014: 'Lead (30-Day_Avg)'!#REF!
Name Lead_Table_2014: 'Lead (30-Day_Avg)'!#REF!
Name Lead_Table_2014: 'Lead (30-Day_Avg)'!#REF!
Name Lead_Table_2014: 'Lead (30-Day_Avg)'!#REF!
Name Lead_Table_2014: 'Lead (30-Day_Avg)'!#REF!
Name Lead_Table_2014: 'Lead (30-Day_Avg)'!#REF!
Name Month_Num_Arsenic: 'Arsenic (Daily)'!#REF!
Name Month_Num_Arsenic: 'Arsenic (Daily)'!#REF!
Name Month_Num_Arsenic: 'Arsenic (Daily)'!#REF!
Name Month_Num_Arsenic: 'Arsenic (Daily)'!#REF!
Name Month_Num_Arsenic: 'Arsenic (Daily)'!#REF!
Name Month_Num_Lead: 'Lead (30-Day_Avg)'!#REF!
Name Month_Num_Lead: 'Lead (30-Day_Avg)'!#REF!
Name Month_Num_Lead: 'Lead (30-Day_Avg)'!#REF!
Name Month_Num_Lead: 'Lead (30-Day_Avg)'!#REF!
Name Month_Num_Lead: 'Lead (30-Day_Avg)'!#REF!
Name Reporting_Limit_Table: #REF!
Name Reporting_Limit_Table: #REF!
Name Reporting_Limit_Table: #REF!
Name Reporting_Limit_Table: #REF!
Name Reporting_Limit_Table: #REF!
Name Station_1_As_2014: 'Arsenic (Daily)'!#REF!
Name Station_1_As_2014: 'Arsenic (Daily)'!#REF!
Name Station_1_As_2014: 'Arsenic (Daily)'!#REF!
Name Station_1_As_2014: 'Arsenic (Daily)'!#REF!
Name Station_1_As_2014: 'Arsenic (Daily)'!#REF!
Name Station_1_Pb_2014: 'Lead (30-Day_Avg)'!#REF!
Name Station_1_Pb_2014: 'Lead (30-Day_Avg)'!#REF!
Name Station_1_Pb_2014: 'Lead (30-Day_Avg)'!#REF!
Name Station_1_Pb_2014: 'Lead (30-Day_Avg)'!#REF!
Name Station_1_Pb_2014: 'Lead (30-Day_Avg)'!#REF!
Name Station_2_As_2014: 'Arsenic (Daily)'!#REF!
Name Station_2_As_2014: 'Arsenic (Daily)'!#REF!
Name Station_2_As_2014: 'Arsenic (Daily)'!#REF!
Name Station_2_As_2014: 'Arsenic (Daily)'!#REF!
Name Station_2_As_2014: 'Arsenic (Daily)'!#REF!
Name Station_2_Pb_2014: 'Lead (30-Day_Avg)'!#REF!
Name Station_2_Pb_2014: 'Lead (30-Day_Avg)'!#REF!
Name Station_2_Pb_2014: 'Lead (30-Day_Avg)'!#REF!
Name Station_2_Pb_2014: 'Lead (30-Day_Avg)'!#REF!
Name Station_2_Pb_2014: 'Lead (30-Day_Avg)'!#REF!
Name Station_4_As_2014: 'Arsenic (Daily)'!#REF!
Name Station_4_As_2014: 'Arsenic (Daily)'!#REF!
Name Station_4_As_2014: 'Arsenic (Daily)'!#REF!
Name Station_4_As_2014: 'Arsenic (Daily)'!#REF!
Name Station_4_As_2014: 'Arsenic (Daily)'!#REF!
Name Station_4_Pb_2014: 'Lead (30-Day_Avg)'!#REF!
Name Station_4_Pb_2014: 'Lead (30-Day_Avg)'!#REF!
Name Station_4_Pb_2014: 'Lead (30-Day_Avg)'!#REF!
Name Station_4_Pb_2014: 'Lead (30-Day_Avg)'!#REF!
Name Station_4_Pb_2014: 'Lead (30-Day_Avg)'!#REF!
Name Station_5_As_2014: 'Arsenic (Daily)'!#REF!
Name Station_5_As_2014: 'Arsenic (Daily)'!#REF!
Name Station_5_As_2014: 'Arsenic (Daily)'!#REF!
Name Station_5_As_2014: 'Arsenic (Daily)'!#REF!
Name Station_5_As_2014: 'Arsenic (Daily)'!#REF!

Sheet 2018 Summary
A1: Weekend / Weekday Ambient Monitor Results
C4: Lead (µg/m3) | F4: Arsenic (ng/m3)
A5: Parameter | B5: WeekEND | C5: WeekDAY | D5: % WD Diff | E5: WeekEND | F5: WeekDAY | G5: % WD Diff
A6: Maximum: | B6: ='Lead (30-Day_Avg)'!Z5 -> 0.1439475 | C6: ='Lead (30-Day_Avg)'!AA5 -> 0.194825 | D6: =(C6-B6)/B6 -> 0.35344483 | E6: ='Arsenic (Daily)'!V5 -> 3.848 | F6: ='Arsenic (Daily)'!W5 -> 5.832875 | G6: =(F6-E6)/E6 -> 0.51581991
A7: 90th percentile: | B7: ='Lead (30-Day_Avg)'!Z6 -> 0.026462972 | C7: ='Lead (30-Day_Avg)'!AA6 -> 0.051125 | D7: =(C7-B7)/B7 -> 0.93194473 | E7: ='Arsenic (Daily)'!V6 -> 1.297 | F7: ='Arsenic (Daily)'!W6 -> 1.7136451 | G7: =(F7-E7)/E7 -> 0.32123752
A8: 75th percentile: | B8: ='Lead (30-Day_Avg)'!Z7 -> 0.020052822 | C8: ='Lead (30-Day_Avg)'!AA7 -> 0.03815 | D8: =(C8-B8)/B8 -> 0.90247535 | E8: ='Arsenic (Daily)'!V7 -> 1.0465813 | F8: ='Arsenic (Daily)'!W7 -> 1.3592797 | G8: =(F8-E8)/E8 -> 0.29878087
A9: Average: | B9: ='Lead (30-Day_Avg)'!Z8 -> 0.017377401 | C9: ='Lead (30-Day_Avg)'!AA8 -> 0.03235197 | D9: =(C9-B9)/B9 -> 0.86172659 | E9: ='Arsenic (Daily)'!V8 -> 0.84828132 | F9: ='Arsenic (Daily)'!W8 -> 1.1258336 | G9: =(F9-E9)/E9 -> 0.32719369
A12: Excluding extraordinary events (looking at "normal" operations only).
A15: LEAD
C16: Averages | G16: Maximum
A17: Month | B17: Station 1 | C17: Station 2 | D17: Station 4 | E17: Station 5 | F17: Station 1 | G17: Station 2 | H17: Station 4 | I17: Station 5
A18: January | B18: ='Lead (30-Day_Avg)'!AA400 -> 0.020225806 | C18: ='Lead (30-Day_Avg)'!AB400 -> 0.023955556 | D18: ='Lead (30-Day_Avg)'!AC400 -> 0.027339677 | E18: ='Lead (30-Day_Avg)'!AD400 -> 0.030751613 | F18: ='Lead (30-Day_Avg)'!AA401 -> 0.0489 | G18: ='Lead (30-Day_Avg)'!AB401 -> 0.115 | H18: ='Lead (30-Day_Avg)'!AC401 -> 0.0629 | I18: ='Lead (30-Day_Avg)'!AD401 -> 0.0569 | J18: =AVERAGE(B18:E18) -> 0.025568163 | K18: =(J18-$B$33)/$B$33 -> -0.045211828
A19: February | B19: ='Lead (30-Day_Avg)'!AA428 -> 0.034275 | C19: ='Lead (30-Day_Avg)'!AB428 -> 0.023180909 | D19: ='Lead (30-Day_Avg)'!AC428 -> 0.020457143 | E19: ='Lead (30-Day_Avg)'!AD428 -> 0.024435714 | F19: ='Lead (30-Day_Avg)'!AA429 -> 0.4 | G19: ='Lead (30-Day_Avg)'!AB429 -> 0.058 | H19: ='Lead (30-Day_Avg)'!AC429 -> 0.0458 | I19: ='Lead (30-Day_Avg)'!AD429 -> 0.0462 | J19: =AVERAGE(B19:E19) -> 0.025587192 | K19: =(J19-$B$33)/$B$33 -> -0.04450125
A20: March | B20: ='Lead (30-Day_Avg)'!AA459 -> 0.027303226 | C20: ='Lead (30-Day_Avg)'!AB459 -> 0.023790833 | D20: ='Lead (30-Day_Avg)'!AC459 -> 0.023975161 | E20: ='Lead (30-Day_Avg)'!AD459 -> 0.025377419 | F20: ='Lead (30-Day_Avg)'!AA460 -> 0.097 | G20: ='Lead (30-Day_Avg)'!AB460 -> 0.0474 | H20: ='Lead (30-Day_Avg)'!AC460 -> 0.0714 | I20: ='Lead (30-Day_Avg)'!AD460 -> 0.0454 | J20: =AVERAGE(B20:E20) -> 0.02511166 | K20: =(J20-$B$33)/$B$33 -> -0.062258957
A21: April | B21: ='Lead (30-Day_Avg)'!AA489 -> 0.03312 | C21: ='Lead (30-Day_Avg)'!AB489 -> 0.026265714 | D21: ='Lead (30-Day_Avg)'!AC489 -> 0.12723167 | E21: ='Lead (30-Day_Avg)'!AD489 -> 0.0277 | F21: ='Lead (30-Day_Avg)'!AA490 -> 0.16 | G21: ='Lead (30-Day_Avg)'!AB490 -> 0.0947 | H21: ='Lead (30-Day_Avg)'!AC490 -> 3.145 | I21: ='Lead (30-Day_Avg)'!AD490 -> 0.0496 | J21: =AVERAGE(B21:E21) -> 0.053579345 | K21: =(J21-$B$33)/$B$33 -> 1.0008056
A22: May | B22: ='Lead (30-Day_Avg)'!AA520 -> 0.028093548 | C22: ='Lead (30-Day_Avg)'!AB520 -> 0.020872222 | D22: ='Lead (30-Day_Avg)'!AC520 -> 0.021795484 | E22: ='Lead (30-Day_Avg)'!AD520 -> 0.029919355 | F22: ='Lead (30-Day_Avg)'!AA521 -> 0.0523 | G22: ='Lead (30-Day_Avg)'!AB521 -> 0.049 | H22: ='Lead (30-Day_Avg)'!AC521 -> 0.176 | I22: ='Lead (30-Day_Avg)'!AD521 -> 0.119 | J22: =AVERAGE(B22:E22) -> 0.025170152 | K22: =(J22-$B$33)/$B$33 -> -0.060074685
A23: June | B23: ='Lead (30-Day_Avg)'!AA550 -> 0.02999 | C23: ='Lead (30-Day_Avg)'!AB550 -> 0.01992 | D23: ='Lead (30-Day_Avg)'!AC550 -> 0.018500667 | E23: ='Lead (30-Day_Avg)'!AD550 -> 0.021396667 | F23: ='Lead (30-Day_Avg)'!AA551 -> 0.0935 | G23: ='Lead (30-Day_Avg)'!AB551 -> 0.046 | H23: ='Lead (30-Day_Avg)'!AC551 -> 0.0618 | I23: ='Lead (30-Day_Avg)'!AD551 -> 0.0354 | J23: =AVERAGE(B23:E23) -> 0.022451833 | K23: =(J23-$B$33)/$B$33 -> -0.16158447
A24: July | B24: ='Lead (30-Day_Avg)'!AA581 -> 0.023290323 | C24: ='Lead (30-Day_Avg)'!AB581 -> 0.022496667 | D24: ='Lead (30-Day_Avg)'!AC581 -> 0.018733548 | E24: ='Lead (30-Day_Avg)'!AD581 -> 0.021112903 | F24: ='Lead (30-Day_Avg)'!AA582 -> 0.047 | G24: ='Lead (30-Day_Avg)'!AB582 -> 0.0391 | H24: ='Lead (30-Day_Avg)'!AC582 -> 0.0437 | I24: ='Lead (30-Day_Avg)'!AD582 -> 0.034 | J24: =AVERAGE(B24:E24) -> 0.02140836 | K24: =(J24-$B$33)/$B$33 -> -0.20055074
A25: August | B25: ='Lead (30-Day_Avg)'!AA612 -> 0.024664516 | C25: ='Lead (30-Day_Avg)'!AB612 -> 0.024602778 | D25: ='Lead (30-Day_Avg)'!AC612 -> 0.020794194 | E25: ='Lead (30-Day_Avg)'!AD612 -> 0.021948387 | F25: ='Lead (30-Day_Avg)'!AA613 -> 0.0518 | G25: ='Lead (30-Day_Avg)'!AB613 -> 0.0431 | H25: ='Lead (30-Day_Avg)'!AC613 -> 0.0446 | I25: ='Lead (30-Day_Avg)'!AD613 -> 0.0321 | J25: =AVERAGE(B25:E25) -> 0.023002469 | K25: =(J25-$B$33)/$B$33 -> -0.14102218
A26: September | B26: ='Lead (30-Day_Avg)'!AA642 -> 0.022075862 | C26: ='Lead (30-Day_Avg)'!AB642 -> 0.019264857 | D26: ='Lead (30-Day_Avg)'!AC642 -> 0.022983 | E26: ='Lead (30-Day_Avg)'!AD642 -> 0.02582 | F26: ='Lead (30-Day_Avg)'!AA643 -> 0.0346 | G26: ='Lead (30-Day_Avg)'!AB643 -> 0.0518 | H26: ='Lead (30-Day_Avg)'!AC643 -> 0.127 | I26: ='Lead (30-Day_Avg)'!AD643 -> 0.0442 | J26: =AVERAGE(B26:E26) -> 0.02253593 | K26: =(J26-$B$33)/$B$33 -> -0.15844407
A27: October | B27: ='Lead (30-Day_Avg)'!AA673 -> 0.024912903 | C27: ='Lead (30-Day_Avg)'!AB673 -> 0.027980556 | D27: ='Lead (30-Day_Avg)'!AC673 -> 0.026790323 | E27: ='Lead (30-Day_Avg)'!AD673 -> 0.039992903 | F27: ='Lead (30-Day_Avg)'!AA674 -> 0.0852 | G27: ='Lead (30-Day_Avg)'!AB674 -> 0.0732 | H27: ='Lead (30-Day_Avg)'!AC674 -> 0.0756 | I27: ='Lead (30-Day_Avg)'!AD674 -> 0.229 | J27: =AVERAGE(B27:E27) -> 0.029919171 | K27: =(J27-$B$33)/$B$33 -> 0.11726723
A28: November | B28: ='Lead (30-Day_Avg)'!AA703 -> 0.02031 | C28: ='Lead (30-Day_Avg)'!AB703 -> 0.023934286 | D28: ='Lead (30-Day_Avg)'!AC703 -> 0.022763333 | E28: ='Lead (30-Day_Avg)'!AD703 -> 0.026626667 | F28: ='Lead (30-Day_Avg)'!AA704 -> 0.048 | G28: ='Lead (30-Day_Avg)'!AB704 -> 0.0689 | H28: ='Lead (30-Day_Avg)'!AC704 -> 0.0773 | I28: ='Lead (30-Day_Avg)'!AD704 -> 0.0485 | J28: =AVERAGE(B28:E28) -> 0.023408571 | K28: =(J28-$B$33)/$B$33 -> -0.12585714
A29: December | B29: ='Lead (30-Day_Avg)'!AA734 -> 0.014403226 | C29: ='Lead (30-Day_Avg)'!AB734 -> 0.015713784 | D29: ='Lead (30-Day_Avg)'!AC734 -> 0.024961613 | E29: ='Lead (30-Day_Avg)'!AD734 -> 0.020625806 | F29: ='Lead (30-Day_Avg)'!AA735 -> 0.044 | G29: ='Lead (30-Day_Avg)'!AB735 -> 0.0518 | H29: ='Lead (30-Day_Avg)'!AC735 -> 0.0655 | I29: ='Lead (30-Day_Avg)'!AD735 -> 0.0419 | J29: =AVERAGE(B29:E29) -> 0.018926107 | K29: =(J29-$B$33)/$B$33 -> -0.29324515
B31: ='Lead (30-Day_Avg)'!AA741 -> 0.025143407 | C31: ='Lead (30-Day_Avg)'!AB741 -> 0.022647887 | D31: ='Lead (30-Day_Avg)'!AC741 -> 0.031269178 | E31: ='Lead (30-Day_Avg)'!AD741 -> 0.026334466 | F31: ='Lead (30-Day_Avg)'!AA742 -> 0.4 | G31: ='Lead (30-Day_Avg)'!AB742 -> 0.115 | H31: ='Lead (30-Day_Avg)'!AC742 -> 3.145 | I31: ='Lead (30-Day_Avg)'!AD742 -> 0.229
B33: ='Lead (30-Day_Avg)'!AA744 -> 0.026778885
A36: ARSENIC
C37: Averages | G37: Maximum
A38: Month | B38: Station 1 | C38: Station 2 | D38: Station 4 | E38: Station 5 | F38: Station 1 | G38: Station 2 | H38: Station 4 | I38: Station 5
A39: January | B39: ='Arsenic (Daily)'!V35 -> 1.6030323 | C39: ='Arsenic (Daily)'!W35 -> 1.4038778 | D39: ='Arsenic (Daily)'!X35 -> 1.2265581 | E39: ='Arsenic (Daily)'!Y35 -> 1.4970645 | F39: ='Arsenic (Daily)'!V36 -> 10.99 | G39: ='Arsenic (Daily)'!W36 -> 9.29 | H39: ='Arsenic (Daily)'!X36 -> 3.608 | I39: ='Arsenic (Daily)'!Y36 -> 8.132 | J39: =AVERAGE(B39:E39) -> 1.4326332 | K39: =(J39-$B$54)/$B$54 -> 0.35412302
A40: February | B40: ='Arsenic (Daily)'!V63 -> 1.0420036 | C40: ='Arsenic (Daily)'!W63 -> 1.0304879 | D40: ='Arsenic (Daily)'!X63 -> 0.89647143 | E40: ='Arsenic (Daily)'!Y63 -> 1.0923321 | F40: ='Arsenic (Daily)'!V64 -> 1.84 | G40: ='Arsenic (Daily)'!W64 -> 1.752 | H40: ='Arsenic (Daily)'!X64 -> 1.714 | I40: ='Arsenic (Daily)'!Y64 -> 1.851 | J40: =AVERAGE(B40:E40) -> 1.0153238 | K40: =(J40-$B$54)/$B$54 -> -0.040317287
A41: March | B41: ='Arsenic (Daily)'!V94 -> 0.80372258 | C41: ='Arsenic (Daily)'!W94 -> 0.82285 | D41: ='Arsenic (Daily)'!X94 -> 0.63034194 | E41: ='Arsenic (Daily)'!Y94 -> 0.77344194 | F41: ='Arsenic (Daily)'!V95 -> 1.474 | G41: ='Arsenic (Daily)'!W95 -> 1.86 | H41: ='Arsenic (Daily)'!X95 -> 1.278 | I41: ='Arsenic (Daily)'!Y95 -> 1.488 | J41: =AVERAGE(B41:E41) -> 0.75758911 | K41: =(J41-$B$54)/$B$54 -> -0.28392774
A42: April | B42: ='Arsenic (Daily)'!V125 -> 0.97844 | C42: ='Arsenic (Daily)'!W125 -> 0.98598857 | D42: ='Arsenic (Daily)'!X125 -> 0.82104667 | E42: ='Arsenic (Daily)'!Y125 -> 0.96965 | F42: ='Arsenic (Daily)'!V126 -> 1.45 | G42: ='Arsenic (Daily)'!W126 -> 1.378 | H42: ='Arsenic (Daily)'!X126 -> 1.32 | I42: ='Arsenic (Daily)'!Y126 -> 1.704 | J42: =AVERAGE(B42:E42) -> 0.93878131 | K42: =(J42-$B$54)/$B$54 -> -0.11266511
A43: May | B43: ='Arsenic (Daily)'!V155 -> 0.8812129 | C43: ='Arsenic (Daily)'!W155 -> 0.84896944 | D43: ='Arsenic (Daily)'!X155 -> 0.68919677 | E43: ='Arsenic (Daily)'!Y155 -> 0.86710323 | F43: ='Arsenic (Daily)'!V156 -> 1.915 | G43: ='Arsenic (Daily)'!W156 -> 1.552 | H43: ='Arsenic (Daily)'!X156 -> 1.807 | I43: ='Arsenic (Daily)'!Y156 -> 1.852 | J43: =AVERAGE(B43:E43) -> 0.82162059 | K43: =(J43-$B$54)/$B$54 -> -0.22340527
A44: June | B44: ='Arsenic (Daily)'!V186 -> 1.33064 | C44: ='Arsenic (Daily)'!W186 -> 1.1071571 | D44: ='Arsenic (Daily)'!X186 -> 0.78369333 | E44: ='Arsenic (Daily)'!Y186 -> 0.91445 | F44: ='Arsenic (Daily)'!V187 -> 8.973 | G44: ='Arsenic (Daily)'!W187 -> 1.996 | H44: ='Arsenic (Daily)'!X187 -> 1.263 | I44: ='Arsenic (Daily)'!Y187 -> 1.506 | J44: =AVERAGE(B44:E44) -> 1.0339851 | K44: =(J44-$B$54)/$B$54 -> -0.02267859
A45: July | B45: ='Arsenic (Daily)'!V216 -> 1.480829 | C45: ='Arsenic (Daily)'!W216 -> 1.538625 | D45: ='Arsenic (Daily)'!X216 -> 1.0962 | E45: ='Arsenic (Daily)'!Y216 -> 1.2611548 | F45: ='Arsenic (Daily)'!V217 -> 3.83 | G45: ='Arsenic (Daily)'!W217 -> 5.133 | H45: ='Arsenic (Daily)'!X217 -> 3.421 | I45: ='Arsenic (Daily)'!Y217 -> 3.673 | J45: =AVERAGE(B45:E45) -> 1.3442022 | K45: =(J45-$B$54)/$B$54 -> 0.27053821
A46: August | B46: ='Arsenic (Daily)'!V247 -> 1.3591097 | C46: ='Arsenic (Daily)'!W247 -> 1.2067472 | D46: ='Arsenic (Daily)'!X247 -> 0.95609677 | E46: ='Arsenic (Daily)'!Y247 -> 1.1385935 | F46: ='Arsenic (Daily)'!V248 -> 4.197 | G46: ='Arsenic (Daily)'!W248 -> 2.194 | H46: ='Arsenic (Daily)'!X248 -> 1.725 | I46: ='Arsenic (Daily)'!Y248 -> 2.396 | J46: =AVERAGE(B46:E46) -> 1.1651368 | K46: =(J46-$B$54)/$B$54 -> 0.10128582
A47: September | B47: ='Arsenic (Daily)'!V278 -> 1.3191333 | C47: ='Arsenic (Daily)'!W278 -> 1.2964 | D47: ='Arsenic (Daily)'!X278 -> 1.06708 | E47: ='Arsenic (Daily)'!Y278 -> 1.2148667 | F47: ='Arsenic (Daily)'!V279 -> 4.04 | G47: ='Arsenic (Daily)'!W279 -> 3.656 | H47: ='Arsenic (Daily)'!X279 -> 3.335 | I47: ='Arsenic (Daily)'!Y279 -> 3.974 | J47: =AVERAGE(B47:E47) -> 1.22437 | K47: =(J47-$B$54)/$B$54 -> 0.15727296
A48: October | B48: ='Arsenic (Daily)'!V308 -> 1.1526516 | C48: ='Arsenic (Daily)'!W308 -> 1.1786568 | D48: ='Arsenic (Daily)'!X308 -> 1.007671 | E48: ='Arsenic (Daily)'!Y308 -> 1.0550484 | F48: ='Arsenic (Daily)'!V309 -> 1.765 | G48: ='Arsenic (Daily)'!W309 -> 2.335 | H48: ='Arsenic (Daily)'!X309 -> 1.947 | I48: ='Arsenic (Daily)'!Y309 -> 1.759 | J48: =AVERAGE(B48:E48) -> 1.0985069 | K48: =(J48-$B$54)/$B$54 -> 0.038307344
A49: November | B49: ='Arsenic (Daily)'!V339 -> 1.2221033 | C49: ='Arsenic (Daily)'!W339 -> 1.1164829 | D49: ='Arsenic (Daily)'!X339 -> 1.10671 | E49: ='Arsenic (Daily)'!Y339 -> 1.2580233 | F49: ='Arsenic (Daily)'!V340 -> 1.914 | G49: ='Arsenic (Daily)'!W340 -> 1.855 | H49: ='Arsenic (Daily)'!X340 -> 1.971 | I49: ='Arsenic (Daily)'!Y340 -> 3.453 | J49: =AVERAGE(B49:E49) -> 1.1758299 | K49: =(J49-$B$54)/$B$54 -> 0.1113929
A50: December | B50: ='Arsenic (Daily)'!V369 -> 1.016471 | C50: ='Arsenic (Daily)'!W369 -> 1.0189278 | D50: ='Arsenic (Daily)'!X369 -> 1.0546548 | E50: ='Arsenic (Daily)'!Y369 -> 1.037071 | F50: ='Arsenic (Daily)'!V370 -> 2.007 | G50: ='Arsenic (Daily)'!W370 -> 1.866 | H50: ='Arsenic (Daily)'!X370 -> 1.766 | I50: ='Arsenic (Daily)'!Y370 -> 1.853 | J50: =AVERAGE(B50:E50) -> 1.0317811 | K50: =(J50-$B$54)/$B$54 -> -0.02476179
...

Sheet 2019 Summary
A1: Weekend / Weekday Ambient Monitor Results
C4: Lead (µg/m3) | F4: Arsenic (ng/m3)
A5: Parameter | B5: WeekEND | C5: WeekDAY | D5: % WD Diff | E5: WeekEND | F5: WeekDAY | G5: % WD Diff
A6: Maximum: | B6: ='Lead (30-Day_Avg)'!Z5 -> 0.1439475 | C6: ='Lead (30-Day_Avg)'!AA5 -> 0.194825 | D6: =(C6-B6)/B6 -> 0.35344483 | E6: ='Arsenic (Daily)'!V5 -> 3.848 | F6: ='Arsenic (Daily)'!W5 -> 5.832875 | G6: =(F6-E6)/E6 -> 0.51581991
A7: 90th percentile: | B7: ='Lead (30-Day_Avg)'!Z6 -> 0.026462972 | C7: ='Lead (30-Day_Avg)'!AA6 -> 0.051125 | D7: =(C7-B7)/B7 -> 0.93194473 | E7: ='Arsenic (Daily)'!V6 -> 1.297 | F7: ='Arsenic (Daily)'!W6 -> 1.7136451 | G7: =(F7-E7)/E7 -> 0.32123752
A8: 75th percentile: | B8: ='Lead (30-Day_Avg)'!Z7 -> 0.020052822 | C8: ='Lead (30-Day_Avg)'!AA7 -> 0.03815 | D8: =(C8-B8)/B8 -> 0.90247535 | E8: ='Arsenic (Daily)'!V7 -> 1.0465813 | F8: ='Arsenic (Daily)'!W7 -> 1.3592797 | G8: =(F8-E8)/E8 -> 0.29878087
A9: Average: | B9: ='Lead (30-Day_Avg)'!Z8 -> 0.017377401 | C9: ='Lead (30-Day_Avg)'!AA8 -> 0.03235197 | D9: =(C9-B9)/B9 -> 0.86172659 | E9: ='Arsenic (Daily)'!V8 -> 0.84828132 | F9: ='Arsenic (Daily)'!W8 -> 1.1258336 | G9: =(F9-E9)/E9 -> 0.32719369
A12: Excluding extraordinary events (looking at "normal" operations only).
A15: LEAD
C16: Averages | G16: Maximum
A17: Month | B17: Station 1 | C17: Station 2 | D17: Station 4 | E17: Station 5 | F17: Station 1 | G17: Station 2 | H17: Station 4 | I17: Station 5
A18: January | B18: ='Lead (30-Day_Avg)'!AA400 -> 0.020225806 | C18: ='Lead (30-Day_Avg)'!AB400 -> 0.023955556 | D18: ='Lead (30-Day_Avg)'!AC400 -> 0.027339677 | E18: ='Lead (30-Day_Avg)'!AD400 -> 0.030751613 | F18: ='Lead (30-Day_Avg)'!AA401 -> 0.0489 | G18: ='Lead (30-Day_Avg)'!AB401 -> 0.115 | H18: ='Lead (30-Day_Avg)'!AC401 -> 0.0629 | I18: ='Lead (30-Day_Avg)'!AD401 -> 0.0569 | J18: =AVERAGE(B18:E18) -> 0.025568163 | K18: =(J18-$B$33)/$B$33 -> -0.045211828
A19: February | B19: ='Lead (30-Day_Avg)'!AA428 -> 0.034275 | C19: ='Lead (30-Day_Avg)'!AB428 -> 0.023180909 | D19: ='Lead (30-Day_Avg)'!AC428 -> 0.020457143 | E19: ='Lead (30-Day_Avg)'!AD428 -> 0.024435714 | F19: ='Lead (30-Day_Avg)'!AA429 -> 0.4 | G19: ='Lead (30-Day_Avg)'!AB429 -> 0.058 | H19: ='Lead (30-Day_Avg)'!AC429 -> 0.0458 | I19: ='Lead (30-Day_Avg)'!AD429 -> 0.0462 | J19: =AVERAGE(B19:E19) -> 0.025587192 | K19: =(J19-$B$33)/$B$33 -> -0.04450125
A20: March | B20: ='Lead (30-Day_Avg)'!AA459 -> 0.027303226 | C20: ='Lead (30-Day_Avg)'!AB459 -> 0.023790833 | D20: ='Lead (30-Day_Avg)'!AC459 -> 0.023975161 | E20: ='Lead (30-Day_Avg)'!AD459 -> 0.025377419 | F20: ='Lead (30-Day_Avg)'!AA460 -> 0.097 | G20: ='Lead (30-Day_Avg)'!AB460 -> 0.0474 | H20: ='Lead (30-Day_Avg)'!AC460 -> 0.0714 | I20: ='Lead (30-Day_Avg)'!AD460 -> 0.0454 | J20: =AVERAGE(B20:E20) -> 0.02511166 | K20: =(J20-$B$33)/$B$33 -> -0.062258957
A21: April | B21: ='Lead (30-Day_Avg)'!AA489 -> 0.03312 | C21: ='Lead (30-Day_Avg)'!AB489 -> 0.026265714 | D21: ='Lead (30-Day_Avg)'!AC489 -> 0.12723167 | E21: ='Lead (30-Day_Avg)'!AD489 -> 0.0277 | F21: ='Lead (30-Day_Avg)'!AA490 -> 0.16 | G21: ='Lead (30-Day_Avg)'!AB490 -> 0.0947 | H21: ='Lead (30-Day_Avg)'!AC490 -> 3.145 | I21: ='Lead (30-Day_Avg)'!AD490 -> 0.0496 | J21: =AVERAGE(B21:E21) -> 0.053579345 | K21: =(J21-$B$33)/$B$33 -> 1.0008056
A22: May | B22: ='Lead (30-Day_Avg)'!AA520 -> 0.028093548 | C22: ='Lead (30-Day_Avg)'!AB520 -> 0.020872222 | D22: ='Lead (30-Day_Avg)'!AC520 -> 0.021795484 | E22: ='Lead (30-Day_Avg)'!AD520 -> 0.029919355 | F22: ='Lead (30-Day_Avg)'!AA521 -> 0.0523 | G22: ='Lead (30-Day_Avg)'!AB521 -> 0.049 | H22: ='Lead (30-Day_Avg)'!AC521 -> 0.176 | I22: ='Lead (30-Day_Avg)'!AD521 -> 0.119 | J22: =AVERAGE(B22:E22) -> 0.025170152 | K22: =(J22-$B$33)/$B$33 -> -0.060074685
A23: June | B23: ='Lead (30-Day_Avg)'!AA550 -> 0.02999 | C23: ='Lead (30-Day_Avg)'!AB550 -> 0.01992 | D23: ='Lead (30-Day_Avg)'!AC550 -> 0.018500667 | E23: ='Lead (30-Day_Avg)'!AD550 -> 0.021396667 | F23: ='Lead (30-Day_Avg)'!AA551 -> 0.0935 | G23: ='Lead (30-Day_Avg)'!AB551 -> 0.046 | H23: ='Lead (30-Day_Avg)'!AC551 -> 0.0618 | I23: ='Lead (30-Day_Avg)'!AD551 -> 0.0354 | J23: =AVERAGE(B23:E23) -> 0.022451833 | K23: =(J23-$B$33)/$B$33 -> -0.16158447
A24: July | B24: ='Lead (30-Day_Avg)'!AA581 -> 0.023290323 | C24: ='Lead (30-Day_Avg)'!AB581 -> 0.022496667 | D24: ='Lead (30-Day_Avg)'!AC581 -> 0.018733548 | E24: ='Lead (30-Day_Avg)'!AD581 -> 0.021112903 | F24: ='Lead (30-Day_Avg)'!AA582 -> 0.047 | G24: ='Lead (30-Day_Avg)'!AB582 -> 0.0391 | H24: ='Lead (30-Day_Avg)'!AC582 -> 0.0437 | I24: ='Lead (30-Day_Avg)'!AD582 -> 0.034 | J24: =AVERAGE(B24:E24) -> 0.02140836 | K24: =(J24-$B$33)/$B$33 -> -0.20055074
A25: August | B25: ='Lead (30-Day_Avg)'!AA612 -> 0.024664516 | C25: ='Lead (30-Day_Avg)'!AB612 -> 0.024602778 | D25: ='Lead (30-Day_Avg)'!AC612 -> 0.020794194 | E25: ='Lead (30-Day_Avg)'!AD612 -> 0.021948387 | F25: ='Lead (30-Day_Avg)'!AA613 -> 0.0518 | G25: ='Lead (30-Day_Avg)'!AB613 -> 0.0431 | H25: ='Lead (30-Day_Avg)'!AC613 -> 0.0446 | I25: ='Lead (30-Day_Avg)'!AD613 -> 0.0321 | J25: =AVERAGE(B25:E25) -> 0.023002469 | K25: =(J25-$B$33)/$B$33 -> -0.14102218
A26: September | B26: ='Lead (30-Day_Avg)'!AA642 -> 0.022075862 | C26: ='Lead (30-Day_Avg)'!AB642 -> 0.019264857 | D26: ='Lead (30-Day_Avg)'!AC642 -> 0.022983 | E26: ='Lead (30-Day_Avg)'!AD642 -> 0.02582 | F26: ='Lead (30-Day_Avg)'!AA643 -> 0.0346 | G26: ='Lead (30-Day_Avg)'!AB643 -> 0.0518 | H26: ='Lead (30-Day_Avg)'!AC643 -> 0.127 | I26: ='Lead (30-Day_Avg)'!AD643 -> 0.0442 | J26: =AVERAGE(B26:E26) -> 0.02253593 | K26: =(J26-$B$33)/$B$33 -> -0.15844407
A27: October | B27: ='Lead (30-Day_Avg)'!AA673 -> 0.024912903 | C27: ='Lead (30-Day_Avg)'!AB673 -> 0.027980556 | D27: ='Lead (30-Day_Avg)'!AC673 -> 0.026790323 | E27: ='Lead (30-Day_Avg)'!AD673 -> 0.039992903 | F27: ='Lead (30-Day_Avg)'!AA674 -> 0.0852 | G27: ='Lead (30-Day_Avg)'!AB674 -> 0.0732 | H27: ='Lead (30-Day_Avg)'!AC674 -> 0.0756 | I27: ='Lead (30-Day_Avg)'!AD674 -> 0.229 | J27: =AVERAGE(B27:E27) -> 0.029919171 | K27: =(J27-$B$33)/$B$33 -> 0.11726723
A28: November | B28: ='Lead (30-Day_Avg)'!AA703 -> 0.02031 | C28: ='Lead (30-Day_Avg)'!AB703 -> 0.023934286 | D28: ='Lead (30-Day_Avg)'!AC703 -> 0.022763333 | E28: ='Lead (30-Day_Avg)'!AD703 -> 0.026626667 | F28: ='Lead (30-Day_Avg)'!AA704 -> 0.048 | G28: ='Lead (30-Day_Avg)'!AB704 -> 0.0689 | H28: ='Lead (30-Day_Avg)'!AC704 -> 0.0773 | I28: ='Lead (30-Day_Avg)'!AD704 -> 0.0485 | J28: =AVERAGE(B28:E28) -> 0.023408571 | K28: =(J28-$B$33)/$B$33 -> -0.12585714
A29: December | B29: ='Lead (30-Day_Avg)'!AA734 -> 0.014403226 | C29: ='Lead (30-Day_Avg)'!AB734 -> 0.015713784 | D29: ='Lead (30-Day_Avg)'!AC734 -> 0.024961613 | E29: ='Lead (30-Day_Avg)'!AD734 -> 0.020625806 | F29: ='Lead (30-Day_Avg)'!AA735 -> 0.044 | G29: ='Lead (30-Day_Avg)'!AB735 -> 0.0518 | H29: ='Lead (30-Day_Avg)'!AC735 -> 0.0655 | I29: ='Lead (30-Day_Avg)'!AD735 -> 0.0419 | J29: =AVERAGE(B29:E29) -> 0.018926107 | K29: =(J29-$B$33)/$B$33 -> -0.29324515
B31: ='Lead (30-Day_Avg)'!AA741 -> 0.025143407 | C31: ='Lead (30-Day_Avg)'!AB741 -> 0.022647887 | D31: ='Lead (30-Day_Avg)'!AC741 -> 0.031269178 | E31: ='Lead (30-Day_Avg)'!AD741 -> 0.026334466 | F31: ='Lead (30-Day_Avg)'!AA742 -> 0.4 | G31: ='Lead (30-Day_Avg)'!AB742 -> 0.115 | H31: ='Lead (30-Day_Avg)'!AC742 -> 3.145 | I31: ='Lead (30-Day_Avg)'!AD742 -> 0.229
B33: ='Lead (30-Day_Avg)'!AA744 -> 0.026778885
A36: ARSENIC
C37: Averages | G37: Maximum
A38: Month | B38: Station 1 | C38: Station 2 | D38: Station 4 | E38: Station 5 | F38: Station 1 | G38: Station 2 | H38: Station 4 | I38: Station 5
A39: January | B39: ='Arsenic (Daily)'!V400 -> 0.78667742 | C39: ='Arsenic (Daily)'!W400 -> 0.92845556 | D39: ='Arsenic (Daily)'!X400 -> 0.84016129 | E39: ='Arsenic (Daily)'!Y400 -> 0.92447419 | F39: ='Arsenic (Daily)'!V401 -> 1.627 | G39: ='Arsenic (Daily)'!W401 -> 1.922 | H39: ='Arsenic (Daily)'!X401 -> 1.741 | I39: ='Arsenic (Daily)'!Y401 -> 1.846 | J39: =AVERAGE(B39:E39) -> 0.86994211 | K39: =(J39-$B$54)/$B$54 -> -0.068429166
A40: February | B40: ='Arsenic (Daily)'!V428 -> 0.62503214 | C40: ='Arsenic (Daily)'!W428 -> 0.64321818 | D40: ='Arsenic (Daily)'!X428 -> 0.58290714 | E40: ='Arsenic (Daily)'!Y428 -> 0.60734643 | F40: ='Arsenic (Daily)'!V429 -> 1.068 | G40: ='Arsenic (Daily)'!W429 -> 1.149 | H40: ='Arsenic (Daily)'!X429 -> 1.1 | I40: ='Arsenic (Daily)'!Y429 -> 1.12 | J40: =AVERAGE(B40:E40) -> 0.61462597 | K40: =(J40-$B$54)/$B$54 -> -0.34183249
A41: March | B41: ='Arsenic (Daily)'!V459 -> 0.92136129 | C41: ='Arsenic (Daily)'!W459 -> 1.0422528 | D41: ='Arsenic (Daily)'!X459 -> 0.70154839 | E41: ='Arsenic (Daily)'!Y459 -> 0.87112903 | F41: ='Arsenic (Daily)'!V460 -> 1.623 | G41: ='Arsenic (Daily)'!W460 -> 2.032 | H41: ='Arsenic (Daily)'!X460 -> 1.45 | I41: ='Arsenic (Daily)'!Y460 -> 1.69 | J41: =AVERAGE(B41:E41) -> 0.88407287 | K41: =(J41-$B$54)/$B$54 -> -0.053297353
A42: April | B42: ='Arsenic (Daily)'!V490 -> 0.99646 | C42: ='Arsenic (Daily)'!W490 -> 1.0071686 | D42: ='Arsenic (Daily)'!X490 -> 1.6759567 | E42: ='Arsenic (Daily)'!Y490 -> 0.90370333 | F42: ='Arsenic (Daily)'!V491 -> 2.044 | G42: ='Arsenic (Daily)'!W491 -> 2.264 | H42: ='Arsenic (Daily)'!X491 -> 28.43 | I42: ='Arsenic (Daily)'!Y491 -> 1.916 | J42: =AVERAGE(B42:E42) -> 1.1458221 | K42: =(J42-$B$54)/$B$54 -> 0.22699484
A43: May | B43: ='Arsenic (Daily)'!V520 -> 0.84092258 | C43: ='Arsenic (Daily)'!W520 -> 0.76303056 | D43: ='Arsenic (Daily)'!X520 -> 0.60766129 | E43: ='Arsenic (Daily)'!Y520 -> 0.71750968 | F43: ='Arsenic (Daily)'!V521 -> 1.807 | G43: ='Arsenic (Daily)'!W521 -> 1.666 | H43: ='Arsenic (Daily)'!X521 -> 1.354 | I43: ='Arsenic (Daily)'!Y521 -> 1.516 | J43: =AVERAGE(B43:E43) -> 0.73228103 | K43: =(J43-$B$54)/$B$54 -> -0.21584249
A44: June | B44: ='Arsenic (Daily)'!V551 -> 0.96904 | C44: ='Arsenic (Daily)'!W551 -> 0.99971143 | D44: ='Arsenic (Daily)'!X551 -> 0.71663667 | E44: ='Arsenic (Daily)'!Y551 -> 0.75157667 | F44: ='Arsenic (Daily)'!V552 -> 3.303 | G44: ='Arsenic (Daily)'!W552 -> 3.865 | H44: ='Arsenic (Daily)'!X552 -> 1.195 | I44: ='Arsenic (Daily)'!Y552 -> 1.63 | J44: =AVERAGE(B44:E44) -> 0.85924119 | K44: =(J44-$B$54)/$B$54 -> -0.079888168
A45: July | B45: ='Arsenic (Daily)'!V581 -> 0.96095161 | C45: ='Arsenic (Daily)'!W581 -> 0.98111111 | D45: ='Arsenic (Daily)'!X581 -> 0.86676774 | E45: ='Arsenic (Daily)'!Y581 -> 0.94854839 | F45: ='Arsenic (Daily)'!V582 -> 1.956 | G45: ='Arsenic (Daily)'!W582 -> 1.982 | H45: ='Arsenic (Daily)'!X582 -> 1.849 | I45: ='Arsenic (Daily)'!Y582 -> 1.847 | J45: =AVERAGE(B45:E45) -> 0.93934471 | K45: =(J45-$B$54)/$B$54 -> 0.0058900742
A46: August | B46: ='Arsenic (Daily)'!V612 -> 0.99222581 | C46: ='Arsenic (Daily)'!W612 -> 1.0531139 | D46: ='Arsenic (Daily)'!X612 -> 0.8927129 | E46: ='Arsenic (Daily)'!Y612 -> 0.97637097 | F46: ='Arsenic (Daily)'!V613 -> 1.468 | G46: ='Arsenic (Daily)'!W613 -> 1.652 | H46: ='Arsenic (Daily)'!X613 -> 1.386 | I46: ='Arsenic (Daily)'!Y613 -> 1.505 | J46: =AVERAGE(B46:E46) -> 0.97860589 | K46: =(J46-$B$54)/$B$54 -> 0.047932606
A47: September | B47: ='Arsenic (Daily)'!V643 -> 0.98188276 | C47: ='Arsenic (Daily)'!W643 -> 0.97715143 | D47: ='Arsenic (Daily)'!X643 -> 0.89391 | E47: ='Arsenic (Daily)'!Y643 -> 0.93441 | F47: ='Arsenic (Daily)'!V644 -> 2.125 | G47: ='Arsenic (Daily)'!W644 -> 1.839 | H47: ='Arsenic (Daily)'!X644 -> 1.688 | I47: ='Arsenic (Daily)'!Y644 -> 1.536 | J47: =AVERAGE(B47:E47) -> 0.94683855 | K47: =(J47-$B$54)/$B$54 -> 0.013914788
A48: October | B48: ='Arsenic (Daily)'!V673 -> 1.2503806 | C48: ='Arsenic (Daily)'!W673 -> 1.3053917 | D48: ='Arsenic (Daily)'!X673 -> 1.1888097 | E48: ='Arsenic (Daily)'!Y673 -> 1.282929 | F48: ='Arsenic (Daily)'!V674 -> 1.881 | G48: ='Arsenic (Daily)'!W674 -> 1.786 | H48: ='Arsenic (Daily)'!X674 -> 1.711 | I48: ='Arsenic (Daily)'!Y674 -> 1.862 | J48: =AVERAGE(B48:E48) -> 1.2568778 | K48: =(J48-$B$54)/$B$54 -> 0.34591789
A49: November | B49: ='Arsenic (Daily)'!V704 -> 0.98954 | C49: ='Arsenic (Daily)'!W704 -> 1.0925514 | D49: ='Arsenic (Daily)'!X704 -> 0.97944 | E49: ='Arsenic (Daily)'!Y704 -> 1.0412367 | F49: ='Arsenic (Daily)'!V705 -> 1.595 | G49: ='Arsenic (Daily)'!W705 -> 1.926 | H49: ='Arsenic (Daily)'!X705 -> 1.673 | I49: ='Arsenic (Daily)'!Y705 -> 1.556 | J49: =AVERAGE(B49:E49) -> 1.025692 | K49: =(J49-$B$54)/$B$54 -> 0.098354429
A50: December | B50: ='Arsenic (Daily)'!V734 -> 0.8272129 | C50: ='Arsenic (Daily)'!W734 -> 0.85833243 | D50: ='Arsenic (Daily)'!X734 -> 0.87022903 | E50: ='Arsenic (Daily)'!Y734 -> 0.86088387 | F50: ='Arsenic (Daily)'!V735 -> 1.555 | G50: ='Arsenic (Daily)'!W735 -> 1.837 | H50: ='Arsenic (Daily)'!X735 -> 1.775 | I50: ='Arsenic (Daily)'!Y735 -> 1.627 | J50: =AVERAGE(B50:E50) -> 0.85416456 | K50: =(J50-$B$54)/$B$54 -> -0.085324439
...

Sheet 2020 Summary
A1: Weekend / Weekday Ambient Monitor Results
C4: Lead (µg/m3) | F4: Arsenic (ng/m3)
A5: Parameter | B5: WeekEND | C5: WeekDAY | D5: % WD Diff | E5: WeekEND | F5: WeekDAY | G5: % WD Diff
A6: Maximum: | B6: ='Lead (30-Day_Avg)'!Z5 -> 0.1439475 | C6: ='Lead (30-Day_Avg)'!AA5 -> 0.194825 | D6: =(C6-B6)/B6 -> 0.35344483 | E6: ='Arsenic (Daily)'!V5 -> 3.848 | F6: ='Arsenic (Daily)'!W5 -> 5.832875 | G6: =(F6-E6)/E6 -> 0.51581991
A7: 90th percentile: | B7: ='Lead (30-Day_Avg)'!Z6 -> 0.026462972 | C7: ='Lead (30-Day_Avg)'!AA6 -> 0.051125 | D7: =(C7-B7)/B7 -> 0.93194473 | E7: ='Arsenic (Daily)'!V6 -> 1.297 | F7: ='Arsenic (Daily)'!W6 -> 1.7136451 | G7: =(F7-E7)/E7 -> 0.32123752
A8: 75th percentile: | B8: ='Lead (30-Day_Avg)'!Z7 -> 0.020052822 | C8: ='Lead (30-Day_Avg)'!AA7 -> 0.03815 | D8: =(C8-B8)/B8 -> 0.90247535 | E8: ='Arsenic (Daily)'!V7 -> 1.0465813 | F8: ='Arsenic (Daily)'!W7 -> 1.3592797 | G8: =(F8-E8)/E8 -> 0.29878087
A9: Average: | B9: ='Lead (30-Day_Avg)'!Z8 -> 0.017377401 | C9: ='Lead (30-Day_Avg)'!AA8 -> 0.03235197 | D9: =(C9-B9)/B9 -> 0.86172659 | E9: ='Arsenic (Daily)'!V8 -> 0.84828132 | F9: ='Arsenic (Daily)'!W8 -> 1.1258336 | G9: =(F9-E9)/E9 -> 0.32719369
A12: Excluding extraordinary events (looking at "normal" operations only).
A15: LEAD
C16: Averages | G16: Maximum
A17: Month | B17: Station 1 | C17: Station 2 | D17: Station 4 | E17: Station 5 | F17: Station 1 | G17: Station 2 | H17: Station 4 | I17: Station 5
A18: January | B18: ='Lead (30-Day_Avg)'!AA765 -> 0.020658065 | C18: ='Lead (30-Day_Avg)'!AB765 -> 0.024332432 | D18: ='Lead (30-Day_Avg)'!AC765 -> 0.027694194 | E18: ='Lead (30-Day_Avg)'!AD765 -> 0.025616129 | F18: ='Lead (30-Day_Avg)'!AA766 -> 0.0497 | G18: ='Lead (30-Day_Avg)'!AB766 -> 0.0654 | H18: ='Lead (30-Day_Avg)'!AC766 -> 0.0861 | I18: ='Lead (30-Day_Avg)'!AD766 -> 0.0652 | J18: =AVERAGE(B18:E18) -> 0.024575205 | K18: =(J18-$B$33)/$B$33 -> 0.11935515 | N18: 765 | O18: =1+N18 -> 766
A19: February | B19: ='Lead (30-Day_Avg)'!AA795 -> 0.019948276 | C19: ='Lead (30-Day_Avg)'!AB795 -> 0.021505294 | D19: ='Lead (30-Day_Avg)'!AC795 -> 0.023389655 | E19: ='Lead (30-Day_Avg)'!AD795 -> 0.028024138 | F19: ='Lead (30-Day_Avg)'!AA796 -> 0.0331 | G19: ='Lead (30-Day_Avg)'!AB796 -> 0.0576 | H19: ='Lead (30-Day_Avg)'!AC796 -> 0.0372 | I19: ='Lead (30-Day_Avg)'!AD796 -> 0.0507 | J19: =AVERAGE(B19:E19) -> 0.023216841 | K19: =(J19-$B$33)/$B$33 -> 0.057484177 | M19: 29 | N19: =N18+M19+1 -> 795 | O19: =1+N19 -> 796
A20: March | B20: ='Lead (30-Day_Avg)'!AA825 -> 0.02607129 | C20: ='Lead (30-Day_Avg)'!AB825 -> 0.014389444 | D20: ='Lead (30-Day_Avg)'!AC825 -> 0.01999871 | E20: ='Lead (30-Day_Avg)'!AD825 -> 0.02277871 | F20: ='Lead (30-Day_Avg)'!AA826 -> 0.245 | G20: ='Lead (30-Day_Avg)'!AB826 -> 0.036 | H20: ='Lead (30-Day_Avg)'!AC826 -> 0.062 | I20: ='Lead (30-Day_Avg)'!AD826 -> 0.0479 | J20: =AVERAGE(B20:E20) -> 0.020809539 | K20: =(J20-$B$33)/$B$33 -> -0.05216399 | M20: 31 | N20: =N19+M20-1 -> 825 | O20: =1+N20 -> 826
A21: April | B21: ='Lead (30-Day_Avg)'!AA855 -> 0.01655 | C21: ='Lead (30-Day_Avg)'!AB855 -> 0.010814286 | D21: ='Lead (30-Day_Avg)'!AC855 -> 0.0129385 | E21: ='Lead (30-Day_Avg)'!AD855 -> 0.017958667 | F21: ='Lead (30-Day_Avg)'!AA856 -> 0.0517 | G21: ='Lead (30-Day_Avg)'!AB856 -> 0.0308 | H21: ='Lead (30-Day_Avg)'!AC856 -> 0.032 | I21: ='Lead (30-Day_Avg)'!AD856 -> 0.0421 | J21: =AVERAGE(B21:E21) -> 0.014565363 | K21: =(J21-$B$33)/$B$33 -> -0.33657464 | M21: 30 | N21: 855 | O21: =1+N21 -> 856
A22: May | B22: ='Lead (30-Day_Avg)'!AA886 -> 0.024163871 | C22: ='Lead (30-Day_Avg)'!AB886 -> 0.019817222 | D22: ='Lead (30-Day_Avg)'!AC886 -> 0.029860645 | E22: ='Lead (30-Day_Avg)'!AD886 -> 0.022880645 | F22: ='Lead (30-Day_Avg)'!AA887 -> 0.0559 | G22: ='Lead (30-Day_Avg)'!AB887 -> 0.0493 | H22: ='Lead (30-Day_Avg)'!AC887 -> 0.145 | I22: ='Lead (30-Day_Avg)'!AD887 -> 0.0389 | J22: =AVERAGE(B22:E22) -> 0.024180596 | K22: =(J22-$B$33)/$B$33 -> 0.10138144 | M22: 31 | N22: 886 | O22: =1+N22 -> 887
A23: June | B23: ='Lead (30-Day_Avg)'!AA916 -> 0.022321333 | C23: ='Lead (30-Day_Avg)'!AB916 -> 0.017382571 | D23: ='Lead (30-Day_Avg)'!AC916 -> 0.016929 | E23: ='Lead (30-Day_Avg)'!AD916 -> 0.020437 | F23: ='Lead (30-Day_Avg)'!AA917 -> 0.125 | G23: ='Lead (30-Day_Avg)'!AB917 -> 0.0351 | H23: ='Lead (30-Day_Avg)'!AC917 -> 0.0325 | I23: ='Lead (30-Day_Avg)'!AD917 -> 0.0444 | J23: =AVERAGE(B23:E23) -> 0.019267476 | K23: =(J23-$B$33)/$B$33 -> -0.12240208 | M23: 30 | N23: 916 | O23: =1+N23 -> 917
A24: July | B24: ='Lead (30-Day_Avg)'!AA947 -> 0.017601613 | C24: ='Lead (30-Day_Avg)'!AB947 -> 0.017146111 | D24: ='Lead (30-Day_Avg)'!AC947 -> 0.017000968 | E24: ='Lead (30-Day_Avg)'!AD947 -> 0.017382903 | F24: ='Lead (30-Day_Avg)'!AA948 -> 0.0306 | G24: ='Lead (30-Day_Avg)'!AB948 -> 0.0299 | H24: ='Lead (30-Day_Avg)'!AC948 -> 0.0266 | I24: ='Lead (30-Day_Avg)'!AD948 -> 0.0281 | J24: =AVERAGE(B24:E24) -> 0.017282899 | K24: =(J24-$B$33)/$B$33 -> -0.21279591 | M24: 31 | N24: 947 | O24: =1+N24 -> 948
A25: August | B25: ='Lead (30-Day_Avg)'!AA978 -> 0.018927419 | C25: ='Lead (30-Day_Avg)'!AB978 -> 0.02025 | D25: ='Lead (30-Day_Avg)'!AC978 -> 0.018438065 | E25: ='Lead (30-Day_Avg)'!AD978 -> 0.022017 | F25: ='Lead (30-Day_Avg)'!AA979 -> 0.0334 | G25: ='Lead (30-Day_Avg)'!AB979 -> 0.0333 | H25: ='Lead (30-Day_Avg)'!AC979 -> 0.0598 | I25: ='Lead (30-Day_Avg)'!AD979 -> 0.0379 | J25: =AVERAGE(B25:E25) -> 0.019908121 | K25: =(J25-$B$33)/$B$33 -> -0.093221894 | M25: 31 | N25: 978 | O25: =1+N25 -> 979
A26: September | B26: ='Lead (30-Day_Avg)'!AA1008 -> 0.022266667 | C26: ='Lead (30-Day_Avg)'!AB1008 -> 0.023388 | D26: ='Lead (30-Day_Avg)'!AC1008 -> 0.024256 | E26: ='Lead (30-Day_Avg)'!AD1008 -> 0.029543333 | F26: ='Lead (30-Day_Avg)'!AA1009 -> 0.04 | G26: ='Lead (30-Day_Avg)'!AB1009 -> 0.044 | H26: ='Lead (30-Day_Avg)'!AC1009 -> 0.0531 | I26: ='Lead (30-Day_Avg)'!AD1009 -> 0.0472 | J26: =AVERAGE(B26:E26) -> 0.0248635 | K26: =(J26-$B$33)/$B$33 -> 0.13248646 | M26: 30 | N26: 1008 | O26: =1+N26 -> 1009
A27: October | B27: ='Lead (30-Day_Avg)'!AA1039 -> 0.022789677 | C27: ='Lead (30-Day_Avg)'!AB1039 -> 0.024784444 | D27: ='Lead (30-Day_Avg)'!AC1039 -> 0.027038387 | E27: ='Lead (30-Day_Avg)'!AD1039 -> 0.033132258 | F27: ='Lead (30-Day_Avg)'!AA1040 -> 0.088 | G27: ='Lead (30-Day_Avg)'!AB1040 -> 0.0905 | H27: ='Lead (30-Day_Avg)'!AC1040 -> 0.0909 | I27: ='Lead (30-Day_Avg)'!AD1040 -> 0.122 | J27: =AVERAGE(B27:E27) -> 0.026936192 | K27: =(J27-$B$33)/$B$33 -> 0.22689374 | M27: 31 | N27: 1039 | O27: =1+N27 -> 1040
A28: November | B28: ='Lead (30-Day_Avg)'!AA1069 -> 0.021753333 | C28: ='Lead (30-Day_Avg)'!AB1069 -> 0.023133714 | D28: ='Lead (30-Day_Avg)'!AC1069 -> 0.022006333 | E28: ='Lead (30-Day_Avg)'!AD1069 -> 0.03282 | F28: ='Lead (30-Day_Avg)'!AA1070 -> 0.0644 | G28: ='Lead (30-Day_Avg)'!AB1070 -> 0.0705 | H28: ='Lead (30-Day_Avg)'!AC1070 -> 0.0465 | I28: ='Lead (30-Day_Avg)'!AD1070 -> 0.073 | J28: =AVERAGE(B28:E28) -> 0.024928345 | K28: =(J28-$B$33)/$B$33 -> 0.13544004 | M28: 30 | N28: 1069 | O28: =1+N28 -> 1070
A29: December | B29: ='Lead (30-Day_Avg)'!AA1100 -> 0.01814871 | C29: ='Lead (30-Day_Avg)'!AB1100 -> 0.019063784 | D29: ='Lead (30-Day_Avg)'!AC1100 -> 0.018861935 | E29: ='Lead (30-Day_Avg)'!AD1100 -> 0.026611935 | F29: ='Lead (30-Day_Avg)'!AA1101 -> 0.0352 | G29: ='Lead (30-Day_Avg)'!AB1101 -> 0.0412 | H29: ='Lead (30-Day_Avg)'!AC1101 -> 0.0364 | I29: ='Lead (30-Day_Avg)'!AD1101 -> 0.0496 | J29: =AVERAGE(B29:E29) -> 0.020671591 | K29: =(J29-$B$33)/$B$33 -> -0.05844724 | M29: 31 | N29: 1100 | O29: =1+N29 -> 1101
B31: ='Lead (30-Day_Avg)'!AA741 -> 0.025143407 | C31: ='Lead (30-Day_Avg)'!AB741 -> 0.022647887 | D31: ='Lead (30-Day_Avg)'!AC741 -> 0.031269178 | E31: ='Lead (30-Day_Avg)'!AD741 -> 0.026334466 | F31: ='Lead (30-Day_Avg)'!AA742 -> 0.4 | G31: ='Lead (30-Day_Avg)'!AB742 -> 0.115 | H31: ='Lead (30-Day_Avg)'!AC742 -> 3.145 | I31: ='Lead (30-Day_Avg)'!AD742 -> 0.229
B33: ='Lead (30-Day_Avg)'!AA1110 -> 0.021954788
A36: ARSENIC | M36: ARSENIC
C37: Averages | G37: Maximum
A38: Month | B38: Station 1 | C38: Station 2 | D38: Station 4 | E38: Station 5 | F38: Station 1 | G38: Station 2 | H38: Station 4 | I38: Station 5 | M38: Month | N38: Average
A39: January | B39: ='Arsenic (Daily)'!V765 -> 1.0317032 | C39: ='Arsenic (Daily)'!W765 -> 1.1796054 | D39: ='Arsenic (Daily)'!X765 -> 1.0751226 | E39: ='Arsenic (Daily)'!Y765 -> 1.0684097 | F39: ='Arsenic (Daily)'!V766 -> 1.668 | G39: ='Arsenic (Daily)'!W766 -> 1.98 | H39: ='Arsenic (Daily)'!X766 -> 1.818 | I39: ='Arsenic (Daily)'!Y766 -> 1.802 | J39: =AVERAGE(B39:E39) -> 1.0887102 | K39: =(J39-$B$54)/$B$54 -> 0.081955697 | M39: January | N39: 1.0887102
A40: February | B40: ='Arsenic (Daily)'!V793 -> 1.0439207 | C40: ='Arsenic (Daily)'!W793 -> 1.0917912 | D40: ='Arsenic (Daily)'!X793 -> 1.0705103 | E40: ='Arsenic (Daily)'!Y793 -> 1.0809483 | F40: ='Arsenic (Daily)'!V794 -> 2.122 | G40: ='Arsenic (Daily)'!W794 -> 2.319 | H40: ='Arsenic (Daily)'!X794 -> 2.924 | I40: ='Arsenic (Daily)'!Y794 -> 2.423 | J40: =AVERAGE(B40:E40) -> 1.0717926 | K40: =(J40-$B$54)/$B$54 -> 0.065143056 | M40: February | N40: 1.0717926
A41: March | B41: ='Arsenic (Daily)'!V825 -> 0.59493871 | C41: ='Arsenic (Daily)'!W825 -> 0.6185 | D41: ='Arsenic (Daily)'!X825 -> 0.52580968 | E41: ='Arsenic (Daily)'!Y825 -> 0.58219355 | F41: ='Arsenic (Daily)'!V826 -> 2.072 | G41: ='Arsenic (Daily)'!W826 -> 1.158 | H41: ='Arsenic (Daily)'!X826 -> 1.129 | I41: ='Arsenic (Daily)'!Y826 -> 1.072 | J41: =AVERAGE(B41:E41) -> 0.58036048 | K41: =(J41-$B$54)/$B$54 -> -0.42324016 | M41: March | N41: 0.58036048
A42: April | B42: ='Arsenic (Daily)'!V856 -> 0.65752667 | C42: ='Arsenic (Daily)'!W856 -> 0.6198 | D42: ='Arsenic (Daily)'!X856 -> 0.57664667 | E42: ='Arsenic (Daily)'!Y856 -> 0.6727 | F42: ='Arsenic (Daily)'!V857 -> 1.377 | G42: ='Arsenic (Daily)'!W857 -> 1.534 | H42: ='Arsenic (Daily)'!X857 -> 1.224 | I42: ='Arsenic (Daily)'!Y857 -> 1.479 | J42: =AVERAGE(B42:E42) -> 0.63166833 | K42: =(J42-$B$54)/$B$54 -> -0.37225063 | M42: April | N42: 0.63166833
A43: May | B43: ='Arsenic (Daily)'!V886 -> 0.80149355 | C43: ='Arsenic (Daily)'!W886 -> 0.76463333 | D43: ='Arsenic (Daily)'!X886 -> 0.70420968 | E43: ='Arsenic (Daily)'!Y886 -> 0.73268065 | F43: ='Arsenic (Daily)'!V887 -> 1.727 | G43: ='Arsenic (Daily)'!W887 -> 1.663 | H43: ='Arsenic (Daily)'!X887 -> 1.712 | I43: ='Arsenic (Daily)'!Y887 -> 1.42 | J43: =AVERAGE(B43:E43) -> 0.7507543 | K43: =(J43-$B$54)/$B$54 -> -0.25390349 | M43: May | N43: 0.7507543
A44: June | B44: ='Arsenic (Daily)'!V917 -> 0.71643 | C44: ='Arsenic (Daily)'!W917 -> 0.70858 | D44: ='Arsenic (Daily)'!X917 -> 0.63011667 | E44: ='Arsenic (Daily)'!Y917 -> 0.69807333 | F44: ='Arsenic (Daily)'!V918 -> 1.981 | G44: ='Arsenic (Daily)'!W918 -> 1.677 | H44: ='Arsenic (Daily)'!X918 -> 1.031 | I44: ='Arsenic (Daily)'!Y918 -> 1.218 | J44: =AVERAGE(B44:E44) -> 0.6883 | K44: =(J44-$B$54)/$B$54 -> -0.31597032 | M44: June | N44: 0.6883
A45: July | B45: ='Arsenic (Daily)'!V947 -> 0.92119355 | C45: ='Arsenic (Daily)'!W947 -> 0.92514167 | D45: ='Arsenic (Daily)'!X947 -> 0.85078065 | E45: ='Arsenic (Daily)'!Y947 -> 0.89032581 | F45: ='Arsenic (Daily)'!V948 -> 3.026 | G45: ='Arsenic (Daily)'!W948 -> 3.227 | H45: ='Arsenic (Daily)'!X948 -> 2.865 | I45: ='Arsenic (Daily)'!Y948 -> 2.986 | J45: =AVERAGE(B45:E45) -> 0.89686042 | K45: =(J45-$B$54)/$B$54 -> -0.10870384 | M45: July | N45: 0.89686042
A46: August | B46: ='Arsenic (Daily)'!V978 -> 0.93962903 | C46: ='Arsenic (Daily)'!W978 -> 0.96251111 | D46: ='Arsenic (Daily)'!X978 -> 0.91809032 | E46: ='Arsenic (Daily)'!Y978 -> 0.96564667 | F46: ='Arsenic (Daily)'!V979 -> 1.473 | G46: ='Arsenic (Daily)'!W979 -> 1.569 | H46: ='Arsenic (Daily)'!X979 -> 1.55 | I46: ='Arsenic (Daily)'!Y979 -> 1.455 | J46: =AVERAGE(B46:E46) -> 0.94646928 | K46: =(J46-$B$54)/$B$54 -> -0.059402757 | M46: August | N46: 0.94646928
A47: September | B47: ='Arsenic (Daily)'!V1009 -> 1.30455 | C47: ='Arsenic (Daily)'!W1009 -> 1.2968057 | D47: ='Arsenic (Daily)'!X1009 -> 1.3057767 | E47: ='Arsenic (Daily)'!Y1009 -> 1.37711 | F47: ='Arsenic (Daily)'!V1010 -> 2.003 | G47: ='Arsenic (Daily)'!W1010 -> 2.282 | H47: ='Arsenic (Daily)'!X1010 -> 2.271 | I47: ='Arsenic (Daily)'!Y1010 -> 2.212 | J47: =AVERAGE(B47:E47) -> 1.3210606 | K47: =(J47-$B$54)/$B$54 -> 0.31286453 | M47: September | N47: 1.3210606
A48: October | B48: ='Arsenic (Daily)'!V1039 -> 1.5982903 | C48: ='Arsenic (Daily)'!W1039 -> 1.6874194 | D48: ='Arsenic (Daily)'!X1039 -> 1.6701226 | E48: ='Arsenic (Daily)'!Y1039 -> 1.7393355 | F48: ='Arsenic (Daily)'!V1040 -> 5.541 | G48: ='Arsenic (Daily)'!W1040 -> 5.626 | H48: ='Arsenic (Daily)'!X1040 -> 5.916 | I48: ='Arsenic (Daily)'!Y1040 -> 6.464 | J48: =AVERAGE(B48:E48) -> 1.673792 | K48: =(J48-$B$54)/$B$54 -> 0.6634075 | M48: October | N48: 1.673792
A49: November | B49: ='Arsenic (Daily)'!V1070 -> 1.2706467 | C49: ='Arsenic (Daily)'!W1070 -> 1.1829029 | D49: ='Arsenic (Daily)'!X1070 -> 1.1906867 | E49: ='Arsenic (Daily)'!Y1070 -> 1.3093733 | F49: ='Arsenic (Daily)'!V1071 -> 2.613 | G49: ='Arsenic (Daily)'!W1071 -> 2.307 | H49: ='Arsenic (Daily)'!X1071 -> 2.064 | I49: ='Arsenic (Daily)'!Y1071 -> 2.196 | J49: =AVERAGE(B49:E49) -> 1.2384024 | K49: =(J49-$B$54)/$B$54 -> 0.23071914 | M49: November | N49: 1.2384024
A50: December | B50: ='Arsenic (Daily)'!V1100 -> 1.2636839 | C50: ='Arsenic (Daily)'!W1100 -> 1.1543486 | D50: ='Arsenic (Daily)'!X1100 -> 1.0771097 | E50: ='Arsenic (Daily)'!Y1100 -> 1.2194 | F50: ='Arsenic (Daily)'!V1101 -> 2.481 | G50: ='Arsenic (Daily)'!W1101 -> 2.655 | H50: ='Arsenic (Daily)'!X1101 -> 2.095 | I50: ='Arsenic (Daily)'!Y1101 -> 2.164 | J50: =AVERAGE(B50:E50) -> 1.1786355 | K50: =(J50-$B$54)/$B$54 -> 0.17132311 | M50: December | N50: 1.6062174
...

Sheet 2021 Summary
A1: Monthly Ambient Monitor Statistics -- 2021
C4: Lead (µg/m3) | F4: Arsenic (ng/m3)
A5: Parameter | B5: WeekEND | C5: WeekDAY | D5: % WD Diff | E5: WeekEND | F5: WeekDAY | G5: % WD Diff
A6: Maximum: | B6: ='Lead (30-Day_Avg)'!Z5 -> 0.1439475 | C6: ='Lead (30-Day_Avg)'!AA5 -> 0.194825 | D6: =(C6-B6)/B6 -> 0.35344483 | E6: ='Arsenic (Daily)'!V5 -> 3.848 | F6: ='Arsenic (Daily)'!W5 -> 5.832875 | G6: =(F6-E6)/E6 -> 0.51581991
A7: 90th percentile: | B7: ='Lead (30-Day_Avg)'!Z6 -> 0.026462972 | C7: ='Lead (30-Day_Avg)'!AA6 -> 0.051125 | D7: =(C7-B7)/B7 -> 0.93194473 | E7: ='Arsenic (Daily)'!V6 -> 1.297 | F7: ='Arsenic (Daily)'!W6 -> 1.7136451 | G7: =(F7-E7)/E7 -> 0.32123752
A8: 75th percentile: | B8: ='Lead (30-Day_Avg)'!Z7 -> 0.020052822 | C8: ='Lead (30-Day_Avg)'!AA7 -> 0.03815 | D8: =(C8-B8)/B8 -> 0.90247535 | E8: ='Arsenic (Daily)'!V7 -> 1.0465813 | F8: ='Arsenic (Daily)'!W7 -> 1.3592797 | G8: =(F8-E8)/E8 -> 0.29878087
A9: Average: | B9: ='Lead (30-Day_Avg)'!Z8 -> 0.017377401 | C9: ='Lead (30-Day_Avg)'!AA8 -> 0.03235197 | D9: =(C9-B9)/B9 -> 0.86172659 | E9: ='Arsenic (Daily)'!V8 -> 0.84828132 | F9: ='Arsenic (Daily)'!W8 -> 1.1258336 | G9: =(F9-E9)/E9 -> 0.32719369
A12: Excluding extraordinary events (looking at "normal" operations only).
A15: LEAD
C16: Averages | G16: Maximum
A17: Month | B17: Station 1 | C17: Station 2 | D17: Station 4 | E17: Station 5 | F17: Station 1 | G17: Station 2 | H17: Station 4 | I17: Station 5
A18: January | B18: ='Lead (30-Day_Avg)'!AA1131 -> 0.015872258 | C18: ='Lead (30-Day_Avg)'!AB1131 -> 0.013442222 | D18: ='Lead (30-Day_Avg)'!AC1131 -> 0.016110645 | E18: ='Lead (30-Day_Avg)'!AD1131 -> 0.02379129 | F18: ='Lead (30-Day_Avg)'!AA1132 -> 0.0407 | G18: ='Lead (30-Day_Avg)'!AB1132 -> 0.0259 | H18: ='Lead (30-Day_Avg)'!AC766 -> 0.0861 | I18: ='Lead (30-Day_Avg)'!AD766 -> 0.0652 | J18: =AVERAGE(B18:E18) -> 0.017304104 | K18: =(J18-$B$33)/$B$33 -> -0.21183006 | N18: 765 | O18: =1+N18 -> 766
A19: February | B19: ='Lead (30-Day_Avg)'!AA1160 -> 0.024778571 | C19: ='Lead (30-Day_Avg)'!AB1160 -> 0.0243 | D19: ='Lead (30-Day_Avg)'!AC1160 -> 0.020097857 | E19: ='Lead (30-Day_Avg)'!AD1160 -> 0.034053571 | F19: ='Lead (30-Day_Avg)'!AA1161 -> 0.0548 | G19: ='Lead (30-Day_Avg)'!AB1161 -> 0.0613 | H19: ='Lead (30-Day_Avg)'!AC1161 -> 0.037 | I19: ='Lead (30-Day_Avg)'!AD1161 -> 0.0661 | J19: =AVERAGE(B19:E19) -> 0.0258075 | K19: =(J19-$B$33)/$B$33 -> 0.17548392 | M19: 29 | N19: =N18+M19+1 -> 795 | O19: =1+N19 -> 796
A20: March | J20: =AVERAGE(B20:E20) -> #DIV/0! | K20: =(J20-$B$33)/$B$33 -> #DIV/0! | M20: 31 | N20: =N19+M20-1 -> 825 | O20: =1+N20 -> 826
A21: April | J21: =AVERAGE(B21:E21) -> #DIV/0! | K21: =(J21-$B$33)/$B$33 -> #DIV/0! | M21: 30 | N21: 855 | O21: =1+N21 -> 856
A22: May | J22: =AVERAGE(B22:E22) -> #DIV/0! | K22: =(J22-$B$33)/$B$33 -> #DIV/0! | M22: 31 | N22: 886 | O22: =1+N22 -> 887
A23: June | J23: =AVERAGE(B23:E23) -> #DIV/0! | K23: =(J23-$B$33)/$B$33 -> #DIV/0! | M23: 30 | N23: 916 | O23: =1+N23 -> 917
A24: July | J24: =AVERAGE(B24:E24) -> #DIV/0! | K24: =(J24-$B$33)/$B$33 -> #DIV/0! | M24: 31 | N24: 947 | O24: =1+N24 -> 948
A25: August | J25: =AVERAGE(B25:E25) -> #DIV/0! | K25: =(J25-$B$33)/$B$33 -> #DIV/0! | M25: 31 | N25: 978 | O25: =1+N25 -> 979
A26: September | J26: =AVERAGE(B26:E26) -> #DIV/0! | K26: =(J26-$B$33)/$B$33 -> #DIV/0! | M26: 30 | N26: 1008 | O26: =1+N26 -> 1009
A27: October | J27: =AVERAGE(B27:E27) -> #DIV/0! | K27: =(J27-$B$33)/$B$33 -> #DIV/0! | M27: 31 | N27: 1039 | O27: =1+N27 -> 1040
A28: November | J28: =AVERAGE(B28:E28) -> #DIV/0! | K28: =(J28-$B$33)/$B$33 -> #DIV/0! | M28: 30 | N28: 1069 | O28: =1+N28 -> 1070
A29: December | J29: =AVERAGE(B29:E29) -> #DIV/0! | K29: =(J29-$B$33)/$B$33 -> #DIV/0! | M29: 31 | N29: 1100 | O29: =1+N29 -> 1101
B31: ='Lead (30-Day_Avg)'!AA741 -> 0.025143407 | C31: ='Lead (30-Day_Avg)'!AB741 -> 0.022647887 | D31: ='Lead (30-Day_Avg)'!AC741 -> 0.031269178 | E31: ='Lead (30-Day_Avg)'!AD741 -> 0.026334466 | F31: ='Lead (30-Day_Avg)'!AA742 -> 0.4 | G31: ='Lead (30-Day_Avg)'!AB742 -> 0.115 | H31: ='Lead (30-Day_Avg)'!AC742 -> 3.145 | I31: ='Lead (30-Day_Avg)'!AD742 -> 0.229
B33: ='Lead (30-Day_Avg)'!AA1110 -> 0.021954788
A36: ARSENIC | M36: ARSENIC
C37: Averages | G37: Maximum
A38: Month | B38: Station 1 | C38: Station 2 | D38: Station 4 | E38: Station 5 | F38: Station 1 | G38: Station 2 | H38: Station 4 | I38: Station 5 | M38: Month | N38: Average
A39: January | B39: ='Arsenic (Daily)'!V1131 -> 1.8958323 | C39: ='Arsenic (Daily)'!W1131 -> 1.084775 | D39: ='Arsenic (Daily)'!X1131 -> 0.97122581 | E39: ='Arsenic (Daily)'!Y1131 -> 1.2603129 | F39: ='Arsenic (Daily)'!V1132 -> 5.866 | G39: ='Arsenic (Daily)'!W1132 -> 2.069 | H39: ='Arsenic (Daily)'!X1132 -> 1.943 | I39: ='Arsenic (Daily)'!Y1132 -> 2.847 | J39: =AVERAGE(B39:E39) -> 1.3030365 | K39: =(J39-$B$54)/$B$54 -> 0.29495225 | M39: January
A40: February | B40: ='Arsenic (Daily)'!V1159 -> 1.2624107 | C40: ='Arsenic (Daily)'!W1159 -> 1.0674406 | D40: ='Arsenic (Daily)'!X1159 -> 0.99655357 | E40: ='Arsenic (Daily)'!Y1159 -> 1.1090571 | F40: ='Arsenic (Daily)'!V1160 -> 2.609 | G40: ='Arsenic (Daily)'!W1160 -> 1.799 | H40: ='Arsenic (Daily)'!X1160 -> 1.559 | I40: ='Arsenic (Daily)'!Y1160 -> 1.496 | J40: =AVERAGE(B40:E40) -> 1.1088655 | K40: =(J40-$B$54)/$B$54 -> 0.10198594 | M40: February
A41: March | J41: =AVERAGE(B41:E41) -> #DIV/0! | K41: =(J41-$B$54)/$B$54 -> #DIV/0! | M41: March
A42: April | J42: =AVERAGE(B42:E42) -> #DIV/0! | K42: =(J42-$B$54)/$B$54 -> #DIV/0! | M42: April
A43: May | J43: =AVERAGE(B43:E43) -> #DIV/0! | K43: =(J43-$B$54)/$B$54 -> #DIV/0! | M43: May
A44: June | J44: =AVERAGE(B44:E44) -> #DIV/0! | K44: =(J44-$B$54)/$B$54 -> #DIV/0! | M44: June
A45: July | J45: =AVERAGE(B45:E45) -> #DIV/0! | K45: =(J45-$B$54)/$B$54 -> #DIV/0! | M45: July
A46: August | J46: =AVERAGE(B46:E46) -> #DIV/0! | K46: =(J46-$B$54)/$B$54 -> #DIV/0! | M46: August
A47: September | J47: =AVERAGE(B47:E47) -> #DIV/0! | K47: =(J47-$B$54)/$B$54 -> #DIV/0! | M47: September
A48: October | J48: =AVERAGE(B48:E48) -> #DIV/0! | K48: =(J48-$B$54)/$B$54 -> #DIV/0! | M48: October
A49: November | J49: =AVERAGE(B49:E49) -> #DIV/0! | K49: =(J49-$B$54)/$B$54 -> #DIV/0! | M49: November
A50: December | J50: =AVERAGE(B50:E50) -> #DIV/0! | K50: =(J50-$B$54)/$B$54 -> #DIV/0! | M50: December
...

Sheet Average Summary
C3: Lead Averages | G3: Arsenic Averages
A4: Month | B4: Station 1 | C4: Station 2 | D4: Station 4 | E4: Station 5 | F4: Station 1 | G4: Station 2 | H4: Station 4 | I4: Station 5 | J4: All Stations | W4: 0 | X4: 0 | Y4: 0 | Z4: 0
A5: 43101 | F5: ='2018 Summary'!B39 -> 1.6030323 | G5: ='2018 Summary'!C39 -> 1.4038778 | H5: ='2018 Summary'!D39 -> 1.2265581 | I5: ='2018 Summary'!E39 -> 1.4970645 | J5: =AVERAGE(F5:I5) -> 1.4326332 | O5: =IF(F5>=1.25,1,0) -> 1 | P5: =IF(G5>=1.25,1,0) -> 1 | Q5: =IF(H5>=1.25,1,0) -> 0 | R5: =IF(I5>=1.25,1,0) -> 1 | S5: =IF(F5>=1,1,0) -> 1 | T5: =IF(G5>=1,1,0) -> 1 | U5: =IF(H5>=1,1,0) -> 1 | V5: =IF(I5>=1,1,0) -> 1 | W5: =IF(S5=1,S5+W4,0) -> 1 | X5: =IF(T5=1,T5+X4,0) -> 1 | Y5: =IF(U5=1,U5+Y4,0) -> 1 | Z5: =IF(V5=1,V5+Z4,0) -> 1
A6: 43132 | F6: ='2018 Summary'!B40 -> 1.0420036 | G6: ='2018 Summary'!C40 -> 1.0304879 | H6: ='2018 Summary'!D40 -> 0.89647143 | I6: ='2018 Summary'!E40 -> 1.0923321 | J6: =AVERAGE(F6:I6) -> 1.0153238 | O6: =IF(F6>=1.25,1,0) -> 0 | P6: =IF(G6>=1.25,1,0) -> 0 | Q6: =IF(H6>=1.25,1,0) -> 0 | R6: =IF(I6>=1.25,1,0) -> 0 | S6: =IF(F6>=1,1,0) -> 1 | T6: =IF(G6>=1,1,0) -> 1 | U6: =IF(H6>=1,1,0) -> 0 | V6: =IF(I6>=1,1,0) -> 1 | W6: =IF(S6=1,S6+W5,0) -> 2 | X6: =IF(T6=1,T6+X5,0) -> 2 | Y6: =IF(U6=1,U6+Y5,0) -> 0 | Z6: =IF(V6=1,V6+Z5,0) -> 2
A7: 43160 | F7: ='2018 Summary'!B41 -> 0.80372258 | G7: ='2018 Summary'!C41 -> 0.82285 | H7: ='2018 Summary'!D41 -> 0.63034194 | I7: ='2018 Summary'!E41 -> 0.77344194 | J7: =AVERAGE(F7:I7) -> 0.75758911 | O7: =IF(F7>=1.25,1,0) -> 0 | P7: =IF(G7>=1.25,1,0) -> 0 | Q7: =IF(H7>=1.25,1,0) -> 0 | R7: =IF(I7>=1.25,1,0) -> 0 | S7: =IF(F7>=1,1,0) -> 0 | T7: =IF(G7>=1,1,0) -> 0 | U7: =IF(H7>=1,1,0) -> 0 | V7: =IF(I7>=1,1,0) -> 0 | W7: =IF(S7=1,S7+W6,0) -> 0 | X7: =IF(T7=1,T7+X6,0) -> 0 | Y7: =IF(U7=1,U7+Y6,0) -> 0 | Z7: =IF(V7=1,V7+Z6,0) -> 0
A8: 43191 | F8: ='2018 Summary'!B42 -> 0.97844 | G8: ='2018 Summary'!C42 -> 0.98598857 | H8: ='2018 Summary'!D42 -> 0.82104667 | I8: ='2018 Summary'!E42 -> 0.96965 | J8: =AVERAGE(F8:I8) -> 0.93878131 | O8: =IF(F8>=1.25,1,0) -> 0 | P8: =IF(G8>=1.25,1,0) -> 0 | Q8: =IF(H8>=1.25,1,0) -> 0 | R8: =IF(I8>=1.25,1,0) -> 0 | S8: =IF(F8>=1,1,0) -> 0 | T8: =IF(G8>=1,1,0) -> 0 | U8: =IF(H8>=1,1,0) -> 0 | V8: =IF(I8>=1,1,0) -> 0 | W8: =IF(S8=1,S8+W7,0) -> 0 | X8: =IF(T8=1,T8+X7,0) -> 0 | Y8: =IF(U8=1,U8+Y7,0) -> 0 | Z8: =IF(V8=1,V8+Z7,0) -> 0
A9: 43221 | F9: ='2018 Summary'!B43 -> 0.8812129 | G9: ='2018 Summary'!C43 -> 0.84896944 | H9: ='2018 Summary'!D43 -> 0.68919677 | I9: ='2018 Summary'!E43 -> 0.86710323 | J9: =AVERAGE(F9:I9) -> 0.82162059 | O9: =IF(F9>=1.25,1,0) -> 0 | P9: =IF(G9>=1.25,1,0) -> 0 | Q9: =IF(H9>=1.25,1,0) -> 0 | R9: =IF(I9>=1.25,1,0) -> 0 | S9: =IF(F9>=1,1,0) -> 0 | T9: =IF(G9>=1,1,0) -> 0 | U9: =IF(H9>=1,1,0) -> 0 | V9: =IF(I9>=1,1,0) -> 0 | W9: =IF(S9=1,S9+W8,0) -> 0 | X9: =IF(T9=1,T9+X8,0) -> 0 | Y9: =IF(U9=1,U9+Y8,0) -> 0 | Z9: =IF(V9=1,V9+Z8,0) -> 0
A10: 43252 | F10: ='2018 Summary'!B44 -> 1.33064 | G10: ='2018 Summary'!C44 -> 1.1071571 | H10: ='2018 Summary'!D44 -> 0.78369333 | I10: ='2018 Summary'!E44 -> 0.91445 | J10: =AVERAGE(F10:I10) -> 1.0339851 | O10: =IF(F10>=1.25,1,0) -> 1 | P10: =IF(G10>=1.25,1,0) -> 0 | Q10: =IF(H10>=1.25,1,0) -> 0 | R10: =IF(I10>=1.25,1,0) -> 0 | S10: =IF(F10>=1,1,0) -> 1 | T10: =IF(G10>=1,1,0) -> 1 | U10: =IF(H10>=1,1,0) -> 0 | V10: =IF(I10>=1,1,0) -> 0 | W10: =IF(S10=1,S10+W9,0) -> 1 | X10: =IF(T10=1,T10+X9,0) -> 1 | Y10: =IF(U10=1,U10+Y9,0) -> 0 | Z10: =IF(V10=1,V10+Z9,0) -> 0
A11: 43282 | F11: ='2018 Summary'!B45 -> 1.480829 | G11: ='2018 Summary'!C45 -> 1.538625 | H11: ='2018 Summary'!D45 -> 1.0962 | I11: ='2018 Summary'!E45 -> 1.2611548 | J11: =AVERAGE(F11:I11) -> 1.3442022 | O11: =IF(F11>=1.25,1,0) -> 1 | P11: =IF(G11>=1.25,1,0) -> 1 | Q11: =IF(H11>=1.25,1,0) -> 0 | R11: =IF(I11>=1.25,1,0) -> 1 | S11: =IF(F11>=1,1,0) -> 1 | T11: =IF(G11>=1,1,0) -> 1 | U11: =IF(H11>=1,1,0) -> 1 | V11: =IF(I11>=1,1,0) -> 1 | W11: =IF(S11=1,S11+W10,0) -> 2 | X11: =IF(T11=1,T11+X10,0) -> 2 | Y11: =IF(U11=1,U11+Y10,0) -> 1 | Z11: =IF(V11=1,V11+Z10,0) -> 1
A12: 43313 | F12: ='2018 Summary'!B46 -> 1.3591097 | G12: ='2018 Summary'!C46 -> 1.2067472 | H12: ='2018 Summary'!D46 -> 0.95609677 | I12: ='2018 Summary'!E46 -> 1.1385935 | J12: =AVERAGE(F12:I12) -> 1.1651368 | O12: =IF(F12>=1.25,1,0) -> 1 | P12: =IF(G12>=1.25,1,0) -> 0 | Q12: =IF(H12>=1.25,1,0) -> 0 | R12: =IF(I12>=1.25,1,0) -> 0 | S12: =IF(F12>=1,1,0) -> 1 | T12: =IF(G12>=1,1,0) -> 1 | U12: =IF(H12>=1,1,0) -> 0 | V12: =IF(I12>=1,1,0) -> 1 | W12: =IF(S12=1,S12+W11,0) -> 3 | X12: =IF(T12=1,T12+X11,0) -> 3 | Y12: =IF(U12=1,U12+Y11,0) -> 0 | Z12: =IF(V12=1,V12+Z11,0) -> 2
A13: 43344 | F13: ='2018 Summary'!B47 -> 1.3191333 | G13: ='2018 Summary'!C47 -> 1.2964 | H13: ='2018 Summary'!D47 -> 1.06708 | I13: ='2018 Summary'!E47 -> 1.2148667 | J13: =AVERAGE(F13:I13) -> 1.22437 | O13: =IF(F13>=1.25,1,0) -> 1 | P13: =IF(G13>=1.25,1,0) -> 1 | Q13: =IF(H13>=1.25,1,0) -> 0 | R13: =IF(I13>=1.25,1,0) -> 0 | S13: =IF(F13>=1,1,0) -> 1 | T13: =IF(G13>=1,1,0) -> 1 | U13: =IF(H13>=1,1,0) -> 1 | V13: =IF(I13>=1,1,0) -> 1 | W13: =IF(S13=1,S13+W12,0) -> 4 | X13: =IF(T13=1,T13+X12,0) -> 4 | Y13: =IF(U13=1,U13+Y12,0) -> 1 | Z13: =IF(V13=1,V13+Z12,0) -> 3
A14: 43374 | F14: ='2018 Summary'!B48 -> 1.1526516 | G14: ='2018 Summary'!C48 -> 1.1786568 | H14: ='2018 Summary'!D48 -> 1.007671 | I14: ='2018 Summary'!E48 -> 1.0550484 | J14: =AVERAGE(F14:I14) -> 1.0985069 | O14: =IF(F14>=1.25,1,0) -> 0 | P14: =IF(G14>=1.25,1,0) -> 0 | Q14: =IF(H14>=1.25,1,0) -> 0 | R14: =IF(I14>=1.25,1,0) -> 0 | S14: =IF(F14>=1,1,0) -> 1 | T14: =IF(G14>=1,1,0) -> 1 | U14: =IF(H14>=1,1,0) -> 1 | V14: =IF(I14>=1,1,0) -> 1 | W14: =IF(S14=1,S14+W13,0) -> 5 | X14: =IF(T14=1,T14+X13,0) -> 5 | Y14: =IF(U14=1,U14+Y13,0) -> 2 | Z14: =IF(V14=1,V14+Z13,0) -> 4
A15: 43405 | F15: ='2018 Summary'!B49 -> 1.2221033 | G15: ='2018 Summary'!C49 -> 1.1164829 | H15: ='2018 Summary'!D49 -> 1.10671 | I15: ='2018 Summary'!E49 -> 1.2580233 | J15: =AVERAGE(F15:I15) -> 1.1758299 | O15: =IF(F15>=1.25,1,0) -> 0 | P15: =IF(G15>=1.25,1,0) -> 0 | Q15: =IF(H15>=1.25,1,0) -> 0 | R15: =IF(I15>=1.25,1,0) -> 1 | S15: =IF(F15>=1,1,0) -> 1 | T15: =IF(G15>=1,1,0) -> 1 | U15: =IF(H15>=1,1,0) -> 1 | V15: =IF(I15>=1,1,0) -> 1 | W15: =IF(S15=1,S15+W14,0) -> 6 | X15: =IF(T15=1,T15+X14,0) -> 6 | Y15: =IF(U15=1,U15+Y14,0) -> 3 | Z15: =IF(V15=1,V15+Z14,0) -> 5
A16: 43435 | F16: ='2018 Summary'!B50 -> 1.016471 | G16: ='2018 Summary'!C50 -> 1.0189278 | H16: ='2018 Summary'!D50 -> 1.0546548 | I16: ='2018 Summary'!E50 -> 1.037071 | J16: =AVERAGE(F16:I16) -> 1.0317811 | O16: =IF(F16>=1.25,1,0) -> 0 | P16: =IF(G16>=1.25,1,0) -> 0 | Q16: =IF(H16>=1.25,1,0) -> 0 | R16: =IF(I16>=1.25,1,0) -> 0 | S16: =IF(F16>=1,1,0) -> 1 | T16: =IF(G16>=1,1,0) -> 1 | U16: =IF(H16>=1,1,0) -> 1 | V16: =IF(I16>=1,1,0) -> 1 | W16: =IF(S16=1,S16+W15,0) -> 7 | X16: =IF(T16=1,T16+X15,0) -> 7 | Y16: =IF(U16=1,U16+Y15,0) -> 4 | Z16: =IF(V16=1,V16+Z15,0) -> 6
A17: 43466 | F17: ='2019 Summary'!B39 -> 0.78667742 | G17: ='2019 Summary'!C39 -> 0.92845556 | H17: ='2019 Summary'!D39 -> 0.84016129 | I17: ='2019 Summary'!E39 -> 0.92447419 | J17: =AVERAGE(F17:I17) -> 0.86994211 | O17: =IF(F17>=1.25,1,0) -> 0 | P17: =IF(G17>=1.25,1,0) -> 0 | Q17: =IF(H17>=1.25,1,0) -> 0 | R17: =IF(I17>=1.25,1,0) -> 0 | S17: =IF(F17>=1,1,0) -> 0 | T17: =IF(G17>=1,1,0) -> 0 | U17: =IF(H17>=1,1,0) -> 0 | V17: =IF(I17>=1,1,0) -> 0 | W17: =IF(S17=1,S17+W16,0) -> 0 | X17: =IF(T17=1,T17+X16,0) -> 0 | Y17: =IF(U17=1,U17+Y16,0) -> 0 | Z17: =IF(V17=1,V17+Z16,0) -> 0
A18: 43497 | F18: ='2019 Summary'!B40 -> 0.62503214 | G18: ='2019 Summary'!C40 -> 0.64321818 | H18: ='2019 Summary'!D40 -> 0.58290714 | I18: ='2019 Summary'!E40 -> 0.60734643 | J18: =AVERAGE(F18:I18) -> 0.61462597 | O18: =IF(F18>=1.25,1,0) -> 0 | P18: =IF(G18>=1.25,1,0) -> 0 | Q18: =IF(H18>=1.25,1,0) -> 0 | R18: =IF(I18>=1.25,1,0) -> 0 | S18: =IF(F18>=1,1,0) -> 0 | T18: =IF(G18>=1,1,0) -> 0 | U18: =IF(H18>=1,1,0) -> 0 | V18: =IF(I18>=1,1,0) -> 0 | W18: =IF(S18=1,S18+W17,0) -> 0 | X18: =IF(T18=1,T18+X17,0) -> 0 | Y18: =IF(U18=1,U18+Y17,0) -> 0 | Z18: =IF(V18=1,V18+Z17,0) -> 0
A19: 43525 | F19: ='2019 Summary'!B41 -> 0.92136129 | G19: ='2019 Summary'!C41 -> 1.0422528 | H19: ='2019 Summary'!D41 -> 0.70154839 | I19: ='2019 Summary'!E41 -> 0.87112903 | J19: =AVERAGE(F19:I19) -> 0.88407287 | O19: =IF(F19>=1.25,1,0) -> 0 | P19: =IF(G19>=1.25,1,0) -> 0 | Q19: =IF(H19>=1.25,1,0) -> 0 | R19: =IF(I19>=1.25,1,0) -> 0 | S19: =IF(F19>=1,1,0) -> 0 | T19: =IF(G19>=1,1,0) -> 1 | U19: =IF(H19>=1,1,0) -> 0 | V19: =IF(I19>=1,1,0) -> 0 | W19: =IF(S19=1,S19+W18,0) -> 0 | X19: =IF(T19=1,T19+X18,0) -> 1 | Y19: =IF(U19=1,U19+Y18,0) -> 0 | Z19: =IF(V19=1,V19+Z18,0) -> 0
A20: 43556 | F20: ='2019 Summary'!B42 -> 0.99646 | G20: ='2019 Summary'!C42 -> 1.0071686 | H20: ='2019 Summary'!D42 -> 1.6759567 | I20: ='2019 Summary'!E42 -> 0.90370333 | J20: =AVERAGE(F20:I20) -> 1.1458221 | O20: =IF(F20>=1.25,1,0) -> 0 | P20: =IF(G20>=1.25,1,0) -> 0 | Q20: =IF(H20>=1.25,1,0) -> 1 | R20: =IF(I20>=1.25,1,0) -> 0 | S20: =IF(F20>=1,1,0) -> 0 | T20: =IF(G20>=1,1,0) -> 1 | U20: =IF(H20>=1,1,0) -> 1 | V20: =IF(I20>=1,1,0) -> 0 | W20: =IF(S20=1,S20+W19,0) -> 0 | X20: =IF(T20=1,T20+X19,0) -> 2 | Y20: =IF(U20=1,U20+Y19,0) -> 1 | Z20: =IF(V20=1,V20+Z19,0) -> 0 | AA20: <--Curtailment
A21: 43586 | F21: ='2019 Summary'!B43 -> 0.84092258 | G21: ='2019 Summary'!C43 -> 0.76303056 | H21: ='2019 Summary'!D43 -> 0.60766129 | I21: ='2019 Summary'!E43 -> 0.71750968 | J21: =AVERAGE(F21:I21) -> 0.73228103 | O21: =IF(F21>=1.25,1,0) -> 0 | P21: =IF(G21>=1.25,1,0) -> 0 | Q21: =IF(H21>=1.25,1,0) -> 0 | R21: =IF(I21>=1.25,1,0) -> 0 | S21: =IF(F21>=1,1,0) -> 0 | T21: =IF(G21>=1,1,0) -> 0 | U21: =IF(H21>=1,1,0) -> 0 | V21: =IF(I21>=1,1,0) -> 0 | W21: =IF(S21=1,S21+W20,0) -> 0 | X21: =IF(T21=1,T21+X20,0) -> 0 | Y21: =IF(U21=1,U21+Y20,0) -> 0 | Z21: =IF(V21=1,V21+Z20,0) -> 0
A22: 43617 | F22: ='2019 Summary'!B44 -> 0.96904 | G22: ='2019 Summary'!C44 -> 0.99971143 | H22: ='2019 Summary'!D44 -> 0.71663667 | I22: ='2019 Summary'!E44 -> 0.75157667 | J22: =AVERAGE(F22:I22) -> 0.85924119 | O22: =IF(F22>=1.25,1,0) -> 0 | P22: =IF(G22>=1.25,1,0) -> 0 | Q22: =IF(H22>=1.25,1,0) -> 0 | R22: =IF(I22>=1.25,1,0) -> 0 | S22: =IF(F22>=1,1,0) -> 0 | T22: =IF(G22>=1,1,0) -> 0 | U22: =IF(H22>=1,1,0) -> 0 | V22: =IF(I22>=1,1,0) -> 0 | W22: =IF(S22=1,S22+W21,0) -> 0 | X22: =IF(T22=1,T22+X21,0) -> 0 | Y22: =IF(U22=1,U22+Y21,0) -> 0 | Z22: =IF(V22=1,V22+Z21,0) -> 0
A23: 43647 | F23: ='2019 Summary'!B45 -> 0.96095161 | G23: ='2019 Summary'!C45 -> 0.98111111 | H23: ='2019 Summary'!D45 -> 0.86676774 | I23: ='2019 Summary'!E45 -> 0.94854839 | J23: =AVERAGE(F23:I23) -> 0.93934471 | O23: =IF(F23>=1.25,1,0) -> 0 | P23: =IF(G23>=1.25,1,0) -> 0 | Q23: =IF(H23>=1.25,1,0) -> 0 | R23: =IF(I23>=1.25,1,0) -> 0 | S23: =IF(F23>=1,1,0) -> 0 | T23: =IF(G23>=1,1,0) -> 0 | U23: =IF(H23>=1,1,0) -> 0 | V23: =IF(I23>=1,1,0) -> 0 | W23: =IF(S23=1,S23+W22,0) -> 0 | X23: =IF(T23=1,T23+X22,0) -> 0 | Y23: =IF(U23=1,U23+Y22,0) -> 0 | Z23: =IF(V23=1,V23+Z22,0) -> 0
A24: 43678 | F24: ='2019 Summary'!B46 -> 0.99222581 | G24: ='2019 Summary'!C46 -> 1.0531139 | H24: ='2019 Summary'!D46 -> 0.8927129 | I24: ='2019 Summary'!E46 -> 0.97637097 | J24: =AVERAGE(F24:I24) -> 0.97860589 | O24: =IF(F24>=1.25,1,0) -> 0 | P24: =IF(G24>=1.25,1,0) -> 0 | Q24: =IF(H24>=1.25,1,0) -> 0 | R24: =IF(I24>=1.25,1,0) -> 0 | S24: =IF(F24>=1,1,0) -> 0 | T24: =IF(G24>=1,1,0) -> 1 | U24: =IF(H24>=1,1,0) -> 0 | V24: =IF(I24>=1,1,0) -> 0 | W24: =IF(S24=1,S24+W23,0) -> 0 | X24: =IF(T24=1,T24+X23,0) -> 1 | Y24: =IF(U24=1,U24+Y23,0) -> 0 | Z24: =IF(V24=1,V24+Z23,0) -> 0
