Workbook
Name Average_CE: '100000MP'!$B$26
Name Average_CE: '5000000MP '!$B$15
Name Average_CE: '500000MP'!$B$16
Name VOC_Credit: '100000MP'!#REF!
Name VOC_Credit: '5000000MP '!$B$16
Name VOC_Credit: '500000MP'!$B$17

Sheet 100000MP
A1: Small Model Plant
C2: Crude Petroleum | D2: Gasoline | E2: Kerosene | F2: Distillate Fuel Oil | G2: Residual Fuel Oil | H2: Naphtha & Solvents | I2: Benzene & Toluene | J2: Alcohols | K2: Total
A3: Gallons Loaded (1000 gal/yr) | C3: 12700 | D3: 6200 | E3: 6000 | F3: 41700 | G3: 7800 | H3: 200 | I3: 13500 | J3: 11900 | K3: =SUM(C3:J3) -> 100000
A4: VOC Loading Loss (TPY) | B4: Ships | C4: =C3*'Loading Loss'!H20/2000 -> 5.860978 | D4: =D3*'Loading Loss'!B24/2000 -> 5.58 | E4: =E3*'Loading Loss'!H4/2000 -> 0.01836165 | F4: =F3*'Loading Loss'!H5/2000 -> 0.11107108 | G4: =G3*'Loading Loss'!H6/2000 -> 0.014255787 | H4: =H3*'Loading Loss'!H3/2000 -> 0.61741032 | I4: =I3*(AVERAGE('Loading Loss'!H7:H8))/2000 -> 3.1249567 | J4: =J3*(AVERAGE('Loading Loss'!H9:H10))/2000 -> 0.83638347 | K4: =SUM(C4:J4) -> 16.163417
B5: Barges | C5: =C3*'Loading Loss'!H20/2000 -> 5.860978 | D5: =D3*'Loading Loss'!C24/2000 -> 10.54 | E5: ='Loading Loss'!I4*'50000MP'!E3/2000 -> 0.0015332526 | F5: =F3*'Loading Loss'!I5/2000 -> 0.27767759 | G5: =G3*'Loading Loss'!I6/2000 -> 0.035639487 | H5: =H3*'Loading Loss'!I3/2000 -> 1.5435258 | I5: =I3*(AVERAGE('Loading Loss'!I7:I8))/2000 -> 7.8123917 | J5: =J3*(AVERAGE('Loading Loss'!I9:I10))/2000 -> 2.0909587 | K5: =SUM(C5:J5) -> 28.162705
B6: Model Plant | C6: =AVERAGE(C4:C5) -> 5.860978 | D6: =AVERAGE(D4:D5) -> 8.06 | E6: =AVERAGE(E4:E5) -> 0.0099474513 | F6: =AVERAGE(F4:F5) -> 0.19437433 | G6: =AVERAGE(G4:G5) -> 0.024947637 | H6: =AVERAGE(H4:H5) -> 1.0804681 | I6: =AVERAGE(I4:I5) -> 5.4686742 | J6: =AVERAGE(J4:J5) -> 1.4636711 | K6: =SUM(C6:J6) -> 22.163061
A7: Percent of Total Loading Loss | C7: =C6/$K$6 -> 0.26444804 | D7: =D6/$K$6 -> 0.36366818 | E7: =E6/$K$6 -> 0.00044883021 | F7: =F6/$K$6 -> 0.0087701936 | G7: =G6/$K$6 -> 0.0011256404 | H7: =H6/$K$6 -> 0.04875085 | I7: =I6/$K$6 -> 0.24674725 | J7: =J6/$K$6 -> 0.066041017 | K7: =SUM(C7:J7) -> 1
A9: Small Model Plant Emissions
B10: Benzene (TPY) | C10: Biphenyl (TPY) | D10: Chlorine (TPY) | E10: Cumene (TPY) | F10: Ethylbenzene (TPY) | G10: Ethylene Glycol (TPY) | H10: Hexane (TPY) | I10: Methanol (TPY) | J10: Napthalene (TPY) | K10: Phenol (TPY) | L10: Toluene (TPY) | M10: 2,2,4-Trimethyl-pentane (isooctane) (TPY) | N10: Styrene (TPY) | O10: Xylene (TPY) | P10: Total HAP (TPY)
A11: Ships | B11: =(C4*'Fuel Composition'!$J$32/100)+(D4*'Fuel Composition'!$J$6/100)+(E4*'Fuel Composition'!$J$87/100)+(F4*'Fuel Composition'!$J$110/100)+(G4*'Fuel Composition'!$J$135/100)+(H4*'Fuel Composition'!$J$64/100)+(I4*('Loading Loss'!H9/('Loading Loss'!H9+'Loading Loss'!H10))) -> 3.1911438 | C11: =(C4*'Fuel Composition'!$J$33/100)+(E4*'Fuel Composition'!$J$88/100)+(F4*'Fuel Composition'!$J$111/100) -> 6.0445945e-06 | D11: =G4*'Fuel Composition'!$J$137/100 -> 0.0024477186 | E11: =D4*'Fuel Composition'!$J$12/100 -> 0.00023436 | F11: =(D4*'Fuel Composition'!$J$10/100)+(C4*'Fuel Composition'!$J$35/100)+(E4*'Fuel Composition'!$J$89/100)+(F4*'Fuel Composition'!$J$112/100)+(G4*'Fuel Composition'!$J$136/100)+(H4*'Fuel Composition'!$J$74/100) -> 0.0057092378 | G11: =J4*('Loading Loss'!H10/('Loading Loss'!H10+'Loading Loss'!H9)) -> 0.0008899415 | H11: =(D4*'Fuel Composition'!$J$7/100)+(C4*'Fuel Composition'!$J$36/100)+(E4*'Fuel Composition'!$J$90/100)+(F4*'Fuel Composition'!$J$113/100)+(H4*'Fuel Composition'!$J$66/100) -> 0.26859248 | I11: =J4*('Loading Loss'!H9/('Loading Loss'!H9+'Loading Loss'!H10)) -> 0.83549353 | J11: =(D4*'Fuel Composition'!$J$13/100)+(C4*'Fuel Composition'!$J$37/100)+(E4*'Fuel Composition'!$J$91/100)+(F4*'Fuel Composition'!$J$114/100)+(G4*'Fuel Composition'!$J$138/100) -> 7.1631845e-05 | K11: =(C4*'Fuel Composition'!$J$39/100)+(E4*'Fuel Composition'!$J$92/100)+(F4*'Fuel Composition'!$J$115/100) -> 7.1462935e-05 | L11: =(D4*'Fuel Composition'!$J$8/100)+(C4*'Fuel Composition'!$J$40/100)+(E4*'Fuel Composition'!$J$93/100)+(F4*'Fuel Composition'!$J$117/100)+(G4*'Fuel Composition'!$J$139/100)+(H4*'Fuel Composition'!$J$68/100)+(I4*('Loading Loss'!H8/('Loading Loss'!H8+'Loading Loss'!H7))) -> 0.88131247 | M11: =D4*'Fuel Composition'!$J$11/100 -> 0.015624 | N11: =F4*'Fuel Composition'!$J$116/100 -> 1.1107108e-05 | O11: =(C4*'Fuel Composition'!$J$42/100)+(D4*'Fuel Composition'!$J$9/100)+(E4*'Fuel Composition'!$J$94/100)+(F4*'Fuel Composition'!$J$118/100)+(G4*'Fuel Composition'!$J$140/100)+(H4*'Fuel Composition'!$J$69/100) -> 0.023483895 | P11: =SUM(B11:O11) -> 5.2250917
A12: Barges | B12: =(C5*'Fuel Composition'!$J$32/100)+(D5*'Fuel Composition'!$J$6/100)+(E5*'Fuel Composition'!$J$87/100)+(F5*'Fuel Composition'!$J$110/100)+(G5*'Fuel Composition'!$J$135/100)+(H5*'Fuel Composition'!$J$64/100)+(I5*('Loading Loss'!H10/('Loading Loss'!H10+'Loading Loss'!H11))) -> 7.9298271 | C12: =(C5*'Fuel Composition'!$J$33/100)+(E5*'Fuel Composition'!$J$88/100)+(F5*'Fuel Composition'!$J$111/100) -> 5.8763106e-06 | D12: =G5*'Fuel Composition'!$J$137/100 -> 0.0061192999 | E12: =D5*'Fuel Composition'!$J$12/100 -> 0.00044268 | F12: =(D5*'Fuel Composition'!$J$10/100)+(C5*'Fuel Composition'!$J$35/100)+(E5*'Fuel Composition'!$J$89/100)+(F5*'Fuel Composition'!$J$112/100)+(G5*'Fuel Composition'!$J$136/100)+(H5*'Fuel Composition'!$J$74/100) -> 0.009972503 | G12: =J5*('Loading Loss'!I10/('Loading Loss'!I10+'Loading Loss'!I9)) -> 0.0022248835 | H12: =(D5*'Fuel Composition'!$J$7/100)+(C5*'Fuel Composition'!$J$36/100)+(E5*'Fuel Composition'!$J$90/100)+(F5*'Fuel Composition'!$J$113/100)+(H5*'Fuel Composition'!$J$66/100) -> 0.38914216 | I12: =J5*('Loading Loss'!I9/('Loading Loss'!I10+'Loading Loss'!I9)) -> 2.0887338 | J12: =(D5*'Fuel Composition'!$J$13/100)+(C5*'Fuel Composition'!$J$37/100)+(E5*'Fuel Composition'!$J$91/100)+(F5*'Fuel Composition'!$J$114/100)+(G5*'Fuel Composition'!$J$138/100) -> 0.0001046783 | K12: =(C5*'Fuel Composition'!$J$39/100)+(E5*'Fuel Composition'!$J$92/100)+(F5*'Fuel Composition'!$J$115/100) -> 5.9683057e-05 | L12: =(D5*'Fuel Composition'!$J$8/100)+(C5*'Fuel Composition'!$J$40/100)+(E5*'Fuel Composition'!$J$93/100)+(F5*'Fuel Composition'!$J$117/100)+(G5*'Fuel Composition'!$J$139/100)+(H5*'Fuel Composition'!$J$68/100)+(I5*('Loading Loss'!I8/('Loading Loss'!I8+'Loading Loss'!I7))) -> 2.1506209 | M12: =D5*'Fuel Composition'!$J$11/100 -> 0.029512 | N12: =F5*'Fuel Composition'!$J$116/100 -> 2.7767759e-05 | O12: =(C5*'Fuel Composition'!$J$42/100)+(D5*'Fuel Composition'!$J$9/100)+(E5*'Fuel Composition'!$J$94/100)+(F5*'Fuel Composition'!$J$118/100)+(G5*'Fuel Composition'!$J$140/100)+('100000MP'!H5*'Fuel Composition'!$J$69/100) -> 0.039875887 | P12: =SUM(B12:O12) -> 12.646669
A13: Model Plant | B13: =AVERAGE(B11:B12) -> 5.5604854 | C13: =AVERAGE(C11:C12) -> 5.9604526e-06 | D13: =AVERAGE(D11:D12) -> 0.0042835093 | E13: =AVERAGE(E11:E12) -> 0.00033852 | F13: =AVERAGE(F11:F12) -> 0.0078408704 | G13: =AVERAGE(G11:G12) -> 0.0015574125 | H13: =AVERAGE(H11:H12) -> 0.32886732 | I13: =AVERAGE(I11:I12) -> 1.4621137 | ... O13: =AVERAGE(O11:O12) -> 0.031679891 | P13: =SUM(B13:O13) -> 8.9358804
A15: Average CE | B15: 0.97
A16: VOC Credit ($/ton) | B16: 672
A18: Hours Loading | B18: Hours Loading >1.5 psia
A19: =K3*1000/42/5000 -> 476.19048 | B19: =SUM(C3,D3,H3,(0.5*I3),(0.5*J3))*1000/42/5000 -> 151.42857
A20: Total Hours Operating (1.1 factor of safety + 100 startup hours)
A21: =A19*1.1+100 -> 623.80952 | B21: =B19*1.1+100 -> 266.57143
A23: lb VOC emitted /hr | C23: VOC Reduced (TPY)
A24: (based on gasoline)
A25: =D6*2000/(D3*1000/42/5000) -> 546 | C25: =B15*SUM(C6,D6,H6,(0.74*I6),J6) -> 19.896578
B27: Carbon Adsorber | M27: Thermal Oxidizer
B28: Costs (2023 dollars) | H28: HAP Emission Reductions (tpy) | I28: HAP Cost Effectiveness ($/ton) | J28: Incremental HAP Cost Effectiveness ($/ton) | M28: Costs (2023 dollars) | Q28: HAP Emission Reductions (tpy) | R28: HAP Cost Effectiveness ($/ton) | S28: Incremental HAP Cost Effectiveness ($/ton)
B29: Capital Costs | C29: Annual Operating Costs | D29: Annual Capital Recovery | E29: Total Annual Costs | F29: Solvent Recovery Credit | G29: Total Annual Costs with Credits | M29: Capital Costs | N29: Annual Operating Costs | O29: Annual Capital Recovery | P29: Total Annual Costs
A30: Typical MTVLO Facility | L30: Typical MTVLO Facility
A31: 275 hrs (1.5 psia) | B31: 3686375 | C31: 267215 | D31: =E43*(B31-((1.08*E45*E46)+(E47*E46/E48))) -> 373972.32 | E31: =C31+D31 -> 641187.32 | F31: =B16*B15*SUM(C6,D6,H6,(0.74*I6),J6) -> 13370.5 | G31: =C31+D31-F31 -> 627816.82 | H31: =($P$13*B15*SUM(C7,D7,H7,(0.74*I7),J7)) -> 8.0220617 | I31: =G31/H31 -> 78261.28 | L31: 275 hrs (1.5 psia) | M31: 447809 | N31: 75093 | O31: =M31*O43 -> 50731.044 | P31: =N31+O31 -> 125824.04 | Q31: =H31 -> 8.0220617 | R31: =(N31+O31)/Q31 -> 15684.751
A32: 650 hrs (no exemption) | B32: 3686375 | C32: 295097 | D32: =E43*(B32-((1.08*E45*E46)+(E47*E46/E48))) -> 373972.32 | E32: =C32+D32 -> 669069.32 | F32: =K6*B16*B15 -> 14446.77 | G32: =C32+D32-F32 -> 654622.55 | H32: =$P$13*B15 -> 8.667804 | I32: =G32/H32 -> 75523.46 | J32: =(G32-G31)/(H32-H31) -> 41511.5 | L32: 650 hrs (no exemption) | M32: 447809 | N32: 153068 | O32: =M32*O43 -> 50731.044 | P32: =N32+O32 -> 203799.04 | Q32: =H32 -> 8.667804 | R32: =(N32+O32)/Q32 -> 23512.189 | S32: =(N32+O32-N31-O31)/(Q32-Q31) -> 120752.51
A35: Assumptions:
A36: 1. Loading Rate = 5000 bbl/hr
A37: 2. Ships and Barges are loaded equally
A38: 3. Up to 1 vessel can be loaded at once
D42: = CRFAdsorber × (TCI - [(1.08 x CC x Mc) + (LR x Mc/CRR)] = | N42: =CRF x TCI
D43: CRF = | E43: =(E49*(1+E49)^15)/(((1+E49)^15)-1) -> 0.11328724 | F43: Capital Recovery Factor for adsorber vessels and auxiliary equipment | N43: CRF = | O43: =(O45*(1+O45)^15)/(((1+O45)^15)-1) -> 0.11328724
D44: TCI = | E44: =B32 -> 3686375 | F44: Total Capital Investment | N44: TCI = | O44: =M31 -> 447809
D45: CC = | E45: 5.56 | F45: Carbon Cost | N45: Interest Rate | O45: 0.075
D46: Mc = | E46: 62932 | F46: Carbon Consumption
D47: LR = | E47: 44.46 | F47: Labor Rate
D48: CRR = | E48: 379 | F48: (lb/hr) Carbon Replacement Rate
D49: Interest Rate | E49: 0.075

Sheet 500000MP
A1: Medium Model Plant
C2: Crude Petroleum | D2: Gasoline | E2: Kerosene | F2: Distillate Fuel Oil | G2: Residual Fuel Oil | H2: Naphtha & Solvents | I2: Benzene & Toluene | J2: Alcohols | K2: Total
A3: Gallons Loaded (1000 gal/yr) | C3: 78300 | D3: 87000 | E3: 27400 | F3: 144400 | G3: 62400 | H3: 20900 | I3: 4100 | J3: 75500 | K3: =SUM(C3:J3) -> 500000
A4: VOC Loading Loss (TPY) | B4: Ships | C4: =C3*'Loading Loss'!H20/2000 -> 36.135006 | D4: =D3*'Loading Loss'!B24/2000 -> 78.3 | E4: =E3*'Loading Loss'!H4/2000 -> 0.083851535 | F4: =F3*'Loading Loss'!H5/2000 -> 0.38462023 | G4: =G3*'Loading Loss'!H6/2000 -> 0.1140463 | H4: =H3*'Loading Loss'!H3/2000 -> 64.519378 | I4: =I3*(AVERAGE('Loading Loss'!H7:H8))/2000 -> 0.94906092 | J4: =J3*(AVERAGE('Loading Loss'!H9:H10))/2000 -> 5.3064665 | K4: =SUM(C4:J4) -> 185.79243
B5: Barges | C5: =C3*'Loading Loss'!H20/2000 -> 36.135006 | D5: =D3*'Loading Loss'!C24/2000 -> 147.9 | E5: ='Loading Loss'!I4*'50000MP'!E3/2000 -> 0.0015332526 | F5: =F3*'Loading Loss'!I5/2000 -> 0.96155021 | G5: =G3*'Loading Loss'!I6/2000 -> 0.2851159 | H5: =H3*'Loading Loss'!I3/2000 -> 161.29845 | I5: =I3*(AVERAGE('Loading Loss'!I7:I8))/2000 -> 2.3726523 | J5: =J3*(AVERAGE('Loading Loss'!I9:I10))/2000 -> 13.266166 | K5: =SUM(C5:J5) -> 362.22047
B6: Model Plant | C6: =AVERAGE(C4:C5) -> 36.135006 | D6: =AVERAGE(D4:D5) -> 113.1 | E6: =AVERAGE(E4:E5) -> 0.042692394 | F6: =AVERAGE(F4:F5) -> 0.67308522 | G6: =AVERAGE(G4:G5) -> 0.1995811 | H6: =AVERAGE(H4:H5) -> 112.90891 | I6: =AVERAGE(I4:I5) -> 1.6608566 | J6: =AVERAGE(J4:J5) -> 9.2863164 | K6: =SUM(C6:J6) -> 274.00645
A7: Percent of Total Loading Loss | C7: =C6/$K$6 -> 0.13187648 | D7: =D6/$K$6 -> 0.41276401 | E7: =E6/$K$6 -> 0.00015580799 | F7: =F6/$K$6 -> 0.0024564576 | G7: =G6/$K$6 -> 0.00072838101 | H7: =H6/$K$6 -> 0.41206662 | I7: =I6/$K$6 -> 0.0060613778 | J7: =J6/$K$6 -> 0.033890868 | K7: =SUM(C7:J7) -> 1
A9: Medium Model Plant Emissions
B10: Benzene (TPY) | C10: Biphenyl (TPY) | D10: Chlorine (TPY) | E10: Cumene (TPY) | F10: Ethylbenzene (TPY) | G10: Ethylene Glycol (TPY) | H10: Hexane (TPY) | I10: Methanol (TPY) | J10: Napthalene (TPY) | K10: Phenol (TPY) | L10: Toluene (TPY) | M10: 2,2,4-Trimethyl-pentane (isooctane) (TPY) | N10: Styrene (TPY) | O10: Xylene (TPY) | P10: Total HAP (TPY)
A11: Ships | B11: =(C4*'Fuel Composition'!$J$32/100)+(D4*'Fuel Composition'!$J$6/100)+(E4*'Fuel Composition'!$J$87/100)+(F4*'Fuel Composition'!$J$110/100)+(G4*'Fuel Composition'!$J$135/100)+(H4*'Fuel Composition'!$J$64/100)+(I4*('Loading Loss'!H9/('Loading Loss'!H9+'Loading Loss'!H10))) -> 2.268081 | C11: =(C4*'Fuel Composition'!$J$33/100)+(E4*'Fuel Composition'!$J$88/100)+(F4*'Fuel Composition'!$J$111/100) -> 3.6973522e-05 | D11: =G4*'Fuel Composition'!$J$137/100 -> 0.019581749 | E11: =D4*'Fuel Composition'!$J$12/100 -> 0.0032886 | F11: =(D4*'Fuel Composition'!$J$10/100)+(C4*'Fuel Composition'!$J$35/100)+(E4*'Fuel Composition'!$J$89/100)+(F4*'Fuel Composition'!$J$112/100)+(G4*'Fuel Composition'!$J$136/100)+(H4*'Fuel Composition'!$J$74/100) -> 0.12043638 | G11: =J4*('Loading Loss'!H10/('Loading Loss'!H10+'Loading Loss'!H9)) -> 0.0056462675 | H11: =(D4*'Fuel Composition'!$J$7/100)+(C4*'Fuel Composition'!$J$36/100)+(E4*'Fuel Composition'!$J$90/100)+(F4*'Fuel Composition'!$J$113/100)+(H4*'Fuel Composition'!$J$66/100) -> 6.0969981 | I11: =J4*('Loading Loss'!H9/('Loading Loss'!H9+'Loading Loss'!H10)) -> 5.3008203 | J11: =(D4*'Fuel Composition'!$J$13/100)+(C4*'Fuel Composition'!$J$37/100)+(E4*'Fuel Composition'!$J$91/100)+(F4*'Fuel Composition'!$J$114/100)+(G4*'Fuel Composition'!$J$138/100) -> 0.00061642782 | K11: =(C4*'Fuel Composition'!$J$39/100)+(E4*'Fuel Composition'!$J$92/100)+(F4*'Fuel Composition'!$J$115/100) -> 0.00042004614 | L11: =(D4*'Fuel Composition'!$J$8/100)+(C4*'Fuel Composition'!$J$40/100)+(E4*'Fuel Composition'!$J$93/100)+(F4*'Fuel Composition'!$J$117/100)+(G4*'Fuel Composition'!$J$139/100)+(H4*'Fuel Composition'!$J$68/100)+(I4*('Loading Loss'!H8/('Loading Loss'!H8+'Loading Loss'!H7))) -> 1.4073672 | M11: =D4*'Fuel Composition'!$J$11/100 -> 0.21924 | N11: =F4*'Fuel Composition'!$J$116/100 -> 3.8462023e-05 | O11: =(C4*'Fuel Composition'!$J$42/100)+(D4*'Fuel Composition'!$J$9/100)+(E4*'Fuel Composition'!$J$94/100)+(F4*'Fuel Composition'!$J$118/100)+(G4*'Fuel Composition'!$J$140/100)+(H4*'Fuel Composition'!$J$69/100) -> 0.35343692 | P11: =SUM(B11:O11) -> 15.796008
A12: Barges | B12: =(C5*'Fuel Composition'!$J$32/100)+(D5*'Fuel Composition'!$J$6/100)+(E5*'Fuel Composition'!$J$87/100)+(F5*'Fuel Composition'!$J$110/100)+(G5*'Fuel Composition'!$J$135/100)+(H5*'Fuel Composition'!$J$64/100)+(I5*('Loading Loss'!H10/('Loading Loss'!H10+'Loading Loss'!H11))) -> 5.110809 | C12: =(C5*'Fuel Composition'!$J$33/100)+(E5*'Fuel Composition'!$J$88/100)+(F5*'Fuel Composition'!$J$111/100) -> 3.6150339e-05 | D12: =G5*'Fuel Composition'!$J$137/100 -> 0.048954399 | E12: =D5*'Fuel Composition'!$J$12/100 -> 0.0062118 | F12: =(D5*'Fuel Composition'!$J$10/100)+(C5*'Fuel Composition'!$J$35/100)+(E5*'Fuel Composition'!$J$89/100)+(F5*'Fuel Composition'!$J$112/100)+(G5*'Fuel Composition'!$J$136/100)+(H5*'Fuel Composition'!$J$74/100) -> 0.25602712 | G12: =J5*('Loading Loss'!I10/('Loading Loss'!I10+'Loading Loss'!I9)) -> 0.014115858 | H12: =(D5*'Fuel Composition'!$J$7/100)+(C5*'Fuel Composition'!$J$36/100)+(E5*'Fuel Composition'!$J$90/100)+(F5*'Fuel Composition'!$J$113/100)+(H5*'Fuel Composition'!$J$66/100) -> 13.287323 | I12: =J5*('Loading Loss'!I9/('Loading Loss'!I10+'Loading Loss'!I9)) -> 13.25205 | J12: =(D5*'Fuel Composition'!$J$13/100)+(C5*'Fuel Composition'!$J$37/100)+(E5*'Fuel Composition'!$J$91/100)+(F5*'Fuel Composition'!$J$114/100)+(G5*'Fuel Composition'!$J$138/100) -> 0.00098096167 | K12: =(C5*'Fuel Composition'!$J$39/100)+(E5*'Fuel Composition'!$J$92/100)+(F5*'Fuel Composition'!$J$115/100) -> 0.00036242334 | L12: =(D5*'Fuel Composition'!$J$8/100)+(C5*'Fuel Composition'!$J$40/100)+(E5*'Fuel Composition'!$J$93/100)+(F5*'Fuel Composition'!$J$117/100)+(G5*'Fuel Composition'!$J$139/100)+(H5*'Fuel Composition'!$J$68/100)+(I5*('Loading Loss'!I8/('Loading Loss'!I8+'Loading Loss'!I7))) -> 2.9154833 | M12: =D5*'Fuel Composition'!$J$11/100 -> 0.41412 | N12: =F5*'Fuel Composition'!$J$116/100 -> 9.6155021e-05 | O12: =(C5*'Fuel Composition'!$J$42/100)+(D5*'Fuel Composition'!$J$9/100)+(E5*'Fuel Composition'!$J$94/100)+(F5*'Fuel Composition'!$J$118/100)+(G5*'Fuel Composition'!$J$140/100)+('500000MP'!H5*'Fuel Composition'!$J$69/100) -> 0.68483109 | P12: =SUM(B12:O12) -> 35.991402
A13: Model Plant | B13: =AVERAGE(B11:B12) -> 3.689445 | C13: =AVERAGE(C11:C12) -> 3.656193e-05 | D13: =AVERAGE(D11:D12) -> 0.034268074 | E13: =AVERAGE(E11:E12) -> 0.0047502 | F13: =AVERAGE(F11:F12) -> 0.18823175 | G13: =AVERAGE(G11:G12) -> 0.0098810625 | H13: =AVERAGE(H11:H12) -> 9.6921606 | I13: =AVERAGE(I11:I12) -> 9.2764354 | ... O13: =AVERAGE(O11:O12) -> 0.519134 | P13: =SUM(B13:O13) -> 25.893705
B14: =B13/$P$13 -> 0.14248424 | C14: =C13/$P$13 -> 1.4120007e-06 | D14: =D13/$P$13 -> 0.0013234133 | E14: =E13/$P$13 -> 0.00018344999 | F14: =F13/$P$13 -> 0.0072694021 | G14: =G13/$P$13 -> 0.00038160095 | H14: =H13/$P$13 -> 0.37430567 | I14: =I13/$P$13 -> 0.3582506 | ... O14: =O13/$P$13 -> 0.020048657
A16: Average CE | B16: 0.97
A17: VOC Credit ($/ton) | B17: 672
A19: Total Hours Loading | B19: Hours Loading >1.5 psia
A20: =K3*1000/42/5000 -> 2380.9524 | B20: =SUM(C3,D3,H3,(0.5*J3),(0.5*I3))*1000/42/5000 -> 1076.1905
A21: Total Hours Operating (1.1 factor of safety + 100 startup hours)
A22: =A20*1.1+100 -> 2719.0476 | B22: =B20*1.1+100 -> 1283.8095
A24: lb VOC emitted /hr | C24: VOC Reduced (TPY)
A25: (based on gasoline)
A26: =D6*2000/(D3*1000/42/5000) -> 546 | C26: =B16*SUM(C6,D6,H6,(0.74*I6),J6) -> 264.47949
B28: Carbon Adsorber | M28: Thermal Oxidizer
B29: Costs (2023 dollars) | H29: HAP Emission Reductions (tpy) | I29: HAP Cost Effectiveness ($/ton) | J29: Incremental HAP Cost Effectiveness ($/ton) | M29: Costs (2023 dollars) | Q29: HAP Emission Reductions (tpy) | R29: HAP Cost Effectiveness ($/ton) | S29: Incremental HAP Cost Effectiveness ($/ton)
B30: Capital Costs | C30: Annual Operating Costs | D30: Annual Capital Recovery | E30: Total Annual Costs | F30: Solvent Recovery Credit | G30: Total Annual Costs with Credits | M30: Capital Costs | N30: Annual Operating Costs | O30: Annual Capital Recovery | P30: Total Annual Costs
A31: Typical MTVLO Facility | L31: Typical MTVLO Facility
A32: 1300 hrs (1.5 psia) | B32: 3686375 | C32: 343426 | D32: =E43*(B32-((1.08*E45*E46)+(E47*E46/E48))) -> 373972.32 | E32: =C32+D32 -> 717398.32 | F32: =VOC_Credit*Average_CE*SUM(C6,D6,H6,(0.74*I6),J6) -> 177730.22 | G32: =C32+D32-F32 -> 539668.1 | H32: =($P$13*Average_CE*SUM(C7,D7,H7,(0.74*I7),J7)) -> 24.993404 | I32: =G32/H32 -> 21592.421 | L32: 1300 hrs (1.5 psia) | M32: 447809 | N32: 288223 | O32: =M32*O43 -> 50731.044 | P32: =N32+O32 -> 338954.04 | Q32: =H32 -> 24.993404 | R32: =(N32+O32)/Q32 -> 13561.74
A33: 2725 hrs (no exemption) | B33: 3686375 | C33: 449379 | D33: =E43*(B33-((1.08*E45*E46)+(E47*E46/E48))) -> 373972.32 | E33: =C33+D33 -> 823351.32 | F33: =K6*VOC_Credit*Average_CE -> 178608.36 | G33: =C33+D33-F33 -> 644742.96 | H33: =$P$13*Average_CE -> 25.116894 | I33: =G33/H33 -> 25669.693 | J33: =(G33-G32)/(H33-H32) -> 850878.52 | L33: 2725 hrs (no exemption) | M33: 447809 | N33: 584525 | O33: =M33*O43 -> 50731.044 | P33: =N33+O33 -> 635256.04 | Q33: =H33 -> 25.116894 | R33: =(N33+O33)/Q33 -> 25291.983 | S33: =(N33+O33-N32-O32)/(Q33-Q32) -> 2399403.8
N34: TAC
A36: Assumptions:
A37: 1. Loading Rate = 5000 bbl/hr
A38: 2. Ships and Barges are loaded equally
A39: 3. Up to 1 vessel can be loaded at once
D42: = CRFAdsorber × (TCI - [(1.08 x CC x Mc) + (LR x Mc/CRR)] = | N42: =CRF x TCI
D43: CRF = | E43: =(E49*(1+E49)^15)/(((1+E49)^15)-1) -> 0.11328724 | F43: Capital Recovery Factor for adsorber vessels and auxiliary equipment | N43: CRF = | O43: =(O45*(1+O45)^15)/(((1+O45)^15)-1) -> 0.11328724
D44: TCI = | E44: =B32 -> 3686375 | F44: Total Capital Investment | N44: TCI = | O44: =M33 -> 447809
D45: CC = | E45: 5.56 | F45: Carbon Cost | N45: Interest Rate | O45: 0.075
D46: Mc = | E46: 62932 | F46: Carbon Consumption
D47: LR = | E47: 44.46 | F47: Labor Rate
D48: CRR = | E48: 379 | F48: (lb/hr) Carbon Replacement Rate
...

Sheet 5000000MP 
A1: Large Model Plant
C2: Crude Petroleum | D2: Gasoline | E2: Kerosene | F2: Distillate Fuel Oil | G2: Residual Fuel Oil | H2: Naphtha & Solvents | I2: Benzene & Toluene | J2: Alcohols | K2: Total
A3: Gallons Loaded (1000 gal/yr) | C3: 136000 | D3: 1929000 | E3: 620000 | F3: 1493000 | G3: 191000 | H3: 320000 | I3: 85000 | J3: 226000 | K3: =SUM(C3:J3) -> 5000000
A4: VOC Loading Loss (TPY) | B4: Ships | C4: =C3*'Loading Loss'!H20/2000 -> 62.76323 | D4: =D3*'Loading Loss'!B24/2000 -> 1736.1 | E4: =E3*'Loading Loss'!H4/2000 -> 1.8973705 | F4: =F3*'Loading Loss'!H5/2000 -> 3.9767175 | G4: =G3*'Loading Loss'!H6/2000 -> 0.34908402 | H4: =H3*'Loading Loss'!H3/2000 -> 987.85651 | I4: =I3*(AVERAGE('Loading Loss'!H7:H8))/2000 -> 19.675653 | J4: =J3*(AVERAGE('Loading Loss'!H9:H10))/2000 -> 15.884257 | K4: =SUM(C4:J4) -> 2828.5028
B5: Barges | C5: =C3*'Loading Loss'!H20/2000 -> 62.76323 | D5: =D3*'Loading Loss'!C24/2000 -> 3279.3 | E5: ='Loading Loss'!I4*'50000MP'!E3/2000 -> 0.0015332526 | F5: =F3*'Loading Loss'!I5/2000 -> 9.94179 | G5: =G3*'Loading Loss'!I6/2000 -> 0.87271051 | H5: =H3*'Loading Loss'!I3/2000 -> 2469.6413 | I5: =I3*(AVERAGE('Loading Loss'!I7:I8))/2000 -> 49.189133 | J5: =J3*(AVERAGE('Loading Loss'!I9:I10))/2000 -> 39.710644 | K5: =SUM(C5:J5) -> 5911.4203
B6: Model Plant | C6: =AVERAGE(C4:C5) -> 62.76323 | D6: =AVERAGE(D4:D5) -> 2507.7 | E6: =AVERAGE(E4:E5) -> 0.94945188 | F6: =AVERAGE(F4:F5) -> 6.9592537 | G6: =AVERAGE(G4:G5) -> 0.61089726 | H6: =AVERAGE(H4:H5) -> 1728.7489 | I6: =AVERAGE(I4:I5) -> 34.432393 | J6: =AVERAGE(J4:J5) -> 27.797451 | K6: =SUM(C6:J6) -> 4369.9616
A7: Percent of Total Loading Loss | C7: =C6/$K$6 -> 0.014362421 | D7: =D6/$K$6 -> 0.57384944 | E7: =E6/$K$6 -> 0.00021726779 | F7: =F6/$K$6 -> 0.0015925206 | G7: =G6/$K$6 -> 0.00013979465 | H7: =H6/$K$6 -> 0.39559819 | I7: =I6/$K$6 -> 0.0078793355 | J7: =J6/$K$6 -> 0.0063610286 | K7: =SUM(C7:J7) -> 1
A9: Large Model Plant Emissions
B10: Benzene (TPY) | C10: Biphenyl (TPY) | D10: Chlorine (TPY) | E10: Cumene (TPY) | F10: Ethylbenzene (TPY) | G10: Ethylene Glycol (TPY) | H10: Hexane (TPY) | I10: Methanol (TPY) | J10: Napthalene (TPY) | K10: Phenol (TPY) | L10: Toluene (TPY) | M10: 2,2,4-Trimethyl-pentane (isooctane) (TPY) | N10: Styrene (TPY) | O10: Xylene (TPY) | P10: Total HAP (TPY)
A11: Ships | B11: =(C4*'Fuel Composition'!$J$32/100)+(D4*'Fuel Composition'!$J$6/100)+(E4*'Fuel Composition'!$J$87/100)+(F4*'Fuel Composition'!$J$110/100)+(G4*'Fuel Composition'!$J$135/100)+(H4*'Fuel Composition'!$J$64/100)+(I4*('Loading Loss'!H9/('Loading Loss'!H9+'Loading Loss'!H10))) -> 42.545304 | C11: =(C4*'Fuel Composition'!$J$33/100)+(E4*'Fuel Composition'!$J$88/100)+(F4*'Fuel Composition'!$J$111/100) -> 8.1736935e-05 | D11: =G4*'Fuel Composition'!$J$137/100 -> 0.059937725 | E11: =D4*'Fuel Composition'!$J$12/100 -> 0.0729162 | F11: =(D4*'Fuel Composition'!$J$10/100)+(C4*'Fuel Composition'!$J$35/100)+(E4*'Fuel Composition'!$J$89/100)+(F4*'Fuel Composition'!$J$112/100)+(G4*'Fuel Composition'!$J$136/100)+(H4*'Fuel Composition'!$J$74/100) -> 2.123932 | G11: =J4*('Loading Loss'!H10/('Loading Loss'!H10+'Loading Loss'!H9)) -> 0.01690141 | H11: =(D4*'Fuel Composition'!$J$7/100)+(C4*'Fuel Composition'!$J$36/100)+(E4*'Fuel Composition'!$J$90/100)+(F4*'Fuel Composition'!$J$113/100)+(H4*'Fuel Composition'!$J$66/100) -> 83.219225 | I11: =J4*('Loading Loss'!H9/('Loading Loss'!H9+'Loading Loss'!H10)) -> 15.867356 | J11: =(D4*'Fuel Composition'!$J$13/100)+(C4*'Fuel Composition'!$J$37/100)+(E4*'Fuel Composition'!$J$91/100)+(F4*'Fuel Composition'!$J$114/100)+(G4*'Fuel Composition'!$J$138/100) -> 0.01027791 | K11: =(C4*'Fuel Composition'!$J$39/100)+(E4*'Fuel Composition'!$J$92/100)+(F4*'Fuel Composition'!$J$115/100) -> 0.0019557916 | L11: =(D4*'Fuel Composition'!$J$8/100)+(C4*'Fuel Composition'!$J$40/100)+(E4*'Fuel Composition'!$J$93/100)+(F4*'Fuel Composition'!$J$117/100)+(G4*'Fuel Composition'!$J$139/100)+(H4*'Fuel Composition'!$J$68/100)+(I4*('Loading Loss'!H8/('Loading Loss'!H8+'Loading Loss'!H7))) -> 27.541082 | M11: =D4*'Fuel Composition'!$J$11/100 -> 4.86108 | N11: =F4*'Fuel Composition'!$J$116/100 -> 0.00039767175 | O11: =(C4*'Fuel Composition'!$J$42/100)+(D4*'Fuel Composition'!$J$9/100)+(E4*'Fuel Composition'!$J$94/100)+(F4*'Fuel Composition'!$J$118/100)+(G4*'Fuel Composition'!$J$140/100)+(H4*'Fuel Composition'!$J$69/100) -> 6.6396791 | P11: =SUM(B11:O11) -> 182.96013
A12: Barges | B12: =(C5*'Fuel Composition'!$J$32/100)+(D5*'Fuel Composition'!$J$6/100)+(E5*'Fuel Composition'!$J$87/100)+(F5*'Fuel Composition'!$J$110/100)+(G5*'Fuel Composition'!$J$135/100)+(H5*'Fuel Composition'!$J$64/100)+(I5*('Loading Loss'!H10/('Loading Loss'!H10+'Loading Loss'!H11))) -> 97.61163 | C12: =(C5*'Fuel Composition'!$J$33/100)+(E5*'Fuel Composition'!$J$88/100)+(F5*'Fuel Composition'!$J$111/100) -> 6.2778562e-05 | D12: =G5*'Fuel Composition'!$J$137/100 -> 0.1498444 | E12: =D5*'Fuel Composition'!$J$12/100 -> 0.1377306 | F12: =(D5*'Fuel Composition'!$J$10/100)+(C5*'Fuel Composition'!$J$35/100)+(E5*'Fuel Composition'!$J$89/100)+(F5*'Fuel Composition'!$J$112/100)+(G5*'Fuel Composition'!$J$136/100)+(H5*'Fuel Composition'!$J$74/100) -> 4.5317393 | G12: =J5*('Loading Loss'!I10/('Loading Loss'!I10+'Loading Loss'!I9)) -> 0.04225409 | H12: =(D5*'Fuel Composition'!$J$7/100)+(C5*'Fuel Composition'!$J$36/100)+(E5*'Fuel Composition'!$J$90/100)+(F5*'Fuel Composition'!$J$113/100)+(H5*'Fuel Composition'!$J$66/100) -> 196.81888 | I12: =J5*('Loading Loss'!I9/('Loading Loss'!I10+'Loading Loss'!I9)) -> 39.66839 | J12: =(D5*'Fuel Composition'!$J$13/100)+(C5*'Fuel Composition'!$J$37/100)+(E5*'Fuel Composition'!$J$91/100)+(F5*'Fuel Composition'!$J$114/100)+(G5*'Fuel Composition'!$J$138/100) -> 0.017642499 | K12: =(C5*'Fuel Composition'!$J$39/100)+(E5*'Fuel Composition'!$J$92/100)+(F5*'Fuel Composition'!$J$115/100) -> 0.00062870557 | L12: =(D5*'Fuel Composition'!$J$8/100)+(C5*'Fuel Composition'!$J$40/100)+(E5*'Fuel Composition'!$J$93/100)+(F5*'Fuel Composition'!$J$117/100)+(G5*'Fuel Composition'!$J$139/100)+(H5*'Fuel Composition'!$J$68/100)+(I5*('Loading Loss'!I8/('Loading Loss'!I8+'Loading Loss'!I7))) -> 57.587315 | M12: =D5*'Fuel Composition'!$J$11/100 -> 9.18204 | N12: =F5*'Fuel Composition'!$J$116/100 -> 0.000994179 | O12: =(C5*'Fuel Composition'!$J$42/100)+(D5*'Fuel Composition'!$J$9/100)+(E5*'Fuel Composition'!$J$94/100)+(F5*'Fuel Composition'!$J$118/100)+(G5*'Fuel Composition'!$J$140/100)+('5000000MP '!H5*'Fuel Composition'!$J$69/100) -> 13.188061 | P12: =SUM(B12:O12) -> 418.93721
A13: Model Plant | B13: =AVERAGE(B11:B12) -> 70.078467 | C13: =AVERAGE(C11:C12) -> 7.2257748e-05 | D13: =AVERAGE(D11:D12) -> 0.10489106 | E13: =AVERAGE(E11:E12) -> 0.1053234 | F13: =AVERAGE(F11:F12) -> 3.3278357 | G13: =AVERAGE(G11:G12) -> 0.02957775 | H13: =AVERAGE(H11:H12) -> 140.01905 | I13: =AVERAGE(I11:I12) -> 27.767873 | ... O13: =AVERAGE(O11:O12) -> 9.9138703 | P13: =SUM(B13:O13) -> 300.94867
A15: Average CE | B15: 0.97
A16: VOC Credit ($/ton) | B16: 672
A18: Hours Loading | B18: Vessels Loading Simultaneously | C18: Hours Loading Per Vessel | D18: Hours Loading >1.5 psia | E18: Vessels Loading Simultaneously | F18: Hours Loading Per Vessel >1.5 psia
A19: =K3*1000/42/5000 -> 23809.524 | B19: =A19/8760 -> 2.7179822 | C19: =2.62/3*8760 -> 7650.4 | D19: =SUM(C3,D3,H3,(0.5*J3),(0.5*I3))*1000/42/5000 -> 12097.619 | E19: =D19/8760 -> 1.3810067 | F19: =1.33/2*8760 -> 5825.4
C20: Total Hours Operating (1.1 factor of safety + 100 startup hours)
C21: =C19*1.1+100 -> 8515.44 | F21: =F19*1.1+100 -> 6507.94
A24: lb VOC emitted /hr | B24: lb VOC/hr | D24: VOC Reduced (TPY)
A25: (based on gasoline) | B25: (assumes 2 loading simultaneously)
A26: =D6*2000/(D3*1000/42/5000) -> 546 | B26: =A26*2 -> 1092 | D26: =B15*SUM(C6,D6,H6,(0.74*I6),J6) -> 4221.9149
B28: Carbon Adsorber | M28: Thermal Oxidizer
B29: Costs (2023 dollars) | H29: HAP Emission Reductions (tpy) | I29: HAP Cost Effectiveness ($/ton) | J29: Incremental HAP Cost Effectiveness ($/ton) | M29: Costs (2023 dollars) | Q29: HAP Emission Reductions (tpy) | R29: HAP Cost Effectiveness ($/ton) | S29: Incremental HAP Cost Effectiveness ($/ton)
B30: Capital Costs | C30: Annual Operating Costs | D30: Annual Capital Recovery | E30: Total Annual Costs | F30: Solvent Recovery Credit | G30: Total Annual Costs with Credits | M30: Capital Costs | N30: Annual Operating Costs | O30: Annual Capital Recovery | P30: Total Annual Costs
A31: Typical MTVLO Facility | L31: Typical MTVLO Facility
A32: 6525 hrs (1.5 psia) | B32: =3686375*2 -> 7372750 | C32: =731920*2 -> 1463840 | D32: =E43*(B32-((1.08*E45*E46)+(E47*E46/E48))) -> 791591.56 | E32: =C32+D32 -> 2255431.6 | F32: =VOC_Credit*Average_CE*SUM(C6,D6,H6,(0.74*I6),J6) -> 2837126.8 | G32: =C32+D32-F32 -> -581695.23 | H32: =($P$13*Average_CE*SUM(C7,D7,H7,(0.74*I7),J7)) -> 290.75305 | I32: =G32/H32 -> -2000.6505 | L32: 6525 hrs (1.5 psia) | M32: =447809*2 -> 895618 | N32: =1374664*2 -> 2749328 | O32: =M32*O43 -> 101462.09 | P32: =N32+O32 -> 2850790.1 | Q32: =H32 -> 290.75305 | R32: =(N32+O32)/Q32 -> 9804.8501
A33: 8525 hrs (no exemption) | B33: =3686375*3 -> 11059125 | C33: =880626*3 -> 2641878 | D33: =E43*(B33-((1.08*E45*E46)+(E47*E46/E48))) -> 1209210.8 | E33: =C33+D33 -> 3851088.8 | F33: =K6*VOC_Credit*Average_CE -> 2848515.8 | G33: =C33+D33-F33 -> 1002573 | H33: =$P$13*Average_CE -> 291.92021 | I33: =G33/H33 -> 3434.4078 | J33: =(G33-G32)/(H33-H32) -> 1357372.1 | L33: 8525 hrs (no exemption) | M33: =447809*3 -> 1343427 | N33: =1788447*3 -> 5365341 | O33: =M33*O43 -> 152193.13 | P33: =N33+O33 -> 5517534.1 | Q33: =H33 -> 291.92021 | R33: =(N33+O33)/Q33 -> 18900.83 | S33: =(N33+O33-N32-O32)/(Q33-Q32) -> 2284817.6
A36: Assumptions:
A37: 1. Loading Rate = 5000 bbl/hr
A38: 2. Ships and Barges are loaded equally
A39: 3. Up to 2 vessels can be loaded at once
A40: 4. Costs assume two control systems are required
D42: = CRFAdsorber × (TCI - [(1.08 x CC x Mc) + (LR x Mc/CRR)] = | N42: =CRF x TCI
D43: CRF = | E43: =(E49*(1+E49)^15)/(((1+E49)^15)-1) -> 0.11328724 | F43: Capital Recovery Factor for adsorber vessels and auxiliary equipment | N43: CRF = | O43: =(O45*(1+O45)^15)/(((1+O45)^15)-1) -> 0.11328724
D44: TCI = | E44: =B32 -> 7372750 | F44: Total Capital Investment | N44: TCI = | O44: =M32 -> 895618
D45: CC = | E45: 5.56 | F45: Carbon Cost | N45: Interest Rate | O45: 0.075
D46: Mc = | E46: 62932 | F46: Carbon Consumption
D47: LR = | E47: 44.46 | F47: Labor Rate
D48: CRR = | E48: 379 | F48: (lb/hr) Carbon Replacement Rate
D49: Interest Rate | E49: 0.075

Sheet Loading Loss
A1: Commodities | B1: Saturation Factor (S) | C1: Saturation Factor (S) | D1: True Vapor Pressure (P) | E1: Molecular Weight | F1: Temperature | G1: Density | H1: Loading Loss (ships) | I1: Loading Loss (Barges) | L1: Reid Vapor Pressure | M1: Loading Loss (ships) | N1: Loading Loss (Barges) | O1: Average Loading Loss
B2: ships | C2: barges | D2: psia | E2: lb/lb-mole | F2: °R | G2: lb/gal | H2: lb/1000 gal | I2: lb/1000 gal | L2: psia | M2: lb/hr | N2: lb/hr | O2: lb/hr
A3: Naptha and Solvents | B3: 0.2 | C3: 0.5 | D3: 10.2 | E3: 128.1705 | F3: 527.67 | G3: 5.55 | H3: 6.1741032 | I3: 15.435258 | L3: 13 | M3: 735.01229 | N3: 1837.5307 | O3: =AVERAGE(M3:N3) -> 1286.2715
A4: Kerosene | B4: 0.2 | C4: 0.5 | D4: 0.1 | E4: 162 | F4: 527.67 | G4: 6.82 | H4: 0.00612055 | I4: 0.01530138 | L4: 9 | M4: 0.72863722 | N4: 1.821593 | O4: =AVERAGE(M4:N4) -> 1.2751151
A5: Distillate Oil No. 2 | B5: 0.2 | C5: 0.5 | D5: 0.006 | E5: 188 | F5: 527.67 | G5: 7 | H5: 0.00532715 | I5: 0.01331787 | L5: 0.1 | M5: 0.63418424 | N5: 1.5854606 | O5: =AVERAGE(M5:N5) -> 1.1098224
A6: Residual Oil No. 6 | B6: 0.2 | C6: 0.5 | D6: 0.002 | E6: 387 | F6: 527.67 | G6: 8.3 | H6: 0.00365533 | I6: 0.00913833 | L6: 0.1 | M6: 0.43515834 | N6: 1.0878958 | O6: =AVERAGE(M6:N6) -> 0.76152709
A7: Benzene | B7: 0.2 | C7: 0.5 | D7: 1.86 | E7: 78.112 | F7: 527.67 | G7: 7.29 | H7: 0.68614568 | I7: 1.7153642 | J7: =I7/(I7+I8) -> 0.74104761 | L7: 1.4 | M7: 81.68401 | N7: 204.21003 | O7: =AVERAGE(M7:N7) -> 142.94702 | R7: 0.941215 | S7: 2.353037 | T7: =AVERAGE(R7:S7) -> 1.647126
A8: Toluene | B8: 0.2 | C8: 0.5 | D8: 0.551 | E8: 92.141 | F8: 527.67 | G8: 7.2 | H8: 0.23976741 | I8: 0.59941853 | L8: 1.1 | M8: 28.54374 | N8: 71.359349 | O8: =AVERAGE(M8:N8) -> 49.951544 | R8: 0.33301 | S8: 0.832526 | T8: =AVERAGE(R8:S8) -> 0.582768
A9: Methanol | B9: 0.2 | C9: 0.5 | D9: 1.856 | E9: 32.04 | F9: 527.67 | G9: 6.6 | H9: 0.28083816 | I9: 0.70209539 | J9: =I9/(I9+I10) -> 0.99893595 | L9: 1.8 | M9: 33.433114 | N9: 83.582785 | O9: =AVERAGE(M9:N9) -> 58.507949 | R9: 0.425512 | S9: 1.063781 | T9: =AVERAGE(R9:S9) -> 0.7446465
A10: Ethylene glycol | B10: 0.2 | C10: 0.5 | D10: 0.00102 | E10: 62.1 | F10: 527.67 | G10: 9.15 | H10: 0.00029914 | I10: 0.00074786 | L10: 0.01 | M10: 0.03561214 | N10: 0.08903036 | O10: =AVERAGE(M10:N10) -> 0.06232125 | R10: 0.000327 | S10: 0.000817 | T10: =AVERAGE(R10:S10) -> 0.000572
M13: *assume 5000 bbl/hr
B14: True Vapor Pressure (P) | C14: Molecular Weight | D14: Temperature | E14: Vapor Growth Factor | F14: CG | G14: Density | H14: Arrival Emission Factor (uncleaned) | I14: Arrival Emisson Factor (ballasted) | J14: Arrival Emisson Factor (cleaned or gas-freed)
B15: psia | C15: lb/lb-mole | D15: °R | G15: lb/gal | H15: lb/1000 gal | I15: lb/1000 gal | J15: lb/1000 gal
A16: Crude Oil (RVP5) | B16: 3.36 | C16: 60 | D16: 527.67 | E16: 1.02 | F16: =1.84*(0.44*B16-0.42)*C16*E16/D16 -> 0.22586902 | G16: 7.21 | H16: 0.86 | I16: 0.46 | J16: 0.33
H17: Loading Loss (uncleaned) | I17: Loading Loss (Ballasted) | J17: Loading Loss (cleaned or gas-freed) | M17: Loading Loss (uncleaned) | N17: Loading Loss (Ballasted) | O17: Loading Loss (cleaned or gas-freed)
H18: lb/1000 gal | I18: lb/1000 gal | J18: lb/1000 gal | M18: lb/hr | N18: lb/hr | O18: lb/hr
H19: =H16+$F16 -> 1.085869 | I19: =I16+$F16 -> 0.68586902 | J19: =J16+$F16 -> 0.55586902 | L19: 5 | M19: 287.77633 | N19: 240.15728 | O19: 224.68109
G20: Total VOC lossed (assuming 15% is methane and ethane): | H20: =0.85*H19 -> 0.92298867
B22: Loading Loss (ships) | C22: Loading Loss (Barges) | D22: Density | M22: Loading Loss (ships) | N22: Loading Loss (Barges)
B23: lb/1000 gal | C23: lb/1000 gal | D23: lb/gal | M23: lb/hr | N23: lb/hr
A24: Gasoline | B24: 1.8 | C24: 3.4 | D24: 6.26 | L24: 6 | M24: 214.28571 | N24: 404.76191 | O24: =AVERAGE(M24:N24) -> 309.52381

Sheet Fuel Composition
A2: API PERF data - Reformulated Gasoline (added Ethanol)
D3: wt%/wt frac liq | E3: n liq | F3: x | H3: y | J3: wt frac vapor | O3: Antoine Eqn coefficients
B4: MW | C4: VP, pure component, psia | D4: Gasoline, Liquid, wt% | E4: Gasoline, Liquid, moles | F4: Gasoline, Liquid, mole frac | G4: Gasoline, Partial Pressure, Pi, psia | H4: Gasoline, Vapor, mole frac | I4: Avg MW vapor = y(i)*MW(i) | J4: Gasoline, Vapor, wt% | L4: T = | M4: 68 | N4: F | O4: A | P4: B | Q4: C | T4: Ships | U4: Barges
M5: 20 | N5: C | T5: ppm | U5: ppm
A6: Benzene | B6: 78.11 | C6: 1.454 | D6: 1.61 | E6: 0.000206 | F6: 0.0173 | G6: 0.0252 | H6: 0.00672 | I6: 0.525 | J6: 0.8 | O6: 6.90565 | P6: 1211.033 | Q6: 220.79 | T6: 2.29 | U6: 4.33 | V6: =AVERAGE(T6:U6) -> 3.31
A7: Hexane | B7: 86.18 | C7: 2.347 | D7: 1 | E7: 0.000116 | F7: 0.00976 | G7: 0.0229 | H7: 0.00611 | I7: 0.527 | J7: 0.8 | O7: 6.87601 | P7: 1171.17 | Q7: 224.41 | T7: 2.3 | U7: 4.34 | V7: =AVERAGE(T7:U7) -> 3.32
A8: Toluene | B8: 92.14 | C8: 0.422 | D8: 7.2 | E8: 0.000783 | F8: 0.0658 | G8: 0.0278 | H8: 0.00742 | I8: 0.684 | J8: 1.04 | O8: 6.95464 | P8: 1344.8 | Q8: 219.48 | T8: 2.98 | U8: 5.63 | V8: =AVERAGE(T8:U8) -> 4.305
A9: Xylene | B9: 106.14 | C9: 0.126 | D9: 7.17 | E9: 0.000676 | F9: 0.0568 | G9: 0.00716 | H9: 0.00191 | I9: 0.203 | J9: 0.31 | O9: 6.99052 | P9: 1453.43 | Q9: 215.31 | T9: 0.88 | U9: 1.67 | V9: =AVERAGE(T9:U9) -> 1.275
A10: Ethylbenzene | B10: 106.17 | C10: 0.137 | D10: 1.605 | E10: 0.000151 | F10: 0.0127 | G10: 0.00174 | H10: 0.000465 | I10: 0.0493 | J10: 0.07 | O10: 6.95719 | P10: 1424.255 | Q10: 213.21 | T10: 0.22 | U10: 0.41 | V10: =AVERAGE(T10:U10) -> 0.315
A11: 2,2,4-Trimethylpentane (isooctane) | B11: 114.23 | C11: 0.747 | D11: 1.098 | E11: 9.61e-05 | F11: 0.00808 | G11: 0.00604 | H11: 0.00161 | I11: 0.184 | J11: 0.28 | O11: 6.81189 | P11: 1257.84 | Q11: 220.74 | T11: 0.8 | U11: 1.52 | V11: =AVERAGE(T11:U11) -> 1.16
A12: Cumene | B12: 120.19 | C12: 0.065 | D12: 0.19 | E12: 1.58e-05 | F12: 0.00133 | G12: 8.58e-05 | H12: 2.29e-05 | I12: 0.00275 | J12: 0.0042 | O12: 6.93666 | P12: 1460.793 | Q12: 207.78 | T12: 0.01 | U12: 0.02 | V12: =AVERAGE(T12:U12) -> 0.015
A13: Naphthalene | B13: 128.17 | C13: 0.003 | D13: 0.444 | E13: 3.46e-05 | F13: 0.00291 | G13: 1.02e-05 | H13: 2.72e-06 | I13: 0.000348 | J13: 0.0005 | O13: 7.37 | P13: 1968.36 | Q13: 222.61 | T13: 0 | U13: 0 | V13: =AVERAGE(T13:U13) -> 0
A14: Ethanol | B14: 46.07 | C14: 0.897 | D14: 8 | E14: 0.00174 | F14: 0.146 | G14: 0.131 | H14: 0.035 | I14: 1.61 | J14: 2.4442 | O14: 8.2109 | P14: 1718.1 | Q14: 237.52 | T14: 7.03 | U14: 13.28 | V14: =AVERAGE(T14:U14) -> 10.155
A15: n-Butane | B15: 58.12 | C15: 30.076 | D15: 4.7 | E15: 0.000809 | F15: 0.068 | G15: 2.05 | H15: 0.546 | I15: 31.7 | J15: 48.16 | O15: 6.80896 | P15: 935.86 | Q15: 238.73 | T15: 138.49 | U15: 261.59 | V15: =AVERAGE(T15:U15) -> 200.04
A16: Isobutane | B16: 58.12 | C16: 11.103 | D16: 1.7 | E16: 0.000292 | F16: 0.0246 | G16: 0.273 | H16: 0.0729 | I16: 4.24 | J16: 6.43 | O16: 6.83315 | P16: 1040.73 | Q16: 235.45 | T16: 18.49 | U16: 34.93 | V16: =AVERAGE(T16:U16) -> 26.71
A17: Pentane | B17: 72.15 | C17: 8.524 | D17: 3.9 | E17: 0.000541 | F17: 0.0455 | G17: 0.387 | H17: 0.103 | I17: 7.46 | J17: 11.33 | O17: 6.85296 | P17: 1064.84 | Q17: 233.01 | T17: 32.57 | U17: 61.52 | V17: =AVERAGE(T17:U17) -> 47.045
... A23: Other VOC (assume Heptane is the surrogate for Other VOC) | B23: 100.2 | C23: 0.685 | D23: 25.68 | E23: 0.00256 | F23: 0.216 | G23: 0.148 | H23: 0.0394 | I23: 3.95 | J23: 5.99 | O23: 6.89677 | P23: 1264.9 | Q23: 216.54 | T23: 17.23 | U23: 32.55 | V23: =AVERAGE(T23:U23) -> 24.89
D25: 100 | E25: 0.01189096 | F25: 1 | G25: 3.75 | H25: 1 | I25: 65.88 | J25: 100
D26: 20.33 | G26: Total VP of mixture
D27: wt%HAP in liq | H27: 1 | J27: 3.3 | K27: HAP only %
B30: MW | C30: VP, pure component, psia | D30: Crude Oil, Liquid, wt% | E30: Crude Oil, Liquid, moles | F30: Crude Oil, Liquid, mole frac | G30: Crude Oil, Partial Pressure, Pi, psia | H30: Crude Oil, Vapor, mole frac | I30: Avg MW vapor = y(i)*MW(i) | J30: Crude Oil, Vapor, wt% | L30: T = | M30: 68 | N30: F | O30: A | P30: B | Q30: C | T30: Uncleaned | U30: Ballasted | V30: Cleaned or gas-freed
M31: 20 | N31: C | T31: ppm | U31: ppm | V31: ppm
A32: Benzene | B32: 78.11 | C32: 1.454 | D32: 0.446 | E32: 5.7099e-05 | F32: 0.00548 | G32: 0.00797 | H32: 0.00303 | I32: 0.237 | J32: 0.33 | O32: 6.90565 | P32: 1211.033 | Q32: 220.79 | T32: 1.0917148 | U32: 0.9110661 | V32: 0.852355
A33: Biphenyl | B33: 154.21 | C33: 0 | D33: 0.6 | E33: 3.89085e-05 | F33: 0.00373 | G33: 1.35e-06 | H33: 5.14e-07 | I33: 7.92e-05 | J33: 0.0001 | O33: 7.2454 | P33: 1998.72 | Q33: 202.74 | T33: 0.0003654 | U33: 0.0003049 | V33: 0.000285
A34: Cyclohexane | B34: 84.16 | C34: 1.499 | D34: 0.7 | E34: 8.31729e-05 | F34: 0.00798 | G34: 0.012 | H34: 0.00455 | I34: 0.383 | J34: 0.53 | O34: 6.8413 | P34: 1201.531 | Q34: 222.647 | T34: 1.7667404 | U34: 1.4743936 | V34: 1.379381
A35: Ethylbenzene | B35: 106.17 | C35: 0.137 | D35: 0.346 | E35: 3.25892e-05 | F35: 0.00313 | G35: 0.000428 | H35: 0.000163 | I35: 0.0173 | J35: 0.02 | O35: 6.95719 | P35: 1424.255 | Q35: 213.21 | T35: 0.0797312 | U35: 0.0665378 | V35: 0.06225
A36: n-Hexane | B36: 86.18 | C36: 2.347 | D36: 2.463 | E36: 0.000285797 | F36: 0.0274 | G36: 0.0644 | H36: 0.0245 | I36: 2.11 | J36: 2.9 | O36: 6.87601 | P36: 1171.17 | Q36: 224.41 | T36: 9.7317114 | U36: 8.1213815 | V36: 7.598024
A37: Naphthalene | B37: 128.17 | C37: 0.003 | D37: 0.219 | E37: 1.70867e-05 | F37: 0.00164 | G37: 5.72e-06 | H37: 2.18e-06 | I37: 0.000279 | J37: 0.0004 | O37: 7.37 | P37: 1968.36 | Q37: 222.61 | T37: 0.0012874 | U37: 0.0010744 | V37: 0.001005
A38: PAC (Thiophene used as surrogate) | B38: 84.14 | C38: 1.21 | D38: 0.0004 | E38: 4.75398e-08 | F38: 4.56e-06 | G38: 5.52e-06 | H38: 2.1e-06 | I38: 0.000177 | J38: 0.0002 | O38: 6.95926 | P38: 1246.02 | Q38: 221.35 | T38: 0.000815 | U38: 0.0006801 | V38: 0.000636
A39: Phenol | B39: 94.11 | C39: 0.004 | D39: 0.323 | E39: 3.43211e-05 | F39: 0.00329 | G39: 1.4e-05 | H39: 5.33e-06 | I39: 0.000502 | J39: 0.001 | O39: 7.1345 | P39: 1516.07 | Q39: 174.57 | T39: 0.0023139 | U39: 0.001931 | V39: 0.001807
A40: Toluene | B40: 92.14 | C40: 0.422 | D40: 0.878 | E40: 9.52898e-05 | F40: 0.00914 | G40: 0.00386 | H40: 0.00147 | I40: 0.135 | J40: 0.19 | O40: 6.95464 | P40: 1344.8 | Q40: 219.48 | T40: 0.6239852 | U40: 0.5207329 | V40: 0.487176
A41: 1,2,4-Trimethylbenzene | B41: 120.19 | C41: 0.028 | D41: 0.326 | E41: 2.71237e-05 | F41: 0.0026 | G41: 7.28e-05 | H41: 2.77e-05 | I41: 0.00333 | J41: 0.005 | O41: 7.04383 | P41: 1573.267 | Q41: 208.564 | T41: 0.0153575 | U41: 0.0128163 | V41: 0.01199
A42: Xylene | B42: 106.14 | C42: 0.126 | D42: 1.42 | E42: 0.000133786 | F42: 0.0128 | G42: 0.00162 | H42: 0.000615 | I42: 0.0653 | J42: 0.09 | O42: 6.99052 | P42: 1453.43 | Q42: 215.31 | T42: 0.3010841 | U42: 0.251263 | V42: 0.235071
A43: n-Butane | B43: 58.12 | C43: 30.076 | D43: 2.5 | E43: 0.000430145 | F43: 0.0413 | G43: 1.24 | H43: 0.472 | I43: 27.4 | J43: 37.75 | O43: 6.80896 | P43: 935.86 | Q43: 238.73 | T43: 126.564 | U43: 105.62115 | V43: 98.81472
... A46: Other VOC/Heptane Plus (assume Heptane is the surrogate for Other VOC) | B46: 100.2 | C46: 0.685 | D46: 80.7786 | E46: 0.008061737 | F46: 0.773 | G46: 0.53 | H46: 0.202 | I46: 20.2 | J46: 27.78 | O46: 6.89677 | P46: 1264.9 | Q46: 216.54 | T46: 93.13146 | U46: 77.720771 | V46: 72.7123
D48: 100 | E48: 0.01 | F48: 1 | G48: 2.63 | H48: 1 | I48: 72.7 | J48: 100
G50: 0.0782 | J50: 3.53 | K50: HAP only %
C51: Crude Oil True Vapor Pressure:
C52: 5.762
A54: EPCRA Section 313 Industry Guidance for Petroleum Terminals and Bulk Storage Facilities | O54: Antoine coefficient table | PDF
...

Sheet 50000MP
A1: 50,000 Model Plant
C2: Crude Petroleum | D2: Gasoline | E2: Kerosene | F2: Distillate Fuel Oil | G2: Residual Fuel Oil | H2: Naphtha & Solvents | I2: Benzene & Toluene | J2: Alcohols | K2: Total | M2: Hours Loading
A3: Gallons Loaded (1000 gal/yr) | C3: 4120.2338 | D3: 10338.9 | E3: 200.4071 | F3: 12521.45 | G3: 12212.37 | H3: 458.3607 | I3: 940.1768 | J3: 7641.983 | K3: 48433.883 | M3: =K3*1000/42/5000 -> 230.63754
A4: Loading Loss (TPY) | B4: Ships | C4: =C3*'Loading Loss'!H20/2000 -> 1.9014645 | D4: =D3*'Loading Loss'!B24/2000 -> 9.30501 | E4: =E3*'Loading Loss'!H4/2000 -> 0.00061330084 | F4: =F3*'Loading Loss'!H5/2000 -> 0.033351821 | G4: =G3*'Loading Loss'!H6/2000 -> 0.022320121 | H4: =H3*'Loading Loss'!H3/2000 -> 1.4149831 | I4: =I3*(AVERAGE('Loading Loss'!H7:H8))/2000 -> 0.2176305 | J4: =J3*(AVERAGE('Loading Loss'!H9:H10))/2000 -> 0.53711162 | K4: =SUM(C4:J4) -> 13.432485
B5: Barges | C5: =C3*'Loading Loss'!H20/2000 -> 1.9014645 | D5: =D3*'Loading Loss'!C24/2000 -> 17.57613 | E5: ='Loading Loss'!I4*'50000MP'!E3/2000 -> 0.0015332526 | F5: =F3*'Loading Loss'!I5/2000 -> 0.083379522 | G5: =G3*'Loading Loss'!I6/2000 -> 0.055800334 | H5: =H3*'Loading Loss'!I3/2000 -> 3.5374578 | I5: =I3*(AVERAGE('Loading Loss'!I7:I8))/2000 -> 0.54407626 | J5: =J3*(AVERAGE('Loading Loss'!I9:I10))/2000 -> 1.342779 | K5: =SUM(C5:J5) -> 25.042621 | M5: lb VOC emitted /hr
B6: Model Plant | C6: =AVERAGE(C4:C5) -> 1.9014645 | D6: =AVERAGE(D4:D5) -> 13.44057 | E6: =AVERAGE(E4:E5) -> 0.0010732767 | F6: =AVERAGE(F4:F5) -> 0.058365671 | G6: =AVERAGE(G4:G5) -> 0.039060227 | H6: =AVERAGE(H4:H5) -> 2.4762205 | I6: =AVERAGE(I4:I5) -> 0.38085338 | J6: =AVERAGE(J4:J5) -> 0.93994533 | K6: =SUM(C6:J6) -> 19.237553 | M6: =K6*2000/2400 -> 16.031294
A7: Percent of Total Loading Loss | C7: =C6/$K$6 -> 0.09884129 | D7: =D6/$K$6 -> 0.69866319 | E7: =E6/$K$6 -> 5.5790709e-05 | F7: =F6/$K$6 -> 0.0030339447 | G7: =G6/$K$6 -> 0.0020304156 | H7: =H6/$K$6 -> 0.12871806 | I7: =I6/$K$6 -> 0.019797392 | J7: =J6/$K$6 -> 0.048859922 | K7: =SUM(C7:J7) -> 1
A9: 50,000 Model Plant Emissions
B10: Benzene (TPY) | C10: Biphenyl (TPY) | D10: Chlorine (TPY) | E10: Cumene (TPY) | F10: Ethylbenzene (TPY) | G10: Ethylene Glycol (TPY) | H10: Hexane (TPY) | I10: Methanol (TPY) | J10: Napthalene (TPY) | K10: Phenol (TPY) | L10: Toluene (TPY) | M10: 2,2,4-Trimethyl-pentane (isooctane) (TPY) | N10: Styrene (TPY) | O10: Xylene (TPY) | P10: Total HAP (TPY)
A11: Ships | B11: =(C4*'Fuel Composition'!$J$32/100)+(D4*'Fuel Composition'!$J$6/100)+(E4*'Fuel Composition'!$J$87/100)+(F4*'Fuel Composition'!$J$110/100)+(G4*'Fuel Composition'!$J$135/100)+(H4*'Fuel Composition'!$J$64/100)+(I4*('Loading Loss'!H7/('Loading Loss'!H7+'Loading Loss'!H8))) -> 0.25459136 | C11: =(C4*'Fuel Composition'!$J$33/100)+(E4*'Fuel Composition'!$J$88/100)+(F4*'Fuel Composition'!$J$111/100) -> 1.9075976e-06 | D11: =G4*'Fuel Composition'!$J$137/100 -> 0.0038323648 | E11: =D4*'Fuel Composition'!$J$12/100 -> 0.00039081042 | F11: =(D4*'Fuel Composition'!$J$10/100)+(C4*'Fuel Composition'!$J$35/100)+(E4*'Fuel Composition'!$J$89/100)+(F4*'Fuel Composition'!$J$112/100)+(G4*'Fuel Composition'!$J$136/100)+(H4*'Fuel Composition'!$J$74/100) -> 0.0081727665 | G11: =J4*('Loading Loss'!H10/('Loading Loss'!H10+'Loading Loss'!H9)) -> 0.0005715057 | H11: =(D4*'Fuel Composition'!$J$7/100)+(C4*'Fuel Composition'!$J$36/100)+(E4*'Fuel Composition'!$J$90/100)+(F4*'Fuel Composition'!$J$113/100)+(H4*'Fuel Composition'!$J$66/100) -> 0.22927005 | I11: =J4*('Loading Loss'!H9/('Loading Loss'!H9+'Loading Loss'!H10)) -> 0.53654011 | J11: =(D4*'Fuel Composition'!$J$13/100)+(C4*'Fuel Composition'!$J$37/100)+(E4*'Fuel Composition'!$J$91/100)+(F4*'Fuel Composition'!$J$114/100)+(G4*'Fuel Composition'!$J$138/100) -> 5.7772741e-05 | K11: =(C4*'Fuel Composition'!$J$39/100)+(E4*'Fuel Composition'!$J$92/100)+(F4*'Fuel Composition'!$J$115/100) -> 1.9443956e-05 | L11: =(D4*'Fuel Composition'!$J$8/100)+(C4*'Fuel Composition'!$J$40/100)+(E4*'Fuel Composition'!$J$93/100)+(F4*'Fuel Composition'!$J$117/100)+(G4*'Fuel Composition'!$J$139/100)+(H4*'Fuel Composition'!$J$68/100)+(I4*('Loading Loss'!H8/('Loading Loss'!H8+'Loading Loss'!H7))) -> 0.16285877 | M11: =D4*'Fuel Composition'!$J$11/100 -> 0.026054028 | N11: =F4*'Fuel Composition'!$J$116/100 -> 3.3351821e-06 | O11: =(C4*'Fuel Composition'!$J$42/100)+(D4*'Fuel Composition'!$J$9/100)+(E4*'Fuel Composition'!$J$94/100)+(F4*'Fuel Composition'!$J$118/100)+(G4*'Fuel Composition'!$J$140/100)+(H4*'Fuel Composition'!$J$69/100) -> 0.032270808 | P11: =SUM(B11:O11) -> 1.254635
A12: Barges | B12: =(C5*'Fuel Composition'!$J$32/100)+(D5*'Fuel Composition'!$J$6/100)+(E5*'Fuel Composition'!$J$87/100)+(F5*'Fuel Composition'!$J$110/100)+(G5*'Fuel Composition'!$J$135/100)+(H5*'Fuel Composition'!$J$64/100)+(I5*('Loading Loss'!I7/('Loading Loss'!I7+'Loading Loss'!I8))) -> 0.58157499 | C12: =(C5*'Fuel Composition'!$J$33/100)+(E5*'Fuel Composition'!$J$88/100)+(F5*'Fuel Composition'!$J$111/100) -> 1.9167971e-06 | D12: =G5*'Fuel Composition'!$J$137/100 -> 0.0095809173 | E12: =D5*'Fuel Composition'!$J$12/100 -> 0.00073819746 | F12: =(D5*'Fuel Composition'!$J$10/100)+(C5*'Fuel Composition'!$J$35/100)+(E5*'Fuel Composition'!$J$89/100)+(F5*'Fuel Composition'!$J$112/100)+(G5*'Fuel Composition'!$J$136/100)+(H5*'Fuel Composition'!$J$74/100) -> 0.015881 | G12: =J5*('Loading Loss'!I10/('Loading Loss'!I10+'Loading Loss'!I9)) -> 0.0014287834 | H12: =(D5*'Fuel Composition'!$J$7/100)+(C5*'Fuel Composition'!$J$36/100)+(E5*'Fuel Composition'!$J$90/100)+(F5*'Fuel Composition'!$J$113/100)+(H5*'Fuel Composition'!$J$66/100) -> 0.44497024 | I12: =J5*('Loading Loss'!I9/('Loading Loss'!I9+'Loading Loss'!I10)) -> 1.3413503 | J12: =(D5*'Fuel Composition'!$J$13/100)+(C5*'Fuel Composition'!$J$37/100)+(E5*'Fuel Composition'!$J$91/100)+(F5*'Fuel Composition'!$J$114/100)+(G5*'Fuel Composition'!$J$138/100) -> 0.00010459109 | K12: =(C5*'Fuel Composition'!$J$39/100)+(E5*'Fuel Composition'!$J$92/100)+(F5*'Fuel Composition'!$J$115/100) -> 2.0087922e-05 | L12: =(D5*'Fuel Composition'!$J$8/100)+(C5*'Fuel Composition'!$J$40/100)+(E5*'Fuel Composition'!$J$93/100)+(F5*'Fuel Composition'!$J$117/100)+(G5*'Fuel Composition'!$J$139/100)+(H5*'Fuel Composition'!$J$68/100)+(I5*('Loading Loss'!I8/('Loading Loss'!I8+'Loading Loss'!I7))) -> 0.34258924 | M12: =D5*'Fuel Composition'!$J$11/100 -> 0.049213164 | N12: =F5*'Fuel Composition'!$J$116/100 -> 8.3379522e-06 | O12: =(C5*'Fuel Composition'!$J$42/100)+(D5*'Fuel Composition'!$J$9/100)+(E5*'Fuel Composition'!$J$94/100)+(F5*'Fuel Composition'!$J$118/100)+(G5*'Fuel Composition'!$J$140/100)+(H5*'Fuel Composition'!$J$69/100) -> 0.060482219 | P12: =SUM(B12:O12) -> 2.8479439
A13: Model Plant | B13: =AVERAGE(B11:B12) -> 0.41808318 | C13: =AVERAGE(C11:C12) -> 1.9121973e-06 | D13: =AVERAGE(D11:D12) -> 0.006706641 | E13: =AVERAGE(E11:E12) -> 0.00056450394 | F13: =AVERAGE(F11:F12) -> 0.012026883 | G13: =AVERAGE(G11:G12) -> 0.0010001445 | H13: =AVERAGE(H11:H12) -> 0.33712014 | I13: =AVERAGE(I11:I12) -> 0.93894518 | ... O13: =AVERAGE(O11:O12) -> 0.046376514 | P13: =SUM(B13:O13) -> 2.0512895
A15: Ships | B15: =(C4*'Fuel Composition'!$J$32/100)+(D4*'Fuel Composition'!$J$6/100)+(E4*'Fuel Composition'!$J$87/100)+(H4*'Fuel Composition'!$J$64/100)+(I4*('Loading Loss'!H7/('Loading Loss'!H7+'Loading Loss'!H8))) -> 0.25458356 | C15: =(C4*'Fuel Composition'!$J$33/100)+(E4*'Fuel Composition'!$J$88/100) -> 1.9075976e-06 | D15: 0 | E15: =D4*'Fuel Composition'!$J$12/100 -> 0.00039081042 | F15: =(D4*'Fuel Composition'!$J$10/100)+(C4*'Fuel Composition'!$J$35/100)+(E4*'Fuel Composition'!$J$89/100)+(H4*'Fuel Composition'!$J$74/100) -> 0.0081694313 | G15: 0 | H15: =(D4*'Fuel Composition'!$J$7/100)+(C4*'Fuel Composition'!$J$36/100)+(E4*'Fuel Composition'!$J$90/100)+(H4*'Fuel Composition'!$J$66/100) -> 0.22566138 | I15: 0 | J15: =(D4*'Fuel Composition'!$J$13/100)+(C4*'Fuel Composition'!$J$37/100)+(E4*'Fuel Composition'!$J$91/100) -> 5.4437559e-05 | K15: =(C4*'Fuel Composition'!$J$39/100)+(E4*'Fuel Composition'!$J$92/100)+(F4*'Fuel Composition'!$J$115/100) -> 1.9443956e-05 | L15: =(D8*'Fuel Composition'!$J$8/100)+(C8*'Fuel Composition'!$J$40/100)+(E8*'Fuel Composition'!$J$93/100)+(F8*'Fuel Composition'!$J$117/100)+(G8*'Fuel Composition'!$J$139/100)+(H8*'Fuel Composition'!$J$68/100)+(I8*('Loading Loss'!H12/('Loading Loss'!H12+'Loading Loss'!H11))) -> #DIV/0! | M15: =D8*'Fuel Composition'!$J$11/100 -> 0 | N15: =F8*'Fuel Composition'!$J$116/100 -> 0 | O15: =(C8*'Fuel Composition'!$J$42/100)+(D8*'Fuel Composition'!$J$9/100)+(E8*'Fuel Composition'!$J$94/100)+(F8*'Fuel Composition'!$J$118/100)+(G8*'Fuel Composition'!$J$140/100)+(H8*'Fuel Composition'!$J$69/100) -> 0 | P15: =SUM(B15:O15) -> #DIV/0!
A16: Barges | B16: =(C5*'Fuel Composition'!$J$32/100)+(D5*'Fuel Composition'!$J$6/100)+(E5*'Fuel Composition'!$J$87/100)+(H5*'Fuel Composition'!$J$64/100)+(I9*('Loading Loss'!I7/('Loading Loss'!I7+'Loading Loss'!I8))) -> 0.17836909 | C16: =(C5*'Fuel Composition'!$J$33/100)+(E5*'Fuel Composition'!$J$88/100) -> 1.9167971e-06 | D16: 0 | E16: =D5*'Fuel Composition'!$J$12/100 -> 0.00073819746 | F16: =(D5*'Fuel Composition'!$J$10/100)+(C5*'Fuel Composition'!$J$35/100)+(E5*'Fuel Composition'!$J$89/100)+(H5*'Fuel Composition'!$J$74/100) -> 0.015872662 | G16: 0 | H16: =(D5*'Fuel Composition'!$J$7/100)+(C5*'Fuel Composition'!$J$36/100)+(E5*'Fuel Composition'!$J$90/100)+(H5*'Fuel Composition'!$J$66/100) -> 0.43594858 | I16: 0 | J16: =(D5*'Fuel Composition'!$J$13/100)+(C5*'Fuel Composition'!$J$37/100)+(E5*'Fuel Composition'!$J$91/100) -> 9.6253134e-05 | K16: =(C5*'Fuel Composition'!$J$39/100)+(E5*'Fuel Composition'!$J$92/100)+(F5*'Fuel Composition'!$J$115/100) -> 2.0087922e-05 | L16: =(D9*'Fuel Composition'!$J$8/100)+(C9*'Fuel Composition'!$J$40/100)+(E9*'Fuel Composition'!$J$93/100)+(F9*'Fuel Composition'!$J$117/100)+(G9*'Fuel Composition'!$J$139/100)+(H9*'Fuel Composition'!$J$68/100)+(I9*('Loading Loss'!I12/('Loading Loss'!I12+'Loading Loss'!I11))) -> #DIV/0! | M16: =D9*'Fuel Composition'!$J$11/100 -> 0 | N16: =F9*'Fuel Composition'!$J$116/100 -> 0 | O16: =(C9*'Fuel Composition'!$J$42/100)+(D9*'Fuel Composition'!$J$9/100)+(E9*'Fuel Composition'!$J$94/100)+(F9*'Fuel Composition'!$J$118/100)+(G9*'Fuel Composition'!$J$140/100)+(H9*'Fuel Composition'!$J$69/100) -> 0 | P16: =SUM(B16:O16) -> #DIV/0!
A17: Model Plant | B17: =AVERAGE(B15:B16) -> 0.21647632 | C17: =AVERAGE(C15:C16) -> 1.9121973e-06 | D17: 0 | E17: =AVERAGE(E15:E16) -> 0.00056450394 | F17: =AVERAGE(F15:F16) -> 0.012021047 | G17: =AVERAGE(G15:G16) -> 0 | H17: =AVERAGE(H15:H16) -> 0.33080498 | I17: =AVERAGE(I15:I16) -> 0 | J17: =AVERAGE(J15:J16) -> 7.5345347e-05 | K17: =AVERAGE(K15:K16) -> 1.9765939e-05 | L17: =AVERAGE(L15:L16) -> #DIV/0! | ... O17: =AVERAGE(O15:O16) -> 0 | P17: =SUM(B17:O17) -> #DIV/0!
B24: Carbon Adsorber | I24: Recuperative Oxidizer
B25: Costs (2021 dollars) | F25: Cost Effectiveness ($/ton) | I25: Costs (2021 dollars) | L25: Cost Effectiveness ($/ton)
B26: Capital (TCI) | C26: Annual Costs | D26: Solvent Recovery Credit | E26: Total Annual Cost (TAC) | I26: Capital (TCI) | J26: Annual Costs | K26: Total Annual Cost (TAC)
A27: Typical MTVLO Facility | H27: Typical MTVLO Facility | P27: Average Loading Loss
A28: 240 hrs (no exemption) | B28: 2064594 | C28: =57779+268364 -> 326143 | D28: 30054 | E28: 296090 | F28: =E28/P13 -> 144343.35 | H28: 240 hrs (no exemption) | I28: 946003 | J28: =13347+117770 -> 131117 | K28: 131117 | L28: =K28/P13 -> 63919.306 | P28: lb/hr
A29: 72 hrs (1.5 psia) | B29: 2064594 | C29: =52246+267784 -> 320030 | D29: 9016 | E29: 311014 | H29: 72 hrs (1.5 psia) | I29: 946003 | J29: =4004+117232 -> 121236 | K29: 121236 | O29: Naptha and Solvents | P29: 1286.2715 | Q29: 0.11521589 | R29: =Q29*P29 -> 148.19891
A30: 78 hrs (1 or 0.5 psia) | B30: 2064594 | C30: =52444+267805 -> 320249 | D30: 9767 | E30: 310481 | H30: 78 hrs (1 or 0.5 psia) | I30: 946003 | J30: =4338+117251 -> 121589 | K30: 121589 | O30: Kerosene | P30: 1.2751151 | Q30: 4.9938416e-05 | R30: =Q30*P30 -> 6.3677229e-05
O31: Distillate Oil No. 2 | P31: 1.1098224 | Q31: 0.0027156922 | R31: =Q31*P31 -> 0.0030139361
A32: Assumptions: | O32: Residual Oil No. 6 | P32: 0.76152709 | Q32: 0.0018174305 | R32: =Q32*P32 -> 0.0013840226
A33: 1. Loading Rate = 5000 bbl/hr | O33: Benzene | P33: 142.94702 | Q33: =I7/2 -> 0.0098986961 | R33: =Q33*P33 -> 1.4149891
A34: 2. Ships and Barges are loaded equally | O34: Toluene | P34: 49.951544 | Q34: =Q33 -> 0.0098986961 | R34: =Q34*P34 -> 0.49445515
A35: 3. Up to 1 vessel can be loaded at once | O35: Methanol | P35: 58.507949 | Q35: =J7/2 -> 0.024429961 | R35: =Q35*P35 -> 1.4293469
O36: Ethylene glycol | P36: 0.06232125 | Q36: =Q35 -> 0.024429961 | R36: =Q36*P36 -> 0.0015225057
O37: Crude Oil | P37: 240.15728 | Q37: 0.19337038 | R37: =Q37*P37 -> 46.439305
O38: Gasoline | P38: 309.52381 | Q38: 0.62537532 | R38: =Q38*P38 -> 193.56855
Q39: =SUM(Q29:Q38) -> 1.007202 | R39: =SUM(R29:R38) -> 391.55154 | S39: VOC Emission Rate lb/hr

Sheet 25000000MP
A1: 25,000,000 Model Plant
C2: Crude Petroleum | D2: Gasoline | E2: Kerosene | F2: Distillate Fuel Oil | G2: Residual Fuel Oil | H2: Naphtha & Solvents | I2: Benzene & Toluene | J2: Alcohols | K2: Total | M2: Hours Loading
A3: Gallons Loaded (1000 gal/yr) | C3: 11575663 | D3: 4344659 | E3: 430616.7 | F3: 3936982 | G3: 663764.7 | H3: 1525854 | I3: 144434.7 | J3: 642589.7 | K3: =SUM(C3:J3) -> 23264564 | M3: =K3*1000/42/7500 -> 73855.759 | N3: =M3/8760 -> 8.4310227
A4: Loading Loss (TPY) | B4: Ships | C4: =C3*'Loading Loss'!H20/2000 -> 5342.103 | D4: =D3*'Loading Loss'!B24/2000 -> 3910.1931 | E4: =E3*'Loading Loss'!H4/2000 -> 1.3178055 | F4: =F3*'Loading Loss'!H5/2000 -> 10.486447 | G4: =G3*'Loading Loss'!H6/2000 -> 1.2131395 | H4: =H3*'Loading Loss'!H3/2000 -> 4710.39 | I4: =I3*(AVERAGE('Loading Loss'!H7:H8))/2000 -> 33.433495 | J4: =J3*(AVERAGE('Loading Loss'!H9:H10))/2000 -> 45.163983 | K4: =SUM(C4:J4) -> 14054.301
B5: Barges | C5: =C3*'Loading Loss'!H20/2000 -> 5342.103 | D5: =D3*'Loading Loss'!C24/2000 -> 7385.9203 | E5: ='Loading Loss'!I4*'25000000MP'!E3/2000 -> 3.2945149 | F5: =F3*'Loading Loss'!I5/2000 -> 26.216107 | G5: =G3*'Loading Loss'!I6/2000 -> 3.0328504 | H5: =H3*'Loading Loss'!I3/2000 -> 11775.975 | I5: =I3*(AVERAGE('Loading Loss'!I7:I8))/2000 -> 83.583738 | J5: =J3*(AVERAGE('Loading Loss'!I9:I10))/2000 -> 112.90996 | K5: =SUM(C5:J5) -> 24733.036 | M5: lb VOC emitted /hr
B6: Model Plant | C6: =AVERAGE(C4:C5) -> 5342.103 | D6: =AVERAGE(D4:D5) -> 5648.0567 | E6: =AVERAGE(E4:E5) -> 2.3061602 | F6: =AVERAGE(F4:F5) -> 18.351277 | G6: =AVERAGE(G4:G5) -> 2.122995 | H6: =AVERAGE(H4:H5) -> 8243.1826 | I6: =AVERAGE(I4:I5) -> 58.508616 | J6: =AVERAGE(J4:J5) -> 79.036971 | K6: =SUM(C6:J6) -> 19393.668 | M6: =K6*2000/8760 -> 4427.7782
A7: Percent of Total Loading Loss | C7: =C6/$K$6 -> 0.27545604 | D7: =D6/$K$6 -> 0.29123199 | E7: =E6/$K$6 -> 0.00011891305 | F7: =F6/$K$6 -> 0.00094625095 | G7: =G6/$K$6 -> 0.00010946846 | H7: =H6/$K$6 -> 0.42504504 | I7: =I6/$K$6 -> 0.0030168927 | J7: =J6/$K$6 -> 0.0040754008 | K7: =SUM(C7:J7) -> 1
A9: 25,000,000 Model Plant Emissions
B10: Benzene (TPY) | C10: Biphenyl (TPY) | D10: Chlorine (TPY) | E10: Cumene (TPY) | F10: Ethylbenzene (TPY) | G10: Ethylene Glycol (TPY) | H10: Hexane (TPY) | I10: Methanol (TPY) | J10: Napthalene (TPY) | K10: Phenol (TPY) | L10: Toluene (TPY) | M10: 2,2,4-Trimethyl-pentane (isooctane) (TPY) | N10: Styrene (TPY) | O10: Xylene (TPY) | P10: Total HAP (TPY)
