Workbook
Name degR_degF: [1]Truck_leaks!$K$5
Name psi_atm: [1]Truck_leaks!$K$4
Name R__ideal_gas_constant: [1]Truck_leaks!$K$6

Sheet Gasoline MP
A1: Loading Threshold (1000 gal/yr) | B1: Gasoline
B2: Loading Loss (TPY) | C2: Emissions | L2: Number of Facilities Greater than Threshold
C3: Benzene (TPY) | D3: Hexane (TPY) | E3: Toluene (TPY) | F3: Xylene (TPY) | G3: Ethylbenzene (TPY) | H3: 2,2,4-Trimethyl-pentane (isooctane) (TPY) | I3: Cumene (TPY) | J3: Naphthalene (TPY) | K3: Total HAP (TPY)
A4: Typical MTVLO Facility
A5: Barges
A6: 5000000 | B6: =A6*'Loading Loss'!$C$24/2000 -> 8500 | C6: =$B6*'Fuel Composition'!$J$6/100 -> 67.721706 | D6: =$B6*'Fuel Composition'!$J$7/100 -> 67.981745 | E6: =$B6*'Fuel Composition'!$J$8/100 -> 88.186679 | F6: =$B6*'Fuel Composition'!$J$9/100 -> 26.15689 | G6: =$B6*'Fuel Composition'!$J$10/100 -> 6.363477 | H6: =$B6*'Fuel Composition'!$J$11/100 -> 23.758003 | I6: =$B6*'Fuel Composition'!$J$12/100 -> 0.35517806 | J6: =$B6*'Fuel Composition'!$J$13/100 -> 0.044907852 | K6: =SUM(C6:J6) -> 280.56859 | L6: 2
A7: 1000000 | B7: =A7*'Loading Loss'!$C$24/2000 -> 1700 | C7: =$B7*'Fuel Composition'!$J$6/100 -> 13.544341 | D7: =$B7*'Fuel Composition'!$J$7/100 -> 13.596349 | E7: =$B7*'Fuel Composition'!$J$8/100 -> 17.637336 | F7: =$B7*'Fuel Composition'!$J$9/100 -> 5.2313779 | G7: =$B7*'Fuel Composition'!$J$10/100 -> 1.2726954 | H7: =$B7*'Fuel Composition'!$J$11/100 -> 4.7516007 | I7: =$B7*'Fuel Composition'!$J$12/100 -> 0.071035612 | J7: =$B7*'Fuel Composition'!$J$13/100 -> 0.0089815704 | K7: =SUM(C7:J7) -> 56.113717 | L7: 17
A8: 500000 | B8: =A8*'Loading Loss'!$C$24/2000 -> 850 | C8: =$B8*'Fuel Composition'!$J$6/100 -> 6.7721706 | D8: =$B8*'Fuel Composition'!$J$7/100 -> 6.7981745 | E8: =$B8*'Fuel Composition'!$J$8/100 -> 8.8186679 | F8: =$B8*'Fuel Composition'!$J$9/100 -> 2.615689 | G8: =$B8*'Fuel Composition'!$J$10/100 -> 0.6363477 | H8: =$B8*'Fuel Composition'!$J$11/100 -> 2.3758003 | I8: =$B8*'Fuel Composition'!$J$12/100 -> 0.035517806 | J8: =$B8*'Fuel Composition'!$J$13/100 -> 0.0044907852 | K8: =SUM(C8:J8) -> 28.056859 | L8: 22
A9: 100000 | B9: =A9*'Loading Loss'!$C$24/2000 -> 170 | C9: =$B9*'Fuel Composition'!$J$6/100 -> 1.3544341 | D9: =$B9*'Fuel Composition'!$J$7/100 -> 1.3596349 | E9: =$B9*'Fuel Composition'!$J$8/100 -> 1.7637336 | F9: =$B9*'Fuel Composition'!$J$9/100 -> 0.52313779 | G9: =$B9*'Fuel Composition'!$J$10/100 -> 0.12726954 | H9: =$B9*'Fuel Composition'!$J$11/100 -> 0.47516007 | I9: =$B9*'Fuel Composition'!$J$12/100 -> 0.0071035612 | J9: =$B9*'Fuel Composition'!$J$13/100 -> 0.00089815704 | K9: =SUM(C9:J9) -> 5.6113717 | L9: 41
A10: Ships
A11: 5000000 | B11: =A11*'Loading Loss'!$B$24/2000 -> 4500 | C11: =$B11*'Fuel Composition'!$J$6/100 -> 35.852668 | D11: =$B11*'Fuel Composition'!$J$7/100 -> 35.990336 | E11: =$B11*'Fuel Composition'!$J$8/100 -> 46.687065 | F11: =$B11*'Fuel Composition'!$J$9/100 -> 13.847765 | G11: =$B11*'Fuel Composition'!$J$10/100 -> 3.3688996 | H11: =$B11*'Fuel Composition'!$J$11/100 -> 12.577766 | I11: =$B11*'Fuel Composition'!$J$12/100 -> 0.18803544 | J11: =$B11*'Fuel Composition'!$J$13/100 -> 0.023774745 | K11: =SUM(C11:J11) -> 148.53631 | L11: 2
A12: 1000000 | B12: =A12*'Loading Loss'!$B$24/2000 -> 900 | C12: =$B12*'Fuel Composition'!$J$6/100 -> 7.1705336 | D12: =$B12*'Fuel Composition'!$J$7/100 -> 7.1980671 | E12: =$B12*'Fuel Composition'!$J$8/100 -> 9.3374131 | F12: =$B12*'Fuel Composition'!$J$9/100 -> 2.769553 | G12: =$B12*'Fuel Composition'!$J$10/100 -> 0.67377992 | H12: =$B12*'Fuel Composition'!$J$11/100 -> 2.5155533 | I12: =$B12*'Fuel Composition'!$J$12/100 -> 0.037607089 | J12: =$B12*'Fuel Composition'!$J$13/100 -> 0.004754949 | K12: =SUM(C12:J12) -> 29.707262 | L12: 17
A13: 500000 | B13: =A13*'Loading Loss'!$B$24/2000 -> 450 | C13: =$B13*'Fuel Composition'!$J$6/100 -> 3.5852668 | D13: =$B13*'Fuel Composition'!$J$7/100 -> 3.5990336 | E13: =$B13*'Fuel Composition'!$J$8/100 -> 4.6687065 | F13: =$B13*'Fuel Composition'!$J$9/100 -> 1.3847765 | G13: =$B13*'Fuel Composition'!$J$10/100 -> 0.33688996 | H13: =$B13*'Fuel Composition'!$J$11/100 -> 1.2577766 | I13: =$B13*'Fuel Composition'!$J$12/100 -> 0.018803544 | J13: =$B13*'Fuel Composition'!$J$13/100 -> 0.0023774745 | K13: =SUM(C13:J13) -> 14.853631 | L13: 22
A14: 100000 | B14: =A14*'Loading Loss'!$B$24/2000 -> 90 | C14: =$B14*'Fuel Composition'!$J$6/100 -> 0.71705336 | D14: =$B14*'Fuel Composition'!$J$7/100 -> 0.71980671 | E14: =$B14*'Fuel Composition'!$J$8/100 -> 0.93374131 | F14: =$B14*'Fuel Composition'!$J$9/100 -> 0.2769553 | G14: =$B14*'Fuel Composition'!$J$10/100 -> 0.067377992 | H14: =$B14*'Fuel Composition'!$J$11/100 -> 0.25155533 | I14: =$B14*'Fuel Composition'!$J$12/100 -> 0.0037607089 | J14: =$B14*'Fuel Composition'!$J$13/100 -> 0.0004754949 | K14: =SUM(C14:J14) -> 2.9707262 | L14: 41
B19: Carbon Adsorber | I19: Recuperative Oxidizer
B20: Costs (2021 dollars) | F20: Cost Effectiveness ($/ton) | I20: Costs (2021 dollars) | L20: Cost Effectiveness ($/ton)
B21: Capital (TCI) | C21: Annual Costs | D21: Solvent Recovery Credit | E21: Total Annual Cost (TAC) | I21: Capital (TCI) | J21: Annual Costs | K21: Total Annual Cost (TAC)
A22: Typical MTVLO Facility | H22: Typical MTVLO Facility
A23: Barges | B23: 3058425 | C23: =112292+418458 -> 530750 | D23: 269492 | E23: 261258 | H23: Barges | I23: 946196 | J23: =122892+123686 -> 246578 | K23: 246579
A24: 5000000 | F24: =$E$23/(K6-(K6*0.03)) -> 959.97256 | H24: 5000000 | L24: =$K$23/(K6-(K6*0.03)) -> 906.0357
A25: 1000000 | F25: =$E$23/(K7-(K7*0.03)) -> 4799.8628 | H25: 1000000 | L25: =$K$23/(K7-(K7*0.03)) -> 4530.1785
A26: 500000 | F26: =$E$23/(K8-(K8*0.03)) -> 9599.7256 | H26: 500000 | L26: =$K$23/(K8-(K8*0.03)) -> 9060.357
A27: 100000 | F27: =$E$23/(K9-(K9*0.03)) -> 47998.628 | H27: 100000 | L27: =$K$23/(K9-(K9*0.03)) -> 45301.785
A28: Ships | B28: 1368100 | C28: =65216+189861 -> 255077 | D28: 142683 | E28: 112407 | H28: Ships | I28: 946368 | J28: =129356+123708 -> 253064 | K28: 253064
A29: 5000000 | F29: =$E$28/(K11-(K11*0.03)) -> 780.16954 | H29: 5000000 | L29: =$K$28/(K11-(K11*0.03)) -> 1756.4104
A30: 1000000 | F30: =$E$28/(K12-(K12*0.03)) -> 3900.8477 | H30: 1000000 | L30: =$K$28/(K12-(K12*0.03)) -> 8782.052
A31: 500000 | F31: =$E$28/(K13-(K13*0.03)) -> 7801.6954 | H31: 500000 | L31: =$K$28/(K13-(K13*0.03)) -> 17564.104
A32: 100000 | F32: =$E$28/(K14-(K14*0.03)) -> 39008.477 | H32: 100000 | L32: =$K$28/(K14-(K14*0.03)) -> 87820.52
A35: 5000 bbl/hr
A38: Tons/Yr Emissions | B38: Hours/yr | C38: Tons VOC Removed | D38: Tons HAP removed | E38: Annual Cost | F38: Cost/Ton Removed
A39: 1000 | B39: =A39*2000/'Loading Loss'!$N$24 -> 4941.1765 | C39: =A39-(A39*0.03) -> 970 | D39: =C39*SUM('Fuel Composition'!$J$6:$J$13)/100 -> 32.017827 | E39: 2345 | F39: =E39/D39 -> 73.240448
A40: 500 | B40: =A40*2000/'Loading Loss'!$N$24 -> 2470.5882 | C40: =A40-(A40*0.03) -> 485 | D40: =C40*SUM('Fuel Composition'!$J$6:$J$13)/100 -> 16.008913 | E40: 225875 | F40: =E40/D40 -> 14109.327
A41: 100 | B41: =A41*2000/'Loading Loss'!$N$24 -> 494.11765 | C41: =A41-(A41*0.03) -> 97 | D41: =C41*SUM('Fuel Composition'!$J$6:$J$13)/100 -> 3.2017827 | E41: 404789 | F41: =E41/D41 -> 126426.13
A42: 50 | B42: =A42*2000/'Loading Loss'!$N$24 -> 247.05882 | C42: =A42-(A42*0.03) -> 48.5 | D42: =C42*SUM('Fuel Composition'!$J$6:$J$13)/100 -> 1.6008913 | F42: =E42/D42 -> 0
A43: 25 | B43: =A43*2000/'Loading Loss'!$N$24 -> 123.52941 | C43: =A43-(A43*0.03) -> 24.25 | D43: =C43*SUM('Fuel Composition'!$J$6:$J$13)/100 -> 0.80044567 | F43: =E43/D43 -> 0
A44: 10 | B44: =A44*2000/'Loading Loss'!$N$24 -> 49.411765 | C44: =A44-(A44*0.03) -> 9.7 | D44: =C44*SUM('Fuel Composition'!$J$6:$J$13)/100 -> 0.32017827 | F44: =E44/D44 -> 0
A45: 5 | B45: =A45*2000/'Loading Loss'!$N$24 -> 24.705882 | C45: =A45-(A45*0.03) -> 4.85 | D45: =C45*SUM('Fuel Composition'!$J$6:$J$13)/100 -> 0.16008913 | F45: =E45/D45 -> 0
A46: 1 | B46: =A46*2000/'Loading Loss'!$N$24 -> 4.9411765 | C46: =A46-(A46*0.03) -> 0.97 | D46: =C46*SUM('Fuel Composition'!$J$6:$J$13)/100 -> 0.032017827 | F46: =E46/D46 -> 0

Sheet Crude Oil MP
A1: Loading Threshold (1000 gal/yr) | B1: Crude Oil
B2: Loading Loss (TPY) | C2: Emissions | L2: Number of Facilities Greater than Threshold
C3: Benzene (TPY) | D3: Biphenyl (TPY) | E3: Ethylbenzene (TPY) | F3: n-Hexane (TPY) | G3: Naphthalene (TPY) | H3: Phenol (TPY) | I3: Toluene (TPY) | J3: Xylene (TPY) | K3: Total HAP (TPY)
A4: Typical MTVLO Facility
A5: Uncleaned
A6: 10000000 | B6: =A6*'Loading Loss'!$H$19/2000 -> 12086.606 | C6: =$B6*'Fuel Composition'!$J$32/100 -> 39.35632 | D6: =$B6*'Fuel Composition'!$J$33/100 -> 0.013172385 | E6: =$B6*'Fuel Composition'!$J$35/100 -> 2.8743081 | F6: =$B6*'Fuel Composition'!$J$36/100 -> 350.8282 | G6: =$B6*'Fuel Composition'!$J$37/100 -> 0.046411029 | H6: =$B6*'Fuel Composition'!$J$39/100 -> 0.083415686 | I6: =$B6*'Fuel Composition'!$J$40/100 -> 22.494666 | J6: =$B6*'Fuel Composition'!$J$42/100 -> 10.854081 | K6: =SUM(C6:J6) -> 426.55057 | L6: 2
A7: 5000000 | B7: =A7*'Loading Loss'!$H$19/2000 -> 6043.3029 | C7: =$B7*'Fuel Composition'!$J$32/100 -> 19.67816 | D7: =$B7*'Fuel Composition'!$J$33/100 -> 0.0065861924 | E7: =$B7*'Fuel Composition'!$J$35/100 -> 1.437154 | F7: =$B7*'Fuel Composition'!$J$36/100 -> 175.4141 | G7: =$B7*'Fuel Composition'!$J$37/100 -> 0.023205515 | H7: =$B7*'Fuel Composition'!$J$39/100 -> 0.041707843 | I7: =$B7*'Fuel Composition'!$J$40/100 -> 11.247333 | J7: =$B7*'Fuel Composition'!$J$42/100 -> 5.4270405 | K7: =SUM(C7:J7) -> 213.27529 | L7: 6
A8: 1000000 | B8: =A8*'Loading Loss'!$H$19/2000 -> 1208.6606 | C8: =$B8*'Fuel Composition'!$J$32/100 -> 3.935632 | D8: =$B8*'Fuel Composition'!$J$33/100 -> 0.0013172385 | E8: =$B8*'Fuel Composition'!$J$35/100 -> 0.28743081 | F8: =$B8*'Fuel Composition'!$J$36/100 -> 35.08282 | G8: =$B8*'Fuel Composition'!$J$37/100 -> 0.0046411029 | H8: =$B8*'Fuel Composition'!$J$39/100 -> 0.0083415686 | I8: =$B8*'Fuel Composition'!$J$40/100 -> 2.2494666 | J8: =$B8*'Fuel Composition'!$J$42/100 -> 1.0854081 | K8: =SUM(C8:J8) -> 42.655057 | L8: 8
A9: 500000 | B9: =A9*'Loading Loss'!$H$19/2000 -> 604.33029 | C9: =$B9*'Fuel Composition'!$J$32/100 -> 1.967816 | D9: =$B9*'Fuel Composition'!$J$33/100 -> 0.00065861924 | E9: =$B9*'Fuel Composition'!$J$35/100 -> 0.1437154 | F9: =$B9*'Fuel Composition'!$J$36/100 -> 17.54141 | G9: =$B9*'Fuel Composition'!$J$37/100 -> 0.0023205515 | H9: =$B9*'Fuel Composition'!$J$39/100 -> 0.0041707843 | I9: =$B9*'Fuel Composition'!$J$40/100 -> 1.1247333 | J9: =$B9*'Fuel Composition'!$J$42/100 -> 0.54270405 | K9: =SUM(C9:J9) -> 21.327529 | L9: 13
A10: Ballasted
A11: 10000000 | B11: =A6*'Loading Loss'!$I$19/2000 -> 10086.606 | C11: =$B11*'Fuel Composition'!$J$32/100 -> 32.843934 | D11: =$B11*'Fuel Composition'!$J$33/100 -> 0.010992718 | E11: =$B11*'Fuel Composition'!$J$35/100 -> 2.3986893 | F11: =$B11*'Fuel Composition'!$J$36/100 -> 292.7758 | G11: =$B11*'Fuel Composition'!$J$37/100 -> 0.038731283 | H11: =$B11*'Fuel Composition'!$J$39/100 -> 0.06961269 | I11: =$B11*'Fuel Composition'!$J$40/100 -> 18.772419 | J11: =$B11*'Fuel Composition'!$J$42/100 -> 9.0580299 | K11: =SUM(C11:J11) -> 355.96821 | L11: 2
A12: 5000000 | B12: =A7*'Loading Loss'!$I$19/2000 -> 5043.3029 | C12: =$B12*'Fuel Composition'!$J$32/100 -> 16.421967 | D12: =$B12*'Fuel Composition'!$J$33/100 -> 0.0054963591 | E12: =$B12*'Fuel Composition'!$J$35/100 -> 1.1993447 | F12: =$B12*'Fuel Composition'!$J$36/100 -> 146.3879 | G12: =$B12*'Fuel Composition'!$J$37/100 -> 0.019365642 | H12: =$B12*'Fuel Composition'!$J$39/100 -> 0.034806345 | I12: =$B12*'Fuel Composition'!$J$40/100 -> 9.3862097 | J12: =$B12*'Fuel Composition'!$J$42/100 -> 4.529015 | K12: =SUM(C12:J12) -> 177.98411 | L12: 6
A13: 1000000 | B13: =A8*'Loading Loss'!$I$19/2000 -> 1008.6606 | C13: =$B13*'Fuel Composition'!$J$32/100 -> 3.2843934 | D13: =$B13*'Fuel Composition'!$J$33/100 -> 0.0010992718 | E13: =$B13*'Fuel Composition'!$J$35/100 -> 0.23986893 | F13: =$B13*'Fuel Composition'!$J$36/100 -> 29.27758 | G13: =$B13*'Fuel Composition'!$J$37/100 -> 0.0038731283 | H13: =$B13*'Fuel Composition'!$J$39/100 -> 0.006961269 | I13: =$B13*'Fuel Composition'!$J$40/100 -> 1.8772419 | J13: =$B13*'Fuel Composition'!$J$42/100 -> 0.90580299 | K13: =SUM(C13:J13) -> 35.596821 | L13: 8
A14: 500000 | B14: =A9*'Loading Loss'!$I$19/2000 -> 504.33029 | C14: =$B14*'Fuel Composition'!$J$32/100 -> 1.6421967 | D14: =$B14*'Fuel Composition'!$J$33/100 -> 0.00054963591 | E14: =$B14*'Fuel Composition'!$J$35/100 -> 0.11993447 | F14: =$B14*'Fuel Composition'!$J$36/100 -> 14.63879 | G14: =$B14*'Fuel Composition'!$J$37/100 -> 0.0019365642 | H14: =$B14*'Fuel Composition'!$J$39/100 -> 0.0034806345 | I14: =$B14*'Fuel Composition'!$J$40/100 -> 0.93862097 | J14: =$B14*'Fuel Composition'!$J$42/100 -> 0.4529015 | K14: =SUM(C14:J14) -> 17.798411 | L14: 13
A15: Cleaned/Gas-Freed
A16: 10000000 | B16: =A6*'Loading Loss'!$J$19/2000 -> 9436.6057 | C16: =$B16*'Fuel Composition'!$J$32/100 -> 30.727408 | D16: =$B16*'Fuel Composition'!$J$33/100 -> 0.010284327 | E16: =$B16*'Fuel Composition'!$J$35/100 -> 2.2441132 | F16: =$B16*'Fuel Composition'!$J$36/100 -> 273.90878 | G16: =$B16*'Fuel Composition'!$J$37/100 -> 0.036235366 | H16: =$B16*'Fuel Composition'!$J$39/100 -> 0.065126716 | I16: =$B16*'Fuel Composition'!$J$40/100 -> 17.562689 | J16: =$B16*'Fuel Composition'!$J$42/100 -> 8.4743133 | K16: =SUM(C16:J16) -> 333.02895 | L16: 2
A17: 5000000 | B17: =A7*'Loading Loss'!$J$19/2000 -> 4718.3029 | C17: =$B17*'Fuel Composition'!$J$32/100 -> 15.363704 | D17: =$B17*'Fuel Composition'!$J$33/100 -> 0.0051421633 | E17: =$B17*'Fuel Composition'!$J$35/100 -> 1.1220566 | F17: =$B17*'Fuel Composition'!$J$36/100 -> 136.95439 | G17: =$B17*'Fuel Composition'!$J$37/100 -> 0.018117683 | H17: =$B17*'Fuel Composition'!$J$39/100 -> 0.032563358 | I17: =$B17*'Fuel Composition'!$J$40/100 -> 8.7813445 | J17: =$B17*'Fuel Composition'!$J$42/100 -> 4.2371567 | K17: =SUM(C17:J17) -> 166.51447 | L17: 6
A18: 1000000 | B18: =A8*'Loading Loss'!$J$19/2000 -> 943.66057 | C18: =$B18*'Fuel Composition'!$J$32/100 -> 3.0727408 | D18: =$B18*'Fuel Composition'!$J$33/100 -> 0.0010284327 | E18: =$B18*'Fuel Composition'!$J$35/100 -> 0.22441132 | F18: =$B18*'Fuel Composition'!$J$36/100 -> 27.390878 | G18: =$B18*'Fuel Composition'!$J$37/100 -> 0.0036235366 | H18: =$B18*'Fuel Composition'!$J$39/100 -> 0.0065126716 | I18: =$B18*'Fuel Composition'!$J$40/100 -> 1.7562689 | J18: =$B18*'Fuel Composition'!$J$42/100 -> 0.84743133 | K18: =SUM(C18:J18) -> 33.302895 | L18: 8
A19: 500000 | B19: =A9*'Loading Loss'!$J$19/2000 -> 471.83029 | C19: =$B19*'Fuel Composition'!$J$32/100 -> 1.5363704 | D19: =$B19*'Fuel Composition'!$J$33/100 -> 0.00051421633 | E19: =$B19*'Fuel Composition'!$J$35/100 -> 0.11220566 | F19: =$B19*'Fuel Composition'!$J$36/100 -> 13.695439 | G19: =$B19*'Fuel Composition'!$J$37/100 -> 0.0018117683 | H19: =$B19*'Fuel Composition'!$J$39/100 -> 0.0032563358 | I19: =$B19*'Fuel Composition'!$J$40/100 -> 0.87813445 | J19: =$B19*'Fuel Composition'!$J$42/100 -> 0.42371567 | K19: =SUM(C19:J19) -> 16.651447 | L19: 13
B25: Carbon Adsorber | I25: Recuperative Oxidizer
B26: Costs (2021 dollars) | F26: Cost Effectiveness ($/ton) | I26: Costs (2021 dollars) | L26: Cost Effectiveness ($/ton)
B27: Capital (TCI) | C27: Annual Costs | D27: Solvent Recovery Credit | E27: Total Annual Cost (TAC) | I27: Capital (TCI) | J27: Annual Costs | K27: Total Annual Cost (TAC)
A28: Typical MTVLO Facility | H28: Typical MTVLO Facility
A29: Uncleaned | B29: 2231973 | C29: =87138+306391 -> 393529 | D29: 191606 | E29: 201923 | H29: Uncleaned | I29: 946189 | J29: =122650+123685 -> 246335 | K29: 246335
A30: 10000000 | F30: =$E$29/(K6-(K6*0.03)) -> 488.02664 | H30: 10000000 | L30: =$K$29/(K6-(K6*0.03)) -> 595.36577
A31: 5000000 | F31: =$E$29/(K7-(K7*0.03)) -> 976.05327 | H31: 5000000 | L31: =$K$29/(K7-(K7*0.03)) -> 1190.7315
A32: 1000000 | F32: =$E$29/(K8-(K8*0.03)) -> 4880.2664 | H32: 1000000 | L32: =$K$29/(K8-(K8*0.03)) -> 5953.6577
A33: 500000 | F33: =$E$29/(K9-(K9*0.03)) -> 9760.5327 | H33: 500000 | L33: =$K$29/(K9-(K9*0.03)) -> 11907.315
A34: Ballasted | B34: 1774647 | C34: =74747+244593 -> 319340 | D34: 159900 | E34: 159440 | H34: Ballasted | I34: 946251 | J34: =124963+123693 -> 248656 | K34: 248656
A35: 10000000 | F35: =$E$34/(K11-(K11*0.03)) -> 461.7579 | H35: 10000000 | L35: =$K$34/(K11-(K11*0.03)) -> 720.13843
A36: 5000000 | F36: =$E$34/(K12-(K12*0.03)) -> 923.5158 | H36: 5000000 | L36: =$K$34/(K12-(K12*0.03)) -> 1440.2769
A37: 1000000 | F37: =$E$34/(K13-(K13*0.03)) -> 4617.579 | H37: 1000000 | L37: =$K$34/(K13-(K13*0.03)) -> 7201.3843
A38: 500000 | F38: =$E$34/(K14-(K14*0.03)) -> 9235.158 | H38: 500000 | L38: =$K$34/(K14-(K14*0.03)) -> 14402.769
A39: Cleaned/Gas-Freed | B39: 1635636 | C39: =70719+225853 -> 296572 | D39: 149594 | E39: 146978 | H39: Cleaned/Gas-Freed | I39: 946271 | J39: =125715+123696 -> 249411 | K39: 249410
A40: 10000000 | F40: =$E$39/(K16-(K16*0.03)) -> 454.98661 | H40: 10000000 | L40: =$K$39/(K16-(K16*0.03)) -> 772.07616
A41: 5000000 | F41: =$E$39/(K17-(K17*0.03)) -> 909.97322 | H41: 5000000 | L41: =$K$39/(K17-(K17*0.03)) -> 1544.1523
A42: 1000000 | F42: =$E$39/(K18-(K18*0.03)) -> 4549.8661 | H42: 1000000 | L42: =$K$39/(K18-(K18*0.03)) -> 7720.7616
A43: 500000 | F43: =$E$39/(K19-(K19*0.03)) -> 9099.7322 | H43: 500000 | L43: =$K$39/(K19-(K19*0.03)) -> 15441.523

Sheet Benzene_Toluene MP
A1: Loading Threshold (1000 gal/yr) | B1: Chemicals
B2: Emissions | D2: Number of Facilites Greater than Threshold
B3: Benzene (TPY) | C3: Toluene (TPY)
A4: Typical MTVLO Facility
A5: Barges
A6: 100000 | B6: =A6*'Loading Loss'!$I$7/2000 -> 85.768211 | C6: =A6*'Loading Loss'!$I$8/2000 -> 29.970926 | D6: 9
A7: 50000 | B7: =A7*'Loading Loss'!$I$7/2000 -> 42.884105 | C7: =A7*'Loading Loss'!$I$8/2000 -> 14.985463 | D7: 15
A8: 5000 | B8: =A8*'Loading Loss'!$I$7/2000 -> 4.2884105 | C8: =A8*'Loading Loss'!$I$8/2000 -> 1.4985463 | D8: 29
A9: Ships
A10: 100000 | B10: =A10*'Loading Loss'!$H$7/2000 -> 34.307284 | C10: =A10*'Loading Loss'!$H$8/2000 -> 11.988371 | D10: 9
A11: 50000 | B11: =A11*'Loading Loss'!$H$7/2000 -> 17.153642 | C11: =A11*'Loading Loss'!$H$8/2000 -> 5.9941853 | D11: 15
A12: 5000 | B12: =A12*'Loading Loss'!$H$7/2000 -> 1.7153642 | C12: =A12*'Loading Loss'!$H$8/2000 -> 0.59941853 | D12: 29
B17: Carbon Adsorber (Benzene) | G17: Carbon Adsorber (Toluene)
B18: Costs (2021 dollars) | F18: Cost Effectiveness ($/ton) | G18: Costs (2021 dollars) | K18: Cost Effectiveness ($/ton)
B19: Capital (TCI) | C19: Annual Costs | D19: Solvent Recovery Credit | E19: Total Annual Cost (TAC) | G19: Capital (TCI) | H19: Annual Costs | I19: Solvent Recovery Credit | J19: Total Annual Cost (TAC)
A20: Typical MTVLO Facility
A21: Barges | B21: 989089 | C21: =57262+139118 -> 196380 | D21: 135965 | E21: 60415 | G21: 431507 | H21: =25743+66007 -> 91750 | I21: 47512 | J21: 44239
A22: 100000 | F22: =$E$21/(B6-(B6*0.03)) -> 726.18403 | K22: =$J$21/(C6-(C6*0.03)) -> 1521.7153
A23: 50000 | F23: =$E$21/(B7-(B7*0.03)) -> 1452.3681 | K23: =$J$21/(C7-(C7*0.03)) -> 3043.4305
A24: 5000 | F24: =$E$21/(B8-(B8*0.03)) -> 14523.681 | K24: =$J$21/(C8-(C8*0.03)) -> 30434.305
A25: Ships | B25: 514987 | C25: =30258+76620 -> 106878 | D25: 54383 | E25: 52495 | G25: 383514 | H25: =17651+60160 -> 77811 | I25: 19002 | J25: 58809
A26: 100000 | F26: =$E$25/(B10-(B10*0.03)) -> 1577.4655 | K26: =$J$25/(C10-(C10*0.03)) -> 5057.2206
A27: 50000 | F27: =$E$25/(B11-(B11*0.03)) -> 3154.931 | K27: =$J$25/(C11-(C11*0.03)) -> 10114.441
A28: 5000 | F28: =$E$25/(B12-(B12*0.03)) -> 31549.31 | K28: =$J$25/(C12-(C12*0.03)) -> 101144.41
B32: Recuperative Oxidizer (Benzene) | F32: Recuperative Oxidizer (Toluene)
B33: Costs (2021 dollars) | E33: Cost Effectiveness ($/ton) | F33: Costs (2021 dollars) | I33: Cost Effectiveness ($/ton)
B34: Capital (TCI) | C34: Annual Costs | D34: Total Annual Cost (TAC) | F34: Capital (TCI) | G34: Annual Costs | H34: Total Annual Cost (TAC)
A35: Typical MTVLO Facility
A36: Barges | B36: 946560 | C36: =136543+123731 -> 260274 | D36: 260274 | F36: 946561 | G36: =136590+123731 -> 260321 | H36: 260322
A37: 100000 | E37: =$D$36/(B6-(B6*0.03)) -> 3128.4751 | I37: =$H$36/(C6-(C6*0.03)) -> 8954.4511
A38: 50000 | E38: =$D$36/(B7-(B7*0.03)) -> 6256.9502 | I38: =$H$36/(C7-(C7*0.03)) -> 17908.902
A39: 5000 | E39: =$D$36/(B8-(B8*0.03)) -> 62569.502 | I39: =$H$36/(C8-(C8*0.03)) -> 179089.02
A40: Ships | B40: 946561 | C40: =136593+123731 -> 260324 | D40: 260325 | F40: 946562 | G40: =136612+123731 -> 260343 | H40: 260344
A41: 100000 | E41: =$D$40/(B10-(B10*0.03)) -> 7822.7203 | I41: =$H$40/(C10-(C10*0.03)) -> 22388.02
A42: 50000 | E42: =$D$40/(B11-(B11*0.03)) -> 15645.441 | I42: =$H$40/(C11-(C11*0.03)) -> 44776.039
A43: 5000 | E43: =$D$40/(B12-(B12*0.03)) -> 156454.41 | I43: =$H$40/(C12-(C12*0.03)) -> 447760.39

Sheet Alcohols MP
A1: Loading Threshold (1000 gal/yr) | B1: Alcohols
B2: Emissions | D2: Number of Facilites Greater than Threshold
B3: Methanol (TPY) | C3: Ethylene Glycol (TPY)
A4: Typical MTVLO Facility
A5: Barges
A6: 500000 | B6: =A6*'Loading Loss'!$I$9/2000 -> 175.52385 | C6: =A6*'Loading Loss'!$I$10/2000 -> 0.18696376 | D6: 16
A7: 100000 | B7: =A7*'Loading Loss'!$I$9/2000 -> 35.10477 | C7: =A7*'Loading Loss'!$I$10/2000 -> 0.037392751 | D7: 26
A8: 50000 | B8: =A8*'Loading Loss'!$I$9/2000 -> 17.552385 | C8: =A8*'Loading Loss'!$I$10/2000 -> 0.018696376 | D8: 36
A9: 5000 | B9: =A9*'Loading Loss'!$I$9/2000 -> 1.7552385 | C9: =A9*'Loading Loss'!$I$10/2000 -> 0.0018696376 | D9: 65
A10: Ships
A11: 500000 | B11: =A11*'Loading Loss'!$H$9/2000 -> 70.209539 | C11: =A11*'Loading Loss'!$H$10/2000 -> 0.074785502 | D11: 16
A12: 100000 | B12: =A12*'Loading Loss'!$H$9/2000 -> 14.041908 | C12: =A12*'Loading Loss'!$H$10/2000 -> 0.0149571 | D12: 26
A13: 50000 | B13: =A13*'Loading Loss'!$H$9/2000 -> 7.0209539 | C13: =A13*'Loading Loss'!$H$10/2000 -> 0.0074785502 | D13: 36
A14: 5000 | B14: =A14*'Loading Loss'!$H$9/2000 -> 0.70209539 | C14: =A14*'Loading Loss'!$H$10/2000 -> 0.00074785502 | D14: 65
B18: Carbon Adsorber (Methanol) | G18: Carbon Adsorber (Ethylene Glycol)
B19: Costs (2021 dollars) | F19: Cost Effectiveness ($/ton) | G19: Costs (2021 dollars) | K19: Cost Effectiveness ($/ton)
B20: Capital (TCI) | C20: Annual Costs | D20: Solvent Recovery Credit | E20: Total Annual Cost (TAC) | G20: Capital (TCI) | H20: Annual Costs | I20: Solvent Recovery Credit | J20: Total Annual Cost (TAC)
A21: Typical MTVLO Facility
A22: Barges | B22: 416205 | C22: =26578+64109 -> 90687 | D22: 55648 | E22: 35039 | G22: 362648 | H22: =12300+57805 -> 70105 | I22: 59 | J22: 70046
A23: 500000 | F23: =$E$22/(B6-(B6*0.03)) -> 205.79927 | K23: =$J$22/(C6-(C6*0.03)) -> 386237.27
A24: 100000 | F24: =$E$22/(B7-(B7*0.03)) -> 1028.9964 | K24: =$J$22/(C7-(C7*0.03)) -> 1931186.4
A25: 50000 | F25: =$E$22/(B8-(B8*0.03)) -> 2057.9927 | K25: =$J$22/(C8-(C8*0.03)) -> 3862372.7
A26: 5000 | F26: =$E$22/(B9-(B9*0.03)) -> 20579.927 | K26: =$J$22/(C9-(C9*0.03)) -> 38623727
A27: Ships | B27: 379360 | C27: =17985+59675 -> 77660 | D27: 22258 | E27: 55402 | G27: 362463 | H27: =12274+57786 -> 70060 | I27: 24 | J27: 70036
A28: 500000 | F28: =$E$27/(B11-(B11*0.03)) -> 813.50005 | K28: =$J$27/(C11-(C11*0.03)) -> 965455.33
A29: 100000 | F29: =$E$27/(B12-(B12*0.03)) -> 4067.5003 | K29: =$J$27/(C12-(C12*0.03)) -> 4827276.7
A30: 50000 | F30: =$E$27/(B13-(B13*0.03)) -> 8135.0005 | K30: =$J$27/(C13-(C13*0.03)) -> 9654553.3
A31: 5000 | F31: =$E$27/(B14-(B14*0.03)) -> 81350.005 | K31: =$J$27/(C14-(C14*0.03)) -> 96545533
B34: Recuperative Oxidizer (Methanol) | F34: Recuperative Oxidizer (Ethylene Glycol)
B35: Costs (2021 dollars) | E35: Cost Effectiveness ($/ton) | F35: Costs (2021 dollars) | I35: Cost Effectiveness ($/ton)
B36: Capital (TCI) | C36: Annual Costs | D36: Total Annual Cost (TAC) | F36: Capital (TCI) | G36: Annual Costs | H36: Total Annual Cost (TAC)
A37: Typical MTVLO Facility
A38: Barges | B38: 946546 | C38: =136001+123729 -> 259730 | D38: 259740 | F38: 946562 | G38: =136626+123732 -> 260358 | H38: 260358
A39: 500000 | E39: =$D$38/(B6-(B6*0.03)) -> 1525.5659 | I39: =$H$38/(C6-(C6*0.03)) -> 1435627.5
A40: 100000 | E40: =$D$38/(B7-(B7*0.03)) -> 7627.8295 | I40: =$H$38/(C7-(C7*0.03)) -> 7178137.5
A41: 50000 | E41: =$D$38/(B8-(B8*0.03)) -> 15255.659 | I41: =$H$38/(C8-(C8*0.03)) -> 14356275
A42: 5000 | E42: =$D$38/(B9-(B9*0.03)) -> 152556.59 | I42: =$H$38/(C9-(C9*0.03)) -> 1.4356275e+08
A43: Ships | B43: 946556 | C43: =136383+123731 -> 260114 | D43: 260113 | F43: 946562 | G43: =136626+123732 -> 260358 | H43: 260358
A44: 500000 | E44: =$D$43/(B11-(B11*0.03)) -> 3819.3917 | I44: =$H$43/(C11-(C11*0.03)) -> 3589068.8
A45: 100000 | E45: =$D$43/(B12-(B12*0.03)) -> 19096.959 | I45: =$H$43/(C12-(C12*0.03)) -> 17945344
...

Sheet Naphtha MP
A1: Loading Threshold (1000 gal/yr) | B1: Naphtha
B2: Loading Loss (TPY) | C2: Emissions | I2: Number of Facilities Greater than Threshold
C3: Benzene (TPY) | D3: Hexane (TPY) | E3: Toluene (TPY) | F3: Xylene (TPY) | G3: Ethylbenzene (TPY) | H3: Total HAP (TPY)
A4: Typical MTVLO Facility
A5: Barges
A6: 500000 | B6: =A6*'Loading Loss'!$I$3/2000 -> 3858.8145 | C6: =$B6*'Fuel Composition'!$J$6/100 -> 30.744177 | D6: =$B6*'Fuel Composition'!$J$7/100 -> 30.862229 | E6: =$B6*'Fuel Composition'!$J$8/100 -> 40.034828 | F6: =$B6*'Fuel Composition'!$J$9/100 -> 11.874657 | G6: =$B6*'Fuel Composition'!$J$10/100 -> 2.8888797 | H6: =SUM(C6:G6) -> 116.40477 | I6: 5
A7: 100000 | B7: =A7*'Loading Loss'!$I$3/2000 -> 771.7629 | C7: =$B7*'Fuel Composition'!$J$6/100 -> 6.1488354 | D7: =$B7*'Fuel Composition'!$J$7/100 -> 6.1724457 | E7: =$B7*'Fuel Composition'!$J$8/100 -> 8.0069656 | F7: =$B7*'Fuel Composition'!$J$9/100 -> 2.3749314 | G7: =$B7*'Fuel Composition'!$J$10/100 -> 0.57777594 | H7: =SUM(C7:G7) -> 23.280954 | I7: 15
A8: 50000 | B8: =A8*'Loading Loss'!$I$3/2000 -> 385.88145 | C8: =$B8*'Fuel Composition'!$J$6/100 -> 3.0744177 | D8: =$B8*'Fuel Composition'!$J$7/100 -> 3.0862229 | E8: =$B8*'Fuel Composition'!$J$8/100 -> 4.0034828 | F8: =$B8*'Fuel Composition'!$J$9/100 -> 1.1874657 | G8: =$B8*'Fuel Composition'!$J$10/100 -> 0.28888797 | H8: =SUM(C8:G8) -> 11.640477 | I8: 21
A9: Ships
A10: 500000 | B10: =A10*'Loading Loss'!$H$3/2000 -> 1543.5258 | C10: =$B10*'Fuel Composition'!$J$6/100 -> 12.297671 | D10: =$B10*'Fuel Composition'!$J$7/100 -> 12.344891 | E10: =$B10*'Fuel Composition'!$J$8/100 -> 16.013931 | F10: =$B10*'Fuel Composition'!$J$9/100 -> 4.7498628 | G10: =$B10*'Fuel Composition'!$J$10/100 -> 1.1555519 | H10: =SUM(C10:G10) -> 46.561908 | I10: 5
A11: 100000 | B11: =A11*'Loading Loss'!$H$3/2000 -> 308.70516 | C11: =$B11*'Fuel Composition'!$J$6/100 -> 2.4595341 | D11: =$B11*'Fuel Composition'!$J$7/100 -> 2.4689783 | E11: =$B11*'Fuel Composition'!$J$8/100 -> 3.2027862 | F11: =$B11*'Fuel Composition'!$J$9/100 -> 0.94997257 | G11: =$B11*'Fuel Composition'!$J$10/100 -> 0.23111037 | H11: =SUM(C11:G11) -> 9.3123816 | I11: 15
A12: 50000 | B12: =A12*'Loading Loss'!$H$3/2000 -> 154.35258 | C12: =$B12*'Fuel Composition'!$J$6/100 -> 1.2297671 | D12: =$B12*'Fuel Composition'!$J$7/100 -> 1.2344891 | E12: =$B12*'Fuel Composition'!$J$8/100 -> 1.6013931 | F12: =$B12*'Fuel Composition'!$J$9/100 -> 0.47498628 | G12: =$B12*'Fuel Composition'!$J$10/100 -> 0.11555519 | H12: =SUM(C12:G12) -> 4.6561908 | I12: 21
B17: Carbon Adsorber | I17: Recuperative Oxidizer
B18: Costs (2021 dollars) | F18: Cost Effectiveness ($/ton) | I18: Costs (2021 dollars) | L18: Cost Effectiveness ($/ton)
B19: Capital (TCI) | C19: Annual Costs | D19: Solvent Recovery Credit | E19: Total Annual Cost (TAC) | I19: Capital (TCI) | J19: Annual Costs | K19: Total Annual Cost (TAC)
A20: Typical MTVLO Facility | H20: Typical MTVLO Facility
A21: Barges | B21: 85143088 | C21: =708381+11744767 -> 12453148 | D21: 1223422 | E21: 1223442 | H21: Barges | I21: 944273 | J21: =51072+123488 -> 174560 | K21: 174520
A22: 500000 | F22: =$E$21/(H6-(H6*0.03)) -> 10835.298 | H22: 500000 | L22: =$K$21/(H6-(H6*0.03)) -> 1545.6199
A23: 100000 | F23: =$E$21/(H7-(H7*0.03)) -> 54176.492 | H23: 100000 | L23: =$K$21/(H7-(H7*0.03)) -> 7728.0994
A24: 50000 | F24: =$E$21/(H8-(H8*0.03)) -> 108352.98 | H24: 50000 | L24: =$K$21/(H8-(H8*0.03)) -> 15456.199
A25: Ships | B25: 21276854 | C25: =290705+2917747 -> 3208452 | D25: 489376 | E25: 2719077 | H25: Ships | I25: 945649 | J25: =102413+123619 -> 226032 | K25: 226032
A26: 500000 | F26: =$E$25/(H10-(H10*0.03)) -> 60203.121 | H26: 500000 | L26: =$K$25/(H10-(H10*0.03)) -> 5004.5776
A27: 100000 | F27: =$E$25/(H11-(H11*0.03)) -> 301015.6 | H27: 100000 | L27: =$K$25/(H11-(H11*0.03)) -> 25022.888
A28: 50000 | F28: =$E$25/(H12-(H12*0.03)) -> 602031.21 | H28: 50000 | L28: =$K$25/(H12-(H12*0.03)) -> 50045.776

Sheet Kerosene MP
A1: Loading Threshold (1000 gal/yr) | B1: Kerosene
B2: Loading Loss (TPY) | C2: Emissions | L2: Number of Facilities Greater than Threshold
C3: Benzene (TPY) | D3: Biphenyl (TPY) | E3: Ethylbenzene (TPY) | F3: Hexane (TPY) | G3: Naphthalene (TPY) | H3: Phenol (TPY) | I3: Toluene (TPY) | J3: Xylene (TPY) | K3: Total HAP (TPY)
A4: Typical MTVLO Facility
A5: Barges
A6: 1000000 | B6: =A6*'Loading Loss'!$I$4/2000 -> 7.6506908 | C6: =$B6*'Fuel Composition'!$J$87/100 -> 0.0089841114 | D6: =$B6*'Fuel Composition'!$J$88/100 -> 6.7054807e-05 | E6: =$B6*'Fuel Composition'!$J$89/100 -> 0.026853225 | F6: =$B6*'Fuel Composition'!$J$90/100 -> 0.018127403 | G6: =$B6*'Fuel Composition'!$J$91/100 -> 0.0039538171 | H6: =$B6*'Fuel Composition'!$J$92/100 -> 0.0050614092 | I6: =$B6*'Fuel Composition'!$J$93/100 -> 0.084774241 | J6: =$B6*'Fuel Composition'!$J$94/100 -> 0.060311749 | K6: =SUM(C6:J6) -> 0.20813301 | L6: 1
A7: 500000 | B7: =A7*'Loading Loss'!$I$4/2000 -> 3.8253454 | C7: =$B7*'Fuel Composition'!$J$87/100 -> 0.0044920557 | D7: =$B7*'Fuel Composition'!$J$88/100 -> 3.3527404e-05 | E7: =$B7*'Fuel Composition'!$J$89/100 -> 0.013426612 | F7: =$B7*'Fuel Composition'!$J$90/100 -> 0.0090637017 | G7: =$B7*'Fuel Composition'!$J$91/100 -> 0.0019769085 | H7: =$B7*'Fuel Composition'!$J$92/100 -> 0.0025307046 | I7: =$B7*'Fuel Composition'!$J$93/100 -> 0.04238712 | J7: =$B7*'Fuel Composition'!$J$94/100 -> 0.030155875 | K7: =SUM(C7:J7) -> 0.10406651 | L7: 6
A8: 100000 | B8: =A8*'Loading Loss'!$I$4/2000 -> 0.76506908 | C8: =$B8*'Fuel Composition'!$J$87/100 -> 0.00089841114 | D8: =$B8*'Fuel Composition'!$J$88/100 -> 6.7054807e-06 | E8: =$B8*'Fuel Composition'!$J$89/100 -> 0.0026853225 | F8: =$B8*'Fuel Composition'!$J$90/100 -> 0.0018127403 | G8: =$B8*'Fuel Composition'!$J$91/100 -> 0.00039538171 | H8: =$B8*'Fuel Composition'!$J$92/100 -> 0.00050614092 | I8: =$B8*'Fuel Composition'!$J$93/100 -> 0.0084774241 | J8: =$B8*'Fuel Composition'!$J$94/100 -> 0.0060311749 | K8: =SUM(C8:J8) -> 0.020813301 | L8: 25
A9: Ships
A10: 1000000 | B10: =A10*'Loading Loss'!$H$4/2000 -> 3.0602763 | C10: =$B10*'Fuel Composition'!$J$87/100 -> 0.0035936445 | D10: =$B10*'Fuel Composition'!$J$88/100 -> 2.6821923e-05 | E10: =$B10*'Fuel Composition'!$J$89/100 -> 0.01074129 | F10: =$B10*'Fuel Composition'!$J$90/100 -> 0.0072509614 | G10: =$B10*'Fuel Composition'!$J$91/100 -> 0.0015815268 | H10: =$B10*'Fuel Composition'!$J$92/100 -> 0.0020245637 | I10: =$B10*'Fuel Composition'!$J$93/100 -> 0.033909696 | J10: =$B10*'Fuel Composition'!$J$94/100 -> 0.0241247 | K10: =SUM(C10:J10) -> 0.083253204 | L10: 1
A11: 500000 | B11: =A11*'Loading Loss'!$H$4/2000 -> 1.5301382 | C11: =$B11*'Fuel Composition'!$J$87/100 -> 0.0017968223 | D11: =$B11*'Fuel Composition'!$J$88/100 -> 1.3410961e-05 | E11: =$B11*'Fuel Composition'!$J$89/100 -> 0.005370645 | F11: =$B11*'Fuel Composition'!$J$90/100 -> 0.0036254807 | G11: =$B11*'Fuel Composition'!$J$91/100 -> 0.00079076342 | H11: =$B11*'Fuel Composition'!$J$92/100 -> 0.0010122818 | I11: =$B11*'Fuel Composition'!$J$93/100 -> 0.016954848 | J11: =$B11*'Fuel Composition'!$J$94/100 -> 0.01206235 | K11: =SUM(C11:J11) -> 0.041626602 | L11: 6
A12: 100000 | B12: =A12*'Loading Loss'!$H$4/2000 -> 0.30602763 | C12: =$B12*'Fuel Composition'!$J$87/100 -> 0.00035936445 | D12: =$B12*'Fuel Composition'!$J$88/100 -> 2.6821923e-06 | E12: =$B12*'Fuel Composition'!$J$89/100 -> 0.001074129 | F12: =$B12*'Fuel Composition'!$J$90/100 -> 0.00072509614 | G12: =$B12*'Fuel Composition'!$J$91/100 -> 0.00015815268 | H12: =$B12*'Fuel Composition'!$J$92/100 -> 0.00020245637 | I12: =$B12*'Fuel Composition'!$J$93/100 -> 0.0033909696 | J12: =$B12*'Fuel Composition'!$J$94/100 -> 0.00241247 | K12: =SUM(C12:J12) -> 0.0083253204 | L12: 25
B17: Carbon Adsorber | I17: Recuperative Oxidizer
B18: Costs (2021 dollars) | F18: Cost Effectiveness ($/ton) | I18: Costs (2021 dollars) | L18: Cost Effectiveness ($/ton)
B19: Capital (TCI) | C19: Annual Costs | D19: Solvent Recovery Credit | E19: Total Annual Cost (TAC) | I19: Capital (TCI) | J19: Annual Costs | K19: Total Annual Cost (TAC)
A20: Typical MTVLO Facility | H20: Typical MTVLO Facility
A21: Barges | B21: 304982 | C21: =12751+48679 -> 61430 | D21: 1212 | E21: 60219 | H21: Barges | I21: 946559 | J21: =136488+123731 -> 260219 | K21: 260219
A22: 1000000 | F22: =$E$21/(K6-(K6*0.03)) -> 298277.74 | H22: 1000000 | L22: =$K$21/(K6-(K6*0.03)) -> 1288921
A23: 500000 | F23: =$E$21/(K7-(K7*0.03)) -> 596555.47 | H23: 500000 | L23: =$K$21/(K7-(K7*0.03)) -> 2577842
A24: 100000 | F24: =$E$21/(K8-(K8*0.03)) -> 2982777.4 | H24: 100000 | L24: =$K$21/(K8-(K8*0.03)) -> 12889210
A25: Ships | B25: 303387 | C25: =12455+48512 -> 60967 | D25: 485 | E25: 60481 | H25: Ships | I25: 946561 | J25: =136571+123731 -> 260302 | K25: 260303
A26: 1000000 | F26: =$E$25/(K10-(K10*0.03)) -> 748938.7 | H26: 1000000 | L26: =$K$25/(K10-(K10*0.03)) -> 3223342.7
A27: 500000 | F27: =$E$25/(K11-(K11*0.03)) -> 1497877.4 | H27: 500000 | L27: =$K$25/(K11-(K11*0.03)) -> 6446685.4
A28: 100000 | F28: =$E$25/(K12-(K12*0.03)) -> 7489387 | H28: 100000 | L28: =$K$25/(K12-(K12*0.03)) -> 32233427

Sheet Distillate MP
A1: Loading Threshold (1000 gal/yr) | B1: Distillate Fuel Oil (No. 2)
B2: Loading Loss (TPY) | C2: Emissions | M2: Number of Facilities Greater than Threshold
C3: Benzene (TPY) | D3: Biphenyl (TPY) | E3: Ethylbenzene (TPY) | F3: Hexane (TPY) | G3: Naphthalene (TPY) | H3: Phenol (TPY) | I3: Styrene (TPY) | J3: Toluene (TPY) | K3: Xylene (TPY) | L3: Total HAP (TPY)
A4: Typical MTVLO Facility
A5: Barges
A6: 5000000 | B6: =A6*'Loading Loss'!$I$5/2000 -> 33.294673 | C6: =$B6*'Fuel Composition'!$J$110/100 -> 0.0017851486 | D6: =$B6*'Fuel Composition'!$J$111/100 -> 5.5515969e-05 | E6: =$B6*'Fuel Composition'!$J$112/100 -> 0.0027308971 | F6: =$B6*'Fuel Composition'!$J$113/100 -> 3.6019265 | G6: =$B6*'Fuel Composition'!$J$114/100 -> 0.0029474371 | H6: =$B6*'Fuel Composition'!$J$115/100 -> 0.00041795541 | I6: =$B6*'Fuel Composition'!$J$116/100 -> 0.0043065484 | J6: =$B6*'Fuel Composition'!$J$117/100 -> 0.020731933 | K6: =$B6*'Fuel Composition'!$J$118/100 -> 0.0056054113 | L6: =SUM(C6:J6) -> 3.634902 | M6: 1
A7: 1000000 | B7: =A7*'Loading Loss'!$I$5/2000 -> 6.6589346 | C7: =$B7*'Fuel Composition'!$J$110/100 -> 0.00035702972 | D7: =$B7*'Fuel Composition'!$J$111/100 -> 1.1103194e-05 | E7: =$B7*'Fuel Composition'!$J$112/100 -> 0.00054617942 | F7: =$B7*'Fuel Composition'!$J$113/100 -> 0.72038531 | G7: =$B7*'Fuel Composition'!$J$114/100 -> 0.00058948742 | H7: =$B7*'Fuel Composition'!$J$115/100 -> 8.3591082e-05 | I7: =$B7*'Fuel Composition'!$J$116/100 -> 0.00086130968 | J7: =$B7*'Fuel Composition'!$J$117/100 -> 0.0041463866 | K7: =$B7*'Fuel Composition'!$J$118/100 -> 0.0011210823 | L7: =SUM(C7:J7) -> 0.7269804 | M7: 13
A8: 500000 | B8: =A8*'Loading Loss'!$I$5/2000 -> 3.3294673 | C8: =$B8*'Fuel Composition'!$J$110/100 -> 0.00017851486 | D8: =$B8*'Fuel Composition'!$J$111/100 -> 5.5515969e-06 | E8: =$B8*'Fuel Composition'!$J$112/100 -> 0.00027308971 | F8: =$B8*'Fuel Composition'!$J$113/100 -> 0.36019265 | G8: =$B8*'Fuel Composition'!$J$114/100 -> 0.00029474371 | H8: =$B8*'Fuel Composition'!$J$115/100 -> 4.1795541e-05 | I8: =$B8*'Fuel Composition'!$J$116/100 -> 0.00043065484 | J8: =$B8*'Fuel Composition'!$J$117/100 -> 0.0020731933 | K8: =$B8*'Fuel Composition'!$J$118/100 -> 0.00056054113 | L8: =SUM(C8:J8) -> 0.3634902 | M8: 20
A9: Ships
A10: 5000000 | B10: =A10*'Loading Loss'!$H$5/2000 -> 13.317869 | C10: =$B10*'Fuel Composition'!$J$110/100 -> 0.00071405945 | D10: =$B10*'Fuel Composition'!$J$111/100 -> 2.2206388e-05 | E10: =$B10*'Fuel Composition'!$J$112/100 -> 0.0010923588 | F10: =$B10*'Fuel Composition'!$J$113/100 -> 1.4407706 | G10: =$B10*'Fuel Composition'!$J$114/100 -> 0.0011789748 | H10: =$B10*'Fuel Composition'!$J$115/100 -> 0.00016718216 | I10: =$B10*'Fuel Composition'!$J$116/100 -> 0.0017226194 | J10: =$B10*'Fuel Composition'!$J$117/100 -> 0.0082927731 | K10: =$B10*'Fuel Composition'!$J$118/100 -> 0.0022421645 | L10: =SUM(C10:J10) -> 1.4539608 | M10: 1
A11: 1000000 | B11: =A11*'Loading Loss'!$H$5/2000 -> 2.6635738 | C11: =$B11*'Fuel Composition'!$J$110/100 -> 0.00014281189 | D11: =$B11*'Fuel Composition'!$J$111/100 -> 4.4412776e-06 | E11: =$B11*'Fuel Composition'!$J$112/100 -> 0.00021847177 | F11: =$B11*'Fuel Composition'!$J$113/100 -> 0.28815412 | G11: =$B11*'Fuel Composition'!$J$114/100 -> 0.00023579497 | H11: =$B11*'Fuel Composition'!$J$115/100 -> 3.3436433e-05 | I11: =$B11*'Fuel Composition'!$J$116/100 -> 0.00034452387 | J11: =$B11*'Fuel Composition'!$J$117/100 -> 0.0016585546 | K11: =$B11*'Fuel Composition'!$J$118/100 -> 0.00044843291 | L11: =SUM(C11:J11) -> 0.29079216 | M11: 13
A12: 500000 | B12: =A12*'Loading Loss'!$H$5/2000 -> 1.3317869 | C12: =$B12*'Fuel Composition'!$J$110/100 -> 7.1405945e-05 | D12: =$B12*'Fuel Composition'!$J$111/100 -> 2.2206388e-06 | E12: =$B12*'Fuel Composition'!$J$112/100 -> 0.00010923588 | F12: =$B12*'Fuel Composition'!$J$113/100 -> 0.14407706 | G12: =$B12*'Fuel Composition'!$J$114/100 -> 0.00011789748 | H12: =$B12*'Fuel Composition'!$J$115/100 -> 1.6718216e-05 | I12: =$B12*'Fuel Composition'!$J$116/100 -> 0.00017226194 | J12: =$B12*'Fuel Composition'!$J$117/100 -> 0.00082927731 | K12: =$B12*'Fuel Composition'!$J$118/100 -> 0.00022421645 | L12: =SUM(C12:J12) -> 0.14539608 | M12: 20
B19: Carbon Adsorber | I19: Recuperative Oxidizer
B20: Costs (2021 dollars) | F20: Cost Effectiveness ($/ton) | I20: Costs (2021 dollars) | L20: Cost Effectiveness ($/ton)
B21: Capital (TCI) | C21: Annual Costs | D21: Solvent Recovery Credit | E21: Total Annual Cost (TAC) | I21: Capital (TCI) | J21: Annual Costs | K21: Total Annual Cost (TAC)
A22: Typical MTVLO Facility | H22: Typical MTVLO Facility
A23: Barges | B23: 366104 | C23: =12830+58177 -> 71007 | D23: 1052 | E23: 69952 | H23: Barges | I23: 946560 | J23: =136556+123731 -> 260287 | K23: 260287
A24: 1000000 | F24: =$E$23/(L6-(L6*0.03)) -> 19839.727 | H24: 1000000 | L24: =$K$23/(L6-(L6*0.03)) -> 73822.379
A25: 500000 | F25: =$E$23/(L7-(L7*0.03)) -> 99198.636 | H25: 500000 | L25: =$K$23/(L7-(L7*0.03)) -> 369111.9
A26: 100000 | F26: =$E$23/(L8-(L8*0.03)) -> 198397.27 | H26: 100000 | L26: =$K$23/(L8-(L8*0.03)) -> 738223.79
A27: Ships | B27: 363797 | C27: =12486+57928 -> 70414 | D27: 422 | E27: 69991 | H27: Ships | I27: 946562 | J27: =136598+123731 -> 260329 | K27: 260329
A28: 1000000 | F28: =$E$27/(L10-(L10*0.03)) -> 49626.971 | H28: 1000000 | L28: =$K$27/(L10-(L10*0.03)) -> 184585.73
A29: 500000 | F29: =$E$27/(L11-(L11*0.03)) -> 248134.85 | H29: 500000 | L29: =$K$27/(L11-(L11*0.03)) -> 922928.64
A30: 100000 | F30: =$E$27/(L12-(L12*0.03)) -> 496269.71 | H30: 100000 | L30: =$K$27/(L12-(L12*0.03)) -> 1845857.3

Sheet Residual MP
A1: Loading Threshold (1000 gal/yr) | B1: Residual Fuel Oil (No. 6)
B2: Loading Loss (TPY) | C2: Emissions | J2: Number of Facilities Greater than Threshold
C3: Benzene (TPY) | D3: Ethylbenzene (TPY) | E3: Chlorine (TPY) | F3: Naphthalene (TPY) | G3: Toluene (TPY) | H3: Xylene (TPY) | I3: Total HAP (TPY)
A4: Typical MTVLO Facility
A5: Barges
A6: 1000000 | B6: =A6*'Loading Loss'!$I$6/2000 -> 4.5691625 | C6: =$B6*'Fuel Composition'!$J$135/100 -> 0.00089176772 | D6: =$B6*'Fuel Composition'!$J$136/100 -> 0.00018469367 | E6: =$B6*'Fuel Composition'!$J$137/100 -> 0.78473929 | F6: =$B6*'Fuel Composition'!$J$138/100 -> 0.00021416535 | G6: =$B6*'Fuel Composition'!$J$139/100 -> 0.0015534899 | H6: =$B6*'Fuel Composition'!$J$140/100 -> 0.0010042 | I6: =SUM(C6:H6) -> 0.78858761 | J6: 1
A7: 500000 | B7: =A7*'Loading Loss'!$I$6/2000 -> 2.2845813 | C7: =$B7*'Fuel Composition'!$J$135/100 -> 0.00044588386 | D7: =$B7*'Fuel Composition'!$J$136/100 -> 9.2346837e-05 | E7: =$B7*'Fuel Composition'!$J$137/100 -> 0.39236964 | F7: =$B7*'Fuel Composition'!$J$138/100 -> 0.00010708268 | G7: =$B7*'Fuel Composition'!$J$139/100 -> 0.00077674493 | H7: =$B7*'Fuel Composition'!$J$140/100 -> 0.00050209998 | I7: =SUM(C7:H7) -> 0.3942938 | J7: 4
A8: 100000 | B8: =A8*'Loading Loss'!$I$6/2000 -> 0.45691625 | C8: =$B8*'Fuel Composition'!$J$135/100 -> 8.9176772e-05 | D8: =$B8*'Fuel Composition'!$J$136/100 -> 1.8469367e-05 | E8: =$B8*'Fuel Composition'!$J$137/100 -> 0.078473929 | F8: =$B8*'Fuel Composition'!$J$138/100 -> 2.1416535e-05 | G8: =$B8*'Fuel Composition'!$J$139/100 -> 0.00015534899 | H8: =$B8*'Fuel Composition'!$J$140/100 -> 0.00010042 | I8: =SUM(C8:H8) -> 0.078858761 | J8: 25
A9: Ships
A10: 1000000 | B10: =A10*'Loading Loss'!$H$6/2000 -> 1.827665 | C10: =$B10*'Fuel Composition'!$J$135/100 -> 0.00035670709 | D10: =$B10*'Fuel Composition'!$J$136/100 -> 7.387747e-05 | E10: =$B10*'Fuel Composition'!$J$137/100 -> 0.31389572 | F10: =$B10*'Fuel Composition'!$J$138/100 -> 8.5666141e-05 | G10: =$B10*'Fuel Composition'!$J$139/100 -> 0.00062139594 | H10: =$B10*'Fuel Composition'!$J$140/100 -> 0.00040167998 | I10: =SUM(C10:H10) -> 0.31543504 | J10: 1
A11: 500000 | B11: =A11*'Loading Loss'!$H$6/2000 -> 0.91383251 | C11: =$B11*'Fuel Composition'!$J$135/100 -> 0.00017835354 | D11: =$B11*'Fuel Composition'!$J$136/100 -> 3.6938735e-05 | E11: =$B11*'Fuel Composition'!$J$137/100 -> 0.15694786 | F11: =$B11*'Fuel Composition'!$J$138/100 -> 4.2833071e-05 | G11: =$B11*'Fuel Composition'!$J$139/100 -> 0.00031069797 | H11: =$B11*'Fuel Composition'!$J$140/100 -> 0.00020083999 | I11: =SUM(C11:H11) -> 0.15771752 | J11: 4
A12: 100000 | B12: =A12*'Loading Loss'!$H$6/2000 -> 0.1827665 | C12: =$B12*'Fuel Composition'!$J$135/100 -> 3.5670709e-05 | D12: =$B12*'Fuel Composition'!$J$136/100 -> 7.387747e-06 | E12: =$B12*'Fuel Composition'!$J$137/100 -> 0.031389572 | F12: =$B12*'Fuel Composition'!$J$138/100 -> 8.5666141e-06 | G12: =$B12*'Fuel Composition'!$J$139/100 -> 6.2139594e-05 | H12: =$B12*'Fuel Composition'!$J$140/100 -> 4.0167998e-05 | I12: =SUM(C12:H12) -> 0.031543504 | J12: 25
B19: Carbon Adsorber | I19: Recuperative Oxidizer
B20: Costs (2021 dollars) | F20: Cost Effectiveness ($/ton) | I20: Costs (2021 dollars) | L20: Cost Effectiveness ($/ton)
B21: Capital (TCI) | C21: Annual Costs | D21: Solvent Recovery Credit | E21: Total Annual Cost (TAC) | I21: Capital (TCI) | J21: Annual Costs | K21: Total Annual Cost (TAC)
A22: Typical MTVLO Facility | H22: Typical MTVLO Facility
A23: Barges | B23: 364947 | C23: =12656+58052 -> 70708 | D23: 724 | E23: 69984 | H23: Barges | I23: 946561 | J23: =136586+123731 -> 260317 | K23: 260317
A24: 1000000 | F24: =$E$23/(I6-(I6*0.03)) -> 91490.727 | H24: 1000000 | L24: =$K$23/(I6-(I6*0.03)) -> 340314.81
A25: 500000 | F25: =$E$23/(I7-(I7*0.03)) -> 182981.45 | H25: 500000 | L25: =$K$23/(I7-(I7*0.03)) -> 680629.62
A26: 100000 | F26: =$E$23/(I8-(I8*0.03)) -> 914907.27 | H26: 100000 | L26: =$K$23/(I8-(I8*0.03)) -> 3403148.1
A27: Ships | B27: 363358 | C27: =12416+57881 -> 70297 | D27: 290 | E27: 70008 | H27: Ships | I27: 946562 | J27: =136609+123731 -> 260340 | K27: 260340
A28: 1000000 | F28: =$E$27/(I10-(I10*0.03)) -> 228805.26 | H28: 1000000 | L28: =$K$27/(I10-(I10*0.03)) -> 850862.2
A29: 500000 | F29: =$E$27/(I11-(I11*0.03)) -> 457610.51 | H29: 500000 | L29: =$K$27/(I11-(I11*0.03)) -> 1701724.4
A30: 100000 | F30: =$E$27/(I12-(I12*0.03)) -> 2288052.6 | H30: 100000 | L30: =$K$27/(I12-(I12*0.03)) -> 8508622

Sheet VP Costs
A1: Vapor Pressure Exemption Limit - $/Ton Removed
A2: Loading Thresholds (1000 gal/yr) | B2: Exemption < 1 psia | D2: Exemption < 0.5 psia | F2: No exemption | H2: Exemption < 1.5 psia (no change)
B3: Carbon Adsorber | C3: Recuperative Oxidizer | D3: Carbon Adsorber | E3: Recuperative Oxidizer | F3: Carbon Adsorber | G3: Recuperative Oxidizer | H3: Carbon Adsorber | I3: Recuperative Oxidizer
A4: Gasoline (No additional costs - VP exceeds current exemption threshold)
A5: Barges
A6: 5000000 | B6: ='Gasoline MP'!F24 -> 959.97256 | C6: ='Gasoline MP'!L24 -> 906.0357 | D6: =B6 -> 959.97256 | E6: =C6 -> 906.0357 | F6: =B6 -> 959.97256 | G6: =C6 -> 906.0357 | H6: =B6 -> 959.97256 | I6: =C6 -> 906.0357
A7: 1000000 | B7: ='Gasoline MP'!F25 -> 4799.8628 | C7: ='Gasoline MP'!L25 -> 4530.1785 | D7: =B7 -> 4799.8628 | E7: =C7 -> 4530.1785 | F7: =B7 -> 4799.8628 | G7: =C7 -> 4530.1785 | H7: =B7 -> 4799.8628 | I7: =C7 -> 4530.1785
A8: 500000 | B8: ='Gasoline MP'!F26 -> 9599.7256 | C8: ='Gasoline MP'!L26 -> 9060.357 | D8: =B8 -> 9599.7256 | E8: =C8 -> 9060.357 | F8: =B8 -> 9599.7256 | G8: =C8 -> 9060.357 | H8: =B8 -> 9599.7256 | I8: =C8 -> 9060.357
A9: 100000 | B9: ='Gasoline MP'!F27 -> 47998.628 | C9: ='Gasoline MP'!L27 -> 45301.785 | D9: =B9 -> 47998.628 | E9: =C9 -> 45301.785 | F9: =B9 -> 47998.628 | G9: =C9 -> 45301.785 | H9: =B9 -> 47998.628 | I9: =C9 -> 45301.785
A10: Ships
A11: 5000000 | B11: ='Gasoline MP'!F29 -> 780.16954 | C11: ='Gasoline MP'!L29 -> 1756.4104 | D11: =B11 -> 780.16954 | E11: =C11 -> 1756.4104 | F11: =B11 -> 780.16954 | G11: =C11 -> 1756.4104 | H11: =B11 -> 780.16954 | I11: =C11 -> 1756.4104
A12: 1000000 | B12: ='Gasoline MP'!F30 -> 3900.8477 | C12: ='Gasoline MP'!L30 -> 8782.052 | D12: =B12 -> 3900.8477 | E12: =C12 -> 8782.052 | F12: =B12 -> 3900.8477 | G12: =C12 -> 8782.052 | H12: =B12 -> 3900.8477 | I12: =C12 -> 8782.052
A13: 500000 | B13: ='Gasoline MP'!F31 -> 7801.6954 | C13: ='Gasoline MP'!L31 -> 17564.104 | D13: =B13 -> 7801.6954 | E13: =C13 -> 17564.104 | F13: =B13 -> 7801.6954 | G13: =C13 -> 17564.104 | H13: =B13 -> 7801.6954 | I13: =C13 -> 17564.104
A14: 100000 | B14: ='Gasoline MP'!F32 -> 39008.477 | C14: ='Gasoline MP'!L32 -> 87820.52 | D14: =B14 -> 39008.477 | E14: =C14 -> 87820.52 | F14: =B14 -> 39008.477 | G14: =C14 -> 87820.52 | H14: =B14 -> 39008.477 | I14: =C14 -> 87820.52 | K14: add in submerged fill costs
A15: Crude Oil (No additional costs - VP exceeds current exemption threshold) | K15: separate costs for the submerged fill and the controls
A16: Uncleaned
A17: 10000000 | B17: ='Crude Oil MP'!F30 -> 488.02664 | C17: ='Crude Oil MP'!L30 -> 595.36577 | D17: =B17 -> 488.02664 | E17: =C17 -> 595.36577 | F17: =B17 -> 488.02664 | G17: =C17 -> 595.36577 | H17: =B17 -> 488.02664 | I17: =C17 -> 595.36577
A18: 5000000 | B18: ='Crude Oil MP'!F31 -> 976.05327 | C18: ='Crude Oil MP'!L31 -> 1190.7315 | D18: =B18 -> 976.05327 | E18: =C18 -> 1190.7315 | F18: =B18 -> 976.05327 | G18: =C18 -> 1190.7315 | H18: =B18 -> 976.05327 | I18: =C18 -> 1190.7315
A19: 1000000 | B19: ='Crude Oil MP'!F32 -> 4880.2664 | C19: ='Crude Oil MP'!L32 -> 5953.6577 | D19: =B19 -> 4880.2664 | E19: =C19 -> 5953.6577 | F19: =B19 -> 4880.2664 | G19: =C19 -> 5953.6577 | H19: =B19 -> 4880.2664 | I19: =C19 -> 5953.6577
A20: 500000 | B20: ='Crude Oil MP'!F33 -> 9760.5327 | C20: ='Crude Oil MP'!L33 -> 11907.315 | D20: =B20 -> 9760.5327 | E20: =C20 -> 11907.315 | F20: =B20 -> 9760.5327 | G20: =C20 -> 11907.315 | H20: =B20 -> 9760.5327 | I20: =C20 -> 11907.315
A21: Ballasted
A22: 10000000 | B22: ='Crude Oil MP'!F35 -> 461.7579 | C22: ='Crude Oil MP'!L35 -> 720.13843 | D22: =B22 -> 461.7579 | E22: =C22 -> 720.13843 | F22: =B22 -> 461.7579 | G22: =C22 -> 720.13843 | H22: =B22 -> 461.7579 | I22: =C22 -> 720.13843
A23: 5000000 | B23: ='Crude Oil MP'!F36 -> 923.5158 | C23: ='Crude Oil MP'!L36 -> 1440.2769 | D23: =B23 -> 923.5158 | E23: =C23 -> 1440.2769 | F23: =B23 -> 923.5158 | G23: =C23 -> 1440.2769 | H23: =B23 -> 923.5158 | I23: =C23 -> 1440.2769
A24: 1000000 | B24: ='Crude Oil MP'!F37 -> 4617.579 | C24: ='Crude Oil MP'!L37 -> 7201.3843 | D24: =B24 -> 4617.579 | E24: =C24 -> 7201.3843 | F24: =B24 -> 4617.579 | G24: =C24 -> 7201.3843 | H24: =B24 -> 4617.579 | I24: =C24 -> 7201.3843
A25: 500000 | B25: ='Crude Oil MP'!F38 -> 9235.158 | C25: ='Crude Oil MP'!L38 -> 14402.769 | D25: =B25 -> 9235.158 | E25: =C25 -> 14402.769 | F25: =B25 -> 9235.158 | G25: =C25 -> 14402.769 | H25: =B25 -> 9235.158 | I25: =C25 -> 14402.769
A26: Cleaned/Gas-Freed
A27: 10000000 | B27: ='Crude Oil MP'!F40 -> 454.98661 | C27: ='Crude Oil MP'!L40 -> 772.07616 | D27: =B27 -> 454.98661 | E27: =C27 -> 772.07616 | F27: =B27 -> 454.98661 | G27: =C27 -> 772.07616 | H27: =B27 -> 454.98661 | I27: =C27 -> 772.07616
A28: 5000000 | B28: ='Crude Oil MP'!F41 -> 909.97322 | C28: ='Crude Oil MP'!L41 -> 1544.1523 | D28: =B28 -> 909.97322 | E28: =C28 -> 1544.1523 | F28: =B28 -> 909.97322 | G28: =C28 -> 1544.1523 | H28: =B28 -> 909.97322 | I28: =C28 -> 1544.1523
A29: 1000000 | B29: ='Crude Oil MP'!F42 -> 4549.8661 | C29: ='Crude Oil MP'!L42 -> 7720.7616 | D29: =B29 -> 4549.8661 | E29: =C29 -> 7720.7616 | F29: =B29 -> 4549.8661 | G29: =C29 -> 7720.7616 | H29: =B29 -> 4549.8661 | I29: =C29 -> 7720.7616
A30: 500000 | B30: ='Crude Oil MP'!F43 -> 9099.7322 | C30: ='Crude Oil MP'!L43 -> 15441.523 | D30: =B30 -> 9099.7322 | E30: =C30 -> 15441.523 | F30: =B30 -> 9099.7322 | G30: =C30 -> 15441.523 | H30: =B30 -> 9099.7322 | I30: =C30 -> 15441.523
A31: Benzene
A32: Barges
A33: 100000 | B33: 704.39851 | C33: 3034.6208 | D33: 704.39851 | E33: 3034.6208 | F33: 704.39851 | G33: 3034.6208 | H33: Exempt | I33: Exempt
A34: 50000 | B34: 1408.797 | C34: 17368.432 | D34: 1408.797 | E34: 17368.432 | F34: 1408.797 | G34: 17368.432 | H34: Exempt | I34: Exempt
A35: 5000 | B35: 14087.97 | C35: 173684.32 | D35: 14087.97 | E35: 173684.32 | F35: 14087.97 | G35: 173684.32 | H35: Exempt | I35: Exempt
A36: Ships
A37: 100000 | B37: 1530.1415 | C37: 7588.0387 | D37: 1530.1415 | E37: 7588.0387 | F37: 1530.1415 | G37: 7588.0387 | H37: Exempt | I37: Exempt
A38: 50000 | B38: 3060.283 | C38: 15176.077 | D38: 3060.283 | E38: 15176.077 | F38: 3060.283 | G38: 15176.077 | H38: Exempt | I38: Exempt
A39: 5000 | B39: 30602.83 | C39: 151760.77 | D39: 30602.83 | E39: 151760.77 | F39: 30602.83 | G39: 151760.77 | H39: Exempt | I39: Exempt
A40: Toluene
...

Sheet Threshold Costs
A1: Vapor Pressure Exemption Limit
A3: Loading Rate (bbl/hr) | B3: Lb/hr | C3: TPY (PTE) | D3: TPY (Actual) | E3: Actual Basis | G3: Potential To Emit
A4: Gasoline
A5: Barges | E5: Carbon Adsorber | F5: Recuperative Oxidizer | G5: Carbon Adsorber | H5: Recuperative Oxidizer
A6: 7500 | B6: ='Loading Loss'!$C$24*A6/42 -> 607.14286 | C6: =B6*8760*SUM('Fuel Composition'!$J$6:$J$13)/2000 -> 8777.7886 | D6: =B6*2080*SUM('Fuel Composition'!$J$6:$J$13)/2000 -> 2084.2238 | K6: =A6*2000/2080 -> 7211.5385 | L6: =A6*2000/8760 -> 1712.3288
A7: 5000 | B7: ='Loading Loss'!$C$24*A7/42 -> 404.7619 | C7: =B7*8760*SUM('Fuel Composition'!$J$6:$J$13)/2000 -> 5851.8591 | D7: =B7*2080*SUM('Fuel Composition'!$J$6:$J$13)/2000 -> 1389.4825 | K7: =A7*2000/2080 -> 4807.6923 | L7: =A7*2000/8760 -> 1141.5525 | O7: Tons/Yr Emissions | P7: Hours/yr | Q7: Tons Removed | R7: Annual Cost | S7: Cost/Ton Removed
A8: 2500 | B8: ='Loading Loss'!$C$24*A8/42 -> 202.38095 | C8: =B8*8760*SUM('Fuel Composition'!$J$6:$J$13)/2000 -> 2925.9295 | D8: =B8*2080*SUM('Fuel Composition'!$J$6:$J$13)/2000 -> 694.74126 | K8: =A8*2000/2080 -> 2403.8462 | L8: =A8*2000/8760 -> 570.77626 | O8: 1000 | P8: =O8*2000/'Loading Loss'!$N$24 -> 4941.1765 | Q8: =O8-(O8*0.03) -> 970
A9: 1000 | B9: ='Loading Loss'!$C$24*A9/42 -> 80.952381 | C9: =B9*8760*SUM('Fuel Composition'!$J$6:$J$13)/2000 -> 1170.3718 | D9: =B9*2080*SUM('Fuel Composition'!$J$6:$J$13)/2000 -> 277.8965 | K9: =A9*2000/2080 -> 961.53846 | L9: =A9*2000/8760 -> 228.3105 | O9: 500 | P9: =O9*2000/'Loading Loss'!$N$24 -> 2470.5882 | Q9: =O9-(O9*0.03) -> 485
A10: 500 | B10: ='Loading Loss'!$C$24*A10/42 -> 40.47619 | C10: =B10*8760*SUM('Fuel Composition'!$J$6:$J$13)/2000 -> 585.18591 | D10: =B10*2080*SUM('Fuel Composition'!$J$6:$J$13)/2000 -> 138.94825 | K10: =A10*2000/2080 -> 480.76923 | L10: =A10*2000/8760 -> 114.15525 | O10: 100 | P10: =O10*2000/'Loading Loss'!$N$24 -> 494.11765 | Q10: =O10-(O10*0.03) -> 97
A11: 100 | B11: ='Loading Loss'!$C$24*A11/42 -> 8.0952381 | C11: =B11*8760*SUM('Fuel Composition'!$J$6:$J$13)/2000 -> 117.03718 | D11: =B11*2080*SUM('Fuel Composition'!$J$6:$J$13)/2000 -> 27.78965 | K11: =A11*2000/2080 -> 96.153846 | L11: =A11*2000/8760 -> 22.83105 | O11: 50 | P11: =O11*2000/'Loading Loss'!$N$24 -> 247.05882 | Q11: =O11-(O11*0.03) -> 48.5
K12: =A12*2000/2080 -> 0 | L12: =A12*2000/8760 -> 0 | O12: 25 | P12: =O12*2000/'Loading Loss'!$N$24 -> 123.52941 | Q12: =O12-(O12*0.03) -> 24.25
K13: =A13*2000/2080 -> 0 | L13: =A13*2000/8760 -> 0 | O13: 10 | P13: =O13*2000/'Loading Loss'!$N$24 -> 49.411765 | Q13: =O13-(O13*0.03) -> 9.7
A14: Ships | O14: 5 | P14: =O14*2000/'Loading Loss'!$N$24 -> 24.705882 | Q14: =O14-(O14*0.03) -> 4.85
A15: 100 | C15: =A15-(A15*0.03) -> 97 | K15: =A15*2000/2080 -> 96.153846 | L15: =A15*2000/8760 -> 22.83105 | O15: 1 | P15: =O15*2000/'Loading Loss'!$N$24 -> 4.9411765 | Q15: =O15-(O15*0.03) -> 0.97
A16: 25 | C16: =A16-(A16*0.03) -> 24.25 | K16: =A16*2000/2080 -> 24.038462 | L16: =A16*2000/8760 -> 5.7077626
A17: 10 | C17: =A17-(A17*0.03) -> 9.7 | K17: =A17*2000/2080 -> 9.6153846 | L17: =A17*2000/8760 -> 2.283105
A18: 5 | C18: =A18-(A18*0.03) -> 4.85 | K18: =A18*2000/2080 -> 4.8076923 | L18: =A18*2000/8760 -> 1.1415525
A19: 1 | C19: =A19-(A19*0.03) -> 0.97 | K19: =A19*2000/2080 -> 0.96153846 | L19: =A19*2000/8760 -> 0.2283105
A20: Crude Oil
A21: Uncleaned
A22: 100 | C22: =A22-(A22*0.03) -> 97 | K22: =A22*2000/2080 -> 96.153846 | L22: =A22*2000/8760 -> 22.83105
A23: 25 | C23: =A23-(A23*0.03) -> 24.25 | K23: =A23*2000/2080 -> 24.038462 | L23: =A23*2000/8760 -> 5.7077626
A24: 10 | C24: =A24-(A24*0.03) -> 9.7 | K24: =A24*2000/2080 -> 9.6153846 | L24: =A24*2000/8760 -> 2.283105
A25: 5 | C25: =A25-(A25*0.03) -> 4.85 | K25: =A25*2000/2080 -> 4.8076923 | L25: =A25*2000/8760 -> 1.1415525
A26: 1 | C26: =A26-(A26*0.03) -> 0.97 | K26: =A26*2000/2080 -> 0.96153846 | L26: =A26*2000/8760 -> 0.2283105
A27: Ballasted
A28: 100 | C28: =A28-(A28*0.03) -> 97 | K28: =A28*2000/2080 -> 96.153846 | L28: =A28*2000/8760 -> 22.83105
A29: 25 | C29: =A29-(A29*0.03) -> 24.25 | K29: =A29*2000/2080 -> 24.038462 | L29: =A29*2000/8760 -> 5.7077626
A30: 10 | C30: =A30-(A30*0.03) -> 9.7 | K30: =A30*2000/2080 -> 9.6153846 | L30: =A30*2000/8760 -> 2.283105
A31: 5 | C31: =A31-(A31*0.03) -> 4.85 | K31: =A31*2000/2080 -> 4.8076923 | L31: =A31*2000/8760 -> 1.1415525
A32: 1 | C32: =A32-(A32*0.03) -> 0.97 | K32: =A32*2000/2080 -> 0.96153846 | L32: =A32*2000/8760 -> 0.2283105
A33: Cleaned/Gas-Freed
A34: 100 | C34: =A34-(A34*0.03) -> 97 | K34: =A34*2000/2080 -> 96.153846 | L34: =A34*2000/8760 -> 22.83105
A35: 25 | C35: =A35-(A35*0.03) -> 24.25 | K35: =A35*2000/2080 -> 24.038462 | L35: =A35*2000/8760 -> 5.7077626
A36: 10 | C36: =A36-(A36*0.03) -> 9.7 | K36: =A36*2000/2080 -> 9.6153846 | L36: =A36*2000/8760 -> 2.283105
A37: 5 | C37: =A37-(A37*0.03) -> 4.85 | K37: =A37*2000/2080 -> 4.8076923 | L37: =A37*2000/8760 -> 1.1415525
A38: 1 | C38: =A38-(A38*0.03) -> 0.97 | K38: =A38*2000/2080 -> 0.96153846 | L38: =A38*2000/8760 -> 0.2283105
A39: Benzene
A40: Barges
A41: 100 | C41: =A41-(A41*0.03) -> 97 | K41: =A41*2000/2080 -> 96.153846 | L41: =A41*2000/8760 -> 22.83105
...

Sheet Loading Loss
A1: Commodities | B1: Saturation Factor (S) | C1: Saturation Factor (S) | D1: True Vapor Pressure (P) | E1: Molecular Weight | F1: Temperature | G1: Density | H1: Loading Loss (ships) | I1: Loading Loss (Barges) | L1: Reid Vapor Pressure | M1: Loading Loss (ships) | N1: Loading Loss (Barges)
B2: ships | C2: barges | D2: psia | E2: lb/lb-mole | F2: °R | G2: lb/gal | H2: lb/1000 gal | I2: lb/1000 gal | L2: psia | M2: lb/hr | N2: lb/hr
A3: Naptha and Solvents | B3: 0.2 | C3: 0.5 | D3: 10.2 | E3: 128.1705 | F3: 527.67 | G3: 5.55 | H3: =12.46*(B3*D3*E3/F3) -> 6.1741032 | I3: =12.46*(C3*D3*E3/F3) -> 15.435258 | L3: 13 | M3: =H3*5000/42 -> 735.01229 | N3: =I3*5000/42 -> 1837.5307
A4: Kerosene | B4: 0.2 | C4: 0.5 | D4: 0.008 | E4: 162 | F4: 527.67 | G4: 6.82 | H4: =12.46*(B4*D4*E4/F4) -> 0.0061205526 | I4: =12.46*(C4*D4*E4/F4) -> 0.015301382 | L4: 9 | M4: =H4*5000/42 -> 0.72863722 | N4: =I4*5000/42 -> 1.821593
A5: Distillate Oil No. 2 | B5: 0.2 | C5: 0.5 | D5: 0.006 | E5: 188 | F5: 527.67 | G5: 7 | H5: =12.46*(B5*D5*E5/F5) -> 0.0053271476 | I5: =12.46*(C5*D5*E5/F5) -> 0.013317869 | L5: 0.1 | M5: =H5*5000/42 -> 0.63418424 | N5: =I5*5000/42 -> 1.5854606
A6: Residual Oil No. 6 | B6: 0.2 | C6: 0.5 | D6: 0.002 | E6: 387 | F6: 527.67 | G6: 8.3 | H6: =12.46*(B6*D6*E6/F6) -> 0.00365533 | I6: =12.46*(C6*D6*E6/F6) -> 0.0091383251 | L6: 0.1 | M6: =H6*5000/42 -> 0.43515834 | N6: =I6*5000/42 -> 1.0878958
A7: Benzene | B7: 0.2 | C7: 0.5 | D7: 1.86 | E7: 78.112 | F7: 527.67 | G7: 7.29 | H7: =12.46*(B7*D7*E7/F7) -> 0.68614568 | I7: =12.46*(C7*D7*E7/F7) -> 1.7153642 | L7: 1.4 | M7: =H7*5000/42 -> 81.68401 | N7: =I7*5000/42 -> 204.21003 | P7: =H7/1000/$G7*10000 -> 0.94121493 | Q7: =I7/1000/$G7*10000 -> 2.3530373
A8: Toluene | B8: 0.2 | C8: 0.5 | D8: 0.551 | E8: 92.141 | F8: 527.67 | G8: 7.2 | H8: =12.46*(B8*D8*E8/F8) -> 0.23976741 | I8: =12.46*(C8*D8*E8/F8) -> 0.59941853 | L8: 1.1 | M8: =H8*5000/42 -> 28.543739 | N8: =I8*5000/42 -> 71.359349 | P8: =H8/1000/$G8*10000 -> 0.33301029 | Q8: =I8/1000/$G8*10000 -> 0.83252573
A9: Methanol | B9: 0.2 | C9: 0.5 | D9: 1.856 | E9: 32.04 | F9: 527.67 | G9: 6.6 | H9: =12.46*(B9*D9*E9/F9) -> 0.28083816 | I9: =12.46*(C9*D9*E9/F9) -> 0.70209539 | L9: 1.8 | M9: =H9*5000/42 -> 33.433114 | N9: =I9*5000/42 -> 83.582785 | P9: =H9/1000/$G9*10000 -> 0.42551236 | Q9: =I9/1000/$G9*10000 -> 1.0637809
A10: Ethylene glycol | B10: 0.2 | C10: 0.5 | D10: 0.00102 | E10: 62.1 | F10: 527.67 | G10: 9.15 | H10: =12.46*(B10*D10*E10/F10) -> 0.00029914201 | I10: =12.46*(C10*D10*E10/F10) -> 0.00074785502 | L10: 0.01 | M10: =H10*5000/42 -> 0.035612144 | N10: =I10*5000/42 -> 0.08903036 | P10: =H10/1000/$G10*10000 -> 0.00032693116 | Q10: =I10/1000/$G10*10000 -> 0.00081732789
M13: *assume 5000 bbl/hr
B14: True Vapor Pressure (P) | C14: Molecular Weight | D14: Temperature | E14: Vapor Growth Factor | F14: CG | G14: Density | H14: Arrival Emission Factor (uncleaned) | I14: Arrival Emisson Factor (ballasted) | J14: Arrival Emisson Factor (cleaned or gas-freed)
B15: psia | C15: lb/lb-mole | D15: °R | G15: lb/gal | H15: lb/1000 gal | I15: lb/1000 gal | J15: lb/1000 gal
A16: Crude Oil (RVP5) | B16: ='Fuel Composition'!C52 -> 5.7618271 | C16: 207 | D16: 527.67 | E16: 1.02 | F16: =1.84*(0.44*B16-0.42)*(C16*E16/D16) -> 1.5573211 | G16: 7.21 | H16: 0.86 | I16: 0.46 | J16: 0.33
H17: Loading Loss (uncleaned) | I17: Loading Loss (Ballasted) | J17: Loading Loss (cleaned or gas-freed) | M17: Loading Loss (uncleaned) | N17: Loading Loss (Ballasted) | O17: Loading Loss (cleaned or gas-freed)
H18: lb/1000 gal | I18: lb/1000 gal | J18: lb/1000 gal | M18: lb/hr | N18: lb/hr | O18: lb/hr
H19: =$F$16+H16 -> 2.4173211 | I19: =$F$16+I16 -> 2.0173211 | J19: =$F$16+J16 -> 1.8873211 | L19: 5 | M19: =H19*5000/42 -> 287.77633 | N19: =I19*5000/42 -> 240.15728 | O19: =J19*5000/42 -> 224.68109
B22: Loading Loss (ships) | C22: Loading Loss (Barges) | D22: Density | M22: Loading Loss (ships) | N22: Loading Loss (Barges)
B23: lb/1000 gal | C23: lb/1000 gal | D23: lb/gal | M23: lb/hr | N23: lb/hr
A24: Gasoline (RVP 6) | B24: 1.8 | C24: 3.4 | D24: 6.26 | L24: 6 | M24: =B24*5000/42 -> 214.28571 | N24: =C24*5000/42 -> 404.7619

Sheet Fuel Composition
A2: API PERF data - Reformulated Gasoline (added Ethanol)
D3: wt%/wt frac liq | E3: n liq | F3: x | H3: y | J3: wt frac vapor | O3: Antoine Eqn coefficients
