Workbook
Name CRF: MonitoringOptCosts!$F$1

Sheet Assumptions
A1: Flare costs are in 2019$
A3: Considered the following options:
B4: Flare with continuous natural gas (NG) pilot [Baseline]
B5: Flare with continuous NG pilot + calorimeter + flow meter
B6: Flare with continuous NG pilot + simplified VISR
B7: Flare with consistent flare gas (14-day sampling option)
B8: Flare with once every 5-year performance evaluation
A10: Used $90,000 for simplified VISR based on information collected during call with Dr. Zeng on 4/4/2022.
A12: Converted to 2019$, that is $68,493 (based on 2019 CEPCI of 607.5 and 2022 CEPCI of 816.0)

Sheet MonitoringOptCosts
A1: Control Costs for Flares with monitoring options from OOOOb Storage Tank Analysis | E1: CRF | F1: 0.1098 | K1: Year | L1: CEPCI | N1: Year | O1: NG costs | P1: https://www.eia.gov/dnav/ng/hist/n3035us3m.htm
A2: Costs are in 2019$ | K2: 2019 | L2: 607.5 | N2: 2017 | O2: 4.0683333 | P2: $/Mscf
A3: Flare Size/Monitoring | B3: TCI | C3: AOC | D3: TAC | K3: 2020 | L3: 596.2 | N3: 2018 | O3: 3.8433333
A4: 1 - continuous pilot, NG | B4: 79352 | C4: 22840 | D4: =B4*CRF+C4 -> 31552.85 | K4: 2021 | L4: 708.8 | N4: 2019 | O4: 4.0558333
A5: 1 - flow+calorimeter | B5: 434667 | C5: 37052 | D5: =B5*CRF+C5 -> 84778.437 | F5: =B5-B4 -> 355315 | G5: =C5-C4 -> 14212 | H5: =D5-D4 -> 53225.587 | K5: 2022 | L5: 816 | N5: 2020 | O5: 5.4483333
A6: 1 - VISR | B6: 300141 | C6: 31671 | D6: =B6*CRF+C6 -> 64626.482 | F6: =B6-B4 -> 220789 | G6: =C6-C4 -> 8831 | H6: =D6-D4 -> 33073.632 | K6: 2023 | L6: 797.9 | N6: 2021 | O6: 3.2625
A7: 2 - continuous pilot, NG | B7: 84761 | C7: 23282 | D7: =B7*CRF+C7 -> 32588.758 | N7: 2022 | O7: 7.7625
A8: 2 - flow+calorimeter | B8: 440077 | C8: 37494 | D8: =B8*CRF+C8 -> 85814.455 | F8: =B8-B7 -> 355316 | G8: =C8-C7 -> 14212 | H8: =D8-D7 -> 53225.697 | N8: 2023 | O8: 4.4633333
A9: 2 - VISR | B9: 305551 | C9: 32114 | D9: =B9*CRF+C9 -> 65663.5 | F9: =B9-B7 -> 220790 | G9: =C9-C7 -> 8832 | H9: =D9-D7 -> 33074.742 | N9: 2024 | O9: 3.8841667
A10: 3 - continuous pilot, NG | B10: 92874 | C10: 23812 | D10: =B10*CRF+C10 -> 34009.565
A11: 3 - flow+calorimeter | B11: 448190 | C11: 38024 | D11: =B11*CRF+C11 -> 87235.262 | F11: =B11-B10 -> 355316 | G11: =C11-C10 -> 14212 | H11: =D11-D10 -> 53225.697
A12: 3 - VISR | B12: 313664 | C12: 32643 | D12: =B12*CRF+C12 -> 67083.307 | F12: =B12-B10 -> 220790 | G12: =C12-C10 -> 8831 | H12: =D12-D10 -> 33073.742
A13: 4 - continuous pilot, NG | B13: 145328 | C13: 33526 | D13: =B13*CRF+C13 -> 49483.014
A14: 4 - flow+calorimeter | B14: 500644 | C14: 47738 | D14: =B14*CRF+C14 -> 102708.71 | F14: =B14-B13 -> 355316 | G14: =C14-C13 -> 14212 | H14: =D14-D13 -> 53225.697
A15: 4 - VISR | B15: 366118 | C15: 42357 | D15: =B15*CRF+C15 -> 82556.756 | F15: =B15-B13 -> 220790 | G15: =C15-C13 -> 8831 | H15: =D15-D13 -> 33073.742
F18: Costs escalated to 2023$
A19: Added Costs | F19: TCI | G19: AOC | H19: TAC
A20: Flow and calorimeter | B20: =B5-B4 -> 355315 | C20: =C5-C4 -> 14212 | D20: =D5-D4 -> 53225.587 | F20: =B20*797.9/607.5 -> 466676.28 | G20: =C20*797.9/607.5 -> 18666.263 | H20: =D20*797.9/607.5 -> 69907.318
A21: VISR | B21: =B6-B4 -> 220789 | C21: =C6-C4 -> 8831 | D21: =D6-D4 -> 33073.632 | F21: =B21 -> 220789 | G21: =C21 -> 8831 | H21: =D21 -> 33073.632 | I21: Did not escalate since cost quote was from April 2022 and annual 2022 CEPCI was just slightly less than 2023.
A24: Control Costs for Flares with monitoring options for MTVLO
A25: Flare Size/Monitoring | B25: TCI | C25: AOC | D25: TAC
A26: Continuous pilot, NG | B26: 211648 | C26: 37623 | D26: =B26*CRF+C26 -> 60861.95
A27: Pilot plus flow and calorimeter | B27: 566964 | C27: 56342 | D27: =B27*CRF+C27 -> 118594.65
A28: Pilot plus calorimeter only | B28: 414648 | C28: 50249 | D28: =B28*CRF+C28 -> 95777.35
A29: Pilot plus VISR | B29: 379676 | C29: 48851 | D29: =B29*CRF+C29 -> 90539.425
F30: Costs escalated to 2023$
A31: Added Costs | F31: TCI | G31: AOC | H31: TAC | J31: Annual Cost Capital Only
A32: Flow and calorimeter | B32: =B27-B$26 -> 355316 | C32: =C27-C$26 -> 18719 | D32: =D27-D$26 -> 57732.697 | F32: =B32*$L$6/$L$2 -> 466677.59 | G32: =C32*$L$6/$L$2 -> 24585.827 | H32: =D32*$L$6/$L$2 -> 75827.027 | J32: =F32*CRF -> 51241.199
A33: Calorimeter only | B33: =B28-B$26 -> 203000 | C33: =C28-C$26 -> 12626 | D33: =D28-D$26 -> 34915.4 | F33: =B33*$L$6/$L$2 -> 266623.37 | G33: =C33*$L$6/$L$2 -> 16583.186 | H33: =D33*$L$6/$L$2 -> 45858.432 | J33: =F33*CRF -> 29275.247
A34: VISR | B34: =B29-B$26 -> 168028 | C34: =C29-C$26 -> 11228 | D34: =D29-D$26 -> 29677.474 | F34: =B34*$L$6/$L$2 -> 220690.6 | G34: =C34*$L$6/$L$2 -> 14747.031 | H34: =D34*$L$6/$L$2 -> 38978.859 | I34: Escalated here because used descalated 2019 costs for VISR in spreadsheet input. | J34: =F34*CRF -> 24231.828
A35: NG addition costs (for one-time assessment) | C35: 4507 | D35: 4507 | F35: =B35*$L$6/$L$2 -> 0 | G35: =C35*$L$6/$L$2 -> 5919.5643 | H35: =D35*$L$6/$L$2 -> 5919.5643
A38: Sampling costs | B38: 2023 costs | C38: basis | D38: reference | I38: Fully Loaded Hourly Tech rate | J38: 109.16 | K38: (from memo)
A39: Analysis cost | B39: =ROUNDUP(200*797.9/596.2,0) -> 268 | C39: $200 for GC analysis in 2020 | D39: Fee Schedule 2020 4-17-20 new
A40: Shipping and Handling | B40: 25 | I40: Interest Rate | J40: 0.075
A41: Labor (assuming 1 hr)) | B41: =1*$J$38 -> 109.16 | C41: includes sample collection, mailing, and data review | I41: Life | J41: 5 | K41: years
A42: Tax | B42: =SUM(B39:B41)*0.08 -> 32.1728 | C42: assumes 8% | I42: CRF | J42: =(J40*(1+J40)^J41)/(((1+J40)^J41)-1) -> 0.24716472
A43: Subtotal | B43: =SUM(B39:B42) -> 434.3328 | C43: per sample
A45: Cost of 14-day sampling option | D45: Sample Costs only
A46: No. of samples | B46: 14
A47: Total cost of demonstration | B47: =B46*B43 -> 6080.6592 | D47: =SUM(B39,B40,B42)*B46 -> 4552.4192
...

Sheet 2nd_Impacts
A1: Secondary Impacts | H1: Secondary Impact Factors | K1: Source
B2: Flow/flare (Mscf/yr) | H2: Natural Gas Usage | I2: 117 | J2: lb CO2/10^6 Btu | K2: Converted from Table C-1, 40 CFR part 98, subpart C
A3: NG usage increase for combustors | B3: =MonitoringOptCosts!B72 -> 368.1 | C3: See MonitoringOptCosts tab | H3: Natural Gas Usage | I3: 0.068 | J3: lb NOx/10^6 Btu | K3: AP-42 Table 13.5-1
A4: Natural Gas use increase for flare requirements | B4: 1088.6 | C4: Based on Cell C64 in "Design Parameters" tab for flare 101b cost sheets | H4: Natural Gas Usage | I4: 0.31 | J4: lb CO/10^6 Btu | K4: AP-42 Table 13.5-2
H5: Natural Gas Btu | I5: 1036 | J5: Btu/scf | K5: https://www.eia.gov/energyexplained/units-and-calculators/british-thermal-units.php
A7: National Impacts
B8: Flow/flare (MMscf/yr) | C8: CO2 tons/yr | D8: NOx tons/yr | E8: CO tons/yr
A9: Natural Gas use increase for theroal combustors | B9: =NationalCosts!$C$6*B3/1000 -> 36.81 | C9: =$B9*$I$5*$I2/2000 -> 2230.9069 | D9: =$B9*$I$5*$I3/2000 -> 1.2965954 | E9: =$B9*$I$5*$I4/2000 -> 5.9109498
A10: Natural Gas use increase for flare requirements | B10: =NationalCosts!$C$7*B4/1000 -> 54.43 | C10: =$B10*$I$5*$I2/2000 -> 3298.7846 | D10: =$B10*$I$5*$I3/2000 -> 1.9172423 | E10: =$B10*$I$5*$I4/2000 -> 8.7403694
A12: TOTAL | B12: =SUM(B9:B10) -> 91.24 | C12: =SUM(C9:C10) -> 5529.6914 | D12: =SUM(D9:D10) -> 3.2138378 | E12: =SUM(E9:E10) -> 14.651319

Sheet ElectronicReporting
A2: No.Facilities | B2: 190
A3: First year hrs | B3: 2 | C3: hours | E3: Interest Rate | F3: 0.075 | I3: 0.07
A4: First year cost | B4: =B$2*B3*MonitoringOptCosts!$J$38 -> 41480.8 | E4: Life | F4: 8 | G4: years | I4: 15
A5: Annualized | B5: =B4*F5 -> 7081.8935 | E5: CRF | F5: =(F3*(1+F3)^F4)/(((1+F3)^F4)-1) -> 0.17072702 | I5: =(I3*(1+I3)^I4)/(((1+I3)^I4)-1) -> 0.10979462
A7: Subsequent time saving | B7: 2 | C7: hours
A8: Cost | B8: =-B$2*B7*MonitoringOptCosts!$J$38 -> -41480.8
A10: TAC | B10: =B5+B8 -> -34398.906

Sheet NationalCosts
A1: National Costs | E1: Breakdown of Vapor Recovery Systems
E2: Monitor Type | F2: Fraction | G2: Number | H2: First Year Cost | I2: TCI | J2: AOC | K2: TAC
A3: Assumed Number of Controls1 | B3: 200 | E3: Currently testing annually | F3: 0.2 | G3: =F3*$C$5 -> 10 | H3: 0 | I3: 0 | J3: 0 | K3: 0
A4: Assumed Breakdown of Control | B4: Fraction | C4: Number | E4: Subject to periodic testing | F4: 0.6 | G4: =F4*$C$5 -> 30 | H4: =MonitoringOptCosts!B60 -> 25195.64 | I4: 0 | J4: 0 | K4: =MonitoringOptCosts!B61 -> 6227.4733
A5: - Vapor recovery systems | B5: 0.25 | C5: =$B$3*B5 -> 50 | E5: Subject to annual RATA | F5: =1-SUM(F3:F4) -> 0.2 | G5: =F5*$C$5 -> 10 | H5: 0 | I5: 0 | J5: =MonitoringOptCosts!B67 -> 19005.89 | K5: =J5 -> 19005.89
A6: - Thermal combustor (not flare) | B6: 0.5 | C6: =$B$3*B6 -> 100
A7: - Flare | B7: 0.25 | C7: =$B$3*B7 -> 50 | E7: Breakdown of Flares
E8: Monitor Type | F8: Fraction | G8: Number | H8: First Year Cost | I8: TCI | J8: AOC | K8: TAC
A9: 1 Some sources only require submerged loading but some may have multiple controls) | E9: NHV-flow monitor | F9: 0.04 | G9: =F9*$C$7 -> 2 | I9: =MonitoringOptCosts!F32 -> 466677.59 | J9: =MonitoringOptCosts!G32 -> 24585.827 | K9: =MonitoringOptCosts!H32 -> 75827.027
E10: NHV only | F10: 0.16 | G10: =F10*$C$7 -> 8 | I10: =MonitoringOptCosts!F33 -> 266623.37 | J10: =MonitoringOptCosts!G33 -> 16583.186 | K10: =MonitoringOptCosts!H33 -> 45858.432
E11: VISR | F11: 0 | G11: =F11*$C$7 -> 0 | I11: =MonitoringOptCosts!F34 -> 220690.6 | J11: =MonitoringOptCosts!G34 -> 14747.031 | K11: =MonitoringOptCosts!H34 -> 38978.859
E12: One-time assessment | F12: =1-SUM(F9:F11) -> 0.8 | G12: =F12*$C$7 -> 40 | H12: =MonitoringOptCosts!B47 -> 6080.6592 | I12: 0 | J12: =MonitoringOptCosts!G35 -> 5919.5643 | K12: =MonitoringOptCosts!B48+J12 -> 7422.4887
A14: Option | B14: First Year Cost | C14: Total Capital Investment, TCI ($) | D14: Annual Operating Cost, AOC ($/yr) | E14: Total Annualized Cost, TAC ($/yr) | F14: HAP Emissions Reduction (tpy) | G14: Cost-Effectiveness ($/ton HAP) | H14: VOC Emissions Reduction (tpy) | I14: Cost-Effectiveness ($/ton VOC) | J14: Comments
A15: Electronic Reporting | B15: =ElectronicReporting!B4 -> 41480.8 | D15: =ElectronicReporting!B8 -> -41480.8 | E15: =ElectronicReporting!B10 -> -34398.906
A16: Periodic Performance Testing/RATA | B16: =$C6*MonitoringOptCosts!$B60+SUMPRODUCT($G$3:$G$5,H3:H5) -> 3275433.2 | D16: =C6*MonitoringOptCosts!B62+SUMPRODUCT(G3:G5,J3:J5) -> 354354.2 | E16: =$C6*MonitoringOptCosts!$B61+D16+SUMPRODUCT(G3:G5,K3:K5) -> 1353984.6 | F16: =(C5+C6)*(B$22) -> 180 | G16: =$E16/F16 -> 7522.1368 | H16: =(C5+C6)*(B$22)*B21/B20 -> 2250 | I16: =$E16/H16 -> 601.77094 | J16: Assumes option improves average performance from 95% to 98%
A17: Enhanced Flare Monitoring | B17: =SUMPRODUCT($G9:$G12,H9:H12) -> 243226.37 | C17: =SUMPRODUCT($G9:$G12,I9:I12) -> 3066342.2 | D17: =SUMPRODUCT($G9:$G12,J9:J12) -> 418619.71 | E17: =SUMPRODUCT($G9:$G12,K9:K12) -> 815421.06 | F17: =C7*(B$23) -> 100 | G17: =$E17/F17 -> 8154.2106 | H17: =C7*(B$23)*B21/B20 -> 1250 | I17: =$E17/H17 -> 652.33685 | J17: Assumes option improves average performance from 94% to 99%
A18: Total | B18: =SUM(B15:B17) -> 3560140.4 | C18: =SUM(C15:C17) -> 3066342.2 | D18: =SUM(D15:D17) -> 731493.11 | E18: =SUM(E15:E17) -> 2135006.8 | F18: =SUM(F16:F17) -> 280 | G18: =($E16+$E17)/(F16+F17) -> 7747.8774 | H18: =SUM(H16:H17) -> 3500 | I18: =($E16+$E17)/(H16+H17) -> 619.8302
A20: Assumed per control inlet HAP loading | B20: 40 | C20: tons/year
A21: Assumed per control inlet VOC loading | B21: 500 | C21: tons/year
A22: HAP reductions at 3% CE improvement | B22: =B20*0.03 -> 1.2 | C22: tons/year/contol | G22: First year costs, excluding e-reporting | H22: =C17+B17+B16 -> 6585001.7
A23: HAP reductions at 5% CE improvement | B23: =B20*0.05 -> 2 | C23: tons/year/contol | G23: Total annualized costs, excluding e-reporting | H23: =E17+E16 -> 2169405.7
A25: Speciated HAP Emissions Reductions
A27: HAP | B27: % of total HAP | C27: Emission Reductions (tpy) for:
C28: Periodic Performance Test | D28: Enhanced Flare Monitoring | E28: Total
A29: Hexane | B29: 0.42 | C29: =B29*$F$16 -> 75.6 | D29: =B29*$F$17 -> 42 | E29: =C29+D29 -> 117.6
A30: Benzene | B30: 0.22 | C30: =B30*$F$16 -> 39.6 | D30: =B30*$F$17 -> 22 | E30: =C30+D30 -> 61.6
A31: Methanol | B31: 0.2 | C31: =B31*$F$16 -> 36 | D31: =B31*$F$17 -> 20 | E31: =C31+D31 -> 56
A32: Toluene | B32: 0.12 | C32: =B32*$F$16 -> 21.6 | D32: =B32*$F$17 -> 12 | E32: =C32+D32 -> 33.6
A33: Xylene | B33: 0.03 | C33: =B33*$F$16 -> 5.4 | D33: =B33*$F$17 -> 3 | E33: =C33+D33 -> 8.4
A34: Ethylbenzene | B34: 0.01 | C34: =B34*$F$16 -> 1.8 | D34: =B34*$F$17 -> 1 | E34: =C34+D34 -> 2.8
A35: Total HAP Reductions | C35: =SUM(C29:C34) -> 180 | D35: =SUM(D29:D34) -> 100 | E35: =SUM(E29:E34) -> 280
A38: Secondary Impacts
A39: National Impacts | B39: Flow/flare (MMscf/yr) | C39: CO2 tons/yr | D39: NOx tons/yr | E39: CO tons/yr
A40: Add'l NG usage for flares | B40: ='2nd_Impacts'!B9 -> 36.81 | C40: ='2nd_Impacts'!C9 -> 2230.9069 | D40: ='2nd_Impacts'!D9 -> 1.2965954 | E40: ='2nd_Impacts'!E9 -> 5.9109498
A41: Add'l NG usage for flares | B41: ='2nd_Impacts'!B10 -> 54.43 | C41: ='2nd_Impacts'!C10 -> 3298.7846 | D41: ='2nd_Impacts'!D10 -> 1.9172423 | E41: ='2nd_Impacts'!E10 -> 8.7403694
A42: Total | B42: =SUM(B40:B41) -> 91.24 | C42: =SUM(C40:C41) -> 5529.6914 | D42: =SUM(D40:D41) -> 3.2138378 | E42: =SUM(E40:E41) -> 14.651319
