Workbook

Sheet 1
A1: Start Time | B1: 45220
A2: End Time | B2: 46101
E3: =IF(C7<7/26/2024,"YES","")
C4: Start Time | D4: End Time | E4: CP-539 Recovered Flare Gas | F4: CP-540 Recovered Flare Gas | G4: Total Recovered Flare Gas | H4: Total Fuel Gas | I4: FWS #2 Feed OP | J4: FWS#2 SD | K4: FWS#2 OH Vapor | L4: FWS#2 OH Vapor (filtered) | M4: FWS #3 Feed | N4: FWS#3 SD | O4: FWS#3 OH Vapor | P4: FWS#3 OH Vapor (filtered) | Q4: Total FWS OH Rate | R4: Valve to FGR | S4: Valve to FWS TO | T4: Valve to FWS TO (clamped) | U4: Theoretical Percent Contribution FWS Vapor to FGR | V4: Actual Percent Contribution FWS Vapor to FGR | W4: FG H2S | X4: F19/20 NOx | Y4: F28-33 NOx | Z4: F34 NOx | AA4: F37 NOx | AB4: F55 NOx | AC4: F78 NOx | AD4: FWS TO SO2 (pre-7/26/2024) | AE4: FWS TO SO2 LO (post-7/26/2024) | AF4: FWS TO SO2 HI (post-7/26/2024) | AG4: FWS TO SO2 | AH4: F19 Firing Rate | AI4: F20 Firing Rate | AJ4: F28 Firing Rate | AK4: F29 Firing Rate | AL4: F30 Firign Rate | AM4: F31 Firing Rate | AN4: F32 Firing Rate | AO4: F33 Firing Rate | AP4: F34 Firing Rate | AQ4: F37 Firing Rate | AR4: F55 Firing Rate | AS4: F78 Firing Rate
E5: 019:F1143 | F5: 019:F1144 | G5: 019:F1164 | H5: 003:F4064 | I5: 018:F0113.OP | J5: calc | K5: 018:F0331 | L5: calc | M5: 018:F0450.OP | N5: calc | O5: 018:F0468 | P5: calc | Q5: Calc | R5: 018:Z0767B | S5: 018:Z0767A | T5: Calc | U5: Calc | V5: Calc | W5: 003:A4985A1 | X5: 004:A1161_F | Y5: 068:A1588A.C | Z5: 068:A1920_F | AA5: 069:A0733 | AB5: 076:A0423.C | AC5: 102:A0529 | AD5: 018:A1110 | AE5: 018:A1110A_ | AF5: 018:A1110C_ | AG5: calc | AH5: MTZ.RF.2HDO.F19.Firing Rate.Instant | AI5: MTZ.RF.2HDO.F20.Firing Rate.Instant | AJ5: MTZ.RF.1HDO.F28.Firing Rate.Instant | AK5: MTZ.RF.1HDO.F29.Firing Rate.Instant | AL5: MTZ.RF.1HDO.F30.Firing Rate.Instant | AM5: MTZ.RF.Isom.F31.Firing Rate.Instant | AN5: MTZ.RF.Isom.F32.Firing Rate.Instant | AO5: MTZ.RF.Isom.F33.Firing Rate.Instant | AP5: MTZ.RF.Isom.F34.Firing Rate.Instant | AQ5: MTZ.RF.1H2.F37.Firing Rate.Instant | AR5: MTZ.RF.3HDO.F55.Firing Rate.Instant | AS5: MTZ.RF.Hot Oil-DCU.F78.Firing Rate.Instant
E6: MMSCFD | F6: MMSCFD | G6: MMSCFD | H6: MMSCFD | I6: % | J6: -- | K6: MSCFD | L6: MSCFD | M6: % | N6: -- | O6: MSCFD | P6: MSCFD | Q6: MSCFD | R6: % | S6: % | T6: % | U6: % | V6: % | W6: ppm | X6: ppm | Y6: ppm | Z6: ppm | AA6: ppm | AB6: ppm | AC6: ppm | AD6: ppm | AE6: ppm | AF6: ppm | AG6: ppm
C7: {=_xll.PIAdvCalcDat('1'!$E$5,'1'!$B$1,'1'!$B$2,"1d","average (time-weighted)","time-weighted",0,1,193,"\\PI-MTZ")} -> 45220 | D7: 45221 | E7: 1.3541284 | F7: {=_xll.PIAdvCalcDat('1'!$F$5,'1'!$B$1,'1'!$B$2,"1d","average (time-weighted)","time-weighted",0,1,192,"\\PI-MTZ")} -> 2.4582566 | G7: {=_xll.PIAdvCalcDat('1'!$G$5,'1'!$B$1,'1'!$B$2,"1d","average (time-weighted)","time-weighted",0,1,192,"\\PI-MTZ")} -> 3.8133446 | H7: {=_xll.PIAdvCalcDat('1'!$H$5,'1'!$B$1,'1'!$B$2,"1d","average (time-weighted)","time-weighted",0,1,192,"\\PI-MTZ")} -> 4.4036317 | I7: {=_xll.PIAdvCalcDat('1'!$I$5,'1'!$B$1,'1'!$B$2,"1d","average (time-weighted)","time-weighted",0,1,192,"\\PI-MTZ")} -> 0 | J7: =IF(I7=0, "SD","RUN") -> SD | K7: {=_xll.PIAdvCalcDat('1'!$K$5,'1'!$B$1,'1'!$B$2,"1d","average (time-weighted)","time-weighted",0,1,0,"\\PI-MTZ")} -> 53.275358 | L7: =IF(J7="SD",0,K7) -> 0 | M7: {=_xll.PIAdvCalcDat('1'!$M$5,'1'!$B$1,'1'!$B$2,"1d","average (time-weighted)","time-weighted",0,1,0,"\\PI-MTZ")} -> 0 | N7: =IF(M7=0,"SD","RUN") -> SD | O7: {=_xll.PIAdvCalcDat('1'!$O$5,'1'!$B$1,'1'!$B$2,"1d","average (time-weighted)","time-weighted",0,1,0,"\\PI-MTZ")} -> 0 | P7: =IF(N7="SD",0,O7) -> 0 | Q7: =SUM(P7,L7) -> 0 | R7: {=_xll.PIAdvCalcDat('1'!$R$5,'1'!$B$1,'1'!$B$2,"1d","average (time-weighted)","time-weighted",0,1,0,"\\PI-MTZ")} -> -1.2673586 | S7: {=_xll.PIAdvCalcDat('1'!$S$5,'1'!$B$1,'1'!$B$2,"1d","average (time-weighted)","time-weighted",0,1,0,"\\PI-MTZ")} -> -0.48548037 | T7: =IF(S7<0, 0, S7) -> 0 | U7: =IF(G7<0.1, 0, (Q7/(G7*1000))*100) -> 0 | V7: =IF(G7<0.1, 0, IF(R7<=0,0,Q7*(R7/(R7+T7))/(G7*1000)*100)) -> 0 | W7: {=_xll.PIAdvCalcDat('1'!$W$5,'1'!$B$1,'1'!$B$2,"1d","average (time-weighted)","time-weighted",0,1,0,"\\PI-MTZ")} -> 0 | X7: {=_xll.PIAdvCalcDat('1'!$X$5,'1'!$B$1,'1'!$B$2,"1d","average (time-weighted)","time-weighted",0,1,0,"\\PI-MTZ")} -> 0.11351776 | Y7: {=_xll.PIAdvCalcDat('1'!$Y$5,'1'!$B$1,'1'!$B$2,"1d","average (time-weighted)","time-weighted",0,1,0,"\\PI-MTZ")} -> 1.8329176 | Z7: {=_xll.PIAdvCalcDat('1'!$Z$5,'1'!$B$1,'1'!$B$2,"1d","average (time-weighted)","time-weighted",0,1,0,"\\PI-MTZ")} -> [-11059] No Good Data For Calculation | AA7: {=_xll.PIAdvCalcDat('1'!$AA$5,'1'!$B$1,'1'!$B$2,"1d","average (time-weighted)","time-weighted",0,1,0,"\\PI-MTZ")} -> -9.9804555 | AB7: {=_xll.PIAdvCalcDat('1'!$AB$5,'1'!$B$1,'1'!$B$2,"1d","average (time-weighted)","time-weighted",0,1,0,"\\PI-MTZ")} -> -0.025440409 | AC7: {=_xll.PIAdvCalcDat('1'!$AC$5,'1'!$B$1,'1'!$B$2,"1d","average (time-weighted)","time-weighted",0,1,0,"\\PI-MTZ")} -> 7.2109463 | AD7: {=_xll.PIAdvCalcDat('1'!$AD$5,'1'!$B$1,'1'!$B$2,"1d","average (time-weighted)","time-weighted",0,1,0,"\\PI-MTZ")} -> 0.6173241 | AE7: {=_xll.PIAdvCalcDat('1'!$AE$5,'1'!$B$1,'1'!$B$2,"1d","average (time-weighted)","time-weighted",0,1,0,"\\PI-MTZ")} -> [-11059] No Good Data For Calculation | AF7: {=_xll.PIAdvCalcDat('1'!$AF$5,'1'!$B$1,'1'!$B$2,"1d","average (time-weighted)","time-weighted",0,1,0,"\\PI-MTZ")} -> [-11059] No Good Data For Calculation | AG7: =IF(C7<DATE(2024,7,26), AD7, IF(AE7<100, AE7, AF7)) -> 0.6173241 | AH7: {=_xll.PIAdvCalcDat('1'!$AH$5,'1'!$B$1,'1'!$B$2,"1d","average (time-weighted)","time-weighted",0,1,0,"\\PI-MTZ")} -> 0.020194057 | AI7: {=_xll.PIAdvCalcDat('1'!$AI$5,'1'!$B$1,'1'!$B$2,"1d","average (time-weighted)","time-weighted",0,1,0,"\\PI-MTZ")} -> 0.36017735 | AJ7: {=_xll.PIAdvCalcDat('1'!$AJ$5,'1'!$B$1,'1'!$B$2,"1d","average (time-weighted)","time-weighted",0,1,0,"\\PI-MTZ")} -> 0.0029484771 | AK7: {=_xll.PIAdvCalcDat('1'!$AK$5,'1'!$B$1,'1'!$B$2,"1d","average (time-weighted)","time-weighted",0,1,0,"\\PI-MTZ")} -> [-11059] No Good Data For Calculation | AL7: {=_xll.PIAdvCalcDat('1'!$AL$5,'1'!$B$1,'1'!$B$2,"1d","average (time-weighted)","time-weighted",0,1,0,"\\PI-MTZ")} -> 0.016108204 | AM7: {=_xll.PIAdvCalcDat('1'!$AM$5,'1'!$B$1,'1'!$B$2,"1d","average (time-weighted)","time-weighted",0,1,0,"\\PI-MTZ")} -> 0 | AN7: {=_xll.PIAdvCalcDat('1'!$AN$5,'1'!$B$1,'1'!$B$2,"1d","average (time-weighted)","time-weighted",0,1,0,"\\PI-MTZ")} -> 4.0919823 | AO7: {=_xll.PIAdvCalcDat('1'!$AO$5,'1'!$B$1,'1'!$B$2,"1d","average (time-weighted)","time-weighted",0,1,0,"\\PI-MTZ")} -> 4.0428763 | AP7: {=_xll.PIAdvCalcDat('1'!$AP$5,'1'!$B$1,'1'!$B$2,"1d","average (time-weighted)","time-weighted",0,1,0,"\\PI-MTZ")} -> 0.010865762 | AQ7: {=_xll.PIAdvCalcDat('1'!$AQ$5,'1'!$B$1,'1'!$B$2,"1d","average (time-weighted)","time-weighted",0,1,0,"\\PI-MTZ")} -> 6.604352 | AR7: {=_xll.PIAdvCalcDat('1'!$AR$5,'1'!$B$1,'1'!$B$2,"1d","average (time-weighted)","time-weighted",0,1,0,"\\PI-MTZ")} -> 1.0617424 | AS7: {=_xll.PIAdvCalcDat('1'!$AS$5,'1'!$B$1,'1'!$B$2,"1d","average (time-weighted)","time-weighted",0,1,0,"\\PI-MTZ")} -> 149.4295
C8: 45221 | D8: 45222 | E8: 1.3117768 | F8: 2.4098477 | G8: 3.7207689 | H8: 4.1926003 | I8: 0 | J8: =IF(I8=0, "SD","RUN") -> SD | K8: 53.388433 | L8: =IF(J8="SD",0,K8) -> 0 | M8: 0 | N8: =IF(M8=0,"SD","RUN") -> SD | O8: 0 | P8: =IF(N8="SD",0,O8) -> 0 | Q8: =SUM(P8,L8) -> 0 | R8: -1.2341139 | S8: -0.54571297 | T8: =IF(S8<0, 0, S8) -> 0 | U8: =IF(G8<0.1, 0, (Q8/(G8*1000))*100) -> 0 | V8: =IF(G8<0.1, 0, IF(R8<=0,0,Q8*(R8/(R8+T8))/(G8*1000)*100)) -> 0 | W8: 0 | X8: 0.11351776 | Y8: 1.8810868 | Z8: [-11059] No Good Data For Calculation | AA8: -9.9746094 | AB8: -0.026360684 | AC8: 0.77267335 | AD8: 0.75672299 | AE8: [-11059] No Good Data For Calculation | AF8: [-11059] No Good Data For Calculation | AG8: =IF(C8<DATE(2024,7,26), AD8, IF(AE8<100, AE8, AF8)) -> 0.75672299 | AH8: 0 | AI8: 0.56575199 | AJ8: 0.0030502627 | AK8: [-11059] No Good Data For Calculation | AL8: 0.014960501 | AM8: 0 | AN8: 2.5357515 | AO8: 2.6603706 | AP8: 0.018944361 | AQ8: 6.7852938 | AR8: 1.0372013 | AS8: 145.58442
C9: 45222 | D9: 45223 | E9: 1.061815 | F9: 1.8105921 | G9: 2.8724273 | H9: 2.8580881 | I9: 0 | J9: =IF(I9=0, "SD","RUN") -> SD | K9: 53.159873 | L9: =IF(J9="SD",0,K9) -> 0 | M9: 0 | N9: =IF(M9=0,"SD","RUN") -> SD | O9: 0 | P9: =IF(N9="SD",0,O9) -> 0 | Q9: =SUM(P9,L9) -> 0 | R9: -1.2435659 | S9: -0.49510833 | T9: =IF(S9<0, 0, S9) -> 0 | U9: =IF(G9<0.1, 0, (Q9/(G9*1000))*100) -> 0 | V9: =IF(G9<0.1, 0, IF(R9<=0,0,Q9*(R9/(R9+T9))/(G9*1000)*100)) -> 0 | W9: 0 | X9: 0.11351776 | Y9: 1.9292559 | Z9: [-11059] No Good Data For Calculation | AA9: -9.9746094 | AB9: 1.2324543 | AC9: 0.63634123 | AD9: 0.88520059 | AE9: [-11059] No Good Data For Calculation | AF9: [-11059] No Good Data For Calculation | AG9: =IF(C9<DATE(2024,7,26), AD9, IF(AE9<100, AE9, AF9)) -> 0.88520059 | AH9: 0.019284098 | AI9: 0.61634966 | AJ9: 0.0027827542 | AK9: [-11059] No Good Data For Calculation | AL9: 0.011884197 | AM9: 0 | AN9: 0.12886576 | AO9: 0 | AP9: 0.018856411 | AQ9: 6.807873 | AR9: 2.9142594 | AS9: 131.7098
C10: 45223 | D10: 45224 | E10: 1.0640019 | F10: 2.0532206 | G10: 3.1168696 | H10: 2.3539679 | I10: 0 | J10: =IF(I10=0, "SD","RUN") -> SD | K10: 53.200324 | L10: =IF(J10="SD",0,K10) -> 0 | M10: 0 | N10: =IF(M10=0,"SD","RUN") -> SD | O10: 0 | P10: =IF(N10="SD",0,O10) -> 0 | Q10: =SUM(P10,L10) -> 0 | R10: -1.161537 | S10: -0.50298132 | T10: =IF(S10<0, 0, S10) -> 0 | U10: =IF(G10<0.1, 0, (Q10/(G10*1000))*100) -> 0 | V10: =IF(G10<0.1, 0, IF(R10<=0,0,Q10*(R10/(R10+T10))/(G10*1000)*100)) -> 0 | W10: 0 | X10: 0.11351776 | Y10: 1.9774251 | Z10: [-11059] No Good Data For Calculation | AA10: -9.9746094 | AB10: 5.9925369 | AC10: 0.23737277 | AD10: 0.69563194 | AE10: [-11059] No Good Data For Calculation | AF10: [-11059] No Good Data For Calculation | AG10: =IF(C10<DATE(2024,7,26), AD10, IF(AE10<100, AE10, AF10)) -> 0.69563194 | AH10: 0.0034243149 | AI10: 0.40556352 | AJ10: 0.0027170762 | AK10: [-11059] No Good Data For Calculation | AL10: 0.01094486 | AM10: 0 | AN10: 0 | AO10: 0 | AP10: 0.01893079 | AQ10: 6.7619999 | AR10: 8.3131673 | AS10: 136.12862
C11: 45224 | D11: 45225 | E11: 1.5135437 | F11: 2.7959353 | G11: 4.3094714 | H11: 2.2433298 | I11: 0 | J11: =IF(I11=0, "SD","RUN") -> SD | K11: 53.451409 | L11: =IF(J11="SD",0,K11) -> 0 | M11: 0 | N11: =IF(M11=0,"SD","RUN") -> SD | O11: 0.0011688512 | P11: =IF(N11="SD",0,O11) -> 0 | Q11: =SUM(P11,L11) -> 0 | R11: -1.1658707 | S11: -0.58437927 | T11: =IF(S11<0, 0, S11) -> 0 | U11: =IF(G11<0.1, 0, (Q11/(G11*1000))*100) -> 0 | V11: =IF(G11<0.1, 0, IF(R11<=0,0,Q11*(R11/(R11+T11))/(G11*1000)*100)) -> 0 | W11: 0.312632 | X11: 0.60534743 | Y11: 2.0255943 | Z11: [-11059] No Good Data For Calculation | AA11: -9.9746094 | AB11: 0.054986676 | AC11: 0.16928976 | AD11: 0.67401491 | AE11: [-11059] No Good Data For Calculation | AF11: [-11059] No Good Data For Calculation | AG11: =IF(C11<DATE(2024,7,26), AD11, IF(AE11<100, AE11, AF11)) -> 0.67401491 | AH11: 0 | AI11: 0.072162329 | AJ11: 0.0030222159 | AK11: [-11059] No Good Data For Calculation | AL11: 0.010637521 | AM11: 0 | AN11: 0 | AO11: 0 | AP11: 0.019061078 | AQ11: 8.1797202 | AR11: 11.98106 | AS11: 144.28275
C12: 45225 | D12: 45226 | E12: 1.6765536 | F12: 3.3234423 | G12: 4.9995986 | H12: 1.4592365 | I12: 0 | J12: =IF(I12=0, "SD","RUN") -> SD | K12: 53.291623 | L12: =IF(J12="SD",0,K12) -> 0 | M12: 0 | N12: =IF(M12=0,"SD","RUN") -> SD | O12: 0 | P12: =IF(N12="SD",0,O12) -> 0 | Q12: =SUM(P12,L12) -> 0 | R12: -1.2279552 | S12: -0.60437117 | T12: =IF(S12<0, 0, S12) -> 0 | U12: =IF(G12<0.1, 0, (Q12/(G12*1000))*100) -> 0 | V12: =IF(G12<0.1, 0, IF(R12<=0,0,Q12*(R12/(R12+T12))/(G12*1000)*100)) -> 0 | W12: 10.440411 | X12: 0.38933056 | Y12: 2.0737635 | Z12: [-11059] No Good Data For Calculation | AA12: -9.9746094 | AB12: 0.77209927 | AC12: 0.61866117 | AD12: 0.68446454 | AE12: [-11059] No Good Data For Calculation | AF12: [-11059] No Good Data For Calculation | AG12: =IF(C12<DATE(2024,7,26), AD12, IF(AE12<100, AE12, AF12)) -> 0.68446454 | AH12: 0.03765269 | AI12: 0.17502404 | AJ12: 0.004134906 | AK12: [-11059] No Good Data For Calculation | AL12: 0.012131829 | AM12: 0 | AN12: 0 | AO12: 0 | AP12: 0.057194616 | AQ12: 11.218343 | AR12: 35.162613 | AS12: 170.35774
C13: 45226 | D13: 45227 | E13: 1.3927046 | F13: 2.6481849 | G13: 4.0408133 | H13: 1.1110957 | I13: 0 | J13: =IF(I13=0, "SD","RUN") -> SD | K13: 53.315487 | L13: =IF(J13="SD",0,K13) -> 0 | M13: 0 | N13: =IF(M13=0,"SD","RUN") -> SD | O13: 1.044966 | P13: =IF(N13="SD",0,O13) -> 0 | Q13: =SUM(P13,L13) -> 0 | R13: -1.1627435 | S13: -0.54443043 | T13: =IF(S13<0, 0, S13) -> 0 | U13: =IF(G13<0.1, 0, (Q13/(G13*1000))*100) -> 0 | V13: =IF(G13<0.1, 0, IF(R13<=0,0,Q13*(R13/(R13+T13))/(G13*1000)*100)) -> 0 | W13: 7.1302374 | X13: 0.14679896 | Y13: 2.3438356 | Z13: 0.36047004 | AA13: -3.2304128 | AB13: 0.10029583 | AC13: 0.32380166 | AD13: 0.6671807 | AE13: [-11059] No Good Data For Calculation | AF13: [-11059] No Good Data For Calculation | AG13: =IF(C13<DATE(2024,7,26), AD13, IF(AE13<100, AE13, AF13)) -> 0.6671807 | AH13: 0.031094611 | AI13: 0.089821723 | AJ13: 0.0054039059 | AK13: [-11059] No Good Data For Calculation | AL13: 0.013669627 | AM13: 0 | AN13: 0 | AO13: 0 | AP13: 0.059515011 | AQ13: 11.538799 | AR13: 22.846435 | AS13: 174.7426
C14: 45227 | D14: 45228 | E14: 1.1048867 | F14: 1.8957259 | G14: 3.0010174 | H14: 0.78840597 | I14: 0 | J14: =IF(I14=0, "SD","RUN") -> SD | K14: 53.282516 | L14: =IF(J14="SD",0,K14) -> 0 | M14: 0 | N14: =IF(M14=0,"SD","RUN") -> SD | O14: 0.91768648 | P14: =IF(N14="SD",0,O14) -> 0 | Q14: =SUM(P14,L14) -> 0 | R14: 2.7388408 | S14: -0.53885523 | T14: =IF(S14<0, 0, S14) -> 0 | U14: =IF(G14<0.1, 0, (Q14/(G14*1000))*100) -> 0 | V14: =IF(G14<0.1, 0, IF(R14<=0,0,Q14*(R14/(R14+T14))/(G14*1000)*100)) -> 0 | W14: 0 | X14: 0.1329234 | Y14: 5.3378752 | Z14: 0.036964417 | AA14: 0.63591953 | AB14: -0.02919831 | AC14: 0.31271883 | AD14: 0.72145518 | AE14: [-11059] No Good Data For Calculation | AF14: [-11059] No Good Data For Calculation | AG14: =IF(C14<DATE(2024,7,26), AD14, IF(AE14<100, AE14, AF14)) -> 0.72145518 | AH14: 0.019786169 | AI14: 0.11603021 | AJ14: 0.013922225 | AK14: 12.972394 | AL14: 0.031849177 | AM14: 0.51955625 | AN14: 0 | AO14: 0.80685773 | AP14: 0.059452649 | AQ14: 23.819466 | AR14: 1.5703473 | AS14: 175.92639
C15: 45228 | D15: 45229 | E15: 1.1178139 | F15: 1.8821708 | G15: 2.9998518 | H15: 1.2602867 | I15: 0 | J15: =IF(I15=0, "SD","RUN") -> SD | K15: 53.224019 | L15: =IF(J15="SD",0,K15) -> 0 | M15: 0 | N15: =IF(M15=0,"SD","RUN") -> SD | O15: 12.69572 | P15: =IF(N15="SD",0,O15) -> 0 | Q15: =SUM(P15,L15) -> 0 | R15: -1.1909603 | S15: -0.51064265 | T15: =IF(S15<0, 0, S15) -> 0 | U15: =IF(G15<0.1, 0, (Q15/(G15*1000))*100) -> 0 | V15: =IF(G15<0.1, 0, IF(R15<=0,0,Q15*(R15/(R15+T15))/(G15*1000)*100)) -> 0 | W15: 0 | X15: 0.14350893 | Y15: 3.2723407 | Z15: 0.036964417 | AA15: 5.8944524 | AB15: -0.030383204 | AC15: 3.8665909 | AD15: 0.76402989 | AE15: [-11059] No Good Data For Calculation | AF15: [-11059] No Good Data For Calculation | AG15: =IF(C15<DATE(2024,7,26), AD15, IF(AE15<100, AE15, AF15)) -> 0.76402989 | AH15: 0.019338779 | AI15: 0.24968209 | AJ15: 0.016269662 | AK15: 0.57176115 | AL15: 0.03450467 | AM15: 0.61306729 | AN15: 0.085008313 | AO15: 0.55760054 | AP15: 0.059082484 | AQ15: 76.548475 | AR15: 1.7081737 | AS15: 185.0658
C16: 45229 | D16: 45230 | E16: 1.1334372 | F16: 1.8671335 | G16: 2.9999565 | H16: 1.4671687 | I16: 0 | J16: =IF(I16=0, "SD","RUN") -> SD | K16: 53.15796 | L16: =IF(J16="SD",0,K16) -> 0 | M16: 0 | N16: =IF(M16=0,"SD","RUN") -> SD | O16: 48.801844 | P16: =IF(N16="SD",0,O16) -> 0 | Q16: =SUM(P16,L16) -> 0 | R16: 19.379117 | S16: -0.57819047 | T16: =IF(S16<0, 0, S16) -> 0 | U16: =IF(G16<0.1, 0, (Q16/(G16*1000))*100) -> 0 | V16: =IF(G16<0.1, 0, IF(R16<=0,0,Q16*(R16/(R16+T16))/(G16*1000)*100)) -> 0 | W16: 0 | X16: 0.29435355 | Y16: 8.5517182 | Z16: 0.036964417 | AA16: 9.2228334 | AB16: 0.60852737 | AC16: 1.1026729 | AD16: 3.3389538 | AE16: [-11059] No Good Data For Calculation | AF16: [-11059] No Good Data For Calculation | AG16: =IF(C16<DATE(2024,7,26), AD16, IF(AE16<100, AE16, AF16)) -> 3.3389538 | AH16: 0.020784289 | AI16: 0.19065348 | AJ16: 0.017297717 | AK16: 0 | AL16: 0.03417169 | AM16: 3.396825 | AN16: 0.93064393 | AO16: 4.1754161 | AP16: 0.059271908 | AQ16: 99.932244 | AR16: 10.575209 | AS16: 196.36927
C17: 45230 | D17: 45231 | E17: 1.0167018 | F17: 1.730331 | G17: 2.7463881 | H17: 1.2623507 | I17: 0 | J17: =IF(I17=0, "SD","RUN") -> SD | K17: 53.155078 | L17: =IF(J17="SD",0,K17) -> 0 | M17: 0 | N17: =IF(M17=0,"SD","RUN") -> SD | O17: 2.0326655 | P17: =IF(N17="SD",0,O17) -> 0 | Q17: =SUM(P17,L17) -> 0 | R17: 15.181686 | S17: -0.49832176 | T17: =IF(S17<0, 0, S17) -> 0 | U17: =IF(G17<0.1, 0, (Q17/(G17*1000))*100) -> 0 | V17: =IF(G17<0.1, 0, IF(R17<=0,0,Q17*(R17/(R17+T17))/(G17*1000)*100)) -> 0 | W17: 0 | X17: 0.092234282 | Y17: 13.671412 | Z17: 0.041688105 | AA17: 10.654265 | AB17: 0.82660107 | AC17: 0.41849222 | AD17: 0.72434378 | AE17: [-11059] No Good Data For Calculation | AF17: [-11059] No Good Data For Calculation | AG17: =IF(C17<DATE(2024,7,26), AD17, IF(AE17<100, AE17, AF17)) -> 0.72434378 | AH17: 0.004707452 | AI17: 0.2341813 | AJ17: 0.016143255 | AK17: 0 | AL17: 0.031185833 | AM17: 2.5470236 | AN17: 1.7904225 | AO17: 2.8287185 | AP17: 0.059160236 | AQ17: 141.07256 | AR17: 39.590915 | AS17: 202.41212
C18: 45231 | D18: 45232 | E18: 0.75947814 | F18: 1.3479378 | G18: 2.1071481 | H18: 1.795185 | I18: 0 | J18: =IF(I18=0, "SD","RUN") -> SD | K18: 53.290913 | L18: =IF(J18="SD",0,K18) -> 0 | M18: 7.0237557 | N18: =IF(M18=0,"SD","RUN") -> RUN | O18: 5.2409495 | P18: =IF(N18="SD",0,O18) -> 5.2409495 | Q18: =SUM(P18,L18) -> 5.2409495 | R18: 14.591598 | S18: 3.9767045 | T18: =IF(S18<0, 0, S18) -> 3.9767045 | U18: =IF(G18<0.1, 0, (Q18/(G18*1000))*100) -> 0.24872241 | V18: =IF(G18<0.1, 0, IF(R18<=0,0,Q18*(R18/(R18+T18))/(G18*1000)*100)) -> 0.19545445 | W18: 0 | X18: 0.11509249 | Y18: 13.609109 | Z18: 1.406248 | AA18: 12.334422 | AB18: 3.8403622 | AC18: 0.53667351 | AD18: 17.400932 | AE18: [-11059] No Good Data For Calculation | AF18: [-11059] No Good Data For Calculation | AG18: =IF(C18<DATE(2024,7,26), AD18, IF(AE18<100, AE18, AF18)) -> 17.400932 | AH18: 0.13421561 | AI18: 0.25872886 | AJ18: 0.017392332 | AK18: 0 | AL18: 0.033598835 | AM18: 3.6819185 | AN18: 2.9316745 | AO18: 3.8222159 | AP18: 1.3875976 | AQ18: 134.86678 | AR18: 49.264175 | AS18: 209.97872
C19: 45232 | D19: 45233 | E19: 0.41540537 | F19: 1.0856185 | G19: 1.4994117 | H19: 2.941562 | I19: 0 | J19: =IF(I19=0, "SD","RUN") -> SD | K19: 53.102895 | L19: =IF(J19="SD",0,K19) -> 0 | M19: 27.843224 | N19: =IF(M19=0,"SD","RUN") -> RUN | O19: 19.220084 | P19: =IF(N19="SD",0,O19) -> 19.220084 | Q19: =SUM(P19,L19) -> 19.220084 | R19: 4.121243 | S19: 15.435422 | T19: =IF(S19<0, 0, S19) -> 15.435422 | U19: =IF(G19<0.1, 0, (Q19/(G19*1000))*100) -> 1.2818417 | V19: =IF(G19<0.1, 0, IF(R19<=0,0,Q19*(R19/(R19+T19))/(G19*1000)*100)) -> 0.2701269 | W19: 0 | X19: 0.12231919 | Y19: 21.95054 | Z19: 47.087373 | AA19: 14.034701 | AB19: 0.38547371 | AC19: 0.56052622 | AD19: 65.283795 | AE19: [-11059] No Good Data For Calculation | AF19: [-11059] No Good Data For Calculation | AG19: =IF(C19<DATE(2024,7,26), AD19, IF(AE19<100, AE19, AF19)) -> 65.283795 | AH19: 0.079787532 | AI19: 0.33959375 | AJ19: 0.017969255 | AK19: 0 | AL19: 0.034713283 | AM19: 6.8746434 | AN19: 4.047266 | AO19: 6.7416916 | AP19: 77.00221 | AQ19: 246.96553 | AR19: 57.135665 | AS19: 216.01661
C20: 45233 | D20: 45234 | E20: 0.29384128 | F20: 0.91170245 | G20: 1.2056138 | H20: 4.6165885 | I20: 0 | J20: =IF(I20=0, "SD","RUN") -> SD | K20: 52.978508 | L20: =IF(J20="SD",0,K20) -> 0 | M20: 28.100384 | N20: =IF(M20=0,"SD","RUN") -> RUN | O20: 16.523808 | P20: =IF(N20="SD",0,O20) -> 16.523808 | Q20: =SUM(P20,L20) -> 16.523808 | R20: -1.2348965 | S20: 13.594059 | T20: =IF(S20<0, 0, S20) -> 13.594059 | U20: =IF(G20<0.1, 0, (Q20/(G20*1000))*100) -> 1.3705722 | V20: =IF(G20<0.1, 0, IF(R20<=0,0,Q20*(R20/(R20+T20))/(G20*1000)*100)) -> 0 | W20: 0 | X20: 0.10065575 | Y20: 24.821077 | Z20: 53.937231 | AA20: 20.097872 | AB20: 0.14155343 | AC20: 0.6911617 | AD20: 58.929466 | AE20: [-11059] No Good Data For Calculation | AF20: [-11059] No Good Data For Calculation | AG20: =IF(C20<DATE(2024,7,26), AD20, IF(AE20<100, AE20, AF20)) -> 58.929466 | AH20: 0.022453339 | AI20: 0.51056639 | AJ20: 0.019759483 | AK20: 0 | AL20: 0.038171729 | AM20: 9.4677218 | AN20: 5.5584621 | AO20: 8.6518028 | AP20: 89.773083 | AQ20: 307.03367 | AR20: 46.860272 | AS20: 220.68165
C21: 45234 | D21: 45235 | E21: 1.2677313 | F21: 2.1812192 | G21: 3.4469077 | H21: 7.0948369 | I21: 0 | J21: =IF(I21=0, "SD","RUN") -> SD | K21: 52.799775 | L21: =IF(J21="SD",0,K21) -> 0 | M21: 28.247882 | N21: =IF(M21=0,"SD","RUN") -> RUN | O21: 0.1176728 | P21: =IF(N21="SD",0,O21) -> 0.1176728 | Q21: =SUM(P21,L21) -> 0.1176728 | R21: -1.1895854 | S21: 13.475103 | T21: =IF(S21<0, 0, S21) -> 13.475103 | U21: =IF(G21<0.1, 0, (Q21/(G21*1000))*100) -> 0.0034138658 | V21: =IF(G21<0.1, 0, IF(R21<=0,0,Q21*(R21/(R21+T21))/(G21*1000)*100)) -> 0 | W21: 0 | X21: 0.10311178 | Y21: 22.48705 | Z21: 53.452753 | AA21: 19.54534 | AB21: 0.13118413 | AC21: 0.84485135 | AD21: 8.9294422 | AE21: [-11059] No Good Data For Calculation | AF21: [-11059] No Good Data For Calculation | AG21: =IF(C21<DATE(2024,7,26), AD21, IF(AE21<100, AE21, AF21)) -> 8.9294422 | AH21: 0.00049314476 | AI21: 0.4841587 | AJ21: 0.019473137 | AK21: 0 | AL21: 0.037618612 | AM21: 8.3949425 | AN21: 6.5213837 | AO21: 7.5288567 | AP21: 71.2305 | AQ21: 310.04664 | AR21: 46.945426 | AS21: 226.83182
C22: 45235 | D22: 45236 | E22: 2.5664515 | F22: 4.3360512 | G22: 6.9024656 | H22: 10.132482 | I22: 0 | J22: =IF(I22=0, "SD","RUN") -> SD | K22: 53.088524 | L22: =IF(J22="SD",0,K22) -> 0 | M22: 27.789095 | N22: =IF(M22=0,"SD","RUN") -> RUN | O22: 72.805161 | P22: =IF(N22="SD",0,O22) -> 72.805161 | Q22: =SUM(P22,L22) -> 72.805161 | R22: -1.18512 | S22: 12.987391 | T22: =IF(S22<0, 0, S22) -> 12.987391 | U22: =IF(G22<0.1, 0, (Q22/(G22*1000))*100) -> 1.0547704 | V22: =IF(G22<0.1, 0, IF(R22<=0,0,Q22*(R22/(R22+T22))/(G22*1000)*100)) -> 0 | W22: 0 | X22: 0.11251138 | Y22: 17.582819 | Z22: 52.177725 | AA22: 18.545506 | AB22: 0.14323991 | AC22: 0.52388758 | AD22: 11.130919 | AE22: [-11059] No Good Data For Calculation | AF22: [-11059] No Good Data For Calculation | AG22: =IF(C22<DATE(2024,7,26), AD22, IF(AE22<100, AE22, AF22)) -> 11.130919 | AH22: 0 | AI22: 0.47108772 | AJ22: 0.21726422 | AK22: 0 | AL22: 0.28959528 | AM22: 8.25519 | AN22: 7.2099563 | AO22: 8.6147793 | AP22: 87.066685 | AQ22: 306.32506 | AR22: 47.92187 | AS22: 226.51579
C23: 45236 | D23: 45237 | E23: 1.9328892 | F23: 3.3424359 | G23: 5.2749887 | H23: 7.1829344 | I23: 0 | J23: =IF(I23=0, "SD","RUN") -> SD | K23: 52.979009 | L23: =IF(J23="SD",0,K23) -> 0 | M23: 28.342896 | N23: =IF(M23=0,"SD","RUN") -> RUN | O23: 250.88991 | P23: =IF(N23="SD",0,O23) -> 250.88991 | Q23: =SUM(P23,L23) -> 250.88991 | R23: -1.2205317 | S23: 20.21168 | T23: =IF(S23<0, 0, S23) -> 20.21168 | U23: =IF(G23<0.1, 0, (Q23/(G23*1000))*100) -> 4.756217 | V23: =IF(G23<0.1, 0, IF(R23<=0,0,Q23*(R23/(R23+T23))/(G23*1000)*100)) -> 0 | W23: 0 | X23: 1.3316209 | Y23: 22.114912 | Z23: 53.150617 | AA23: 20.794586 | AB23: 0.1192537 | AC23: 0.53542292 | AD23: 19.798521 | AE23: [-11059] No Good Data For Calculation | AF23: [-11059] No Good Data For Calculation | AG23: =IF(C23<DATE(2024,7,26), AD23, IF(AE23<100, AE23, AF23)) -> 19.798521 | AH23: 0.00044437278 | AI23: 1.3715861 | AJ23: 6.2170174 | AK23: 0.26164183 | AL23: 4.4061148 | AM23: 9.3759637 | AN23: 8.1072975 | AO23: 9.5331666 | AP23: 87.550638 | AQ23: 335.77514 | AR23: 41.958694 | AS23: 224.00378
C24: 45237 | D24: 45238 | E24: 1.8780801 | F24: 3.5085052 | G24: 5.3862648 | H24: 7.0003496 | I24: 0 | J24: =IF(I24=0, "SD","RUN") -> SD | K24: 52.84412 | L24: =IF(J24="SD",0,K24) -> 0 | M24: 26.630454 | N24: =IF(M24=0,"SD","RUN") -> RUN | O24: 163.99604 | P24: =IF(N24="SD",0,O24) -> 163.99604 | Q24: =SUM(P24,L24) -> 163.99604 | R24: -1.2270392 | S24: 27.005671 | T24: =IF(S24<0, 0, S24) -> 27.005671 | U24: =IF(G24<0.1, 0, (Q24/(G24*1000))*100) -> 3.0447081 | V24: =IF(G24<0.1, 0, IF(R24<=0,0,Q24*(R24/(R24+T24))/(G24*1000)*100)) -> 0 | W24: 0.042816781 | X24: 9.6038379 | Y24: 19.339847 | Z24: 54.375758 | AA24: 21.09478 | AB24: 0.081843185 | AC24: 0.45176765 | AD24: 3.3998948 | AE24: [-11059] No Good Data For Calculation | AF24: [-11059] No Good Data For Calculation | AG24: =IF(C24<DATE(2024,7,26), AD24, IF(AE24<100, AE24, AF24)) -> 3.3998948 | AH24: 0 | AI24: 7.8183423 | AJ24: 8.2142556 | AK24: 0 | AL24: 4.7013932 | AM24: 9.1353194 | AN24: 8.7973942 | AO24: 9.7272967 | AP24: 86.552876 | AQ24: 351.3611 | AR24: 39.035652 | AS24: 227.10281
C25: 45238 | D25: 45239 | E25: 1.6689279 | F25: 3.8403011 | G25: 5.5079259 | H25: 6.9874513 | I25: 0 | J25: =IF(I25=0, "SD","RUN") -> SD | K25: 53.042644 | L25: =IF(J25="SD",0,K25) -> 0 | M25: 25.300917 | N25: =IF(M25=0,"SD","RUN") -> RUN | O25: 210.36627 | P25: =IF(N25="SD",0,O25) -> 210.36627 | Q25: =SUM(P25,L25) -> 210.36627 | R25: 6.9859032 | S25: 17.1952 | T25: =IF(S25<0, 0, S25) -> 17.1952 | U25: =IF(G25<0.1, 0, (Q25/(G25*1000))*100) -> 3.8193374 | V25: =IF(G25<0.1, 0, IF(R25<=0,0,Q25*(R25/(R25+T25))/(G25*1000)*100)) -> 1.1034038 | W25: 0.1786637 | X25: 15.203773 | Y25: 19.548326 | Z25: 52.419779 | AA25: 20.977642 | AB25: 0.10573707 | AC25: 0.4246428 | AD25: 10.557147 | AE25: [-11059] No Good Data For Calculation | AF25: [-11059] No Good Data For Calculation | AG25: =IF(C25<DATE(2024,7,26), AD25, IF(AE25<100, AE25, AF25)) -> 10.557147 | AH25: 0.0055051075 | AI25: 19.602021 | AJ25: 7.8203679 | AK25: 0 | AL25: 4.9281678 | AM25: 8.2459097 | AN25: 8.7341243 | AO25: 9.4163828 | AP25: 80.551904 | AQ25: 351.72782 | AR25: 41.049006 | AS25: 221.50279
... C36: 45249 | D36: 45250 | E36: 1.1792216 | F36: 2.0391616 | G36: 3.2183194 | H36: 7.1250403 | I36: 0 | J36: =IF(I36=0, "SD","RUN") -> SD | K36: 52.984082 | L36: =IF(J36="SD",0,K36) -> 0 | M36: 29.293515 | N36: =IF(M36=0,"SD","RUN") -> RUN | O36: 41.990107 | P36: =IF(N36="SD",0,O36) -> 41.990107 | Q36: =SUM(P36,L36) -> 41.990107 | R36: -1.2724196 | S36: 16.07359 | T36: =IF(S36<0, 0, S36) -> 16.07359 | U36: =IF(G36<0.1, 0, (Q36/(G36*1000))*100) -> 1.3047215 | V36: =IF(G36<0.1, 0, IF(R36<=0,0,Q36*(R36/(R36+T36))/(G36*1000)*100)) -> 0 | W36: 0 | X36: 26.760755 | Y36: 22.984222 | Z36: 52.058353 | AA36: 26.022052 | AB36: 0.11233336 | AC36: 0.53763237 | AD36: 7.3174139 | AE36: [-11059] No Good Data For Calculation | AF36: [-11059] No Good Data For Calculation | AG36: =IF(C36<DATE(2024,7,26), AD36, IF(AE36<100, AE36, AF36)) -> 7.3174139 | AH36: 13.908796 | AI36: 17.548598 | AJ36: 5.8163568 | AK36: 0 | AL36: 6.2298198 | AM36: 6.9476598 | AN36: 7.3869818 | AO36: 6.4390007 | AP36: 73.481366 | AQ36: 356.81858 | AR36: 44.744833 | AS36: 230.12822
C37: 45250 | D37: 45251 | E37: 1.2416783 | F37: 2.1029138 | G37: 3.3451025 | H37: 7.2333247 | I37: 0 | J37: =IF(I37=0, "SD","RUN") -> SD | K37: 53.250356 | L37: =IF(J37="SD",0,K37) -> 0 | M37: 29.62911 | N37: =IF(M37=0,"SD","RUN") -> RUN | O37: 41.07668 | P37: =IF(N37="SD",0,O37) -> 41.07668 | Q37: =SUM(P37,L37) -> 41.07668 | R37: -1.2892796 | S37: 15.682013 | T37: =IF(S37<0, 0, S37) -> 15.682013 | U37: =IF(G37<0.1, 0, (Q37/(G37*1000))*100) -> 1.2279647 | V37: =IF(G37<0.1, 0, IF(R37<=0,0,Q37*(R37/(R37+T37))/(G37*1000)*100)) -> 0 | W37: 0 | X37: [-11059] No Good Data For Calculation | Y37: 19.872601 | Z37: 52.020137 | AA37: 28.066315 | AB37: 0.10933207 | AC37: 0.56976378 | AD37: 6.2684743 | AE37: [-11059] No Good Data For Calculation | AF37: [-11059] No Good Data For Calculation | AG37: =IF(C37<DATE(2024,7,26), AD37, IF(AE37<100, AE37, AF37)) -> 6.2684743 | AH37: [-11059] No Good Data For Calculation | AI37: [-11059] No Good Data For Calculation | AJ37: 4.8008 | AK37: 0 | AL37: 5.4058115 | AM37: 6.5081867 | AN37: 7.0617828 | AO37: 5.9663789 | AP37: 72.845727 | AQ37: 368.8054 | AR37: 42.900949 | AS37: 229.72487
C38: 45251 | D38: 45252 | E38: 0.45002062 | F38: 2.7768884 | G38: 3.2261886 | H38: 7.4566931 | I38: 0 | J38: =IF(I38=0, "SD","RUN") -> SD | K38: 53.278901 | L38: =IF(J38="SD",0,K38) -> 0 | M38: 29.093465 | N38: =IF(M38=0,"SD","RUN") -> RUN | O38: 60.210938 | P38: =IF(N38="SD",0,O38) -> 60.210938 | Q38: =SUM(P38,L38) -> 60.210938 | R38: -1.2920104 | S38: 18.041795 | T38: =IF(S38<0, 0, S38) -> 18.041795 | U38: =IF(G38<0.1, 0, (Q38/(G38*1000))*100) -> 1.866318 | V38: =IF(G38<0.1, 0, IF(R38<=0,0,Q38*(R38/(R38+T38))/(G38*1000)*100)) -> 0 | W38: 0.0056255625 | X38: [-11059] No Good Data For Calculation | Y38: 17.874741 | Z38: 50.411773 | AA38: 27.725195 | AB38: 0.10528211 | AC38: 0.53828045 | AD38: 5.8928645 | AE38: [-11059] No Good Data For Calculation | AF38: [-11059] No Good Data For Calculation | AG38: =IF(C38<DATE(2024,7,26), AD38, IF(AE38<100, AE38, AF38)) -> 5.8928645 | AH38: [-11059] No Good Data For Calculation | AI38: [-11059] No Good Data For Calculation | AJ38: 4.0298311 | AK38: 0 | AL38: 4.8142976 | AM38: 6.4571974 | AN38: 6.7838569 | AO38: 6.0635086 | AP38: 73.144997 | AQ38: 385.82835 | AR38: 42.709574 | AS38: 229.7923
C39: 45252 | D39: 45253 | E39: 0.0038244139 | F39: 3.3216217 | G39: 3.3242483 | H39: 7.2607677 | I39: 0 | J39: =IF(I39=0, "SD","RUN") -> SD | K39: 59.854535 | L39: =IF(J39="SD",0,K39) -> 0 | M39: 31.068427 | N39: =IF(M39=0,"SD","RUN") -> RUN | O39: 68.87073 | P39: =IF(N39="SD",0,O39) -> 68.87073 | Q39: =SUM(P39,L39) -> 68.87073 | R39: -1.2873274 | S39: 18.515888 | T39: =IF(S39<0, 0, S39) -> 18.515888 | U39: =IF(G39<0.1, 0, (Q39/(G39*1000))*100) -> 2.0717685 | V39: =IF(G39<0.1, 0, IF(R39<=0,0,Q39*(R39/(R39+T39))/(G39*1000)*100)) -> 0 | W39: 0 | X39: [-11059] No Good Data For Calculation | Y39: 15.594937 | Z39: 50.857958 | AA39: 27.492986 | AB39: 0.10901655 | AC39: 0.53879977 | AD39: 7.3177715 | AE39: [-11059] No Good Data For Calculation | AF39: [-11059] No Good Data For Calculation | AG39: =IF(C39<DATE(2024,7,26), AD39, IF(AE39<100, AE39, AF39)) -> 7.3177715 | AH39: [-11059] No Good Data For Calculation | AI39: [-11059] No Good Data For Calculation | AJ39: 3.7096707 | AK39: 0 | AL39: 4.0501607 | AM39: 6.1396623 | AN39: 6.5343021 | AO39: 5.7732089 | AP39: 73.103712 | AQ39: 376.42955 | AR39: 42.454755 | AS39: 225.47685
C40: 45253 | D40: 45254 | E40: 0.0031028116 | F40: 3.3311101 | G40: 3.3343362 | H40: 6.7329317 | I40: 0 | J40: =IF(I40=0, "SD","RUN") -> SD | K40: 53.170195 | L40: =IF(J40="SD",0,K40) -> 0 | M40: 31.277352 | N40: =IF(M40=0,"SD","RUN") -> RUN | O40: 83.699081 | P40: =IF(N40="SD",0,O40) -> 83.699081 | Q40: =SUM(P40,L40) -> 83.699081 | R40: -1.2393491 | S40: 24.729807 | T40: =IF(S40<0, 0, S40) -> 24.729807 | U40: =IF(G40<0.1, 0, (Q40/(G40*1000))*100) -> 2.5102172 | V40: =IF(G40<0.1, 0, IF(R40<=0,0,Q40*(R40/(R40+T40))/(G40*1000)*100)) -> 0 | W40: 0.0055213856 | X40: [-11059] No Good Data For Calculation | Y40: 21.036543 | Z40: 51.43934 | AA40: 28.898222 | AB40: 0.10950929 | AC40: 0.89333291 | AD40: 4.5237413 | AE40: [-11059] No Good Data For Calculation | AF40: [-11059] No Good Data For Calculation | AG40: =IF(C40<DATE(2024,7,26), AD40, IF(AE40<100, AE40, AF40)) -> 4.5237413 | AH40: [-11059] No Good Data For Calculation | AI40: [-11059] No Good Data For Calculation | AJ40: 4.7826547 | AK40: 0 | AL40: 5.0108149 | AM40: 6.6898577 | AN40: 7.2822514 | AO40: 6.450079 | AP40: 73.104624 | AQ40: 342.68975 | AR40: 42.957336 | AS40: 225.49807
C41: 45254 | D41: 45255 | E41: -0.00023437499 | F41: 3.2461636 | G41: 3.2489113 | H41: 6.6779814 | I41: 0 | J41: =IF(I41=0, "SD","RUN") -> SD | K41: 53.227973 | L41: =IF(J41="SD",0,K41) -> 0 | M41: 33.073271 | N41: =IF(M41=0,"SD","RUN") -> RUN | O41: 86.233975 | P41: =IF(N41="SD",0,O41) -> 86.233975 | Q41: =SUM(P41,L41) -> 86.233975 | R41: -1.2565604 | S41: 26.767905 | T41: =IF(S41<0, 0, S41) -> 26.767905 | U41: =IF(G41<0.1, 0, (Q41/(G41*1000))*100) -> 2.6542422 | V41: =IF(G41<0.1, 0, IF(R41<=0,0,Q41*(R41/(R41+T41))/(G41*1000)*100)) -> 0 | W41: 0.023648197 | X41: [-11059] No Good Data For Calculation | Y41: 24.235428 | Z41: 52.818994 | AA41: 29.935962 | AB41: 0.10947948 | AC41: 0.89122609 | AD41: 4.9056596 | AE41: [-11059] No Good Data For Calculation | AF41: [-11059] No Good Data For Calculation | AG41: =IF(C41<DATE(2024,7,26), AD41, IF(AE41<100, AE41, AF41)) -> 4.9056596 | AH41: [-11059] No Good Data For Calculation | AI41: [-11059] No Good Data For Calculation | AJ41: 4.5899028 | AK41: 0 | AL41: 5.1593947 | AM41: 6.885025 | AN41: 7.7705632 | AO41: 6.6343784 | AP41: 73.828112 | AQ41: 336.2273 | AR41: 44.121658 | AS41: 226.91032
C42: 45255 | D42: 45256 | E42: 5.7235512e-05 | F42: 3.2416216 | G42: 3.2431493 | H42: 6.6568498 | I42: 0 | J42: =IF(I42=0, "SD","RUN") -> SD | K42: 53.309137 | L42: =IF(J42="SD",0,K42) -> 0 | M42: 30.482957 | N42: =IF(M42=0,"SD","RUN") -> RUN | O42: 89.929761 | P42: =IF(N42="SD",0,O42) -> 89.929761 | Q42: =SUM(P42,L42) -> 89.929761 | R42: -1.260378 | S42: 22.851427 | T42: =IF(S42<0, 0, S42) -> 22.851427 | U42: =IF(G42<0.1, 0, (Q42/(G42*1000))*100) -> 2.7729146 | V42: =IF(G42<0.1, 0, IF(R42<=0,0,Q42*(R42/(R42+T42))/(G42*1000)*100)) -> 0 | W42: 0.0053130314 | X42: [-11059] No Good Data For Calculation | Y42: 24.378041 | Z42: 52.68706 | AA42: 30.243065 | AB42: 0.10350153 | AC42: 0.93872861 | AD42: 2.1636642 | AE42: [-11059] No Good Data For Calculation | AF42: [-11059] No Good Data For Calculation | AG42: =IF(C42<DATE(2024,7,26), AD42, IF(AE42<100, AE42, AF42)) -> 2.1636642 | AH42: [-11059] No Good Data For Calculation | AI42: [-11059] No Good Data For Calculation | AJ42: 4.7615911 | AK42: 0 | AL42: 5.2113166 | AM42: 6.920198 | AN42: 8.1927118 | AO42: 6.6920031 | AP42: 73.755481 | AQ42: 336.91204 | AR42: 44.096768 | AS42: 226.1712
C43: 45256 | D43: 45257 | E43: 0.0077322601 | F43: 5.7241478 | G43: 5.7298508 | H43: 5.1909058 | I43: 0 | J43: =IF(I43=0, "SD","RUN") -> SD | K43: 53.283267 | L43: =IF(J43="SD",0,K43) -> 0 | M43: 28.230419 | N43: =IF(M43=0,"SD","RUN") -> RUN | O43: 38.209022 | P43: =IF(N43="SD",0,O43) -> 38.209022 | Q43: =SUM(P43,L43) -> 38.209022 | R43: -1.2915568 | S43: 12.902924 | T43: =IF(S43<0, 0, S43) -> 12.902924 | U43: =IF(G43<0.1, 0, (Q43/(G43*1000))*100) -> 0.66684148 | V43: =IF(G43<0.1, 0, IF(R43<=0,0,Q43*(R43/(R43+T43))/(G43*1000)*100)) -> 0 | W43: 0 | X43: [-11059] No Good Data For Calculation | Y43: 24.514506 | Z43: 52.170634 | AA43: 21.823076 | AB43: -0.025490431 | AC43: 0.69893669 | AD43: 0.9410248 | AE43: [-11059] No Good Data For Calculation | AF43: [-11059] No Good Data For Calculation | AG43: =IF(C43<DATE(2024,7,26), AD43, IF(AE43<100, AE43, AF43)) -> 0.9410248 | AH43: [-11059] No Good Data For Calculation | AI43: [-11059] No Good Data For Calculation | AJ43: 5.56902 | AK43: 0 | AL43: 5.8666765 | AM43: 7.4054702 | AN43: 7.8538017 | AO43: 7.1996063 | AP43: 73.929751 | AQ43: 282.27484 | AR43: 4.9208965 | AS43: 222.72205
C44: 45257 | D44: 45258 | E44: 0.0080859372 | F44: 5.9966314 | G44: 5.9945479 | H44: 5.4989298 | I44: 0 | J44: =IF(I44=0, "SD","RUN") -> SD | K44: 53.266542 | L44: =IF(J44="SD",0,K44) -> 0 | M44: 27.18557 | N44: =IF(M44=0,"SD","RUN") -> RUN | O44: 43.886832 | P44: =IF(N44="SD",0,O44) -> 43.886832 | Q44: =SUM(P44,L44) -> 43.886832 | R44: -1.2471061 | S44: 13.928642 | T44: =IF(S44<0, 0, S44) -> 13.928642 | U44: =IF(G44<0.1, 0, (Q44/(G44*1000))*100) -> 0.73211246 | V44: =IF(G44<0.1, 0, IF(R44<=0,0,Q44*(R44/(R44+T44))/(G44*1000)*100)) -> 0 | W44: 0.016564156 | X44: [-11059] No Good Data For Calculation | Y44: 18.440654 | Z44: 51.053398 | AA44: 20.857099 | AB44: -0.027896179 | AC44: 0.55746565 | AD44: 1.9926543 | AE44: [-11059] No Good Data For Calculation | AF44: [-11059] No Good Data For Calculation | AG44: =IF(C44<DATE(2024,7,26), AD44, IF(AE44<100, AE44, AF44)) -> 1.9926543 | AH44: [-11059] No Good Data For Calculation | AI44: [-11059] No Good Data For Calculation | AJ44: 4.7254163 | AK44: 0 | AL44: 4.9135863 | AM44: 7.1358819 | AN44: 7.1968569 | AO44: 7.3058643 | AP44: 74.44644 | AQ44: 295.07216 | AR44: 1.2441472 | AS44: 211.97568
C45: 45258 | D45: 45259 | E45: 0.0058999021 | F45: 5.9402373 | G45: 5.9415261 | H45: 5.0423824 | I45: 0 | J45: =IF(I45=0, "SD","RUN") -> SD | K45: 53.336823 | L45: =IF(J45="SD",0,K45) -> 0 | M45: 25.990857 | N45: =IF(M45=0,"SD","RUN") -> RUN | O45: 42.128883 | P45: =IF(N45="SD",0,O45) -> 42.128883 | Q45: =SUM(P45,L45) -> 42.128883 | R45: -1.3138318 | S45: 17.405706 | T45: =IF(S45<0, 0, S45) -> 17.405706 | U45: =IF(G45<0.1, 0, (Q45/(G45*1000))*100) -> 0.70905829 | V45: =IF(G45<0.1, 0, IF(R45<=0,0,Q45*(R45/(R45+T45))/(G45*1000)*100)) -> 0 | W45: 0.017605927 | X45: [-11059] No Good Data For Calculation | Y45: 17.155095 | Z45: 50.897937 | AA45: 21.008567 | AB45: -0.03641158 | AC45: 0.66792041 | AD45: 4.6357308 | AE45: [-11059] No Good Data For Calculation | AF45: [-11059] No Good Data For Calculation | AG45: =IF(C45<DATE(2024,7,26), AD45, IF(AE45<100, AE45, AF45)) -> 4.6357308 | AH45: [-11059] No Good Data For Calculation | AI45: [-11059] No Good Data For Calculation | AJ45: 4.6101687 | AK45: 0 | AL45: 4.4649293 | AM45: 7.235638 | AN45: 8.0116459 | AO45: 7.5233346 | AP45: 72.669926 | AQ45: 268.33932 | AR45: 1.3429975 | AS45: 220.02209
C46: 45259 | D46: 45260 | E46: 0.76556849 | F46: 4.3320948 | G46: 5.1467975 | H46: 5.115317 | I46: 0 | J46: =IF(I46=0, "SD","RUN") -> SD | K46: 53.448493 | L46: =IF(J46="SD",0,K46) -> 0 | M46: 26.448961 | N46: =IF(M46=0,"SD","RUN") -> RUN | O46: 59.82647 | P46: =IF(N46="SD",0,O46) -> 59.82647 | Q46: =SUM(P46,L46) -> 59.82647 | R46: 3.379618 | S46: 11.105211 | T46: =IF(S46<0, 0, S46) -> 11.105211 | U46: =IF(G46<0.1, 0, (Q46/(G46*1000))*100) -> 1.1624019 | V46: =IF(G46<0.1, 0, IF(R46<=0,0,Q46*(R46/(R46+T46))/(G46*1000)*100)) -> 0.27121302 | W46: 0 | X46: [-11059] No Good Data For Calculation | Y46: 18.658219 | Z46: 50.181049 | AA46: 20.227727 | AB46: -0.0369958 | AC46: 0.52307409 | AD46: 1.6865821 | AE46: [-11059] No Good Data For Calculation | AF46: [-11059] No Good Data For Calculation | AG46: =IF(C46<DATE(2024,7,26), AD46, IF(AE46<100, AE46, AF46)) -> 1.6865821 | AH46: [-11059] No Good Data For Calculation | AI46: [-11059] No Good Data For Calculation | AJ46: 5.1386279 | AK46: 0 | AL46: 4.7911587 | AM46: 7.25024 | AN46: 8.1533922 | AO46: 7.5666741 | AP46: 71.828622 | AQ46: 274.26348 | AR46: 1.4003243 | AS46: 209.46967
C47: 45260 | D47: 45261 | E47: 1.5576356 | F47: 2.9530015 | G47: 4.5110604 | H47: 4.9819479 | I47: 0 | J47: =IF(I47=0, "SD","RUN") -> SD | K47: 53.262836 | L47: =IF(J47="SD",0,K47) -> 0 | M47: 26.782748 | N47: =IF(M47=0,"SD","RUN") -> RUN | O47: 63.020862 | P47: =IF(N47="SD",0,O47) -> 63.020862 | Q47: =SUM(P47,L47) -> 63.020862 | R47: -1.2935824 | S47: 13.194248 | T47: =IF(S47<0, 0, S47) -> 13.194248 | U47: =IF(G47<0.1, 0, (Q47/(G47*1000))*100) -> 1.3970299 | V47: =IF(G47<0.1, 0, IF(R47<=0,0,Q47*(R47/(R47+T47))/(G47*1000)*100)) -> 0 | W47: 0.019277969 | X47: [-11059] No Good Data For Calculation | Y47: 19.141042 | Z47: 50.370064 | AA47: 20.090236 | AB47: -0.035783698 | AC47: 0.46076791 | AD47: 0.76255062 | AE47: [-11059] No Good Data For Calculation | AF47: [-11059] No Good Data For Calculation | AG47: =IF(C47<DATE(2024,7,26), AD47, IF(AE47<100, AE47, AF47)) -> 0.76255062 | AH47: [-11059] No Good Data For Calculation | AI47: [-11059] No Good Data For Calculation | AJ47: 5.1568589 | AK47: 0 | AL47: 4.7889435 | AM47: 7.2062698 | AN47: 8.3851039 | AO47: 7.5661458 | AP47: 72.137931 | AQ47: 266.60991 | AR47: 1.5216407 | AS47: 194.11148
C48: 45261 | D48: 45262 | E48: 0.0062109372 | F48: 5.3432386 | G48: 5.3453884 | H48: 4.8992283 | I48: 0 | J48: =IF(I48=0, "SD","RUN") -> SD | K48: 53.419016 | L48: =IF(J48="SD",0,K48) -> 0 | M48: 26.94622 | N48: =IF(M48=0,"SD","RUN") -> RUN | O48: 94.027524 | P48: =IF(N48="SD",0,O48) -> 94.027524 | Q48: =SUM(P48,L48) -> 94.027524 | R48: 1.1933214 | S48: 21.496742 | T48: =IF(S48<0, 0, S48) -> 21.496742 | U48: =IF(G48<0.1, 0, (Q48/(G48*1000))*100) -> 1.7590401 | V48: =IF(G48<0.1, 0, IF(R48<=0,0,Q48*(R48/(R48+T48))/(G48*1000)*100)) -> 0.092511869 | W48: 0 | X48: [-11059] No Good Data For Calculation | Y48: 18.712797 | Z48: 50.480635 | AA48: 20.321875 | AB48: 2.2187735 | AC48: 0.48958343 | AD48: 1.3694498 | AE48: [-11059] No Good Data For Calculation | AF48: [-11059] No Good Data For Calculation | AG48: =IF(C48<DATE(2024,7,26), AD48, IF(AE48<100, AE48, AF48)) -> 1.3694498 | AH48: [-11059] No Good Data For Calculation | AI48: [-11059] No Good Data For Calculation | AJ48: 4.7154094 | AK48: 0 | AL48: 4.461966 | AM48: 7.1247813 | AN48: 8.3459865 | AO48: 7.5403072 | AP48: 72.298345 | AQ48: 272.28225 | AR48: 4.2475351 | AS48: 194.50485
... C187: 45400 | D187: 45401 | E187: 0.59817589 | F187: 1.8871625 | G187: 2.4840765 | H187: 29.107157 | I187: 0 | J187: =IF(I187=0, "SD","RUN") -> SD | K187: 142.00885 | L187: =IF(J187="SD",0,K187) -> 0 | M187: 21.490341 | N187: =IF(M187=0,"SD","RUN") -> RUN | O187: 3.7148522 | P187: =IF(N187="SD",0,O187) -> 3.7148522 | Q187: =SUM(P187,L187) -> 3.7148522 | R187: -1.2568359 | S187: 14.55889 | T187: =IF(S187<0, 0, S187) -> 14.55889 | U187: =IF(G187<0.1, 0, (Q187/(G187*1000))*100) -> 0.14954661 | V187: =IF(G187<0.1, 0, IF(R187<=0,0,Q187*(R187/(R187+T187))/(G187*1000)*100)) -> 0 | W187: 0 | X187: [-11059] No Good Data For Calculation | Y187: 4.2386194 | Z187: 48.74397 | AA187: 22.647055 | AB187: 0.16822295 | AC187: 0.44887848 | AD187: 24.085454 | AE187: [-11059] No Good Data For Calculation | AF187: [-11059] No Good Data For Calculation | AG187: =IF(C187<DATE(2024,7,26), AD187, IF(AE187<100, AE187, AF187)) -> 24.085454 | AH187: [-11059] No Good Data For Calculation | AI187: [-11059] No Good Data For Calculation | AJ187: 0.0094470388 | AK187: 0 | AL187: 0.05620988 | AM187: 6.1853191 | AN187: 6.4168917 | AO187: 6.4387367 | AP187: 75.163599 | AQ187: 405.65924 | AR187: 53.523426 | AS187: 155.34774
C188: 45401 | D188: 45402 | E188: 0.83243074 | F188: 2.1425874 | G188: 2.9753948 | H188: 29.107157 | I188: 0 | J188: =IF(I188=0, "SD","RUN") -> SD | K188: 112.27655 | L188: =IF(J188="SD",0,K188) -> 0 | M188: 21.510788 | N188: =IF(M188=0,"SD","RUN") -> RUN | O188: 6.2545528 | P188: =IF(N188="SD",0,O188) -> 6.2545528 | Q188: =SUM(P188,L188) -> 6.2545528 | R188: -1.2568359 | S188: 15.131432 | T188: =IF(S188<0, 0, S188) -> 15.131432 | U188: =IF(G188<0.1, 0, (Q188/(G188*1000))*100) -> 0.21020917 | V188: =IF(G188<0.1, 0, IF(R188<=0,0,Q188*(R188/(R188+T188))/(G188*1000)*100)) -> 0 | W188: 0.0061464479 | X188: [-11059] No Good Data For Calculation | Y188: 4.1554457 | Z188: 47.993663 | AA188: 22.752388 | AB188: 0.15714483 | AC188: 0.38220584 | AD188: 34.246861 | AE188: [-11059] No Good Data For Calculation | AF188: [-11059] No Good Data For Calculation | AG188: =IF(C188<DATE(2024,7,26), AD188, IF(AE188<100, AE188, AF188)) -> 34.246861 | AH188: [-11059] No Good Data For Calculation | AI188: 48.352957 | AJ188: 0.0096316336 | AK188: 0 | AL188: 0.05730821 | AM188: 6.3208528 | AN188: 6.4119601 | AO188: 6.404995 | AP188: 76.076431 | AQ188: 407.26746 | AR188: 51.96346 | AS188: 160.17689
...

Sheet 2
A1: Start Time | B1: ='1'!B1 -> 45220
A2: End Time | B2: ='1'!B2 -> 46101
C4: Start Time | D4: End Time | E4: Mixpot 3-hr Rolling Avg H2S | F4: >162 Check
E5: MTZ.RF.5GP.Fuel Gas Mixpot.H2S Conc.3HAvg
E6: ppm
C7: {=_xll.PIAdvCalcDat('2'!$E$5,'2'!$B$1,'2'!$B$2,"1h","average (time-weighted)","time-weighted",0,1,193,"\\PI-MTZ")} -> 45220 | D7: 45220.042 | E7: 0 | F7: =IF(E7="[-11059] No Good Data For Calculation", "", IF(E7<162, "NO", "YES")) -> NO
C8: 45220.042 | D8: 45220.083 | E8: 0 | F8: =IF(E8="[-11059] No Good Data For Calculation", "", IF(E8<162, "NO", "YES")) -> NO
C9: 45220.083 | D9: 45220.125 | E9: 0 | F9: =IF(E9="[-11059] No Good Data For Calculation", "", IF(E9<162, "NO", "YES")) -> NO
C10: 45220.125 | D10: 45220.167 | E10: 0 | F10: =IF(E10="[-11059] No Good Data For Calculation", "", IF(E10<162, "NO", "YES")) -> NO
C11: 45220.167 | D11: 45220.208 | E11: 0 | F11: =IF(E11="[-11059] No Good Data For Calculation", "", IF(E11<162, "NO", "YES")) -> NO
C12: 45220.208 | D12: 45220.25 | E12: 0 | F12: =IF(E12="[-11059] No Good Data For Calculation", "", IF(E12<162, "NO", "YES")) -> NO
C13: 45220.25 | D13: 45220.292 | E13: 0 | F13: =IF(E13="[-11059] No Good Data For Calculation", "", IF(E13<162, "NO", "YES")) -> NO
C14: 45220.292 | D14: 45220.333 | E14: 0 | F14: =IF(E14="[-11059] No Good Data For Calculation", "", IF(E14<162, "NO", "YES")) -> NO
C15: 45220.333 | D15: 45220.375 | E15: 0 | F15: =IF(E15="[-11059] No Good Data For Calculation", "", IF(E15<162, "NO", "YES")) -> NO
C16: 45220.375 | D16: 45220.417 | E16: 0 | F16: =IF(E16="[-11059] No Good Data For Calculation", "", IF(E16<162, "NO", "YES")) -> NO
C17: 45220.417 | D17: 45220.458 | E17: 0 | F17: =IF(E17="[-11059] No Good Data For Calculation", "", IF(E17<162, "NO", "YES")) -> NO
C18: 45220.458 | D18: 45220.5 | E18: 0 | F18: =IF(E18="[-11059] No Good Data For Calculation", "", IF(E18<162, "NO", "YES")) -> NO
C19: 45220.5 | D19: 45220.542 | E19: 0 | F19: =IF(E19="[-11059] No Good Data For Calculation", "", IF(E19<162, "NO", "YES")) -> NO
... C19673: 46039.375 | D19673: 46039.417 | E19673: 0 | F19673: =IF(E19673="[-11059] No Good Data For Calculation", "", IF(E19673<162, "NO", "YES")) -> NO
C19674: 46039.417 | D19674: 46039.458 | E19674: [-11059] No Good Data For Calculation | F19674: =IF(E19674="[-11059] No Good Data For Calculation", "", IF(E19674<162, "NO", "YES"))
C19675: 46039.458 | D19675: 46039.5 | E19675: [-11059] No Good Data For Calculation | F19675: =IF(E19675="[-11059] No Good Data For Calculation", "", IF(E19675<162, "NO", "YES"))
C19676: 46039.5 | D19676: 46039.542 | E19676: [-11059] No Good Data For Calculation | F19676: =IF(E19676="[-11059] No Good Data For Calculation", "", IF(E19676<162, "NO", "YES"))
C19677: 46039.542 | D19677: 46039.583 | E19677: [-11059] No Good Data For Calculation | F19677: =IF(E19677="[-11059] No Good Data For Calculation", "", IF(E19677<162, "NO", "YES"))
C19678: 46039.583 | D19678: 46039.625 | E19678: [-11059] No Good Data For Calculation | F19678: =IF(E19678="[-11059] No Good Data For Calculation", "", IF(E19678<162, "NO", "YES"))
C19679: 46039.625 | D19679: 46039.667 | E19679: [-11059] No Good Data For Calculation | F19679: =IF(E19679="[-11059] No Good Data For Calculation", "", IF(E19679<162, "NO", "YES"))
C19680: 46039.667 | D19680: 46039.708 | E19680: [-11059] No Good Data For Calculation | F19680: =IF(E19680="[-11059] No Good Data For Calculation", "", IF(E19680<162, "NO", "YES"))
C19681: 46039.708 | D19681: 46039.75 | E19681: [-11059] No Good Data For Calculation | F19681: =IF(E19681="[-11059] No Good Data For Calculation", "", IF(E19681<162, "NO", "YES"))
C19682: 46039.75 | D19682: 46039.792 | E19682: [-11059] No Good Data For Calculation | F19682: =IF(E19682="[-11059] No Good Data For Calculation", "", IF(E19682<162, "NO", "YES"))
C19683: 46039.792 | D19683: 46039.833 | E19683: [-11059] No Good Data For Calculation | F19683: =IF(E19683="[-11059] No Good Data For Calculation", "", IF(E19683<162, "NO", "YES"))
C19684: 46039.833 | D19684: 46039.875 | E19684: [-11059] No Good Data For Calculation | F19684: =IF(E19684="[-11059] No Good Data For Calculation", "", IF(E19684<162, "NO", "YES"))
C19685: 46039.875 | D19685: 46039.917 | E19685: [-11059] No Good Data For Calculation | F19685: =IF(E19685="[-11059] No Good Data For Calculation", "", IF(E19685<162, "NO", "YES"))
... C19824: 46045.667 | D19824: 46045.708 | E19824: [-11059] No Good Data For Calculation | F19824: =IF(E19824="[-11059] No Good Data For Calculation", "", IF(E19824<162, "NO", "YES"))
C19825: 46045.708 | D19825: 46045.75 | E19825: 0 | F19825: =IF(E19825="[-11059] No Good Data For Calculation", "", IF(E19825<162, "NO", "YES")) -> NO
C19826: 46045.75 | D19826: 46045.792 | E19826: 0 | F19826: =IF(E19826="[-11059] No Good Data For Calculation", "", IF(E19826<162, "NO", "YES")) -> NO
C19827: 46045.792 | D19827: 46045.833 | E19827: 0 | F19827: =IF(E19827="[-11059] No Good Data For Calculation", "", IF(E19827<162, "NO", "YES")) -> NO
C19828: 46045.833 | D19828: 46045.875 | E19828: 0 | F19828: =IF(E19828="[-11059] No Good Data For Calculation", "", IF(E19828<162, "NO", "YES")) -> NO
C19829: 46045.875 | D19829: 46045.917 | E19829: 0 | F19829: =IF(E19829="[-11059] No Good Data For Calculation", "", IF(E19829<162, "NO", "YES")) -> NO
C19830: 46045.917 | D19830: 46045.958 | E19830: 0 | F19830: =IF(E19830="[-11059] No Good Data For Calculation", "", IF(E19830<162, "NO", "YES")) -> NO
C19831: 46045.958 | D19831: 46046 | E19831: 0 | F19831: =IF(E19831="[-11059] No Good Data For Calculation", "", IF(E19831<162, "NO", "YES")) -> NO
C19832: 46046 | D19832: 46046.042 | E19832: 0 | F19832: =IF(E19832="[-11059] No Good Data For Calculation", "", IF(E19832<162, "NO", "YES")) -> NO
...

Sheet 3
A1: Start Time | B1: 37721
A2: End Time | B2: 45220 | E2: 9.167226
C3: Daily | G3: Annual
D4: MAX: | E4: =MAX(E8:E7506) -> 9.167226 | H4: MAX: | I4: =MAX(I8:I29) -> 4.1591122
C5: Start Time | D5: End Time | E5: Recovered Flare Gas Flow | G5: Start Time | H5: End Time | I5: Total Recovered Flare Gas Amount
E6: 019:F1164 | I6: 019:F1164
E7: MMSCFD | I7: MMSCFD
C8: {=_xll.PIAdvCalcDat('3'!$E$6,'3'!$B$1,'3'!$B$2,"1d","average (time-weighted)","time-weighted",0,1,193,"\\PI-MTZ")} -> 37721 | D8: 37722 | E8: 2.2666951 | G8: {=_xll.PIAdvCalcDat('3'!$I$6,"1/1/2004","1/1/2026","1y","average (time-weighted)","time-weighted",0,1,193,"\\PI-MTZ")} -> 37987 | H8: 38353 | I8: 2.5202894
C9: 37722 | D9: 37723 | E9: 2.8659551 | G9: 38353 | H9: 38718 | I9: 3.7260795
C10: 37723 | D10: 37724 | E10: 2.0560954 | G10: 38718 | H10: 39083 | I10: 3.2884908
C11: 37724 | D11: 37725 | E11: 2.7256824 | G11: 39083 | H11: 39448 | I11: 2.7737283
C12: 37725 | D12: 37726 | E12: 2.9324955 | G12: 39448 | H12: 39814 | I12: 2.7491995
C13: 37726 | D13: 37727 | E13: 1.4573105 | G13: 39814 | H13: 40179 | I13: 3.138853
C14: 37727 | D14: 37728 | E14: 2.5789267 | G14: 40179 | H14: 40544 | I14: 3.607999
C15: 37728 | D15: 37729 | E15: 2.7095792 | G15: 40544 | H15: 40909 | I15: 3.3990073
C16: 37729 | D16: 37730 | E16: 1.6675961 | G16: 40909 | H16: 41275 | I16: 4.1591122
C17: 37730 | D17: 37731 | E17: 3.3990857 | G17: 41275 | H17: 41640 | I17: 3.5462701
C18: 37731 | D18: 37732 | E18: 3.6532364 | G18: 41640 | H18: 42005 | I18: 2.7029977
C19: 37732 | D19: 37733 | E19: 3.1994652 | G19: 42005 | H19: 42370 | I19: 2.618923
C20: 37733 | D20: 37734 | E20: 2.1685994 | G20: 42370 | H20: 42736 | I20: 2.4109989
... C29: 37742 | D29: 37743 | E29: 4.0104601 | G29: 45658 | H29: 46023 | I29: 3.8120022
C30: 37743 | D30: 37744 | E30: 3.3233867
C31: 37744 | D31: 37745 | E31: 2.4959446
C32: 37745 | D32: 37746 | E32: 2.6337973
C33: 37746 | D33: 37747 | E33: 2.636227
C34: 37747 | D34: 37748 | E34: 2.6342164
C35: 37748 | D35: 37749 | E35: 2.5763553
C36: 37749 | D36: 37750 | E36: 2.5890853
C37: 37750 | D37: 37751 | E37: 2.5509143
C38: 37751 | D38: 37752 | E38: 2.4675561
C39: 37752 | D39: 37753 | E39: 2.5017733
C40: 37753 | D40: 37754 | E40: 2.5224909
C41: 37754 | D41: 37755 | E41: 2.5383783
... C551: 38264 | D551: 38265 | E551: 0.0030213296
C552: 38265 | D552: 38266 | E552: [-11059] No Good Data For Calculation
C553: 38266 | D553: 38267 | E553: [-11059] No Good Data For Calculation
C554: 38267 | D554: 38268 | E554: [-11059] No Good Data For Calculation
C555: 38268 | D555: 38269 | E555: [-11059] No Good Data For Calculation
C556: 38269 | D556: 38270 | E556: [-11059] No Good Data For Calculation
C557: 38270 | D557: 38271 | E557: 0.005021629
...
